Workbook

Sheet khachhang
A1: name | B1: tenfile | C1: makh | D1: namenn | E1: mabanggia | F1: diachi | G1: quan | H1: email | I1: sdt | J1: mst | K1: gionhanhang | L1: loaikh | M1: hiengia | N1: ghichu
A2: Nhà hàng 12C | B2: =VLOOKUP(C2,'Trang tính1'!A:C,2,0) -> 12C.xlsx | C2: TG-KS00173 | D2: Nhà hàng 12C | E2: BG25 | F2: Số 12C Trần Phú, Phường 4, Quận 5, Thành phố Hồ Chí Minh | I2: 0908910623 (Nhi), 0908854467 (Dân) | J2: 315087043 | K2: 10H | L2: khachsi | M2: TRUE
A3: 425A Sư Vạn Hạnh, P12, Q10 | B3: =VLOOKUP(C3,'Trang tính1'!A:C,2,0) -> 425A Sư Vạn Hạnh, P12, Q10.xlsx | C3: TG-KS00644 | D3: 425A Sư Vạn Hạnh, P12, Q10 | E3: BG24 | F3: 425A Sư Vạn Hạnh, P12, Q10 | I3: 967812324 | L3: khachsi | M3: TRUE
A4: 5G BIA VÀ MỒI (Đơn tách) | B4: =VLOOKUP(C4,'Trang tính1'!A:C,2,0) -> 5G BIA VÀ MỒI (Đơn tách).xlsx | C4: TG-KS00294 | D4: 5G BIA VÀ MỒI (Đơn tách) | E4: BG24 | F4: 235 Hoàng Diệu, P9, Q4 | H4: vanthutan9x@gmail.com | I4: 327508966 | K4: trước 8h | L4: khachsi | M4: TRUE
A5: 5G BIA VÀ MỒI | B5: =VLOOKUP(C5,'Trang tính1'!A:C,2,0) -> 5G BIA VÀ MỒI.xlsx | C5: TG-KS00057 | D5: 5G BIA VÀ MỒI | E5: BG24 | F5: 235 Hoàng Diệu, P9, Q4 | H5: vanthutan9x@gmail.com | I5: 327508966 | K5: 7h-7h30 | L5: khachsi | M5: TRUE
A6: NHÀ HÀNG 6SEVEN | B6: =VLOOKUP(C6,'Trang tính1'!A:C,2,0) -> 6seven.xlsx | C6: TG-KS00196 | D6: NHÀ HÀNG 6SEVEN | E6: BG12 | F6: Số 68 Đường 23, Phường Tân Phú, Phú Mỹ Hưng, Quận 7 | I6: 937949769 | J6: 0304709006-001 | K6: trước 9h | L6: khachsi | M6: TRUE | N6: không xuất được hóa đơn, thu tiền mặt
A7: 901665270 | B7: =VLOOKUP(C7,'Trang tính1'!A:C,2,0) -> 901665270.xlsx | C7: TG-KS00664 | D7: 901665270 | E7: BG24 | F7: 178 Đường Phú Thọ Hòa, Phường Phú Thọ Hòa, Q.Tân Phú | I7: 901665270 | L7: khachsi | M7: TRUE
A8: 99 Soul (Bar) | B8: =VLOOKUP(C8,'Trang tính1'!A:C,2,0) -> 99 Soul bar.xlsx | C8: TG-KS00482 | D8: 99 Soul (Bar) | E8: BG04 | F8: 99 Phạm Ngũ Lão, Phường Phạm Ngũ Lão, Quận 1 | I8: 936261384 | J8: 316528068 | K8: 7H | L8: khachsi | M8: TRUE
A9: 99 Soul | B9: =VLOOKUP(C9,'Trang tính1'!A:C,2,0) -> 99 Soul.xlsx | C9: TG-KS00430 | D9: 99 Soul | E9: BG04 | F9: 99 Phạm Ngũ Lão, Phường Phạm Ngũ Lão, Quận 1 | I9: 936261384 | K9: 7h30 | L9: khachsi | M9: TRUE
A10: A. Đan EHG | B10: =VLOOKUP(C10,'Trang tính1'!A:C,2,0) -> A. Đan EHG.xlsx | C10: TG-KS00790 | D10: A. Đan EHG | E10: BG39 | F10: 47 Lê Anh Xuân | L10: khachsi | M10: TRUE
A11: A. PHI ( Lấy Hàng Mẫu) | B11: =VLOOKUP(C11,'Trang tính1'!A:C,2,0) -> A. PHI ( Lấy Hàng Mẫu).xlsx | C11: TG-KS01087 | D11: A. PHI ( Lấy Hàng Mẫu) | E11: BG24 | F11: số 11 - Nguyễn Bính ,Nam thiên 2 -Tân Phong ,quận 7 | I11: 037 4730334 | L11: khachsi | M11: TRUE
A12: A.Hiếu | B12: =VLOOKUP(C12,'Trang tính1'!A:C,2,0) -> A.Hiếu.xlsx | C12: TG-KS01118 | D12: A.Hiếu | E12: BG24 | F12: 357A/21 Nguyễn Trọng Tuyển, phường 1, Tân Bình, TPHCM | I12: 097 5246946 | L12: khachsi | M12: TRUE
A13: A.Quân (Nam Phương Lầu) | B13: =VLOOKUP(C13,'Trang tính1'!A:C,2,0) -> A.Quân (Nam Phương Lầu).xlsx | C13: TG-KS00690 | D13: A.Quân (Nam Phương Lầu) | E13: BG24 | L13: khachsi | M13: TRUE
A14: ACECOOK (KCX Tân Thuận) | B14: =VLOOKUP(C14,'Trang tính1'!A:C,2,0) -> ACECOOK TT.xlsx | C14: TG-KS00441 | D14: ACECOOK (KCX Tân Thuận) | E14: BG04 | F14: Lô Vb.20a2, Đường 24, KCX, Quận 7 (Công ty Thuận Hải) | I14: 0937501606 Hoài | K14: sau 8h | L14: khachsi | M14: TRUE
A15: ACECOOK | B15: =VLOOKUP(C15,'Trang tính1'!A:C,2,0) -> ACECOOK.xlsx | C15: TG-KS00073 | D15: ACECOOK | E15: BG04 | F15: 358 Gò Dầu, Phường Tân Quý, Quận Tân Phú | H15: NULL | I15: 0937501606 Hoài | K15: 10h | L15: khachsi | M15: TRUE
A16: Alice Nguyen (0966967768) | B16: =VLOOKUP(C16,'Trang tính1'!A:C,2,0) -> Alice Nguyen (0966967768).xlsx | C16: TG-KS01042 | D16: Alice Nguyen (0966967768) | E16: BG24 | F16: 236-238 Nguyễn công trứ, Phường Nguyễn Thái Bình, Quận 1, Thành phố Hồ Chí Minh | I16: 966967768 | L16: khachsi | M16: TRUE
A17: MẦM NON AN NHIÊN | B17: =VLOOKUP(C17,'Trang tính1'!A:C,2,0) -> An Nhiên.xlsx | C17: TG-KS00001 | D17: MẦM NON AN NHIÊN | E17: BG25 | F17: 28 Hồ Tùng Mậu, KP. Bình Đường 2, P. An Bình, TP. Dĩ An, Bình Dương.(đối diện Nhà 17, Đường 12, Linh Tây, Thủ Đức) | I17: 0908.988.832 C.Thanh | K17: trước 6h30-7h | L17: khachsi | M17: TRUE
A18: AN DUYÊN | B18: =VLOOKUP(C18,'Trang tính1'!A:C,2,0) -> anduyen.xlsx | C18: TG-KS00101 | D18: AN DUYÊN | E18: BG04 | F18: 8B-10 Nguyễn Tri Phương, Phường 6, Quận 5 | I18: 907472989 | K18: 8h30 | L18: khachsi | M18: TRUE
A19: AN DUYÊN (Tách) | B19: =VLOOKUP(C19,'Trang tính1'!A:C,2,0) -> anduyenTACH.xlsx | C19: TG-KS00498 | D19: AN DUYÊN (Tách) | E19: BG04 | F19: 8B-10 Nguyễn Tri Phương, Phường 6, Quận 5 | I19: 907472989 | L19: khachsi | M19: TRUE
A20: anh Ánh (0907546041) | B20: =VLOOKUP(C20,'Trang tính1'!A:C,2,0) -> anh Ánh (0907546041).xlsx | C20: TG-KS00773 | D20: anh Ánh (0907546041) | E20: BG24 | F20: Số 47 đường Bình Phú, Tam Phú Tp. Thủ Đức | L20: khachsi | M20: TRUE
A21: Anh Bảo (0906141216) | B21: =VLOOKUP(C21,'Trang tính1'!A:C,2,0) -> Anh Bảo (0906141216).xlsx | C21: TG-KS00659 | D21: Anh Bảo (0906141216) | E21: BG24 | F21: 39-39A Nguyễn Trung Trực, Phường Bến Thành, Q1 | I21: 906141216 | L21: khachsi | M21: TRUE
A22: Anh Bảo (0931635919) | B22: =VLOOKUP(C22,'Trang tính1'!A:C,2,0) -> Anh Bảo (0931635919).xlsx | C22: TG-KS00686 | D22: Anh Bảo (0931635919) | E22: BG24 | F22: gửi địa chỉ nhà xe Phương Trang | I22: 931635919 | L22: khachsi | M22: TRUE
A23: Anh Bảo (0937892379) | B23: =VLOOKUP(C23,'Trang tính1'!A:C,2,0) -> Anh Bảo (0937892379).xlsx | C23: TG-KS00989 | D23: Anh Bảo (0937892379) | E23: BG24 | F23: 133 Nguyễn Trọng Tuyển, Phường 8, Phú Nhuận | I23: 937892379 | L23: khachsi | M23: TRUE
A24: Anh Bun (0398636302) | B24: =VLOOKUP(C24,'Trang tính1'!A:C,2,0) -> Anh Bun (0398636302).xlsx | C24: TG-KS01020 | D24: Anh Bun (0398636302) | E24: BG24 | F24: 27 Nguyễn Hữu Cảnh, Phường Tân Định, Quận 1, Hồ Chí Minh | I24: 398636302 | L24: khachsi | M24: TRUE
A25: Anh Có (0389222394) | B25: =VLOOKUP(C25,'Trang tính1'!A:C,2,0) -> Anh Có (0389222394).xlsx | C25: TG-KS00941 | D25: Anh Có (0389222394) | E25: BG24 | F25: 645d Quang Trung, Phường 11 Gò Vấp | I25: 389222394 | L25: khachsi | M25: TRUE
A26: Anh Cường (0912564038) | B26: =VLOOKUP(C26,'Trang tính1'!A:C,2,0) -> Anh Cường (0912564038).xlsx | C26: TG-KS01011 | D26: Anh Cường (0912564038) | E26: BG24 | F26: kho SCSC, 30 Phan Thúc Duyện, P4. Quận Tân Bình | I26: 912564038 | L26: khachsi | M26: TRUE
A27: Anh Đạt (0932787965) | B27: =VLOOKUP(C27,'Trang tính1'!A:C,2,0) -> Anh Đạt (0932787965).xlsx | C27: TG-KS00845 | D27: Anh Đạt (0932787965) | E27: BG24 | F27: 241 Chu Văn An, Phường 12, Quận Bình Thạnh, Thành phố Hồ Chí Minh | I27: 932787965 | L27: khachsi | M27: TRUE
A28: Anh Điển | B28: =VLOOKUP(C28,'Trang tính1'!A:C,2,0) -> Anh Điển.xlsx | C28: TG-KS00654 | D28: Anh Điển | E28: BG24 | F28: 49 Trường Sơn P2 Tân Bình | L28: khachsi | M28: TRUE
A29: Anh Hải (0387185058) | B29: =VLOOKUP(C29,'Trang tính1'!A:C,2,0) -> Anh Hải (0387185058).xlsx | C29: TG-KS00680 | D29: Anh Hải (0387185058) | E29: BG24 | F29: 47 Nguyễn Trường Tộ, p12. Quận 4 | L29: khachsi | M29: TRUE
A30: Anh Hảo (Kho TG) | B30: =VLOOKUP(C30,'Trang tính1'!A:C,2,0) -> Anh Hảo (Kho TG).xlsx | C30: TG-KS00951 | D30: Anh Hảo (Kho TG) | E30: BG69 | F30: Kho Trần Gia | L30: khachsi | M30: TRUE
A31: Anh Hòa (0946969087) | B31: =VLOOKUP(C31,'Trang tính1'!A:C,2,0) -> Anh Hòa (0946969087).xlsx | C31: TG-KS00741 | D31: Anh Hòa (0946969087) | E31: BG24 | F31: 130/36 đường 11, k phố 9, trường thọ thủ đức | L31: khachsi | M31: TRUE
A32: anh Hồng 0779694869 | B32: =VLOOKUP(C32,'Trang tính1'!A:C,2,0) -> anh Hồng 0779694869.xlsx | C32: TG-KS00611 | D32: anh Hồng 0779694869 | E32: BG24 | F32: 232/17 đường võ văn Kiệt P cầu ông lảnh Q1 | I32: 779694869 | L32: khachsi | M32: TRUE
A33: Anh Huy (0974943479) | B33: =VLOOKUP(C33,'Trang tính1'!A:C,2,0) -> Anh Huy (0974943479).xlsx | C33: TG-KS01012 | D33: Anh Huy (0974943479) | E33: BG24 | F33: M2 Bis thất sơn, Phường 15, Quận 10 | I33: 974943479 | L33: khachsi | M33: TRUE
A34: Anh Kiệt (Trần Gia) | B34: =VLOOKUP(C34,'Trang tính1'!A:C,2,0) -> Anh Kiệt (Trần Gia).xlsx | C34: TG-KS00970 | D34: Anh Kiệt (Trần Gia) | E34: BG39 | F34: Nhận tại kho TG | L34: khachsi | M34: TRUE
A35: Anh Ký (0985000824) | B35: =VLOOKUP(C35,'Trang tính1'!A:C,2,0) -> Anh Ký (0985000824).xlsx | C35: TG-KS00949 | D35: Anh Ký (0985000824) | E35: BG24 | F35: 38/27/1 Nguyễn Văn Trỗi, P15, Q.Phú Nhuận, TP.HCM | I35: 985000824 | L35: khachsi | M35: TRUE
A36: Anh Lãnh (08686142140) | B36: =VLOOKUP(C36,'Trang tính1'!A:C,2,0) -> Anh Lãnh (08686142140).xlsx | C36: TG-KS00590 | D36: Anh Lãnh (08686142140) | E36: BG69 | F36: Nhận tại kho TG | I36: 868614214 | L36: khachsi | M36: TRUE
A37: Anh Linh (0903382991) | B37: =VLOOKUP(C37,'Trang tính1'!A:C,2,0) -> Anh Linh (0903382991).xlsx | C37: TG-KS01143 | D37: Anh Linh (0903382991) | E37: BG24 | F37: 82-88 Nguyễn Tri Phương, Phường 7, Quận 5 | I37: 903382991 | L37: khachsi | M37: TRUE
A38: Anh Lộc (0343976028) | B38: =VLOOKUP(C38,'Trang tính1'!A:C,2,0) -> Anh Lộc (0343976028).xlsx | C38: TG-KL00003 | E38: BG24 | F38: 120/4B Trần Quốc Thảo, Q3, TPHCM | I38: 0343976028 | K38: 9h-11h | L38: khachle | M38: TRUE
A39: Anh LợI (0967174975) | B39: =VLOOKUP(C39,'Trang tính1'!A:C,2,0) -> Anh LợI (0967174975).xlsx | C39: TG-KS00713 | D39: Anh LợI (0967174975) | E39: BG24 | F39: 42 đường 53 Tân Phong q7 | I39: 967174975 | L39: khachsi | M39: TRUE
A40: Anh Luân (0907219742) | B40: =VLOOKUP(C40,'Trang tính1'!A:C,2,0) -> Anh Luân (0907219742).xlsx | C40: TG-KS00688 | D40: Anh Luân (0907219742) | E40: BG24 | F40: 15a/4 Lê Thánh Tôn, Q1 | L40: khachsi | M40: TRUE
...

Sheet Trang tính1
A1: MÃ KHÁCH HÀNG | B1: TÊN FILE | C1: TÊN TRÊN HỆ THỐNG
A2: TG-KL00001 | B2: CHỊ HIỀN.xlsx | C2: CHỊ HIỀN
A3: TG-KL00002 | B3: Quốc Anh (0355699822).xlsx | C3: Quốc Anh (0355699822)
A4: TG-KL00003 | B4: Anh Lộc (0343976028).xlsx | C4: Anh Lộc (0343976028)
A5: TG-KL00004 | B5: Nhật Điền (0909976975).xlsx | C5: Nhật Điền (0909976975)
A6: TG-KL00005 | B6: Lê Yến (0906649258).xlsx | C6: Lê Yến (0906649258)
A7: TG-KL00006 | B7: Chị Hiền (0903228704).xlsx | C7: Chị Hiền (0903228704)
A8: TG-KL00007 | B8: Chi nhánh công ty TNHH Daesang Việt Nam tại Hải Dương.xlsx | C8: Chi nhánh công ty TNHH Daesang Việt Nam tại Hải Dương
A9: TG-KL00008 | B9: Bia Hơi Hải Xồm.xlsx | C9: Bia Hơi Hải Xồm
A10: TG-KL00009 | B10: FS lá basil.xlsx | C10: FS lá basil
A11: TG-KL00010 | B11: Minh Anh (0389151738).xlsx | C11: Minh Anh (0389151738)
A12: TG-KL00011 | B12: Ngân Nguyễn (0913707197).xlsx | C12: Ngân Nguyễn (0913707197)
... A1221: TG-KS01215 | B1221: beer 300 tách.xlsx | C1221: BEER 300 (Tách)
