Workbook

Sheet sheet1
A1: Mapingcode | B1: masp | C1: title | D1: uomCode | E1: slton | F1: slhuy
A2: dautay | B2: =VLOOKUP(A2,CODE!A:B,2,0) -> I100477 | C2: =VLOOKUP(A2,CODE!A:C,3,0) -> Dâu tây ĐL | D2: =VLOOKUP(A2,CODE!D:E,2,0) -> Kg | E2: 0.2 | F2: 0
A3: sori | B3: =VLOOKUP(A3,CODE!A:B,2,0) -> I100501 | C3: =VLOOKUP(A3,CODE!A:C,3,0) -> Sơ ri | D3: =VLOOKUP(A3,CODE!D:E,2,0) -> Kg | E3: 0.2 | F3: 0
A4: lachanh | B4: =VLOOKUP(A4,CODE!A:B,2,0) -> I100133 | C4: =VLOOKUP(A4,CODE!A:C,3,0) -> Lá chanh | D4: =VLOOKUP(A4,CODE!D:E,2,0) -> Kg | E4: 0.2 | F4: 0
A5: raudang | B5: =VLOOKUP(A5,CODE!A:B,2,0) -> I100176 | C5: =VLOOKUP(A5,CODE!A:C,3,0) -> Rau đắng | D5: =VLOOKUP(A5,CODE!D:E,2,0) -> Kg | E5: 0.2 | F5: 0
A6: gialat | B6: =VLOOKUP(A6,CODE!A:B,2,0) -> I100093 | C6: =VLOOKUP(A6,CODE!A:C,3,0) -> Giá lặt | D6: =VLOOKUP(A6,CODE!D:E,2,0) -> Kg | E6: 0.3 | F6: 0.9
A7: othiemxanh | B7: =VLOOKUP(A7,CODE!A:B,2,0) -> I100168 | C7: =VLOOKUP(A7,CODE!A:C,3,0) -> Ớt hiểm xanh | D7: =VLOOKUP(A7,CODE!D:E,2,0) -> Kg | E7: 0.3 | F7: 0
A8: daudua | B8: =VLOOKUP(A8,CODE!A:B,2,0) -> I100079 | C8: =VLOOKUP(A8,CODE!A:C,3,0) -> Đậu đũa xanh | D8: =VLOOKUP(A8,CODE!D:E,2,0) -> Kg | E8: 0.3 | F8: 0
A9: chuoichat | B9: =VLOOKUP(A9,CODE!A:B,2,0) -> I100063 | C9: =VLOOKUP(A9,CODE!A:C,3,0) -> Chuối chát | D9: =VLOOKUP(A9,CODE!D:E,2,0) -> Kg | E9: 0.3 | F9: 0
A10: rosemary | B10: =VLOOKUP(A10,CODE!A:B,2,0) -> I100196 | C10: =VLOOKUP(A10,CODE!A:C,3,0) -> Rose mary | D10: =VLOOKUP(A10,CODE!D:E,2,0) -> Kg | E10: 0.3 | F10: 0
A11: thila | B11: =VLOOKUP(A11,CODE!A:B,2,0) -> I100219 | C11: =VLOOKUP(A11,CODE!A:C,3,0) -> Thì là | D11: =VLOOKUP(A11,CODE!D:E,2,0) -> Kg | E11: 0.4 | F11: 3.7
A12: cusen | B12: =VLOOKUP(A12,CODE!A:B,2,0) -> I100074 | C12: =VLOOKUP(A12,CODE!A:C,3,0) -> Củ sen | D12: =VLOOKUP(A12,CODE!D:E,2,0) -> Kg | E12: 0.4 | F12: 0
A13: susu | B13: =VLOOKUP(A13,CODE!A:B,2,0) -> I100214 | C13: =VLOOKUP(A13,CODE!A:C,3,0) -> Su Su | D13: =VLOOKUP(A13,CODE!D:E,2,0) -> Kg | E13: 0.4 | F13: 0
... A159: caithao | B159: =VLOOKUP(A159,CODE!A:B,2,0) -> I100051 | C159: =VLOOKUP(A159,CODE!A:C,3,0) -> Cải thảo | D159: =VLOOKUP(A159,CODE!D:E,2,0) -> Kg | E159: 0 | F159: 10
A160: DUAHAU | B160: I100479 | C160: Dưa hấu | D160: Kg | E160: 43 | F160: 0

Sheet CODE
A1: mappingcode | B1: itemcode | C1: ItemName | D1: Column1 | E1: UOMCode | F1: InvStatus | G1: NOTE
A2: BACHA | B2: I100001 | C2: Bạc hà | D2: BACHA | E2: Kg | G2: 1 bó = 5kg, (dọc mùng/cây bạc hà)
A3: BAPCAITIM | B3: I100002 | C3: Bắp cải tím | D3: BAPCAITIM | E3: Kg | G3: 0.8kg/bắp (0.5-1kg/bắp)
A4: BAPCAITRANG | B4: I100003 | C4: Bắp cải trắng | D4: BAPCAITRANG | E4: Kg | G4: 0.8kg/bắp (0.5-1.2kg/bắp)
A5: BAPCHUOIBAO | B5: I100004 | C5: Bắp chuối bào | D5: BAPCHUOIBAO | E5: Kg | F5: xuất hđ đổi thành bắp chuối | G5: xuất hđ đổi thành bắp chuối
A6: BAPCHUOI | B6: I100005 | C6: Bắp chuối nguyên trái | D6: BAPCHUOI | E6: Kg | G6: 1KG/BẮP (0.5-0.8kg/bắp)
A7: BAPMYHAT | B7: I100006 | C7: Bắp mỹ hạt | D7: BAPMYHAT | E7: Kg | G7: 0
A8: BAPMYKG | B8: I100007 | C8: Bắp mỹ kg Lột Vỏ | D8: BAPMYKG | E8: Kg | G8: 3 trái/kg
A9: BAPMYTRAI | B9: I100008 | C9: Bắp mỹ trái (Loại 1) | D9: BAPMYTRAI | E9: Trái | G9: 3 trái/kg
A10: BAPNON | B10: I100009 | C10: Bắp non tươi | D10: BAPNON | E10: Kg | G10: 0
A11: BAUXANH | B11: I100010 | C11: Bầu xanh | D11: BAUXANH | E11: Kg | G11: 0.5kg/trái (0.3-0.5kg/trái)
A12: BIDAO | B12: I100011 | C12: Bí đao | D12: BIDAO | E12: Kg | G12: 0.5kg/trái (0.3-0.5kg/trái)
A13: BIDOHOLO | B13: I100012 | C13: Bí đỏ hồ lô | D13: BIDOHOLO | E13: Kg | G13: 1-2kg/trái
A14: BINHAT | B14: I100013 | C14: Bí nhật | D14: BINHAT | E14: Kg | G14: 0.15-0.35kg/trái
A15: BIDOTRON | B15: I100014 | C15: Bí đỏ tròn | D15: BIDOTRON | E15: Kg | G15: 3kg/trái (2-4kg/trái)
A16: BINGOIVANG | B16: I100015 | C16: Bí ngòi vàng | D16: BINGOIVANG | E16: Kg | G16: 0.1-0.15kg/trái
A17: BINGOIXANH | B17: I100016 | C17: Bí ngòi xanh | D17: BINGOIXANH | E17: Kg | G17: 0.1-0.2kg/trái
A18: BINU | B18: I100017 | C18: Bí nụ | D18: BINU | E18: Kg | G18: 0.03-0.05kg/quả
A19: BOXOI | B19: I100018 | C19: Bó xôi (Nhà Lồng) | D19: BOXOI | E19: Kg | G19: 0.3kg/gói
A20: BONBON | B20: I100019 | C20: Bồn bồn chua | D20: BONBON | E20: Kg | F20: không xuất được hóa đơn | G20: không xuất được hóa đơn
A21: BONGATISO | B21: I100020 | C21: Bông Atiso | D21: BONGATISO | E21: Kg | G21: KHÔNG NHẬN
A22: BONGBI | B22: I100021 | C22: Bông bí | D22: BONGBI | E22: Kg | G22: 0
A23: BONGCAITRANG | B23: I100022 | C23: Bông cải trắng | D23: BONGCAITRANG | E23: Kg | G23: 0.8kg/bông
A24: BONGCAITRANGDL | B24: I100023 | C24: Bông cải trắng ĐaLat | D24: BONGCAITRANGDL | E24: Kg | G24: 0.6kg/bông
A25: BONGCAIXANH | B25: I100024 | C25: Bông cải xanh | D25: BONGCAIXANH | E25: Kg | G25: 0.5kg/bông
A26: bongcaixanhbb | B26: I100025 | C26: Bông cải xanh Baby | D26: bongcaixanhbb | E26: Kg | G26: 25g/cây
A27: BONGCAIXANHDL | B27: I100026 | C27: Bông cải xanh ĐaLat | D27: BONGCAIXANHDL | E27: Kg | G27: 0.5kg/bông
A28: BONGDIENDIEN | B28: I100027 | C28: Bông điên điển | D28: BONGDIENDIEN | E28: Kg | G28: 0
A29: BONGHE | B29: I100028 | C29: Bông hẹ | D29: BONGHE | E29: Kg | G29: 0
A30: BONGKIMCHAM | B30: I100029 | C30: Bông kim châm | D30: BONGKIMCHAM | E30: GÓI | G30: 0
A31: BONGSODUA | B31: I100030 | C31: Bông so đũa | D31: BONGSODUA | E31: Kg | G31: 0
A32: BONGSUNG | B32: I100031 | C32: Bông súng | D32: BONGSUNG | E32: Kg | G32: 0
A33: BONGTHIENLY | B33: I100032 | C33: Bông thiên lý | D33: BONGTHIENLY | E33: Kg | G33: 0
A34: CACHUABI | B34: I100033 | C34: Cà chua bi | D34: CACHUABI | E34: Kg | G34: 0
A35: CACHUA | B35: I100034 | C35: Cà chua | D35: CACHUA | E35: Kg | G35: 0.06-0.08kg/trái
A36: CADIA | B36: I100035 | C36: Cà dĩa | D36: CADIA | E36: Kg | G36: 0
A37: CAPHAO | B37: I100036 | C37: Cà pháo | D37: CAPHAO | E37: Kg | G37: 0
A38: CAPHAOMUOI | B38: I100037 | C38: Cà pháo muối | D38: CAPHAOMUOI | E38: Kg | F38: xuất hđ đổi thành cà pháo | G38: xuất hđ đổi thành cà pháo, 1kg/hũ
A39: CAPHAOXANH | B39: I100038 | C39: Cà pháo xanh | D39: CAPHAOXANH | E39: Kg | G39: 0
A40: CAROT | B40: I100039 | C40: Cà rốt | D40: CAROT | E40: Kg | G40: 0.15-0.25kg/trái
...
