Workbook
Name Slicer_Bộ_phận: #N/A
Name Slicer_Column1: #N/A
Name Slicer_LỆCH_ĐƠN_GIÁ: #N/A
Name Slicer_LỆCH_ĐƠN_GIÁ1: #N/A
Name Slicer_LỆCH_ĐƠN_GIÁ11: #N/A
Name Slicer_LỆCH_ĐƠN_GIÁ111: #N/A
Name Slicer_Ngày_ct: #N/A
Name Slicer_xx: #N/A
Name Slicer_xx1: #N/A
Name Slicer_xx11: #N/A
Name Slicer_xx111: #N/A

Sheet tsg1
A1: TRẦN GIA - TSG1 ( VINCOM THẢO ĐIỀN )
X2: =W5/M5 -> -0.043829255
R3: =DAY(B301) -> 15
S4: =SUMIF(Table1[Mã nx],"tsg01",Table1[Đvt])=S5 -> FALSE | U4: =SUMIF(Table1[Mã nx],"tsg01",Table1[Giá báo])=U5 -> FALSE
K5: =SUM(K7:K1048576) -> 1333.18 | M5: =SUM(M7:M1048576) -> 50171740 | S5: =SUM(S7:S1048576) -> 1266 | U5: =SUM(U7:U1048576) -> 47972750 | V5: =SUM(V7:V1048576) -> -67.18 | W5: =SUM(W7:W1048576) -> -2198990
A6: MÃ ĐƠN HÀNG | B6: NGÀY | C6: MÃ KH | D6: TÊN KH | E6: Line ID | F6: Barcode | G6: MÃ KHO | H6: MÃ HÀNG | I6: TÊN HÀNG | J6: ĐVT | K6: SL | L6: ĐƠN GIÁ | M6: THÀNH TIỀN | N6: MÃ FAST | O6: TÊN FAST | P6: TSG01 | Q6: CT1 | R6: CT2 | S6: THỰC NHẬN | T6: ĐG FAST | U6: THÀNH TIỀN FAST | V6: lệch sl | W6: lệch tổng tiền | X6: LỆCH ĐƠN GIÁ | Y6: CHECK | Z6: Column1
B7: 01/01/2026 | D7: TIANLONG 01 | I7: Bắp mỹ trái (Loại 1) | J7: Trái | K7: 10 | L7: 8500 | M7: =K7*L7 -> 85000 | N7: =VLOOKUP(I7,'MÃ '!$A$2:$E$1048576,4,0) -> NL300107 | O7: =VLOOKUP(I7,'MÃ '!$A$2:$E$1048576,5,0) -> Ngô ngọt ( Bắp trái) | P7: =$P$6 -> TSG01 | Q7: =DAY(Table01[[#This Row],[NGÀY]])&Table01[[#This Row],[TSG01]]&Table01[[#This Row],[MÃ FAST]] -> 1TSG01NL300107 | R7: =COUNTIF($Q$7:Q7,Q7)&Q7 -> 11TSG01NL300107 | S7: =IFERROR(VLOOKUP(R7,Table1[[ct2]:[Số lượng]],13,0),0) -> 10 | T7: =IFERROR(VLOOKUP(R7,Table1[[ct2]:[Giá]],14,0),Table01[[#This Row],[ĐƠN GIÁ]]) -> 8500 | U7: =IFERROR((T7*S7),"0") -> 85000 | V7: =S7-K7 -> 0 | W7: =Table01[[#This Row],[THÀNH TIỀN FAST]]-Table01[[#This Row],[THÀNH TIỀN]] -> 0 | X7: =Table01[[#This Row],[ĐG FAST]]=Table01[[#This Row],[ĐƠN GIÁ]] -> TRUE | Y7: =Table01[[#This Row],[THÀNH TIỀN FAST]]=Table01[[#This Row],[THÀNH TIỀN]] -> TRUE
B8: 01/01/2026 | D8: TIANLONG 01 | I8: Bó xôi (Nhà Lồng) | J8: Kg | K8: 2 | L8: 45000 | M8: =K8*L8 -> 90000 | N8: =VLOOKUP(I8,'MÃ '!$A$2:$E$1048576,4,0) -> NL300203 | O8: =VLOOKUP(I8,'MÃ '!$A$2:$E$1048576,5,0) -> Cải bó xôi | P8: =$P$6 -> TSG01 | Q8: =DAY(Table01[[#This Row],[NGÀY]])&Table01[[#This Row],[TSG01]]&Table01[[#This Row],[MÃ FAST]] -> 1TSG01NL300203 | R8: =COUNTIF($Q$7:Q8,Q8)&Q8 -> 11TSG01NL300203 | S8: =IFERROR(VLOOKUP(R8,Table1[[ct2]:[Số lượng]],13,0),0) -> 1.7 | T8: =IFERROR(VLOOKUP(R8,Table1[[ct2]:[Giá]],14,0),Table01[[#This Row],[ĐƠN GIÁ]]) -> 45000 | U8: =IFERROR((T8*S8),"0") -> 76500 | V8: =S8-K8 -> -0.3 | W8: =Table01[[#This Row],[THÀNH TIỀN FAST]]-Table01[[#This Row],[THÀNH TIỀN]] -> -13500 | X8: =Table01[[#This Row],[ĐG FAST]]=Table01[[#This Row],[ĐƠN GIÁ]] -> TRUE | Y8: =Table01[[#This Row],[THÀNH TIỀN FAST]]=Table01[[#This Row],[THÀNH TIỀN]] -> FALSE
B9: 01/01/2026 | D9: TIANLONG 01 | I9: Cà chua | J9: Kg | K9: 2 | L9: 50000 | M9: =K9*L9 -> 100000 | N9: =VLOOKUP(I9,'MÃ '!$A$2:$E$1048576,4,0) -> NL300013 | O9: =VLOOKUP(I9,'MÃ '!$A$2:$E$1048576,5,0) -> Cà chua | P9: =$P$6 -> TSG01 | Q9: =DAY(Table01[[#This Row],[NGÀY]])&Table01[[#This Row],[TSG01]]&Table01[[#This Row],[MÃ FAST]] -> 1TSG01NL300013 | R9: =COUNTIF($Q$7:Q9,Q9)&Q9 -> 11TSG01NL300013 | S9: =IFERROR(VLOOKUP(R9,Table1[[ct2]:[Số lượng]],13,0),0) -> 2 | T9: =IFERROR(VLOOKUP(R9,Table1[[ct2]:[Giá]],14,0),Table01[[#This Row],[ĐƠN GIÁ]]) -> 50000 | U9: =IFERROR((T9*S9),"0") -> 100000 | V9: =S9-K9 -> 0 | W9: =Table01[[#This Row],[THÀNH TIỀN FAST]]-Table01[[#This Row],[THÀNH TIỀN]] -> 0 | X9: =Table01[[#This Row],[ĐG FAST]]=Table01[[#This Row],[ĐƠN GIÁ]] -> TRUE | Y9: =Table01[[#This Row],[THÀNH TIỀN FAST]]=Table01[[#This Row],[THÀNH TIỀN]] -> TRUE
B10: 01/01/2026 | D10: TIANLONG 01 | I10: Cải thảo | J10: Kg | K10: 10 | L10: 18000 | M10: =K10*L10 -> 180000 | N10: =VLOOKUP(I10,'MÃ '!$A$2:$E$1048576,4,0) -> NL300022 | O10: =VLOOKUP(I10,'MÃ '!$A$2:$E$1048576,5,0) -> Cải thảo | P10: =$P$6 -> TSG01 | Q10: =DAY(Table01[[#This Row],[NGÀY]])&Table01[[#This Row],[TSG01]]&Table01[[#This Row],[MÃ FAST]] -> 1TSG01NL300022 | R10: =COUNTIF($Q$7:Q10,Q10)&Q10 -> 11TSG01NL300022 | S10: =IFERROR(VLOOKUP(R10,Table1[[ct2]:[Số lượng]],13,0),0) -> 9.5 | T10: =IFERROR(VLOOKUP(R10,Table1[[ct2]:[Giá]],14,0),Table01[[#This Row],[ĐƠN GIÁ]]) -> 18000 | U10: =IFERROR((T10*S10),"0") -> 171000 | V10: =S10-K10 -> -0.5 | W10: =Table01[[#This Row],[THÀNH TIỀN FAST]]-Table01[[#This Row],[THÀNH TIỀN]] -> -9000 | X10: =Table01[[#This Row],[ĐG FAST]]=Table01[[#This Row],[ĐƠN GIÁ]] -> TRUE | Y10: =Table01[[#This Row],[THÀNH TIỀN FAST]]=Table01[[#This Row],[THÀNH TIỀN]] -> FALSE
B11: 01/01/2026 | D11: TIANLONG 01 | I11: Cam vàng | J11: Kg | K11: 0.9 | L11: 75000 | M11: =K11*L11 -> 67500 | N11: =VLOOKUP(I11,'MÃ '!$A$2:$E$1048576,4,0) -> NL600067 | O11: =VLOOKUP(I11,'MÃ '!$A$2:$E$1048576,5,0) -> Cam vàng | P11: =$P$6 -> TSG01 | Q11: =DAY(Table01[[#This Row],[NGÀY]])&Table01[[#This Row],[TSG01]]&Table01[[#This Row],[MÃ FAST]] -> 1TSG01NL600067 | R11: =COUNTIF($Q$7:Q11,Q11)&Q11 -> 11TSG01NL600067 | S11: =IFERROR(VLOOKUP(R11,Table1[[ct2]:[Số lượng]],13,0),0) -> 0.9 | T11: =IFERROR(VLOOKUP(R11,Table1[[ct2]:[Giá]],14,0),Table01[[#This Row],[ĐƠN GIÁ]]) -> 75000 | U11: =IFERROR((T11*S11),"0") -> 67500 | V11: =S11-K11 -> 0 | W11: =Table01[[#This Row],[THÀNH TIỀN FAST]]-Table01[[#This Row],[THÀNH TIỀN]] -> 0 | X11: =Table01[[#This Row],[ĐG FAST]]=Table01[[#This Row],[ĐƠN GIÁ]] -> TRUE | Y11: =Table01[[#This Row],[THÀNH TIỀN FAST]]=Table01[[#This Row],[THÀNH TIỀN]] -> TRUE
B12: 01/01/2026 | D12: TIANLONG 01 | I12: Chanh vàng | J12: Kg | K12: 0.5 | L12: 95000 | M12: =K12*L12 -> 47500 | N12: =VLOOKUP(I12,'MÃ '!$A$2:$E$1048576,4,0) -> NL600068 | O12: =VLOOKUP(I12,'MÃ '!$A$2:$E$1048576,5,0) -> Chanh vàng | P12: =$P$6 -> TSG01 | Q12: =DAY(Table01[[#This Row],[NGÀY]])&Table01[[#This Row],[TSG01]]&Table01[[#This Row],[MÃ FAST]] -> 1TSG01NL600068 | R12: =COUNTIF($Q$7:Q12,Q12)&Q12 -> 11TSG01NL600068 | S12: =IFERROR(VLOOKUP(R12,Table1[[ct2]:[Số lượng]],13,0),0) -> 0.5 | T12: =IFERROR(VLOOKUP(R12,Table1[[ct2]:[Giá]],14,0),Table01[[#This Row],[ĐƠN GIÁ]]) -> 95000 | U12: =IFERROR((T12*S12),"0") -> 47500 | V12: =S12-K12 -> 0 | W12: =Table01[[#This Row],[THÀNH TIỀN FAST]]-Table01[[#This Row],[THÀNH TIỀN]] -> 0 | X12: =Table01[[#This Row],[ĐG FAST]]=Table01[[#This Row],[ĐƠN GIÁ]] -> TRUE | Y12: =Table01[[#This Row],[THÀNH TIỀN FAST]]=Table01[[#This Row],[THÀNH TIỀN]] -> TRUE
B13: 01/01/2026 | D13: TIANLONG 01 | I13: Củ cải trắng (Loại 1) | J13: Kg | K13: 1.2 | L13: 13000 | M13: =K13*L13 -> 15600 | N13: =VLOOKUP(I13,'MÃ '!$A$2:$E$1048576,4,0) -> NL300033 | O13: =VLOOKUP(I13,'MÃ '!$A$2:$E$1048576,5,0) -> Củ cải trắng | P13: =$P$6 -> TSG01 | Q13: =DAY(Table01[[#This Row],[NGÀY]])&Table01[[#This Row],[TSG01]]&Table01[[#This Row],[MÃ FAST]] -> 1TSG01NL300033 | R13: =COUNTIF($Q$7:Q13,Q13)&Q13 -> 11TSG01NL300033 | S13: =IFERROR(VLOOKUP(R13,Table1[[ct2]:[Số lượng]],13,0),0) -> 1.2 | T13: =IFERROR(VLOOKUP(R13,Table1[[ct2]:[Giá]],14,0),Table01[[#This Row],[ĐƠN GIÁ]]) -> 13000 | U13: =IFERROR((T13*S13),"0") -> 15600 | V13: =S13-K13 -> 0 | W13: =Table01[[#This Row],[THÀNH TIỀN FAST]]-Table01[[#This Row],[THÀNH TIỀN]] -> 0 | X13: =Table01[[#This Row],[ĐG FAST]]=Table01[[#This Row],[ĐƠN GIÁ]] -> TRUE | Y13: =Table01[[#This Row],[THÀNH TIỀN FAST]]=Table01[[#This Row],[THÀNH TIỀN]] -> TRUE
B14: 01/01/2026 | D14: TIANLONG 01 | I14: Củ sen | J14: Kg | K14: 2 | L14: 47000 | M14: =K14*L14 -> 94000 | N14: =VLOOKUP(I14,'MÃ '!$A$2:$E$1048576,4,0) -> NL300036 | O14: =VLOOKUP(I14,'MÃ '!$A$2:$E$1048576,5,0) -> Củ sen | P14: =$P$6 -> TSG01 | Q14: =DAY(Table01[[#This Row],[NGÀY]])&Table01[[#This Row],[TSG01]]&Table01[[#This Row],[MÃ FAST]] -> 1TSG01NL300036 | R14: =COUNTIF($Q$7:Q14,Q14)&Q14 -> 11TSG01NL300036 | S14: =IFERROR(VLOOKUP(R14,Table1[[ct2]:[Số lượng]],13,0),0) -> 1.8 | T14: =IFERROR(VLOOKUP(R14,Table1[[ct2]:[Giá]],14,0),Table01[[#This Row],[ĐƠN GIÁ]]) -> 47000 | U14: =IFERROR((T14*S14),"0") -> 84600 | V14: =S14-K14 -> -0.2 | W14: =Table01[[#This Row],[THÀNH TIỀN FAST]]-Table01[[#This Row],[THÀNH TIỀN]] -> -9400 | X14: =Table01[[#This Row],[ĐG FAST]]=Table01[[#This Row],[ĐƠN GIÁ]] -> TRUE | Y14: =Table01[[#This Row],[THÀNH TIỀN FAST]]=Table01[[#This Row],[THÀNH TIỀN]] -> FALSE
B15: 01/01/2026 | D15: TIANLONG 01 | I15: Dưa hấu | J15: Kg | K15: 20 | L15: 18000 | M15: =K15*L15 -> 360000 | N15: =VLOOKUP(I15,'MÃ '!$A$2:$E$1048576,4,0) -> NL600004 | O15: =VLOOKUP(I15,'MÃ '!$A$2:$E$1048576,5,0) -> Dưa hấu | P15: =$P$6 -> TSG01 | Q15: =DAY(Table01[[#This Row],[NGÀY]])&Table01[[#This Row],[TSG01]]&Table01[[#This Row],[MÃ FAST]] -> 1TSG01NL600004 | R15: =COUNTIF($Q$7:Q15,Q15)&Q15 -> 11TSG01NL600004 | S15: =IFERROR(VLOOKUP(R15,Table1[[ct2]:[Số lượng]],13,0),0) -> 20 | T15: =IFERROR(VLOOKUP(R15,Table1[[ct2]:[Giá]],14,0),Table01[[#This Row],[ĐƠN GIÁ]]) -> 18000 | U15: =IFERROR((T15*S15),"0") -> 360000 | V15: =S15-K15 -> 0 | W15: =Table01[[#This Row],[THÀNH TIỀN FAST]]-Table01[[#This Row],[THÀNH TIỀN]] -> 0 | X15: =Table01[[#This Row],[ĐG FAST]]=Table01[[#This Row],[ĐƠN GIÁ]] -> TRUE | Y15: =Table01[[#This Row],[THÀNH TIỀN FAST]]=Table01[[#This Row],[THÀNH TIỀN]] -> TRUE
B16: 01/01/2026 | D16: TIANLONG 01 | I16: Hành lá | J16: Kg | K16: 1 | L16: 55000 | M16: =K16*L16 -> 55000 | N16: =VLOOKUP(I16,'MÃ '!$A$2:$E$1048576,4,0) -> NL300058 | O16: =VLOOKUP(I16,'MÃ '!$A$2:$E$1048576,5,0) -> Hành lá | P16: =$P$6 -> TSG01 | Q16: =DAY(Table01[[#This Row],[NGÀY]])&Table01[[#This Row],[TSG01]]&Table01[[#This Row],[MÃ FAST]] -> 1TSG01NL300058 | R16: =COUNTIF($Q$7:Q16,Q16)&Q16 -> 11TSG01NL300058 | S16: =IFERROR(VLOOKUP(R16,Table1[[ct2]:[Số lượng]],13,0),0) -> 1 | T16: =IFERROR(VLOOKUP(R16,Table1[[ct2]:[Giá]],14,0),Table01[[#This Row],[ĐƠN GIÁ]]) -> 55000 | U16: =IFERROR((T16*S16),"0") -> 55000 | V16: =S16-K16 -> 0 | W16: =Table01[[#This Row],[THÀNH TIỀN FAST]]-Table01[[#This Row],[THÀNH TIỀN]] -> 0 | X16: =Table01[[#This Row],[ĐG FAST]]=Table01[[#This Row],[ĐƠN GIÁ]] -> TRUE | Y16: =Table01[[#This Row],[THÀNH TIỀN FAST]]=Table01[[#This Row],[THÀNH TIỀN]] -> TRUE
B17: 01/01/2026 | D17: TIANLONG 01 | I17: Hoa cúc tím | J17: Bó | K17: 1 | L17: 80000 | M17: =K17*L17 -> 80000 | N17: =VLOOKUP(I17,'MÃ '!$A$2:$E$1048576,4,0) -> NL300218 | O17: =VLOOKUP(I17,'MÃ '!$A$2:$E$1048576,5,0) -> Hoa cúc (decor) bó | P17: =$P$6 -> TSG01 | Q17: =DAY(Table01[[#This Row],[NGÀY]])&Table01[[#This Row],[TSG01]]&Table01[[#This Row],[MÃ FAST]] -> 1TSG01NL300218 | R17: =COUNTIF($Q$7:Q17,Q17)&Q17 -> 11TSG01NL300218 | S17: =IFERROR(VLOOKUP(R17,Table1[[ct2]:[Số lượng]],13,0),0) -> 1 | T17: =IFERROR(VLOOKUP(R17,Table1[[ct2]:[Giá]],14,0),Table01[[#This Row],[ĐƠN GIÁ]]) -> 40000 | U17: =IFERROR((T17*S17),"0") -> 40000 | V17: =S17-K17 -> 0 | W17: =Table01[[#This Row],[THÀNH TIỀN FAST]]-Table01[[#This Row],[THÀNH TIỀN]] -> -40000 | X17: =Table01[[#This Row],[ĐG FAST]]=Table01[[#This Row],[ĐƠN GIÁ]] -> FALSE | Y17: =Table01[[#This Row],[THÀNH TIỀN FAST]]=Table01[[#This Row],[THÀNH TIỀN]] -> FALSE
B18: 01/01/2026 | D18: TIANLONG 01 | I18: Húng lũi | J18: Kg | K18: 0.3 | L18: 65000 | M18: =K18*L18 -> 19500 | N18: =VLOOKUP(I18,'MÃ '!$A$2:$E$1048576,4,0) -> NL300062 | O18: =VLOOKUP(I18,'MÃ '!$A$2:$E$1048576,5,0) -> Húng Bạc Hà | P18: =$P$6 -> TSG01 | Q18: =DAY(Table01[[#This Row],[NGÀY]])&Table01[[#This Row],[TSG01]]&Table01[[#This Row],[MÃ FAST]] -> 1TSG01NL300062 | R18: =COUNTIF($Q$7:Q18,Q18)&Q18 -> 11TSG01NL300062 | S18: =IFERROR(VLOOKUP(R18,Table1[[ct2]:[Số lượng]],13,0),0) -> 0.3 | T18: =IFERROR(VLOOKUP(R18,Table1[[ct2]:[Giá]],14,0),Table01[[#This Row],[ĐƠN GIÁ]]) -> 65000 | U18: =IFERROR((T18*S18),"0") -> 19500 | V18: =S18-K18 -> 0 | W18: =Table01[[#This Row],[THÀNH TIỀN FAST]]-Table01[[#This Row],[THÀNH TIỀN]] -> 0 | X18: =Table01[[#This Row],[ĐG FAST]]=Table01[[#This Row],[ĐƠN GIÁ]] -> TRUE | Y18: =Table01[[#This Row],[THÀNH TIỀN FAST]]=Table01[[#This Row],[THÀNH TIỀN]] -> TRUE
... B301: 15/01/2026 | D301: TIANLONG 01 | I301: Xà lách romain | J301: Kg | K301: 8.2 | L301: 62000 | M301: =K301*L301 -> 508400 | N301: =VLOOKUP(I301,'MÃ '!$A$2:$E$1048576,4,0) -> NL300147 | O301: =VLOOKUP(I301,'MÃ '!$A$2:$E$1048576,5,0) -> Xà lách Roman | P301: =$P$6 -> TSG01 | Q301: =DAY(Table01[[#This Row],[NGÀY]])&Table01[[#This Row],[TSG01]]&Table01[[#This Row],[MÃ FAST]] -> 15TSG01NL300147 | R301: =COUNTIF($Q$7:Q301,Q301)&Q301 -> 115TSG01NL300147 | S301: =IFERROR(VLOOKUP(R301,Table1[[ct2]:[Số lượng]],13,0),0) -> 7.5 | T301: =IFERROR(VLOOKUP(R301,Table1[[ct2]:[Giá]],14,0),Table01[[#This Row],[ĐƠN GIÁ]]) -> 62000 | U301: =IFERROR((T301*S301),"0") -> 465000 | V301: =S301-K301 -> -0.7 | W301: =Table01[[#This Row],[THÀNH TIỀN FAST]]-Table01[[#This Row],[THÀNH TIỀN]] -> -43400 | X301: =Table01[[#This Row],[ĐG FAST]]=Table01[[#This Row],[ĐƠN GIÁ]] -> TRUE | Y301: =Table01[[#This Row],[THÀNH TIỀN FAST]]=Table01[[#This Row],[THÀNH TIỀN]] -> FALSE
M302: =K302*L302 -> 0 | N302: =VLOOKUP(I302,'MÃ '!$A$2:$E$1048576,4,0) -> #N/A | O302: =VLOOKUP(I302,'MÃ '!$A$2:$E$1048576,5,0) -> #N/A | P302: =$P$6 -> TSG01 | Q302: =DAY(Table01[[#This Row],[NGÀY]])&Table01[[#This Row],[TSG01]]&Table01[[#This Row],[MÃ FAST]] -> #N/A | R302: =COUNTIF($Q$7:Q302,Q302)&Q302 -> #N/A | S302: =IFERROR(VLOOKUP(R302,Table1[[ct2]:[Số lượng]],13,0),0) -> 0 | T302: =IFERROR(VLOOKUP(R302,Table1[[ct2]:[Giá]],14,0),Table01[[#This Row],[ĐƠN GIÁ]]) -> 0 | U302: =IFERROR((T302*S302),"0") -> 0 | V302: =S302-K302 -> 0 | W302: =Table01[[#This Row],[THÀNH TIỀN FAST]]-Table01[[#This Row],[THÀNH TIỀN]] -> 0 | X302: =Table01[[#This Row],[ĐG FAST]]=Table01[[#This Row],[ĐƠN GIÁ]] -> TRUE | Y302: =Table01[[#This Row],[THÀNH TIỀN FAST]]=Table01[[#This Row],[THÀNH TIỀN]] -> TRUE
M303: =K303*L303 -> 0 | N303: =VLOOKUP(I303,'MÃ '!$A$2:$E$1048576,4,0) -> #N/A | O303: =VLOOKUP(I303,'MÃ '!$A$2:$E$1048576,5,0) -> #N/A | P303: =$P$6 -> TSG01 | Q303: =DAY(Table01[[#This Row],[NGÀY]])&Table01[[#This Row],[TSG01]]&Table01[[#This Row],[MÃ FAST]] -> #N/A | R303: =COUNTIF($Q$7:Q303,Q303)&Q303 -> #N/A | S303: =IFERROR(VLOOKUP(R303,Table1[[ct2]:[Số lượng]],13,0),0) -> 0 | T303: =IFERROR(VLOOKUP(R303,Table1[[ct2]:[Giá]],14,0),Table01[[#This Row],[ĐƠN GIÁ]]) -> 0 | U303: =IFERROR((T303*S303),"0") -> 0 | V303: =S303-K303 -> 0 | W303: =Table01[[#This Row],[THÀNH TIỀN FAST]]-Table01[[#This Row],[THÀNH TIỀN]] -> 0 | X303: =Table01[[#This Row],[ĐG FAST]]=Table01[[#This Row],[ĐƠN GIÁ]] -> TRUE | Y303: =Table01[[#This Row],[THÀNH TIỀN FAST]]=Table01[[#This Row],[THÀNH TIỀN]] -> TRUE
M304: =K304*L304 -> 0 | N304: =VLOOKUP(I304,'MÃ '!$A$2:$E$1048576,4,0) -> #N/A | O304: =VLOOKUP(I304,'MÃ '!$A$2:$E$1048576,5,0) -> #N/A | P304: =$P$6 -> TSG01 | Q304: =DAY(Table01[[#This Row],[NGÀY]])&Table01[[#This Row],[TSG01]]&Table01[[#This Row],[MÃ FAST]] -> #N/A | R304: =COUNTIF($Q$7:Q304,Q304)&Q304 -> #N/A | S304: =IFERROR(VLOOKUP(R304,Table1[[ct2]:[Số lượng]],13,0),0) -> 0 | T304: =IFERROR(VLOOKUP(R304,Table1[[ct2]:[Giá]],14,0),Table01[[#This Row],[ĐƠN GIÁ]]) -> 0 | U304: =IFERROR((T304*S304),"0") -> 0 | V304: =S304-K304 -> 0 | W304: =Table01[[#This Row],[THÀNH TIỀN FAST]]-Table01[[#This Row],[THÀNH TIỀN]] -> 0 | X304: =Table01[[#This Row],[ĐG FAST]]=Table01[[#This Row],[ĐƠN GIÁ]] -> TRUE | Y304: =Table01[[#This Row],[THÀNH TIỀN FAST]]=Table01[[#This Row],[THÀNH TIỀN]] -> TRUE
M305: =K305*L305 -> 0 | N305: =VLOOKUP(I305,'MÃ '!$A$2:$E$1048576,4,0) -> #N/A | O305: =VLOOKUP(I305,'MÃ '!$A$2:$E$1048576,5,0) -> #N/A | P305: =$P$6 -> TSG01 | Q305: =DAY(Table01[[#This Row],[NGÀY]])&Table01[[#This Row],[TSG01]]&Table01[[#This Row],[MÃ FAST]] -> #N/A | R305: =COUNTIF($Q$7:Q305,Q305)&Q305 -> #N/A | S305: =IFERROR(VLOOKUP(R305,Table1[[ct2]:[Số lượng]],13,0),0) -> 0 | T305: =IFERROR(VLOOKUP(R305,Table1[[ct2]:[Giá]],14,0),Table01[[#This Row],[ĐƠN GIÁ]]) -> 0 | U305: =IFERROR((T305*S305),"0") -> 0 | V305: =S305-K305 -> 0 | W305: =Table01[[#This Row],[THÀNH TIỀN FAST]]-Table01[[#This Row],[THÀNH TIỀN]] -> 0 | X305: =Table01[[#This Row],[ĐG FAST]]=Table01[[#This Row],[ĐƠN GIÁ]] -> TRUE | Y305: =Table01[[#This Row],[THÀNH TIỀN FAST]]=Table01[[#This Row],[THÀNH TIỀN]] -> TRUE
M306: =K306*L306 -> 0 | N306: =VLOOKUP(I306,'MÃ '!$A$2:$E$1048576,4,0) -> #N/A | O306: =VLOOKUP(I306,'MÃ '!$A$2:$E$1048576,5,0) -> #N/A | P306: =$P$6 -> TSG01 | Q306: =DAY(Table01[[#This Row],[NGÀY]])&Table01[[#This Row],[TSG01]]&Table01[[#This Row],[MÃ FAST]] -> #N/A | R306: =COUNTIF($Q$7:Q306,Q306)&Q306 -> #N/A | S306: =IFERROR(VLOOKUP(R306,Table1[[ct2]:[Số lượng]],13,0),0) -> 0 | T306: =IFERROR(VLOOKUP(R306,Table1[[ct2]:[Giá]],14,0),Table01[[#This Row],[ĐƠN GIÁ]]) -> 0 | U306: =IFERROR((T306*S306),"0") -> 0 | V306: =S306-K306 -> 0 | W306: =Table01[[#This Row],[THÀNH TIỀN FAST]]-Table01[[#This Row],[THÀNH TIỀN]] -> 0 | X306: =Table01[[#This Row],[ĐG FAST]]=Table01[[#This Row],[ĐƠN GIÁ]] -> TRUE | Y306: =Table01[[#This Row],[THÀNH TIỀN FAST]]=Table01[[#This Row],[THÀNH TIỀN]] -> TRUE
M307: =K307*L307 -> 0 | N307: =VLOOKUP(I307,'MÃ '!$A$2:$E$1048576,4,0) -> #N/A | O307: =VLOOKUP(I307,'MÃ '!$A$2:$E$1048576,5,0) -> #N/A | P307: =$P$6 -> TSG01 | Q307: =DAY(Table01[[#This Row],[NGÀY]])&Table01[[#This Row],[TSG01]]&Table01[[#This Row],[MÃ FAST]] -> #N/A | R307: =COUNTIF($Q$7:Q307,Q307)&Q307 -> #N/A | S307: =IFERROR(VLOOKUP(R307,Table1[[ct2]:[Số lượng]],13,0),0) -> 0 | T307: =IFERROR(VLOOKUP(R307,Table1[[ct2]:[Giá]],14,0),Table01[[#This Row],[ĐƠN GIÁ]]) -> 0 | U307: =IFERROR((T307*S307),"0") -> 0 | V307: =S307-K307 -> 0 | W307: =Table01[[#This Row],[THÀNH TIỀN FAST]]-Table01[[#This Row],[THÀNH TIỀN]] -> 0 | X307: =Table01[[#This Row],[ĐG FAST]]=Table01[[#This Row],[ĐƠN GIÁ]] -> TRUE | Y307: =Table01[[#This Row],[THÀNH TIỀN FAST]]=Table01[[#This Row],[THÀNH TIỀN]] -> TRUE
M308: =K308*L308 -> 0 | N308: =VLOOKUP(I308,'MÃ '!$A$2:$E$1048576,4,0) -> #N/A | O308: =VLOOKUP(I308,'MÃ '!$A$2:$E$1048576,5,0) -> #N/A | P308: =$P$6 -> TSG01 | Q308: =DAY(Table01[[#This Row],[NGÀY]])&Table01[[#This Row],[TSG01]]&Table01[[#This Row],[MÃ FAST]] -> #N/A | R308: =COUNTIF($Q$7:Q308,Q308)&Q308 -> #N/A | S308: =IFERROR(VLOOKUP(R308,Table1[[ct2]:[Số lượng]],13,0),0) -> 0 | T308: =IFERROR(VLOOKUP(R308,Table1[[ct2]:[Giá]],14,0),Table01[[#This Row],[ĐƠN GIÁ]]) -> 0 | U308: =IFERROR((T308*S308),"0") -> 0 | V308: =S308-K308 -> 0 | W308: =Table01[[#This Row],[THÀNH TIỀN FAST]]-Table01[[#This Row],[THÀNH TIỀN]] -> 0 | X308: =Table01[[#This Row],[ĐG FAST]]=Table01[[#This Row],[ĐƠN GIÁ]] -> TRUE | Y308: =Table01[[#This Row],[THÀNH TIỀN FAST]]=Table01[[#This Row],[THÀNH TIỀN]] -> TRUE
M309: =K309*L309 -> 0 | N309: =VLOOKUP(I309,'MÃ '!$A$2:$E$1048576,4,0) -> #N/A | O309: =VLOOKUP(I309,'MÃ '!$A$2:$E$1048576,5,0) -> #N/A | P309: =$P$6 -> TSG01 | Q309: =DAY(Table01[[#This Row],[NGÀY]])&Table01[[#This Row],[TSG01]]&Table01[[#This Row],[MÃ FAST]] -> #N/A | R309: =COUNTIF($Q$7:Q309,Q309)&Q309 -> #N/A | S309: =IFERROR(VLOOKUP(R309,Table1[[ct2]:[Số lượng]],13,0),0) -> 0 | T309: =IFERROR(VLOOKUP(R309,Table1[[ct2]:[Giá]],14,0),Table01[[#This Row],[ĐƠN GIÁ]]) -> 0 | U309: =IFERROR((T309*S309),"0") -> 0 | V309: =S309-K309 -> 0 | W309: =Table01[[#This Row],[THÀNH TIỀN FAST]]-Table01[[#This Row],[THÀNH TIỀN]] -> 0 | X309: =Table01[[#This Row],[ĐG FAST]]=Table01[[#This Row],[ĐƠN GIÁ]] -> TRUE | Y309: =Table01[[#This Row],[THÀNH TIỀN FAST]]=Table01[[#This Row],[THÀNH TIỀN]] -> TRUE
M310: =K310*L310 -> 0 | N310: =VLOOKUP(I310,'MÃ '!$A$2:$E$1048576,4,0) -> #N/A | O310: =VLOOKUP(I310,'MÃ '!$A$2:$E$1048576,5,0) -> #N/A | P310: =$P$6 -> TSG01 | Q310: =DAY(Table01[[#This Row],[NGÀY]])&Table01[[#This Row],[TSG01]]&Table01[[#This Row],[MÃ FAST]] -> #N/A | R310: =COUNTIF($Q$7:Q310,Q310)&Q310 -> #N/A | S310: =IFERROR(VLOOKUP(R310,Table1[[ct2]:[Số lượng]],13,0),0) -> 0 | T310: =IFERROR(VLOOKUP(R310,Table1[[ct2]:[Giá]],14,0),Table01[[#This Row],[ĐƠN GIÁ]]) -> 0 | U310: =IFERROR((T310*S310),"0") -> 0 | V310: =S310-K310 -> 0 | W310: =Table01[[#This Row],[THÀNH TIỀN FAST]]-Table01[[#This Row],[THÀNH TIỀN]] -> 0 | X310: =Table01[[#This Row],[ĐG FAST]]=Table01[[#This Row],[ĐƠN GIÁ]] -> TRUE | Y310: =Table01[[#This Row],[THÀNH TIỀN FAST]]=Table01[[#This Row],[THÀNH TIỀN]] -> TRUE
M311: =K311*L311 -> 0 | N311: =VLOOKUP(I311,'MÃ '!$A$2:$E$1048576,4,0) -> #N/A | O311: =VLOOKUP(I311,'MÃ '!$A$2:$E$1048576,5,0) -> #N/A | P311: =$P$6 -> TSG01 | Q311: =DAY(Table01[[#This Row],[NGÀY]])&Table01[[#This Row],[TSG01]]&Table01[[#This Row],[MÃ FAST]] -> #N/A | R311: =COUNTIF($Q$7:Q311,Q311)&Q311 -> #N/A | S311: =IFERROR(VLOOKUP(R311,Table1[[ct2]:[Số lượng]],13,0),0) -> 0 | T311: =IFERROR(VLOOKUP(R311,Table1[[ct2]:[Giá]],14,0),Table01[[#This Row],[ĐƠN GIÁ]]) -> 0 | U311: =IFERROR((T311*S311),"0") -> 0 | V311: =S311-K311 -> 0 | W311: =Table01[[#This Row],[THÀNH TIỀN FAST]]-Table01[[#This Row],[THÀNH TIỀN]] -> 0 | X311: =Table01[[#This Row],[ĐG FAST]]=Table01[[#This Row],[ĐƠN GIÁ]] -> TRUE | Y311: =Table01[[#This Row],[THÀNH TIỀN FAST]]=Table01[[#This Row],[THÀNH TIỀN]] -> TRUE
M312: =K312*L312 -> 0 | N312: =VLOOKUP(I312,'MÃ '!$A$2:$E$1048576,4,0) -> #N/A | O312: =VLOOKUP(I312,'MÃ '!$A$2:$E$1048576,5,0) -> #N/A | P312: =$P$6 -> TSG01 | Q312: =DAY(Table01[[#This Row],[NGÀY]])&Table01[[#This Row],[TSG01]]&Table01[[#This Row],[MÃ FAST]] -> #N/A | R312: =COUNTIF($Q$7:Q312,Q312)&Q312 -> #N/A | S312: =IFERROR(VLOOKUP(R312,Table1[[ct2]:[Số lượng]],13,0),0) -> 0 | T312: =IFERROR(VLOOKUP(R312,Table1[[ct2]:[Giá]],14,0),Table01[[#This Row],[ĐƠN GIÁ]]) -> 0 | U312: =IFERROR((T312*S312),"0") -> 0 | V312: =S312-K312 -> 0 | W312: =Table01[[#This Row],[THÀNH TIỀN FAST]]-Table01[[#This Row],[THÀNH TIỀN]] -> 0 | X312: =Table01[[#This Row],[ĐG FAST]]=Table01[[#This Row],[ĐƠN GIÁ]] -> TRUE | Y312: =Table01[[#This Row],[THÀNH TIỀN FAST]]=Table01[[#This Row],[THÀNH TIỀN]] -> TRUE
M313: =K313*L313 -> 0 | N313: =VLOOKUP(I313,'MÃ '!$A$2:$E$1048576,4,0) -> #N/A | O313: =VLOOKUP(I313,'MÃ '!$A$2:$E$1048576,5,0) -> #N/A | P313: =$P$6 -> TSG01 | Q313: =DAY(Table01[[#This Row],[NGÀY]])&Table01[[#This Row],[TSG01]]&Table01[[#This Row],[MÃ FAST]] -> #N/A | R313: =COUNTIF($Q$7:Q313,Q313)&Q313 -> #N/A | S313: =IFERROR(VLOOKUP(R313,Table1[[ct2]:[Số lượng]],13,0),0) -> 0 | T313: =IFERROR(VLOOKUP(R313,Table1[[ct2]:[Giá]],14,0),Table01[[#This Row],[ĐƠN GIÁ]]) -> 0 | U313: =IFERROR((T313*S313),"0") -> 0 | V313: =S313-K313 -> 0 | W313: =Table01[[#This Row],[THÀNH TIỀN FAST]]-Table01[[#This Row],[THÀNH TIỀN]] -> 0 | X313: =Table01[[#This Row],[ĐG FAST]]=Table01[[#This Row],[ĐƠN GIÁ]] -> TRUE | Y313: =Table01[[#This Row],[THÀNH TIỀN FAST]]=Table01[[#This Row],[THÀNH TIỀN]] -> TRUE
... M1000: =K1000*L1000 -> 0 | N1000: =VLOOKUP(I1000,'MÃ '!$A$2:$E$1048576,4,0) -> #N/A | O1000: =VLOOKUP(I1000,'MÃ '!$A$2:$E$1048576,5,0) -> #N/A | P1000: =$P$6 -> TSG01 | Q1000: =DAY(Table01[[#This Row],[NGÀY]])&Table01[[#This Row],[TSG01]]&Table01[[#This Row],[MÃ FAST]] -> #N/A | R1000: =COUNTIF($Q$7:Q1000,Q1000)&Q1000 -> #N/A | S1000: =IFERROR(VLOOKUP(R1000,Table1[[ct2]:[Số lượng]],13,0),0) -> 0 | T1000: =IFERROR(VLOOKUP(R1000,Table1[[ct2]:[Giá]],14,0),Table01[[#This Row],[ĐƠN GIÁ]]) -> 0 | U1000: =IFERROR((T1000*S1000),"0") -> 0 | V1000: =S1000-K1000 -> 0 | W1000: =Table01[[#This Row],[THÀNH TIỀN FAST]]-Table01[[#This Row],[THÀNH TIỀN]] -> 0 | X1000: =Table01[[#This Row],[ĐG FAST]]=Table01[[#This Row],[ĐƠN GIÁ]] -> TRUE | Y1000: =Table01[[#This Row],[THÀNH TIỀN FAST]]=Table01[[#This Row],[THÀNH TIỀN]] -> TRUE

Sheet tsg6
A1: TRẦN GIA - TSG6 (landmark 81 )
X2: =W5/M5 -> -0.018797809
R3: =DAY(B301) -> 14
S4: =SUMIF(Table1[Mã nx],"tsg01",Table1[Đvt])=S5 -> FALSE | U4: =SUMIF(Table1[Mã nx],"tsg01",Table1[Giá báo])=U5 -> FALSE
K5: =SUM(K7:K1048576) -> 1219.94 | M5: =SUM(M7:M1048576) -> 47186350 | S5: =SUM(S7:S1048576) -> 1208.444 | U5: =SUM(U7:U1048576) -> 46299350 | V5: =SUM(V7:V1048576) -> -11.496 | W5: =SUM(W7:W1048576) -> -887000
A6: MÃ ĐƠN HÀNG | B6: NGÀY | C6: MÃ KH | D6: TÊN KH | E6: Line ID | F6: Barcode | G6: MÃ KHO | H6: MÃ HÀNG | I6: TÊN HÀNG | J6: ĐVT | K6: SL | L6: ĐƠN GIÁ | M6: THÀNH TIỀN | N6: MÃ FAST | O6: TÊN FAST | P6: TSG06 | Q6: CT1 | R6: CT2 | S6: THỰC NHẬN | T6: ĐG FAST | U6: THÀNH TIỀN FAST | V6: lệch sl | W6: lệch tổng tiền | X6: LỆCH ĐƠN GIÁ | Y6: CHECK | Z6: Column1
B7: 01/01/2026 | D7: TIANLONG 06 | I7: Bắp mỹ trái (Loại 1) | J7: Trái | K7: 10 | L7: 8500 | M7: =K7*L7 -> 85000 | N7: =VLOOKUP(I7,'MÃ '!$A$2:$E$1048576,4,0) -> NL300107 | O7: =VLOOKUP(I7,'MÃ '!$A$2:$E$1048576,5,0) -> Ngô ngọt ( Bắp trái) | P7: =$P$6 -> TSG06 | Q7: =DAY(Table014[[#This Row],[NGÀY]])&Table014[[#This Row],[TSG06]]&Table014[[#This Row],[MÃ FAST]] -> 1TSG06NL300107 | R7: =COUNTIF($Q$7:Q7,Q7)&Q7 -> 11TSG06NL300107 | S7: =IFERROR(VLOOKUP(R7,Table1[[ct2]:[Số lượng]],13,0),0) -> 10 | T7: =IFERROR(VLOOKUP(R7,Table1[[ct2]:[Giá]],14,0),Table014[[#This Row],[ĐƠN GIÁ]]) -> 8500 | U7: =IFERROR((T7*S7),"0") -> 85000 | V7: =S7-K7 -> 0 | W7: =Table014[[#This Row],[THÀNH TIỀN FAST]]-Table014[[#This Row],[THÀNH TIỀN]] -> 0 | X7: =Table014[[#This Row],[ĐG FAST]]=Table014[[#This Row],[ĐƠN GIÁ]] -> TRUE | Y7: =Table014[[#This Row],[THÀNH TIỀN FAST]]=Table014[[#This Row],[THÀNH TIỀN]] -> TRUE
B8: 01/01/2026 | D8: TIANLONG 06 | I8: Bí đỏ hồ lô | J8: Kg | K8: 1 | L8: 30000 | M8: =K8*L8 -> 30000 | N8: =VLOOKUP(I8,'MÃ '!$A$2:$E$1048576,4,0) -> NL300007 | O8: =VLOOKUP(I8,'MÃ '!$A$2:$E$1048576,5,0) -> Bí đỏ | P8: =$P$6 -> TSG06 | Q8: =DAY(Table014[[#This Row],[NGÀY]])&Table014[[#This Row],[TSG06]]&Table014[[#This Row],[MÃ FAST]] -> 1TSG06NL300007 | R8: =COUNTIF($Q$7:Q8,Q8)&Q8 -> 11TSG06NL300007 | S8: =IFERROR(VLOOKUP(R8,Table1[[ct2]:[Số lượng]],13,0),0) -> 1 | T8: =IFERROR(VLOOKUP(R8,Table1[[ct2]:[Giá]],14,0),Table014[[#This Row],[ĐƠN GIÁ]]) -> 30000 | U8: =IFERROR((T8*S8),"0") -> 30000 | V8: =S8-K8 -> 0 | W8: =Table014[[#This Row],[THÀNH TIỀN FAST]]-Table014[[#This Row],[THÀNH TIỀN]] -> 0 | X8: =Table014[[#This Row],[ĐG FAST]]=Table014[[#This Row],[ĐƠN GIÁ]] -> TRUE | Y8: =Table014[[#This Row],[THÀNH TIỀN FAST]]=Table014[[#This Row],[THÀNH TIỀN]] -> TRUE
B9: 01/01/2026 | D9: TIANLONG 06 | I9: Bó xôi (Nhà Lồng) | J9: Kg | K9: 4 | L9: 45000 | M9: =K9*L9 -> 180000 | N9: =VLOOKUP(I9,'MÃ '!$A$2:$E$1048576,4,0) -> NL300203 | O9: =VLOOKUP(I9,'MÃ '!$A$2:$E$1048576,5,0) -> Cải bó xôi | P9: =$P$6 -> TSG06 | Q9: =DAY(Table014[[#This Row],[NGÀY]])&Table014[[#This Row],[TSG06]]&Table014[[#This Row],[MÃ FAST]] -> 1TSG06NL300203 | R9: =COUNTIF($Q$7:Q9,Q9)&Q9 -> 11TSG06NL300203 | S9: =IFERROR(VLOOKUP(R9,Table1[[ct2]:[Số lượng]],13,0),0) -> 4 | T9: =IFERROR(VLOOKUP(R9,Table1[[ct2]:[Giá]],14,0),Table014[[#This Row],[ĐƠN GIÁ]]) -> 45000 | U9: =IFERROR((T9*S9),"0") -> 180000 | V9: =S9-K9 -> 0 | W9: =Table014[[#This Row],[THÀNH TIỀN FAST]]-Table014[[#This Row],[THÀNH TIỀN]] -> 0 | X9: =Table014[[#This Row],[ĐG FAST]]=Table014[[#This Row],[ĐƠN GIÁ]] -> TRUE | Y9: =Table014[[#This Row],[THÀNH TIỀN FAST]]=Table014[[#This Row],[THÀNH TIỀN]] -> TRUE
B10: 01/01/2026 | D10: TIANLONG 06 | I10: Cà chua | J10: Kg | K10: 1 | L10: 50000 | M10: =K10*L10 -> 50000 | N10: =VLOOKUP(I10,'MÃ '!$A$2:$E$1048576,4,0) -> NL300013 | O10: =VLOOKUP(I10,'MÃ '!$A$2:$E$1048576,5,0) -> Cà chua | P10: =$P$6 -> TSG06 | Q10: =DAY(Table014[[#This Row],[NGÀY]])&Table014[[#This Row],[TSG06]]&Table014[[#This Row],[MÃ FAST]] -> 1TSG06NL300013 | R10: =COUNTIF($Q$7:Q10,Q10)&Q10 -> 11TSG06NL300013 | S10: =IFERROR(VLOOKUP(R10,Table1[[ct2]:[Số lượng]],13,0),0) -> 1 | T10: =IFERROR(VLOOKUP(R10,Table1[[ct2]:[Giá]],14,0),Table014[[#This Row],[ĐƠN GIÁ]]) -> 50000 | U10: =IFERROR((T10*S10),"0") -> 50000 | V10: =S10-K10 -> 0 | W10: =Table014[[#This Row],[THÀNH TIỀN FAST]]-Table014[[#This Row],[THÀNH TIỀN]] -> 0 | X10: =Table014[[#This Row],[ĐG FAST]]=Table014[[#This Row],[ĐƠN GIÁ]] -> TRUE | Y10: =Table014[[#This Row],[THÀNH TIỀN FAST]]=Table014[[#This Row],[THÀNH TIỀN]] -> TRUE
B11: 01/01/2026 | D11: TIANLONG 06 | I11: Cải thảo | J11: Kg | K11: 16 | L11: 18000 | M11: =K11*L11 -> 288000 | N11: =VLOOKUP(I11,'MÃ '!$A$2:$E$1048576,4,0) -> NL300022 | O11: =VLOOKUP(I11,'MÃ '!$A$2:$E$1048576,5,0) -> Cải thảo | P11: =$P$6 -> TSG06 | Q11: =DAY(Table014[[#This Row],[NGÀY]])&Table014[[#This Row],[TSG06]]&Table014[[#This Row],[MÃ FAST]] -> 1TSG06NL300022 | R11: =COUNTIF($Q$7:Q11,Q11)&Q11 -> 11TSG06NL300022 | S11: =IFERROR(VLOOKUP(R11,Table1[[ct2]:[Số lượng]],13,0),0) -> 16 | T11: =IFERROR(VLOOKUP(R11,Table1[[ct2]:[Giá]],14,0),Table014[[#This Row],[ĐƠN GIÁ]]) -> 18000 | U11: =IFERROR((T11*S11),"0") -> 288000 | V11: =S11-K11 -> 0 | W11: =Table014[[#This Row],[THÀNH TIỀN FAST]]-Table014[[#This Row],[THÀNH TIỀN]] -> 0 | X11: =Table014[[#This Row],[ĐG FAST]]=Table014[[#This Row],[ĐƠN GIÁ]] -> TRUE | Y11: =Table014[[#This Row],[THÀNH TIỀN FAST]]=Table014[[#This Row],[THÀNH TIỀN]] -> TRUE
B12: 01/01/2026 | D12: TIANLONG 06 | I12: Cam vàng | J12: Kg | K12: 0.55 | L12: 75000 | M12: =K12*L12 -> 41250 | N12: =VLOOKUP(I12,'MÃ '!$A$2:$E$1048576,4,0) -> NL600067 | O12: =VLOOKUP(I12,'MÃ '!$A$2:$E$1048576,5,0) -> Cam vàng | P12: =$P$6 -> TSG06 | Q12: =DAY(Table014[[#This Row],[NGÀY]])&Table014[[#This Row],[TSG06]]&Table014[[#This Row],[MÃ FAST]] -> 1TSG06NL600067 | R12: =COUNTIF($Q$7:Q12,Q12)&Q12 -> 11TSG06NL600067 | S12: =IFERROR(VLOOKUP(R12,Table1[[ct2]:[Số lượng]],13,0),0) -> 0.55 | T12: =IFERROR(VLOOKUP(R12,Table1[[ct2]:[Giá]],14,0),Table014[[#This Row],[ĐƠN GIÁ]]) -> 75000 | U12: =IFERROR((T12*S12),"0") -> 41250 | V12: =S12-K12 -> 0 | W12: =Table014[[#This Row],[THÀNH TIỀN FAST]]-Table014[[#This Row],[THÀNH TIỀN]] -> 0 | X12: =Table014[[#This Row],[ĐG FAST]]=Table014[[#This Row],[ĐƠN GIÁ]] -> TRUE | Y12: =Table014[[#This Row],[THÀNH TIỀN FAST]]=Table014[[#This Row],[THÀNH TIỀN]] -> TRUE
B13: 01/01/2026 | D13: TIANLONG 06 | I13: Chanh không hạt | J13: Kg | K13: 0.5 | L13: 22000 | M13: =K13*L13 -> 11000 | N13: =VLOOKUP(I13,'MÃ '!$A$2:$E$1048576,4,0) -> NL300029 | O13: =VLOOKUP(I13,'MÃ '!$A$2:$E$1048576,5,0) -> Chanh | P13: =$P$6 -> TSG06 | Q13: =DAY(Table014[[#This Row],[NGÀY]])&Table014[[#This Row],[TSG06]]&Table014[[#This Row],[MÃ FAST]] -> 1TSG06NL300029 | R13: =COUNTIF($Q$7:Q13,Q13)&Q13 -> 11TSG06NL300029 | S13: =IFERROR(VLOOKUP(R13,Table1[[ct2]:[Số lượng]],13,0),0) -> 0.5 | T13: =IFERROR(VLOOKUP(R13,Table1[[ct2]:[Giá]],14,0),Table014[[#This Row],[ĐƠN GIÁ]]) -> 22000 | U13: =IFERROR((T13*S13),"0") -> 11000 | V13: =S13-K13 -> 0 | W13: =Table014[[#This Row],[THÀNH TIỀN FAST]]-Table014[[#This Row],[THÀNH TIỀN]] -> 0 | X13: =Table014[[#This Row],[ĐG FAST]]=Table014[[#This Row],[ĐƠN GIÁ]] -> TRUE | Y13: =Table014[[#This Row],[THÀNH TIỀN FAST]]=Table014[[#This Row],[THÀNH TIỀN]] -> TRUE
B14: 01/01/2026 | D14: TIANLONG 06 | I14: Củ cải trắng (Loại 1) | J14: Kg | K14: 3.3 | L14: 13000 | M14: =K14*L14 -> 42900 | N14: =VLOOKUP(I14,'MÃ '!$A$2:$E$1048576,4,0) -> NL300033 | O14: =VLOOKUP(I14,'MÃ '!$A$2:$E$1048576,5,0) -> Củ cải trắng | P14: =$P$6 -> TSG06 | Q14: =DAY(Table014[[#This Row],[NGÀY]])&Table014[[#This Row],[TSG06]]&Table014[[#This Row],[MÃ FAST]] -> 1TSG06NL300033 | R14: =COUNTIF($Q$7:Q14,Q14)&Q14 -> 11TSG06NL300033 | S14: =IFERROR(VLOOKUP(R14,Table1[[ct2]:[Số lượng]],13,0),0) -> 3.3 | T14: =IFERROR(VLOOKUP(R14,Table1[[ct2]:[Giá]],14,0),Table014[[#This Row],[ĐƠN GIÁ]]) -> 13000 | U14: =IFERROR((T14*S14),"0") -> 42900 | V14: =S14-K14 -> 0 | W14: =Table014[[#This Row],[THÀNH TIỀN FAST]]-Table014[[#This Row],[THÀNH TIỀN]] -> 0 | X14: =Table014[[#This Row],[ĐG FAST]]=Table014[[#This Row],[ĐƠN GIÁ]] -> TRUE | Y14: =Table014[[#This Row],[THÀNH TIỀN FAST]]=Table014[[#This Row],[THÀNH TIỀN]] -> TRUE
B15: 01/01/2026 | D15: TIANLONG 06 | I15: Củ sen | J15: Kg | K15: 2.1 | L15: 47000 | M15: =K15*L15 -> 98700 | N15: =VLOOKUP(I15,'MÃ '!$A$2:$E$1048576,4,0) -> NL300036 | O15: =VLOOKUP(I15,'MÃ '!$A$2:$E$1048576,5,0) -> Củ sen | P15: =$P$6 -> TSG06 | Q15: =DAY(Table014[[#This Row],[NGÀY]])&Table014[[#This Row],[TSG06]]&Table014[[#This Row],[MÃ FAST]] -> 1TSG06NL300036 | R15: =COUNTIF($Q$7:Q15,Q15)&Q15 -> 11TSG06NL300036 | S15: =IFERROR(VLOOKUP(R15,Table1[[ct2]:[Số lượng]],13,0),0) -> 2.1 | T15: =IFERROR(VLOOKUP(R15,Table1[[ct2]:[Giá]],14,0),Table014[[#This Row],[ĐƠN GIÁ]]) -> 47000 | U15: =IFERROR((T15*S15),"0") -> 98700 | V15: =S15-K15 -> 0 | W15: =Table014[[#This Row],[THÀNH TIỀN FAST]]-Table014[[#This Row],[THÀNH TIỀN]] -> 0 | X15: =Table014[[#This Row],[ĐG FAST]]=Table014[[#This Row],[ĐƠN GIÁ]] -> TRUE | Y15: =Table014[[#This Row],[THÀNH TIỀN FAST]]=Table014[[#This Row],[THÀNH TIỀN]] -> TRUE
B16: 01/01/2026 | D16: TIANLONG 06 | I16: Dưa hấu | J16: Kg | K16: 45 | L16: 18000 | M16: =K16*L16 -> 810000 | N16: =VLOOKUP(I16,'MÃ '!$A$2:$E$1048576,4,0) -> NL600004 | O16: =VLOOKUP(I16,'MÃ '!$A$2:$E$1048576,5,0) -> Dưa hấu | P16: =$P$6 -> TSG06 | Q16: =DAY(Table014[[#This Row],[NGÀY]])&Table014[[#This Row],[TSG06]]&Table014[[#This Row],[MÃ FAST]] -> 1TSG06NL600004 | R16: =COUNTIF($Q$7:Q16,Q16)&Q16 -> 11TSG06NL600004 | S16: =IFERROR(VLOOKUP(R16,Table1[[ct2]:[Số lượng]],13,0),0) -> 45 | T16: =IFERROR(VLOOKUP(R16,Table1[[ct2]:[Giá]],14,0),Table014[[#This Row],[ĐƠN GIÁ]]) -> 18000 | U16: =IFERROR((T16*S16),"0") -> 810000 | V16: =S16-K16 -> 0 | W16: =Table014[[#This Row],[THÀNH TIỀN FAST]]-Table014[[#This Row],[THÀNH TIỀN]] -> 0 | X16: =Table014[[#This Row],[ĐG FAST]]=Table014[[#This Row],[ĐƠN GIÁ]] -> TRUE | Y16: =Table014[[#This Row],[THÀNH TIỀN FAST]]=Table014[[#This Row],[THÀNH TIỀN]] -> TRUE
B17: 01/01/2026 | D17: TIANLONG 06 | I17: Hành lá | J17: Kg | K17: 2 | L17: 55000 | M17: =K17*L17 -> 110000 | N17: =VLOOKUP(I17,'MÃ '!$A$2:$E$1048576,4,0) -> NL300058 | O17: =VLOOKUP(I17,'MÃ '!$A$2:$E$1048576,5,0) -> Hành lá | P17: =$P$6 -> TSG06 | Q17: =DAY(Table014[[#This Row],[NGÀY]])&Table014[[#This Row],[TSG06]]&Table014[[#This Row],[MÃ FAST]] -> 1TSG06NL300058 | R17: =COUNTIF($Q$7:Q17,Q17)&Q17 -> 11TSG06NL300058 | S17: =IFERROR(VLOOKUP(R17,Table1[[ct2]:[Số lượng]],13,0),0) -> 2 | T17: =IFERROR(VLOOKUP(R17,Table1[[ct2]:[Giá]],14,0),Table014[[#This Row],[ĐƠN GIÁ]]) -> 55000 | U17: =IFERROR((T17*S17),"0") -> 110000 | V17: =S17-K17 -> 0 | W17: =Table014[[#This Row],[THÀNH TIỀN FAST]]-Table014[[#This Row],[THÀNH TIỀN]] -> 0 | X17: =Table014[[#This Row],[ĐG FAST]]=Table014[[#This Row],[ĐƠN GIÁ]] -> TRUE | Y17: =Table014[[#This Row],[THÀNH TIỀN FAST]]=Table014[[#This Row],[THÀNH TIỀN]] -> TRUE
B18: 01/01/2026 | D18: TIANLONG 06 | I18: Hoa cúc tím | J18: Bó | K18: 1 | L18: 80000 | M18: =K18*L18 -> 80000 | N18: =VLOOKUP(I18,'MÃ '!$A$2:$E$1048576,4,0) -> NL300218 | O18: =VLOOKUP(I18,'MÃ '!$A$2:$E$1048576,5,0) -> Hoa cúc (decor) bó | P18: =$P$6 -> TSG06 | Q18: =DAY(Table014[[#This Row],[NGÀY]])&Table014[[#This Row],[TSG06]]&Table014[[#This Row],[MÃ FAST]] -> 1TSG06NL300218 | R18: =COUNTIF($Q$7:Q18,Q18)&Q18 -> 11TSG06NL300218 | S18: =IFERROR(VLOOKUP(R18,Table1[[ct2]:[Số lượng]],13,0),0) -> 1 | T18: =IFERROR(VLOOKUP(R18,Table1[[ct2]:[Giá]],14,0),Table014[[#This Row],[ĐƠN GIÁ]]) -> 40000 | U18: =IFERROR((T18*S18),"0") -> 40000 | V18: =S18-K18 -> 0 | W18: =Table014[[#This Row],[THÀNH TIỀN FAST]]-Table014[[#This Row],[THÀNH TIỀN]] -> -40000 | X18: =Table014[[#This Row],[ĐG FAST]]=Table014[[#This Row],[ĐƠN GIÁ]] -> FALSE | Y18: =Table014[[#This Row],[THÀNH TIỀN FAST]]=Table014[[#This Row],[THÀNH TIỀN]] -> FALSE
... B322: 15/01/2026 | D322: TIANLONG 06 | I322: Xà lách romain | J322: Kg | K322: 5 | L322: 62000 | M322: =K322*L322 -> 310000 | N322: =VLOOKUP(I322,'MÃ '!$A$2:$E$1048576,4,0) -> NL300147 | O322: =VLOOKUP(I322,'MÃ '!$A$2:$E$1048576,5,0) -> Xà lách Roman | P322: =$P$6 -> TSG06 | Q322: =DAY(Table014[[#This Row],[NGÀY]])&Table014[[#This Row],[TSG06]]&Table014[[#This Row],[MÃ FAST]] -> 15TSG06NL300147 | R322: =COUNTIF($Q$7:Q322,Q322)&Q322 -> 115TSG06NL300147 | S322: =IFERROR(VLOOKUP(R322,Table1[[ct2]:[Số lượng]],13,0),0) -> 5 | T322: =IFERROR(VLOOKUP(R322,Table1[[ct2]:[Giá]],14,0),Table014[[#This Row],[ĐƠN GIÁ]]) -> 62000 | U322: =IFERROR((T322*S322),"0") -> 310000 | V322: =S322-K322 -> 0 | W322: =Table014[[#This Row],[THÀNH TIỀN FAST]]-Table014[[#This Row],[THÀNH TIỀN]] -> 0 | X322: =Table014[[#This Row],[ĐG FAST]]=Table014[[#This Row],[ĐƠN GIÁ]] -> TRUE | Y322: =Table014[[#This Row],[THÀNH TIỀN FAST]]=Table014[[#This Row],[THÀNH TIỀN]] -> TRUE
M323: =K323*L323 -> 0 | N323: =VLOOKUP(I323,'MÃ '!$A$2:$E$1048576,4,0) -> #N/A | O323: =VLOOKUP(I323,'MÃ '!$A$2:$E$1048576,5,0) -> #N/A | P323: =$P$6 -> TSG06 | Q323: =DAY(Table014[[#This Row],[NGÀY]])&Table014[[#This Row],[TSG06]]&Table014[[#This Row],[MÃ FAST]] -> #N/A | R323: =COUNTIF($Q$7:Q323,Q323)&Q323 -> #N/A | S323: =IFERROR(VLOOKUP(R323,Table1[[ct2]:[Số lượng]],13,0),0) -> 0 | T323: =IFERROR(VLOOKUP(R323,Table1[[ct2]:[Giá]],14,0),Table014[[#This Row],[ĐƠN GIÁ]]) -> 0 | U323: =IFERROR((T323*S323),"0") -> 0 | V323: =S323-K323 -> 0 | W323: =Table014[[#This Row],[THÀNH TIỀN FAST]]-Table014[[#This Row],[THÀNH TIỀN]] -> 0 | X323: =Table014[[#This Row],[ĐG FAST]]=Table014[[#This Row],[ĐƠN GIÁ]] -> TRUE | Y323: =Table014[[#This Row],[THÀNH TIỀN FAST]]=Table014[[#This Row],[THÀNH TIỀN]] -> TRUE
M324: =K324*L324 -> 0 | N324: =VLOOKUP(I324,'MÃ '!$A$2:$E$1048576,4,0) -> #N/A | O324: =VLOOKUP(I324,'MÃ '!$A$2:$E$1048576,5,0) -> #N/A | P324: =$P$6 -> TSG06 | Q324: =DAY(Table014[[#This Row],[NGÀY]])&Table014[[#This Row],[TSG06]]&Table014[[#This Row],[MÃ FAST]] -> #N/A | R324: =COUNTIF($Q$7:Q324,Q324)&Q324 -> #N/A | S324: =IFERROR(VLOOKUP(R324,Table1[[ct2]:[Số lượng]],13,0),0) -> 0 | T324: =IFERROR(VLOOKUP(R324,Table1[[ct2]:[Giá]],14,0),Table014[[#This Row],[ĐƠN GIÁ]]) -> 0 | U324: =IFERROR((T324*S324),"0") -> 0 | V324: =S324-K324 -> 0 | W324: =Table014[[#This Row],[THÀNH TIỀN FAST]]-Table014[[#This Row],[THÀNH TIỀN]] -> 0 | X324: =Table014[[#This Row],[ĐG FAST]]=Table014[[#This Row],[ĐƠN GIÁ]] -> TRUE | Y324: =Table014[[#This Row],[THÀNH TIỀN FAST]]=Table014[[#This Row],[THÀNH TIỀN]] -> TRUE
M325: =K325*L325 -> 0 | N325: =VLOOKUP(I325,'MÃ '!$A$2:$E$1048576,4,0) -> #N/A | O325: =VLOOKUP(I325,'MÃ '!$A$2:$E$1048576,5,0) -> #N/A | P325: =$P$6 -> TSG06 | Q325: =DAY(Table014[[#This Row],[NGÀY]])&Table014[[#This Row],[TSG06]]&Table014[[#This Row],[MÃ FAST]] -> #N/A | R325: =COUNTIF($Q$7:Q325,Q325)&Q325 -> #N/A | S325: =IFERROR(VLOOKUP(R325,Table1[[ct2]:[Số lượng]],13,0),0) -> 0 | T325: =IFERROR(VLOOKUP(R325,Table1[[ct2]:[Giá]],14,0),Table014[[#This Row],[ĐƠN GIÁ]]) -> 0 | U325: =IFERROR((T325*S325),"0") -> 0 | V325: =S325-K325 -> 0 | W325: =Table014[[#This Row],[THÀNH TIỀN FAST]]-Table014[[#This Row],[THÀNH TIỀN]] -> 0 | X325: =Table014[[#This Row],[ĐG FAST]]=Table014[[#This Row],[ĐƠN GIÁ]] -> TRUE | Y325: =Table014[[#This Row],[THÀNH TIỀN FAST]]=Table014[[#This Row],[THÀNH TIỀN]] -> TRUE
M326: =K326*L326 -> 0 | N326: =VLOOKUP(I326,'MÃ '!$A$2:$E$1048576,4,0) -> #N/A | O326: =VLOOKUP(I326,'MÃ '!$A$2:$E$1048576,5,0) -> #N/A | P326: =$P$6 -> TSG06 | Q326: =DAY(Table014[[#This Row],[NGÀY]])&Table014[[#This Row],[TSG06]]&Table014[[#This Row],[MÃ FAST]] -> #N/A | R326: =COUNTIF($Q$7:Q326,Q326)&Q326 -> #N/A | S326: =IFERROR(VLOOKUP(R326,Table1[[ct2]:[Số lượng]],13,0),0) -> 0 | T326: =IFERROR(VLOOKUP(R326,Table1[[ct2]:[Giá]],14,0),Table014[[#This Row],[ĐƠN GIÁ]]) -> 0 | U326: =IFERROR((T326*S326),"0") -> 0 | V326: =S326-K326 -> 0 | W326: =Table014[[#This Row],[THÀNH TIỀN FAST]]-Table014[[#This Row],[THÀNH TIỀN]] -> 0 | X326: =Table014[[#This Row],[ĐG FAST]]=Table014[[#This Row],[ĐƠN GIÁ]] -> TRUE | Y326: =Table014[[#This Row],[THÀNH TIỀN FAST]]=Table014[[#This Row],[THÀNH TIỀN]] -> TRUE
M327: =K327*L327 -> 0 | N327: =VLOOKUP(I327,'MÃ '!$A$2:$E$1048576,4,0) -> #N/A | O327: =VLOOKUP(I327,'MÃ '!$A$2:$E$1048576,5,0) -> #N/A | P327: =$P$6 -> TSG06 | Q327: =DAY(Table014[[#This Row],[NGÀY]])&Table014[[#This Row],[TSG06]]&Table014[[#This Row],[MÃ FAST]] -> #N/A | R327: =COUNTIF($Q$7:Q327,Q327)&Q327 -> #N/A | S327: =IFERROR(VLOOKUP(R327,Table1[[ct2]:[Số lượng]],13,0),0) -> 0 | T327: =IFERROR(VLOOKUP(R327,Table1[[ct2]:[Giá]],14,0),Table014[[#This Row],[ĐƠN GIÁ]]) -> 0 | U327: =IFERROR((T327*S327),"0") -> 0 | V327: =S327-K327 -> 0 | W327: =Table014[[#This Row],[THÀNH TIỀN FAST]]-Table014[[#This Row],[THÀNH TIỀN]] -> 0 | X327: =Table014[[#This Row],[ĐG FAST]]=Table014[[#This Row],[ĐƠN GIÁ]] -> TRUE | Y327: =Table014[[#This Row],[THÀNH TIỀN FAST]]=Table014[[#This Row],[THÀNH TIỀN]] -> TRUE
M328: =K328*L328 -> 0 | N328: =VLOOKUP(I328,'MÃ '!$A$2:$E$1048576,4,0) -> #N/A | O328: =VLOOKUP(I328,'MÃ '!$A$2:$E$1048576,5,0) -> #N/A | P328: =$P$6 -> TSG06 | Q328: =DAY(Table014[[#This Row],[NGÀY]])&Table014[[#This Row],[TSG06]]&Table014[[#This Row],[MÃ FAST]] -> #N/A | R328: =COUNTIF($Q$7:Q328,Q328)&Q328 -> #N/A | S328: =IFERROR(VLOOKUP(R328,Table1[[ct2]:[Số lượng]],13,0),0) -> 0 | T328: =IFERROR(VLOOKUP(R328,Table1[[ct2]:[Giá]],14,0),Table014[[#This Row],[ĐƠN GIÁ]]) -> 0 | U328: =IFERROR((T328*S328),"0") -> 0 | V328: =S328-K328 -> 0 | W328: =Table014[[#This Row],[THÀNH TIỀN FAST]]-Table014[[#This Row],[THÀNH TIỀN]] -> 0 | X328: =Table014[[#This Row],[ĐG FAST]]=Table014[[#This Row],[ĐƠN GIÁ]] -> TRUE | Y328: =Table014[[#This Row],[THÀNH TIỀN FAST]]=Table014[[#This Row],[THÀNH TIỀN]] -> TRUE
M329: =K329*L329 -> 0 | N329: =VLOOKUP(I329,'MÃ '!$A$2:$E$1048576,4,0) -> #N/A | O329: =VLOOKUP(I329,'MÃ '!$A$2:$E$1048576,5,0) -> #N/A | P329: =$P$6 -> TSG06 | Q329: =DAY(Table014[[#This Row],[NGÀY]])&Table014[[#This Row],[TSG06]]&Table014[[#This Row],[MÃ FAST]] -> #N/A | R329: =COUNTIF($Q$7:Q329,Q329)&Q329 -> #N/A | S329: =IFERROR(VLOOKUP(R329,Table1[[ct2]:[Số lượng]],13,0),0) -> 0 | T329: =IFERROR(VLOOKUP(R329,Table1[[ct2]:[Giá]],14,0),Table014[[#This Row],[ĐƠN GIÁ]]) -> 0 | U329: =IFERROR((T329*S329),"0") -> 0 | V329: =S329-K329 -> 0 | W329: =Table014[[#This Row],[THÀNH TIỀN FAST]]-Table014[[#This Row],[THÀNH TIỀN]] -> 0 | X329: =Table014[[#This Row],[ĐG FAST]]=Table014[[#This Row],[ĐƠN GIÁ]] -> TRUE | Y329: =Table014[[#This Row],[THÀNH TIỀN FAST]]=Table014[[#This Row],[THÀNH TIỀN]] -> TRUE
M330: =K330*L330 -> 0 | N330: =VLOOKUP(I330,'MÃ '!$A$2:$E$1048576,4,0) -> #N/A | O330: =VLOOKUP(I330,'MÃ '!$A$2:$E$1048576,5,0) -> #N/A | P330: =$P$6 -> TSG06 | Q330: =DAY(Table014[[#This Row],[NGÀY]])&Table014[[#This Row],[TSG06]]&Table014[[#This Row],[MÃ FAST]] -> #N/A | R330: =COUNTIF($Q$7:Q330,Q330)&Q330 -> #N/A | S330: =IFERROR(VLOOKUP(R330,Table1[[ct2]:[Số lượng]],13,0),0) -> 0 | T330: =IFERROR(VLOOKUP(R330,Table1[[ct2]:[Giá]],14,0),Table014[[#This Row],[ĐƠN GIÁ]]) -> 0 | U330: =IFERROR((T330*S330),"0") -> 0 | V330: =S330-K330 -> 0 | W330: =Table014[[#This Row],[THÀNH TIỀN FAST]]-Table014[[#This Row],[THÀNH TIỀN]] -> 0 | X330: =Table014[[#This Row],[ĐG FAST]]=Table014[[#This Row],[ĐƠN GIÁ]] -> TRUE | Y330: =Table014[[#This Row],[THÀNH TIỀN FAST]]=Table014[[#This Row],[THÀNH TIỀN]] -> TRUE
M331: =K331*L331 -> 0 | N331: =VLOOKUP(I331,'MÃ '!$A$2:$E$1048576,4,0) -> #N/A | O331: =VLOOKUP(I331,'MÃ '!$A$2:$E$1048576,5,0) -> #N/A | P331: =$P$6 -> TSG06 | Q331: =DAY(Table014[[#This Row],[NGÀY]])&Table014[[#This Row],[TSG06]]&Table014[[#This Row],[MÃ FAST]] -> #N/A | R331: =COUNTIF($Q$7:Q331,Q331)&Q331 -> #N/A | S331: =IFERROR(VLOOKUP(R331,Table1[[ct2]:[Số lượng]],13,0),0) -> 0 | T331: =IFERROR(VLOOKUP(R331,Table1[[ct2]:[Giá]],14,0),Table014[[#This Row],[ĐƠN GIÁ]]) -> 0 | U331: =IFERROR((T331*S331),"0") -> 0 | V331: =S331-K331 -> 0 | W331: =Table014[[#This Row],[THÀNH TIỀN FAST]]-Table014[[#This Row],[THÀNH TIỀN]] -> 0 | X331: =Table014[[#This Row],[ĐG FAST]]=Table014[[#This Row],[ĐƠN GIÁ]] -> TRUE | Y331: =Table014[[#This Row],[THÀNH TIỀN FAST]]=Table014[[#This Row],[THÀNH TIỀN]] -> TRUE
M332: =K332*L332 -> 0 | N332: =VLOOKUP(I332,'MÃ '!$A$2:$E$1048576,4,0) -> #N/A | O332: =VLOOKUP(I332,'MÃ '!$A$2:$E$1048576,5,0) -> #N/A | P332: =$P$6 -> TSG06 | Q332: =DAY(Table014[[#This Row],[NGÀY]])&Table014[[#This Row],[TSG06]]&Table014[[#This Row],[MÃ FAST]] -> #N/A | R332: =COUNTIF($Q$7:Q332,Q332)&Q332 -> #N/A | S332: =IFERROR(VLOOKUP(R332,Table1[[ct2]:[Số lượng]],13,0),0) -> 0 | T332: =IFERROR(VLOOKUP(R332,Table1[[ct2]:[Giá]],14,0),Table014[[#This Row],[ĐƠN GIÁ]]) -> 0 | U332: =IFERROR((T332*S332),"0") -> 0 | V332: =S332-K332 -> 0 | W332: =Table014[[#This Row],[THÀNH TIỀN FAST]]-Table014[[#This Row],[THÀNH TIỀN]] -> 0 | X332: =Table014[[#This Row],[ĐG FAST]]=Table014[[#This Row],[ĐƠN GIÁ]] -> TRUE | Y332: =Table014[[#This Row],[THÀNH TIỀN FAST]]=Table014[[#This Row],[THÀNH TIỀN]] -> TRUE
M333: =K333*L333 -> 0 | N333: =VLOOKUP(I333,'MÃ '!$A$2:$E$1048576,4,0) -> #N/A | O333: =VLOOKUP(I333,'MÃ '!$A$2:$E$1048576,5,0) -> #N/A | P333: =$P$6 -> TSG06 | Q333: =DAY(Table014[[#This Row],[NGÀY]])&Table014[[#This Row],[TSG06]]&Table014[[#This Row],[MÃ FAST]] -> #N/A | R333: =COUNTIF($Q$7:Q333,Q333)&Q333 -> #N/A | S333: =IFERROR(VLOOKUP(R333,Table1[[ct2]:[Số lượng]],13,0),0) -> 0 | T333: =IFERROR(VLOOKUP(R333,Table1[[ct2]:[Giá]],14,0),Table014[[#This Row],[ĐƠN GIÁ]]) -> 0 | U333: =IFERROR((T333*S333),"0") -> 0 | V333: =S333-K333 -> 0 | W333: =Table014[[#This Row],[THÀNH TIỀN FAST]]-Table014[[#This Row],[THÀNH TIỀN]] -> 0 | X333: =Table014[[#This Row],[ĐG FAST]]=Table014[[#This Row],[ĐƠN GIÁ]] -> TRUE | Y333: =Table014[[#This Row],[THÀNH TIỀN FAST]]=Table014[[#This Row],[THÀNH TIỀN]] -> TRUE
M334: =K334*L334 -> 0 | N334: =VLOOKUP(I334,'MÃ '!$A$2:$E$1048576,4,0) -> #N/A | O334: =VLOOKUP(I334,'MÃ '!$A$2:$E$1048576,5,0) -> #N/A | P334: =$P$6 -> TSG06 | Q334: =DAY(Table014[[#This Row],[NGÀY]])&Table014[[#This Row],[TSG06]]&Table014[[#This Row],[MÃ FAST]] -> #N/A | R334: =COUNTIF($Q$7:Q334,Q334)&Q334 -> #N/A | S334: =IFERROR(VLOOKUP(R334,Table1[[ct2]:[Số lượng]],13,0),0) -> 0 | T334: =IFERROR(VLOOKUP(R334,Table1[[ct2]:[Giá]],14,0),Table014[[#This Row],[ĐƠN GIÁ]]) -> 0 | U334: =IFERROR((T334*S334),"0") -> 0 | V334: =S334-K334 -> 0 | W334: =Table014[[#This Row],[THÀNH TIỀN FAST]]-Table014[[#This Row],[THÀNH TIỀN]] -> 0 | X334: =Table014[[#This Row],[ĐG FAST]]=Table014[[#This Row],[ĐƠN GIÁ]] -> TRUE | Y334: =Table014[[#This Row],[THÀNH TIỀN FAST]]=Table014[[#This Row],[THÀNH TIỀN]] -> TRUE
... M1000: =K1000*L1000 -> 0 | N1000: =VLOOKUP(I1000,'MÃ '!$A$2:$E$1048576,4,0) -> #N/A | O1000: =VLOOKUP(I1000,'MÃ '!$A$2:$E$1048576,5,0) -> #N/A | P1000: =$P$6 -> TSG06 | Q1000: =DAY(Table014[[#This Row],[NGÀY]])&Table014[[#This Row],[TSG06]]&Table014[[#This Row],[MÃ FAST]] -> #N/A | R1000: =COUNTIF($Q$7:Q1000,Q1000)&Q1000 -> #N/A | S1000: =IFERROR(VLOOKUP(R1000,Table1[[ct2]:[Số lượng]],13,0),0) -> 0 | T1000: =IFERROR(VLOOKUP(R1000,Table1[[ct2]:[Giá]],14,0),Table014[[#This Row],[ĐƠN GIÁ]]) -> 0 | U1000: =IFERROR((T1000*S1000),"0") -> 0 | V1000: =S1000-K1000 -> 0 | W1000: =Table014[[#This Row],[THÀNH TIỀN FAST]]-Table014[[#This Row],[THÀNH TIỀN]] -> 0 | X1000: =Table014[[#This Row],[ĐG FAST]]=Table014[[#This Row],[ĐƠN GIÁ]] -> TRUE | Y1000: =Table014[[#This Row],[THÀNH TIỀN FAST]]=Table014[[#This Row],[THÀNH TIỀN]] -> TRUE

Sheet tsg8
A1: TRẦN GIA - TSG8 ( nguyễn đình chiểu )
X2: =W5/M5 -> -0.0094206188
R3: =DAY(B301) -> 15
S4: =SUMIF(Table1[Mã nx],"tsg01",Table1[Đvt])=S5 -> FALSE | U4: =SUMIF(Table1[Mã nx],"tsg01",Table1[Giá báo])=U5 -> FALSE
K5: =SUM(K7:K1048576) -> 1509.67 | M5: =SUM(M7:M1048576) -> 59014170 | S5: =SUM(S7:S1048576) -> 1492.32 | U5: =SUM(U7:U1048576) -> 58458220 | V5: =SUM(V7:V1048576) -> -17.35 | W5: =SUM(W7:W1048576) -> -555950
A6: MÃ ĐƠN HÀNG | B6: NGÀY | C6: MÃ KH | D6: TÊN KH | E6: Line ID | F6: Barcode | G6: MÃ KHO | H6: MÃ HÀNG | I6: TÊN HÀNG | J6: ĐVT | K6: SL | L6: ĐƠN GIÁ | M6: THÀNH TIỀN | N6: MÃ FAST | O6: TÊN FAST | P6: TSG08 | Q6: CT1 | R6: CT2 | S6: THỰC NHẬN | T6: ĐG FAST | U6: THÀNH TIỀN FAST | V6: lệch sl | W6: lệch tổng tiền | X6: LỆCH ĐƠN GIÁ | Y6: CHECK | Z6: Column1
B7: 01/01/2026 | D7: TIANLONG 08 | I7: Bắp mỹ trái (Loại 1) | J7: Trái | K7: 8 | L7: 8500 | M7: =K7*L7 -> 68000 | N7: =VLOOKUP(I7,'MÃ '!$A$2:$E$1048576,4,0) -> NL300107 | O7: =VLOOKUP(I7,'MÃ '!$A$2:$E$1048576,5,0) -> Ngô ngọt ( Bắp trái) | P7: =$P$6 -> TSG08 | Q7: =DAY(Table0145[[#This Row],[NGÀY]])&Table0145[[#This Row],[TSG08]]&Table0145[[#This Row],[MÃ FAST]] -> 1TSG08NL300107 | R7: =COUNTIF($Q$7:Q7,Q7)&Q7 -> 11TSG08NL300107 | S7: =IFERROR(VLOOKUP(R7,Table1[[ct2]:[Số lượng]],13,0),0) -> 8 | T7: =IFERROR(VLOOKUP(R7,Table1[[ct2]:[Giá]],14,0),Table0145[[#This Row],[ĐƠN GIÁ]]) -> 8500 | U7: =IFERROR((T7*S7),"0") -> 68000 | V7: =S7-K7 -> 0 | W7: =Table0145[[#This Row],[THÀNH TIỀN FAST]]-Table0145[[#This Row],[THÀNH TIỀN]] -> 0 | X7: =Table0145[[#This Row],[ĐG FAST]]=Table0145[[#This Row],[ĐƠN GIÁ]] -> TRUE | Y7: =Table0145[[#This Row],[THÀNH TIỀN FAST]]=Table0145[[#This Row],[THÀNH TIỀN]] -> TRUE
B8: 01/01/2026 | D8: TIANLONG 08 | I8: Bó xôi (Nhà Lồng) | J8: Kg | K8: 2.7 | L8: 45000 | M8: =K8*L8 -> 121500 | N8: =VLOOKUP(I8,'MÃ '!$A$2:$E$1048576,4,0) -> NL300203 | O8: =VLOOKUP(I8,'MÃ '!$A$2:$E$1048576,5,0) -> Cải bó xôi | P8: =$P$6 -> TSG08 | Q8: =DAY(Table0145[[#This Row],[NGÀY]])&Table0145[[#This Row],[TSG08]]&Table0145[[#This Row],[MÃ FAST]] -> 1TSG08NL300203 | R8: =COUNTIF($Q$7:Q8,Q8)&Q8 -> 11TSG08NL300203 | S8: =IFERROR(VLOOKUP(R8,Table1[[ct2]:[Số lượng]],13,0),0) -> 2.7 | T8: =IFERROR(VLOOKUP(R8,Table1[[ct2]:[Giá]],14,0),Table0145[[#This Row],[ĐƠN GIÁ]]) -> 45000 | U8: =IFERROR((T8*S8),"0") -> 121500 | V8: =S8-K8 -> 0 | W8: =Table0145[[#This Row],[THÀNH TIỀN FAST]]-Table0145[[#This Row],[THÀNH TIỀN]] -> 0 | X8: =Table0145[[#This Row],[ĐG FAST]]=Table0145[[#This Row],[ĐƠN GIÁ]] -> TRUE | Y8: =Table0145[[#This Row],[THÀNH TIỀN FAST]]=Table0145[[#This Row],[THÀNH TIỀN]] -> TRUE
B9: 01/01/2026 | D9: TIANLONG 08 | I9: Cà chua | J9: Kg | K9: 1 | L9: 50000 | M9: =K9*L9 -> 50000 | N9: =VLOOKUP(I9,'MÃ '!$A$2:$E$1048576,4,0) -> NL300013 | O9: =VLOOKUP(I9,'MÃ '!$A$2:$E$1048576,5,0) -> Cà chua | P9: =$P$6 -> TSG08 | Q9: =DAY(Table0145[[#This Row],[NGÀY]])&Table0145[[#This Row],[TSG08]]&Table0145[[#This Row],[MÃ FAST]] -> 1TSG08NL300013 | R9: =COUNTIF($Q$7:Q9,Q9)&Q9 -> 11TSG08NL300013 | S9: =IFERROR(VLOOKUP(R9,Table1[[ct2]:[Số lượng]],13,0),0) -> 1 | T9: =IFERROR(VLOOKUP(R9,Table1[[ct2]:[Giá]],14,0),Table0145[[#This Row],[ĐƠN GIÁ]]) -> 50000 | U9: =IFERROR((T9*S9),"0") -> 50000 | V9: =S9-K9 -> 0 | W9: =Table0145[[#This Row],[THÀNH TIỀN FAST]]-Table0145[[#This Row],[THÀNH TIỀN]] -> 0 | X9: =Table0145[[#This Row],[ĐG FAST]]=Table0145[[#This Row],[ĐƠN GIÁ]] -> TRUE | Y9: =Table0145[[#This Row],[THÀNH TIỀN FAST]]=Table0145[[#This Row],[THÀNH TIỀN]] -> TRUE
B10: 01/01/2026 | D10: TIANLONG 08 | I10: Cải thảo | J10: Kg | K10: 12 | L10: 18000 | M10: =K10*L10 -> 216000 | N10: =VLOOKUP(I10,'MÃ '!$A$2:$E$1048576,4,0) -> NL300022 | O10: =VLOOKUP(I10,'MÃ '!$A$2:$E$1048576,5,0) -> Cải thảo | P10: =$P$6 -> TSG08 | Q10: =DAY(Table0145[[#This Row],[NGÀY]])&Table0145[[#This Row],[TSG08]]&Table0145[[#This Row],[MÃ FAST]] -> 1TSG08NL300022 | R10: =COUNTIF($Q$7:Q10,Q10)&Q10 -> 11TSG08NL300022 | S10: =IFERROR(VLOOKUP(R10,Table1[[ct2]:[Số lượng]],13,0),0) -> 12 | T10: =IFERROR(VLOOKUP(R10,Table1[[ct2]:[Giá]],14,0),Table0145[[#This Row],[ĐƠN GIÁ]]) -> 18000 | U10: =IFERROR((T10*S10),"0") -> 216000 | V10: =S10-K10 -> 0 | W10: =Table0145[[#This Row],[THÀNH TIỀN FAST]]-Table0145[[#This Row],[THÀNH TIỀN]] -> 0 | X10: =Table0145[[#This Row],[ĐG FAST]]=Table0145[[#This Row],[ĐƠN GIÁ]] -> TRUE | Y10: =Table0145[[#This Row],[THÀNH TIỀN FAST]]=Table0145[[#This Row],[THÀNH TIỀN]] -> TRUE
B11: 01/01/2026 | D11: TIANLONG 08 | I11: Chanh Dây | J11: Kg | K11: 0.5 | L11: 34000 | M11: =K11*L11 -> 17000 | N11: =VLOOKUP(I11,'MÃ '!$A$2:$E$1048576,4,0) -> NL300030 | O11: =VLOOKUP(I11,'MÃ '!$A$2:$E$1048576,5,0) -> Chanh dây (chanh leo) | P11: =$P$6 -> TSG08 | Q11: =DAY(Table0145[[#This Row],[NGÀY]])&Table0145[[#This Row],[TSG08]]&Table0145[[#This Row],[MÃ FAST]] -> 1TSG08NL300030 | R11: =COUNTIF($Q$7:Q11,Q11)&Q11 -> 11TSG08NL300030 | S11: =IFERROR(VLOOKUP(R11,Table1[[ct2]:[Số lượng]],13,0),0) -> 0.5 | T11: =IFERROR(VLOOKUP(R11,Table1[[ct2]:[Giá]],14,0),Table0145[[#This Row],[ĐƠN GIÁ]]) -> 34000 | U11: =IFERROR((T11*S11),"0") -> 17000 | V11: =S11-K11 -> 0 | W11: =Table0145[[#This Row],[THÀNH TIỀN FAST]]-Table0145[[#This Row],[THÀNH TIỀN]] -> 0 | X11: =Table0145[[#This Row],[ĐG FAST]]=Table0145[[#This Row],[ĐƠN GIÁ]] -> TRUE | Y11: =Table0145[[#This Row],[THÀNH TIỀN FAST]]=Table0145[[#This Row],[THÀNH TIỀN]] -> TRUE
B12: 01/01/2026 | D12: TIANLONG 08 | I12: Chanh vàng | J12: Kg | K12: 0.5 | L12: 95000 | M12: =K12*L12 -> 47500 | N12: =VLOOKUP(I12,'MÃ '!$A$2:$E$1048576,4,0) -> NL600068 | O12: =VLOOKUP(I12,'MÃ '!$A$2:$E$1048576,5,0) -> Chanh vàng | P12: =$P$6 -> TSG08 | Q12: =DAY(Table0145[[#This Row],[NGÀY]])&Table0145[[#This Row],[TSG08]]&Table0145[[#This Row],[MÃ FAST]] -> 1TSG08NL600068 | R12: =COUNTIF($Q$7:Q12,Q12)&Q12 -> 11TSG08NL600068 | S12: =IFERROR(VLOOKUP(R12,Table1[[ct2]:[Số lượng]],13,0),0) -> 0.5 | T12: =IFERROR(VLOOKUP(R12,Table1[[ct2]:[Giá]],14,0),Table0145[[#This Row],[ĐƠN GIÁ]]) -> 95000 | U12: =IFERROR((T12*S12),"0") -> 47500 | V12: =S12-K12 -> 0 | W12: =Table0145[[#This Row],[THÀNH TIỀN FAST]]-Table0145[[#This Row],[THÀNH TIỀN]] -> 0 | X12: =Table0145[[#This Row],[ĐG FAST]]=Table0145[[#This Row],[ĐƠN GIÁ]] -> TRUE | Y12: =Table0145[[#This Row],[THÀNH TIỀN FAST]]=Table0145[[#This Row],[THÀNH TIỀN]] -> TRUE
B13: 01/01/2026 | D13: TIANLONG 08 | I13: Củ cải trắng (Loại 1) | J13: Kg | K13: 0.9 | L13: 13000 | M13: =K13*L13 -> 11700 | N13: =VLOOKUP(I13,'MÃ '!$A$2:$E$1048576,4,0) -> NL300033 | O13: =VLOOKUP(I13,'MÃ '!$A$2:$E$1048576,5,0) -> Củ cải trắng | P13: =$P$6 -> TSG08 | Q13: =DAY(Table0145[[#This Row],[NGÀY]])&Table0145[[#This Row],[TSG08]]&Table0145[[#This Row],[MÃ FAST]] -> 1TSG08NL300033 | R13: =COUNTIF($Q$7:Q13,Q13)&Q13 -> 11TSG08NL300033 | S13: =IFERROR(VLOOKUP(R13,Table1[[ct2]:[Số lượng]],13,0),0) -> 0.9 | T13: =IFERROR(VLOOKUP(R13,Table1[[ct2]:[Giá]],14,0),Table0145[[#This Row],[ĐƠN GIÁ]]) -> 13000 | U13: =IFERROR((T13*S13),"0") -> 11700 | V13: =S13-K13 -> 0 | W13: =Table0145[[#This Row],[THÀNH TIỀN FAST]]-Table0145[[#This Row],[THÀNH TIỀN]] -> 0 | X13: =Table0145[[#This Row],[ĐG FAST]]=Table0145[[#This Row],[ĐƠN GIÁ]] -> TRUE | Y13: =Table0145[[#This Row],[THÀNH TIỀN FAST]]=Table0145[[#This Row],[THÀNH TIỀN]] -> TRUE
B14: 01/01/2026 | D14: TIANLONG 08 | I14: Củ sen | J14: Kg | K14: 0.9 | L14: 47000 | M14: =K14*L14 -> 42300 | N14: =VLOOKUP(I14,'MÃ '!$A$2:$E$1048576,4,0) -> NL300036 | O14: =VLOOKUP(I14,'MÃ '!$A$2:$E$1048576,5,0) -> Củ sen | P14: =$P$6 -> TSG08 | Q14: =DAY(Table0145[[#This Row],[NGÀY]])&Table0145[[#This Row],[TSG08]]&Table0145[[#This Row],[MÃ FAST]] -> 1TSG08NL300036 | R14: =COUNTIF($Q$7:Q14,Q14)&Q14 -> 11TSG08NL300036 | S14: =IFERROR(VLOOKUP(R14,Table1[[ct2]:[Số lượng]],13,0),0) -> 0.9 | T14: =IFERROR(VLOOKUP(R14,Table1[[ct2]:[Giá]],14,0),Table0145[[#This Row],[ĐƠN GIÁ]]) -> 47000 | U14: =IFERROR((T14*S14),"0") -> 42300 | V14: =S14-K14 -> 0 | W14: =Table0145[[#This Row],[THÀNH TIỀN FAST]]-Table0145[[#This Row],[THÀNH TIỀN]] -> 0 | X14: =Table0145[[#This Row],[ĐG FAST]]=Table0145[[#This Row],[ĐƠN GIÁ]] -> TRUE | Y14: =Table0145[[#This Row],[THÀNH TIỀN FAST]]=Table0145[[#This Row],[THÀNH TIỀN]] -> TRUE
B15: 01/01/2026 | D15: TIANLONG 08 | I15: Dưa hấu | J15: Kg | K15: 50 | L15: 18000 | M15: =K15*L15 -> 900000 | N15: =VLOOKUP(I15,'MÃ '!$A$2:$E$1048576,4,0) -> NL600004 | O15: =VLOOKUP(I15,'MÃ '!$A$2:$E$1048576,5,0) -> Dưa hấu | P15: =$P$6 -> TSG08 | Q15: =DAY(Table0145[[#This Row],[NGÀY]])&Table0145[[#This Row],[TSG08]]&Table0145[[#This Row],[MÃ FAST]] -> 1TSG08NL600004 | R15: =COUNTIF($Q$7:Q15,Q15)&Q15 -> 11TSG08NL600004 | S15: =IFERROR(VLOOKUP(R15,Table1[[ct2]:[Số lượng]],13,0),0) -> 50 | T15: =IFERROR(VLOOKUP(R15,Table1[[ct2]:[Giá]],14,0),Table0145[[#This Row],[ĐƠN GIÁ]]) -> 18000 | U15: =IFERROR((T15*S15),"0") -> 900000 | V15: =S15-K15 -> 0 | W15: =Table0145[[#This Row],[THÀNH TIỀN FAST]]-Table0145[[#This Row],[THÀNH TIỀN]] -> 0 | X15: =Table0145[[#This Row],[ĐG FAST]]=Table0145[[#This Row],[ĐƠN GIÁ]] -> TRUE | Y15: =Table0145[[#This Row],[THÀNH TIỀN FAST]]=Table0145[[#This Row],[THÀNH TIỀN]] -> TRUE
B16: 01/01/2026 | D16: TIANLONG 08 | I16: Gừng còn vỏ VN | J16: Kg | K16: 0.4 | L16: 30000 | M16: =K16*L16 -> 12000 | N16: =VLOOKUP(I16,'MÃ '!$A$2:$E$1048576,4,0) -> NL300053 | O16: =VLOOKUP(I16,'MÃ '!$A$2:$E$1048576,5,0) -> Gừng ta | P16: =$P$6 -> TSG08 | Q16: =DAY(Table0145[[#This Row],[NGÀY]])&Table0145[[#This Row],[TSG08]]&Table0145[[#This Row],[MÃ FAST]] -> 1TSG08NL300053 | R16: =COUNTIF($Q$7:Q16,Q16)&Q16 -> 11TSG08NL300053 | S16: =IFERROR(VLOOKUP(R16,Table1[[ct2]:[Số lượng]],13,0),0) -> 0.4 | T16: =IFERROR(VLOOKUP(R16,Table1[[ct2]:[Giá]],14,0),Table0145[[#This Row],[ĐƠN GIÁ]]) -> 30000 | U16: =IFERROR((T16*S16),"0") -> 12000 | V16: =S16-K16 -> 0 | W16: =Table0145[[#This Row],[THÀNH TIỀN FAST]]-Table0145[[#This Row],[THÀNH TIỀN]] -> 0 | X16: =Table0145[[#This Row],[ĐG FAST]]=Table0145[[#This Row],[ĐƠN GIÁ]] -> TRUE | Y16: =Table0145[[#This Row],[THÀNH TIỀN FAST]]=Table0145[[#This Row],[THÀNH TIỀN]] -> TRUE
B17: 01/01/2026 | D17: TIANLONG 08 | I17: Hành lá | J17: Kg | K17: 2 | L17: 55000 | M17: =K17*L17 -> 110000 | N17: =VLOOKUP(I17,'MÃ '!$A$2:$E$1048576,4,0) -> NL300058 | O17: =VLOOKUP(I17,'MÃ '!$A$2:$E$1048576,5,0) -> Hành lá | P17: =$P$6 -> TSG08 | Q17: =DAY(Table0145[[#This Row],[NGÀY]])&Table0145[[#This Row],[TSG08]]&Table0145[[#This Row],[MÃ FAST]] -> 1TSG08NL300058 | R17: =COUNTIF($Q$7:Q17,Q17)&Q17 -> 11TSG08NL300058 | S17: =IFERROR(VLOOKUP(R17,Table1[[ct2]:[Số lượng]],13,0),0) -> 2 | T17: =IFERROR(VLOOKUP(R17,Table1[[ct2]:[Giá]],14,0),Table0145[[#This Row],[ĐƠN GIÁ]]) -> 55000 | U17: =IFERROR((T17*S17),"0") -> 110000 | V17: =S17-K17 -> 0 | W17: =Table0145[[#This Row],[THÀNH TIỀN FAST]]-Table0145[[#This Row],[THÀNH TIỀN]] -> 0 | X17: =Table0145[[#This Row],[ĐG FAST]]=Table0145[[#This Row],[ĐƠN GIÁ]] -> TRUE | Y17: =Table0145[[#This Row],[THÀNH TIỀN FAST]]=Table0145[[#This Row],[THÀNH TIỀN]] -> TRUE
B18: 01/01/2026 | D18: TIANLONG 08 | I18: Khoai môn cao | J18: Kg | K18: 1.7 | L18: 30000 | M18: =K18*L18 -> 51000 | N18: =VLOOKUP(I18,'MÃ '!$A$2:$E$1048576,4,0) -> NL300209 | O18: =VLOOKUP(I18,'MÃ '!$A$2:$E$1048576,5,0) -> Khoai môn | P18: =$P$6 -> TSG08 | Q18: =DAY(Table0145[[#This Row],[NGÀY]])&Table0145[[#This Row],[TSG08]]&Table0145[[#This Row],[MÃ FAST]] -> 1TSG08NL300209 | R18: =COUNTIF($Q$7:Q18,Q18)&Q18 -> 11TSG08NL300209 | S18: =IFERROR(VLOOKUP(R18,Table1[[ct2]:[Số lượng]],13,0),0) -> 1.7 | T18: =IFERROR(VLOOKUP(R18,Table1[[ct2]:[Giá]],14,0),Table0145[[#This Row],[ĐƠN GIÁ]]) -> 30000 | U18: =IFERROR((T18*S18),"0") -> 51000 | V18: =S18-K18 -> 0 | W18: =Table0145[[#This Row],[THÀNH TIỀN FAST]]-Table0145[[#This Row],[THÀNH TIỀN]] -> 0 | X18: =Table0145[[#This Row],[ĐG FAST]]=Table0145[[#This Row],[ĐƠN GIÁ]] -> TRUE | Y18: =Table0145[[#This Row],[THÀNH TIỀN FAST]]=Table0145[[#This Row],[THÀNH TIỀN]] -> TRUE
... B306: 15/01/2026 | D306: TIANLONG 08 | I306: Xà lách romain | J306: Kg | K306: 10 | L306: 62000 | M306: =K306*L306 -> 620000 | N306: =VLOOKUP(I306,'MÃ '!$A$2:$E$1048576,4,0) -> NL300147 | O306: =VLOOKUP(I306,'MÃ '!$A$2:$E$1048576,5,0) -> Xà lách Roman | P306: =$P$6 -> TSG08 | Q306: =DAY(Table0145[[#This Row],[NGÀY]])&Table0145[[#This Row],[TSG08]]&Table0145[[#This Row],[MÃ FAST]] -> 15TSG08NL300147 | R306: =COUNTIF($Q$7:Q306,Q306)&Q306 -> 115TSG08NL300147 | S306: =IFERROR(VLOOKUP(R306,Table1[[ct2]:[Số lượng]],13,0),0) -> 10 | T306: =IFERROR(VLOOKUP(R306,Table1[[ct2]:[Giá]],14,0),Table0145[[#This Row],[ĐƠN GIÁ]]) -> 62000 | U306: =IFERROR((T306*S306),"0") -> 620000 | V306: =S306-K306 -> 0 | W306: =Table0145[[#This Row],[THÀNH TIỀN FAST]]-Table0145[[#This Row],[THÀNH TIỀN]] -> 0 | X306: =Table0145[[#This Row],[ĐG FAST]]=Table0145[[#This Row],[ĐƠN GIÁ]] -> TRUE | Y306: =Table0145[[#This Row],[THÀNH TIỀN FAST]]=Table0145[[#This Row],[THÀNH TIỀN]] -> TRUE
M307: =K307*L307 -> 0 | N307: =VLOOKUP(I307,'MÃ '!$A$2:$E$1048576,4,0) -> #N/A | O307: =VLOOKUP(I307,'MÃ '!$A$2:$E$1048576,5,0) -> #N/A | P307: =$P$6 -> TSG08 | Q307: =DAY(Table0145[[#This Row],[NGÀY]])&Table0145[[#This Row],[TSG08]]&Table0145[[#This Row],[MÃ FAST]] -> #N/A | R307: =COUNTIF($Q$7:Q307,Q307)&Q307 -> #N/A | S307: =IFERROR(VLOOKUP(R307,Table1[[ct2]:[Số lượng]],13,0),0) -> 0 | T307: =IFERROR(VLOOKUP(R307,Table1[[ct2]:[Giá]],14,0),Table0145[[#This Row],[ĐƠN GIÁ]]) -> 0 | U307: =IFERROR((T307*S307),"0") -> 0 | V307: =S307-K307 -> 0 | W307: =Table0145[[#This Row],[THÀNH TIỀN FAST]]-Table0145[[#This Row],[THÀNH TIỀN]] -> 0 | X307: =Table0145[[#This Row],[ĐG FAST]]=Table0145[[#This Row],[ĐƠN GIÁ]] -> TRUE | Y307: =Table0145[[#This Row],[THÀNH TIỀN FAST]]=Table0145[[#This Row],[THÀNH TIỀN]] -> TRUE
