Workbook

Sheet LW 1
D2: CÔNG TY TNHH NÔNG SẢN THỰC PHẨM TRẦN GIA HTX: Ấp Lộc Tiến, Xã Mỹ Lộc, Huyện Cần Giuộc, Tỉnh Long An VP: Tòa nhà An Phú Plaza, 117-119 Lý Chính Thắng, P.7. Q.3, TP.HCM Kho sơ chế: 30 Kha Vạn Cân, P. Hiệp Bình Chánh, TP.Thủ Đức, TP.HCM Kho Đà Lạt: 69 Trần Thủ Độ, TT Liên Nghĩa, Huyện Đức Trọng, Tỉnh Lâm Đồng. Website: rausachtrangia.com - Hotline: 090.245.8081
A4: CHI TIẾT ĐỐI CHIẾU CÔNG NỢ
A6: Từ ngày 1 tháng 01 đến ngày 15 tháng 01 năm 2026
A8: Tên Khách hàng: LONGWANG 1
A10: Địa chỉ:
A12: Người liên hệ: Email:
J13: =SUBTOTAL(9,J15:J612) -> 78283295
A14: NGÀY | B14: MÃ KHÁCH HÀNG | C14: TÊN KHÁCH HÀNG | D14: MÃ ĐƠN HÀNG | E14: MÃ HÀNG | F14: TÊN HÀNG | G14: ĐVT | H14: SỐ LƯỢNG | I14: ĐƠN GIÁ | J14: THÀNH TIỀN | K14: GHI CHÚ
A15: 01/01/2026 | B15: TG-KS00333 | C15: LONGWANG 1 | D15: TG-AA20661 | E15: I100253 | F15: Bánh ướt | G15: Kg | H15: 5 | I15: 15000 | J15: =H15*I15 -> 75000
A16: 01/01/2026 | B16: TG-KS00333 | C16: LONGWANG 1 | D16: TG-AA20661 | E16: I100008 | F16: Bắp mỹ trái (Loại 1) | G16: Trái | H16: 20 | I16: 8500 | J16: =H16*I16 -> 170000
A17: 01/01/2026 | B17: TG-KS00333 | C17: LONGWANG 1 | D17: TG-AA20661 | E17: I100016 | F17: Bí ngòi xanh | G17: Kg | H17: 18 | I17: 40000 | J17: =H17*I17 -> 720000
A18: 01/01/2026 | B18: TG-KS00333 | C18: LONGWANG 1 | D18: TG-AA20661 | E18: I100024 | F18: Bông cải xanh | G18: Kg | H18: 3.3 | I18: 52000 | J18: =H18*I18 -> 171600
A19: 01/01/2026 | B19: TG-KS00333 | C19: LONGWANG 1 | D19: TG-AA20661 | E19: I100045 | F19: Cải Hongkong(Cai ngong) | G19: Kg | H19: 4 | I19: 30000 | J19: =H19*I19 -> 120000
A20: 01/01/2026 | B20: TG-KS00333 | C20: LONGWANG 1 | D20: TG-AA20661 | E20: I100469 | F20: Cam vàng | G20: Kg | H20: 0.9 | I20: 75000 | J20: =H20*I20 -> 67500
A21: 01/01/2026 | B21: TG-KS00333 | C21: LONGWANG 1 | D21: TG-AA20661 | E21: I100057 | F21: Cần tây | G21: Kg | H21: 2 | I21: 44000 | J21: =H21*I21 -> 88000
A22: 01/01/2026 | B22: TG-KS00333 | C22: LONGWANG 1 | D22: TG-AA20661 | E22: I100474 | F22: Chanh Dây | G22: Kg | H22: 1 | I22: 34000 | J22: =H22*I22 -> 34000
A23: 01/01/2026 | B23: TG-KS00333 | C23: LONGWANG 1 | D23: TG-AA20661 | E23: I100062 | F23: Chanh vàng | G23: Kg | H23: 0.3 | I23: 95000 | J23: =H23*I23 -> 28500
A24: 01/01/2026 | B24: TG-KS00333 | C24: LONGWANG 1 | D24: TG-AA20661 | E24: I100097 | F24: Củ Gừng | G24: Kg | H24: 2 | I24: 38000 | J24: =H24*I24 -> 76000
A25: 01/01/2026 | B25: TG-KS00333 | C25: LONGWANG 1 | D25: TG-AA20661 | E25: I100072 | F25: Củ riềng | G25: Kg | H25: 0.1 | I25: 25000 | J25: =H25*I25 -> 2500
A26: 01/01/2026 | B26: TG-KS00333 | C26: LONGWANG 1 | D26: TG-AA20661 | E26: I100074 | F26: Củ sen | G26: Kg | H26: 3 | I26: 47000 | J26: =H26*I26 -> 141000
... A612: 15/01/2026 | B612: TG-KS00333 | C612: LONGWANG 1 | D612: TG-AA23224 | E612: I100194 | F612: Rau tía tô | G612: Kg | H612: 0.2 | I612: 36000 | J612: =H612*I612 -> 7200

Sheet GMT
D2: CÔNG TY TNHH NÔNG SẢN THỰC PHẨM TRẦN GIA HTX: Ấp Lộc Tiến, Xã Mỹ Lộc, Huyện Cần Giuộc, Tỉnh Long An VP: Tòa nhà An Phú Plaza, 117-119 Lý Chính Thắng, P.7. Q.3, TP.HCM Kho sơ chế: 30 Kha Vạn Cân, P. Hiệp Bình Chánh, TP.Thủ Đức, TP.HCM Kho Đà Lạt: 69 Trần Thủ Độ, TT Liên Nghĩa, Huyện Đức Trọng, Tỉnh Lâm Đồng. Website: rausachtrangia.com - Hotline: 090.245.8081
A4: CHI TIẾT ĐỐI CHIẾU CÔNG NỢ
A6: Từ ngày 1 tháng 01 đến ngày 15 tháng 01 năm 2026
A8: Tên Khách hàng: G-MASTER NƯỚNG
A10: Địa chỉ:
A12: Người liên hệ: Email:
J13: =SUBTOTAL(9,J15:J387) -> 27361370 | N13: GSG01 | O13: =SUBTOTAL(9,O15:O908) -> 23526920 | P13: =O13-Sheet2!N1 -> 0
A14: NGÀY | B14: MÃ KHÁCH HÀNG | C14: TÊN KHÁCH HÀNG | D14: MÃ ĐƠN HÀNG | E14: MÃ HÀNG | F14: TÊN HÀNG | G14: ĐVT | H14: SỐ LƯỢNG | I14: ĐƠN GIÁ | J14: THÀNH TIỀN | K14: GHI CHÚ | L14: MÃ | M14: THỰC NHẬN | N14: GIÁ CHỐT | O14: TỔNG | P14: LỆCH | Q14: NOTE | U14: SAI SL | V14: SAI GIÁ CHỐT
A15: 01/01/2026 | B15: TG-KS01254 | C15: G-MASTER NƯỚNG | D15: TG-AA20733 | E15: I100003 | F15: Bắp cải trắng | G15: Kg | H15: 4.6 | I15: 19000 | J15: =H15*I15 -> 87400 | L15: =+VLOOKUP(E15,mã!$B$2:$F$229,2,0) -> NL300004 | M15: =+VLOOKUP(T15,Sheet2!$B$2:$P$372,10,0) -> 4.6 | N15: =+VLOOKUP(L15,mã!$C$2:$F$229,4,0) -> 19000 | O15: =M15*N15 -> 87400 | P15: =J15-O15 -> 0 | Q15: =IF(U15=0," ","SAI SL NHẬN") | R15: =+VLOOKUP(T15,Sheet2!$B$2:$P$372,13,0) -> 87400 | S15: =O15-R15 -> 0 | T15: =A15&L15 -> 01/01/2026NL300004 | U15: =H15-M15 -> 0 | V15: =I15-N15 -> 0
A16: 01/01/2026 | B16: TG-KS01254 | C16: G-MASTER NƯỚNG | D16: TG-AA20733 | E16: I100008 | F16: Bắp mỹ trái (Loại 1) | G16: Trái | H16: 25 | I16: 8500 | J16: =H16*I16 -> 212500 | L16: =+VLOOKUP(E16,mã!$B$2:$F$229,2,0) -> NL300107 | M16: =+VLOOKUP(T16,Sheet2!$B$2:$P$372,10,0) -> 20 | N16: =+VLOOKUP(L16,mã!$C$2:$F$229,4,0) -> 8500 | O16: =M16*N16 -> 170000 | P16: =J16-O16 -> 42500 | Q16: =IF(U16=0," ","SAI SL NHẬN") -> SAI SL NHẬN | R16: =+VLOOKUP(T16,Sheet2!$B$2:$P$372,13,0) -> 170000 | S16: =O16-R16 -> 0 | T16: =A16&L16 -> 01/01/2026NL300107 | U16: =H16-M16 -> 5 | V16: =I16-N16 -> 0
A17: 01/01/2026 | B17: TG-KS01254 | C17: G-MASTER NƯỚNG | D17: TG-AA20733 | E17: I100012 | F17: Bí đỏ hồ lô | G17: Kg | H17: 2.9 | I17: 30000 | J17: =H17*I17 -> 87000 | L17: =+VLOOKUP(E17,mã!$B$2:$F$229,2,0) -> NL300007 | M17: =+VLOOKUP(T17,Sheet2!$B$2:$P$372,10,0) -> 2.9 | N17: =+VLOOKUP(L17,mã!$C$2:$F$229,4,0) -> 30000 | O17: =M17*N17 -> 87000 | P17: =J17-O17 -> 0 | Q17: =IF(U17=0," ","SAI SL NHẬN") | R17: =+VLOOKUP(T17,Sheet2!$B$2:$P$372,13,0) -> 87000 | S17: =O17-R17 -> 0 | T17: =A17&L17 -> 01/01/2026NL300007 | U17: =H17-M17 -> 0 | V17: =I17-N17 -> 0
A18: 01/01/2026 | B18: TG-KS01254 | C18: G-MASTER NƯỚNG | D18: TG-AA20733 | E18: I100016 | F18: Bí ngòi xanh | G18: Kg | H18: 3.1 | I18: 40000 | J18: =H18*I18 -> 124000 | L18: =+VLOOKUP(E18,mã!$B$2:$F$229,2,0) -> NL300008 | M18: =+VLOOKUP(T18,Sheet2!$B$2:$P$372,10,0) -> 3.1 | N18: =+VLOOKUP(L18,mã!$C$2:$F$229,4,0) -> 40000 | O18: =M18*N18 -> 124000 | P18: =J18-O18 -> 0 | Q18: =IF(U18=0," ","SAI SL NHẬN") | R18: =+VLOOKUP(T18,Sheet2!$B$2:$P$372,13,0) -> 124000 | S18: =O18-R18 -> 0 | T18: =A18&L18 -> 01/01/2026NL300008 | U18: =H18-M18 -> 0 | V18: =I18-N18 -> 0
A19: 01/01/2026 | B19: TG-KS01254 | C19: G-MASTER NƯỚNG | D19: TG-AA20733 | E19: I100034 | F19: Cà chua | G19: Kg | H19: 1 | I19: 50000 | J19: =H19*I19 -> 50000 | L19: =+VLOOKUP(E19,mã!$B$2:$F$229,2,0) -> NL300013 | M19: =+VLOOKUP(T19,Sheet2!$B$2:$P$372,10,0) -> 1 | N19: =+VLOOKUP(L19,mã!$C$2:$F$229,4,0) -> 50000 | O19: =M19*N19 -> 50000 | P19: =J19-O19 -> 0 | Q19: =IF(U19=0," ","SAI SL NHẬN") | R19: =+VLOOKUP(T19,Sheet2!$B$2:$P$372,13,0) -> 50000 | S19: =O19-R19 -> 0 | T19: =A19&L19 -> 01/01/2026NL300013 | U19: =H19-M19 -> 0 | V19: =I19-N19 -> 0
A20: 01/01/2026 | B20: TG-KS01254 | C20: G-MASTER NƯỚNG | D20: TG-AA20733 | E20: I100033 | F20: Cà chua bi | G20: Kg | H20: 1 | I20: 55000 | J20: =H20*I20 -> 55000 | L20: =+VLOOKUP(E20,mã!$B$2:$F$229,2,0) -> NL300014 | M20: =+VLOOKUP(T20,Sheet2!$B$2:$P$372,10,0) -> 1 | N20: =+VLOOKUP(L20,mã!$C$2:$F$229,4,0) -> 55000 | O20: =M20*N20 -> 55000 | P20: =J20-O20 -> 0 | Q20: =IF(U20=0," ","SAI SL NHẬN") | R20: =+VLOOKUP(T20,Sheet2!$B$2:$P$372,13,0) -> 55000 | S20: =O20-R20 -> 0 | T20: =A20&L20 -> 01/01/2026NL300014 | U20: =H20-M20 -> 0 | V20: =I20-N20 -> 0
A21: 01/01/2026 | B21: TG-KS01254 | C21: G-MASTER NƯỚNG | D21: TG-AA20733 | E21: I100039 | F21: Cà rốt | G21: Kg | H21: 3 | I21: 18000 | J21: =H21*I21 -> 54000 | L21: =+VLOOKUP(E21,mã!$B$2:$F$229,2,0) -> NL300027 | M21: =+VLOOKUP(T21,Sheet2!$B$2:$P$372,10,0) -> 3 | N21: =+VLOOKUP(L21,mã!$C$2:$F$229,4,0) -> 18000 | O21: =M21*N21 -> 54000 | P21: =J21-O21 -> 0 | Q21: =IF(U21=0," ","SAI SL NHẬN") | R21: =+VLOOKUP(T21,Sheet2!$B$2:$P$372,13,0) -> 54000 | S21: =O21-R21 -> 0 | T21: =A21&L21 -> 01/01/2026NL300027 | U21: =H21-M21 -> 0 | V21: =I21-N21 -> 0
A22: 01/01/2026 | B22: TG-KS01254 | C22: G-MASTER NƯỚNG | D22: TG-AA20733 | E22: I100046 | F22: Cải mầm (100g) | G22: Hộp | H22: 0.1 | I22: 10000 | J22: =H22*I22 -> 1000 | L22: NL300230 | M22: =+VLOOKUP(T22,Sheet2!$B$2:$P$372,10,0) -> 0.1 | N22: =+VLOOKUP(L22,mã!$C$2:$F$229,4,0) -> 80000 | O22: =M22*N22 -> 8000 | P22: =J22-O22 -> -7000 | Q22: =IF(U22=0," ","SAI SL NHẬN") | R22: =+VLOOKUP(T22,Sheet2!$B$2:$P$372,13,0) -> 8000 | S22: =O22-R22 -> 0 | T22: =A22&L22 -> 01/01/2026NL300230 | U22: =H22-M22 -> 0 | V22: =I22-N22 -> -70000
A23: 01/01/2026 | B23: TG-KS01254 | C23: G-MASTER NƯỚNG | D23: TG-AA20733 | E23: I100064 | F23: Củ cải đỏ (Radis) | G23: Kg | H23: 0.2 | I23: 40000 | J23: =H23*I23 -> 8000 | L23: =+VLOOKUP(E23,mã!$B$2:$F$229,2,0) -> NL300034 | M23: =+VLOOKUP(T23,Sheet2!$B$2:$P$372,10,0) -> 0.2 | N23: =+VLOOKUP(L23,mã!$C$2:$F$229,4,0) -> 40000 | O23: =M23*N23 -> 8000 | P23: =J23-O23 -> 0 | Q23: =IF(U23=0," ","SAI SL NHẬN") | R23: =+VLOOKUP(T23,Sheet2!$B$2:$P$372,13,0) -> 8000 | S23: =O23-R23 -> 0 | T23: =A23&L23 -> 01/01/2026NL300034 | U23: =H23-M23 -> 0 | V23: =I23-N23 -> 0
A24: 01/01/2026 | B24: TG-KS01254 | C24: G-MASTER NƯỚNG | D24: TG-AA20733 | E24: I100067 | F24: Củ cải trắng (Loại 1) | G24: Kg | H24: 4 | I24: 13000 | J24: =H24*I24 -> 52000 | L24: =+VLOOKUP(E24,mã!$B$2:$F$229,2,0) -> NL300033 | M24: =+VLOOKUP(T24,Sheet2!$B$2:$P$372,10,0) -> 4 | N24: =+VLOOKUP(L24,mã!$C$2:$F$229,4,0) -> 13000 | O24: =M24*N24 -> 52000 | P24: =J24-O24 -> 0 | Q24: =IF(U24=0," ","SAI SL NHẬN") | R24: =+VLOOKUP(T24,Sheet2!$B$2:$P$372,13,0) -> 52000 | S24: =O24-R24 -> 0 | T24: =A24&L24 -> 01/01/2026NL300033 | U24: =H24-M24 -> 0 | V24: =I24-N24 -> 0
A25: 01/01/2026 | B25: TG-KS01254 | C25: G-MASTER NƯỚNG | D25: TG-AA20733 | E25: I100097 | F25: Củ Gừng | G25: Kg | H25: 0.5 | I25: 38000 | J25: =H25*I25 -> 19000 | L25: NL300053 | M25: =+VLOOKUP(T25,Sheet2!$B$2:$P$372,10,0) -> 0.5 | N25: =+VLOOKUP(L25,mã!$C$2:$F$229,4,0) -> 30000 | O25: =M25*N25 -> 15000 | P25: =J25-O25 -> 4000 | Q25: =IF(U25=0," ","SAI SL NHẬN") | R25: =+VLOOKUP(T25,Sheet2!$B$2:$P$372,13,0) -> 15000 | S25: =O25-R25 -> 0 | T25: =A25&L25 -> 01/01/2026NL300053 | U25: =H25-M25 -> 0 | V25: =I25-N25 -> 8000
A26: 01/01/2026 | B26: TG-KS01254 | C26: G-MASTER NƯỚNG | D26: TG-AA20733 | E26: I100075 | F26: Đậu bắp | G26: Kg | H26: 3 | I26: 32000 | J26: =H26*I26 -> 96000 | L26: =+VLOOKUP(E26,mã!$B$2:$F$229,2,0) -> NL300038 | M26: =+VLOOKUP(T26,Sheet2!$B$2:$P$372,10,0) -> 3 | N26: =+VLOOKUP(L26,mã!$C$2:$F$229,4,0) -> 32000 | O26: =M26*N26 -> 96000 | P26: =J26-O26 -> 0 | Q26: =IF(U26=0," ","SAI SL NHẬN") | R26: =+VLOOKUP(T26,Sheet2!$B$2:$P$372,13,0) -> 96000 | S26: =O26-R26 -> 0 | T26: =A26&L26 -> 01/01/2026NL300038 | U26: =H26-M26 -> 0 | V26: =I26-N26 -> 0
A27: 01/01/2026 | B27: TG-KS01254 | C27: G-MASTER NƯỚNG | D27: TG-AA20733 | E27: I100883 | F27: Đậu hủ trứng CP 220gr | G27: Cây | H27: 6 | I27: 15000 | J27: =H27*I27 -> 90000 | L27: =+VLOOKUP(E27,mã!$B$2:$F$229,2,0) -> NL300041 | M27: =+VLOOKUP(T27,Sheet2!$B$2:$P$372,10,0) -> 6 | N27: =+VLOOKUP(L27,mã!$C$2:$F$229,4,0) -> 15000 | O27: =M27*N27 -> 90000 | P27: =J27-O27 -> 0 | Q27: =IF(U27=0," ","SAI SL NHẬN") | R27: =+VLOOKUP(T27,Sheet2!$B$2:$P$372,13,0) -> 90000 | S27: =O27-R27 -> 0 | T27: =A27&L27 -> 01/01/2026NL300041 | U27: =H27-M27 -> 0 | V27: =I27-N27 -> 0
A28: 01/01/2026 | B28: TG-KS01254 | C28: G-MASTER NƯỚNG | D28: TG-AA20733 | E28: I100479 | F28: Dưa hấu | G28: Kg | H28: 21 | I28: 18000 | J28: =H28*I28 -> 378000 | L28: =+VLOOKUP(E28,mã!$B$2:$F$229,2,0) -> NL600004 | M28: =+VLOOKUP(T28,Sheet2!$B$2:$P$372,10,0) -> 21 | N28: =+VLOOKUP(L28,mã!$C$2:$F$229,4,0) -> 18000 | O28: =M28*N28 -> 378000 | P28: =J28-O28 -> 0 | Q28: =IF(U28=0," ","SAI SL NHẬN") | R28: =+VLOOKUP(T28,Sheet2!$B$2:$P$372,13,0) -> 378000 | S28: =O28-R28 -> 0 | T28: =A28&L28 -> 01/01/2026NL600004 | U28: =H28-M28 -> 0 | V28: =I28-N28 -> 0
A29: 01/01/2026 | B29: TG-KS01254 | C29: G-MASTER NƯỚNG | D29: TG-AA20733 | E29: I100089 | F29: Dưa leo | G29: Kg | H29: 4 | I29: 18000 | J29: =H29*I29 -> 72000 | L29: =+VLOOKUP(E29,mã!$B$2:$F$229,2,0) -> NL300048 | M29: =+VLOOKUP(T29,Sheet2!$B$2:$P$372,10,0) -> 4 | N29: =+VLOOKUP(L29,mã!$C$2:$F$229,4,0) -> 18000 | O29: =M29*N29 -> 72000 | P29: =J29-O29 -> 0 | Q29: =IF(U29=0," ","SAI SL NHẬN") | R29: =+VLOOKUP(T29,Sheet2!$B$2:$P$372,13,0) -> 72000 | S29: =O29-R29 -> 0 | T29: =A29&L29 -> 01/01/2026NL300048 | U29: =H29-M29 -> 0 | V29: =I29-N29 -> 0
A30: 01/01/2026 | B30: TG-KS01254 | C30: G-MASTER NƯỚNG | D30: TG-AA20733 | E30: I101167 | F30: Giá đậu nành | G30: Kg | H30: 0.5 | J30: =H30*I30 -> 0 | L30: NL300050 | M30: =+VLOOKUP(T30,Sheet2!$B$2:$P$372,10,0) -> 0.5 | N30: =+VLOOKUP(L30,mã!$C$2:$F$229,4,0) -> 9000 | O30: =M30*N30 -> 4500 | P30: =J30-O30 -> -4500 | Q30: =IF(U30=0," ","SAI SL NHẬN") | R30: =+VLOOKUP(T30,Sheet2!$B$2:$P$372,13,0) -> 4500 | S30: =O30-R30 -> 0 | T30: =A30&L30 -> 01/01/2026NL300050 | U30: =H30-M30 -> 0 | V30: =I30-N30 -> -9000
A31: 01/01/2026 | B31: TG-KS01254 | C31: G-MASTER NƯỚNG | D31: TG-AA20733 | E31: I100098 | F31: Hành lá | G31: Kg | H31: 0.3 | I31: 55000 | J31: =H31*I31 -> 16500 | L31: =+VLOOKUP(E31,mã!$B$2:$F$229,2,0) -> NL300058 | M31: =+VLOOKUP(T31,Sheet2!$B$2:$P$372,10,0) -> 0.3 | N31: =+VLOOKUP(L31,mã!$C$2:$F$229,4,0) -> 55000 | O31: =M31*N31 -> 16500 | P31: =J31-O31 -> 0 | Q31: =IF(U31=0," ","SAI SL NHẬN") | R31: =+VLOOKUP(T31,Sheet2!$B$2:$P$372,13,0) -> 16500 | S31: =O31-R31 -> 0 | T31: =A31&L31 -> 01/01/2026NL300058 | U31: =H31-M31 -> 0 | V31: =I31-N31 -> 0
A32: 01/01/2026 | B32: TG-KS01254 | C32: G-MASTER NƯỚNG | D32: TG-AA20733 | E32: I100099 | F32: Hành Paro | G32: Kg | H32: 0.6 | I32: 38000 | J32: =H32*I32 -> 22800 | L32: =+VLOOKUP(E32,mã!$B$2:$F$229,2,0) -> NL300061 | M32: =+VLOOKUP(T32,Sheet2!$B$2:$P$372,10,0) -> 0.6 | N32: =+VLOOKUP(L32,mã!$C$2:$F$229,4,0) -> 38000 | O32: =M32*N32 -> 22800 | P32: =J32-O32 -> 0 | Q32: =IF(U32=0," ","SAI SL NHẬN") | R32: =+VLOOKUP(T32,Sheet2!$B$2:$P$372,13,0) -> 22800 | S32: =O32-R32 -> 0 | T32: =A32&L32 -> 01/01/2026NL300061 | U32: =H32-M32 -> 0 | V32: =I32-N32 -> 0
A33: 01/01/2026 | B33: TG-KS01254 | C33: G-MASTER NƯỚNG | D33: TG-AA20733 | E33: I100101 | F33: Hành tây | G33: Kg | H33: 3.1 | I33: 13000 | J33: =H33*I33 -> 40300 | L33: =+VLOOKUP(E33,mã!$B$2:$F$229,2,0) -> NL300059 | M33: =+VLOOKUP(T33,Sheet2!$B$2:$P$372,10,0) -> 2.2 | N33: =+VLOOKUP(L33,mã!$C$2:$F$229,4,0) -> 13000 | O33: =M33*N33 -> 28600 | P33: =J33-O33 -> 11700 | Q33: =IF(U33=0," ","SAI SL NHẬN") -> SAI SL NHẬN | R33: =+VLOOKUP(T33,Sheet2!$B$2:$P$372,13,0) -> 28600 | S33: =O33-R33 -> 0 | T33: =A33&L33 -> 01/01/2026NL300059 | U33: =H33-M33 -> 0.9 | V33: =I33-N33 -> 0
A34: 01/01/2026 | B34: TG-KS01254 | C34: G-MASTER NƯỚNG | D34: TG-AA20733 | E34: I100121 | F34: Khoai lang nhật | G34: Kg | H34: 3 | I34: 23000 | J34: =H34*I34 -> 69000 | L34: =+VLOOKUP(E34,mã!$B$2:$F$229,2,0) -> NL300070 | M34: =+VLOOKUP(T34,Sheet2!$B$2:$P$372,10,0) -> 3 | N34: =+VLOOKUP(L34,mã!$C$2:$F$229,4,0) -> 23000 | O34: =M34*N34 -> 69000 | P34: =J34-O34 -> 0 | Q34: =IF(U34=0," ","SAI SL NHẬN") | R34: =+VLOOKUP(T34,Sheet2!$B$2:$P$372,13,0) -> 69000 | S34: =O34-R34 -> 0 | T34: =A34&L34 -> 01/01/2026NL300070 | U34: =H34-M34 -> 0 | V34: =I34-N34 -> 0
A35: 01/01/2026 | B35: TG-KS01254 | C35: G-MASTER NƯỚNG | D35: TG-AA20733 | E35: I100128 | F35: Khoai Tây DL lớn | G35: Kg | H35: 1.3 | I35: 20000 | J35: =H35*I35 -> 26000 | L35: =+VLOOKUP(E35,mã!$B$2:$F$229,2,0) -> NL300071 | M35: 0 | N35: =+VLOOKUP(L35,mã!$C$2:$F$229,4,0) -> 20000 | O35: =M35*N35 -> 0 | P35: =J35-O35 -> 26000 | Q35: =IF(U35=0," ","SAI SL NHẬN") -> SAI SL NHẬN | R35: 0 | S35: =O35-R35 -> 0 | T35: =A35&L35 -> 01/01/2026NL300071 | U35: =H35-M35 -> 1.3 | V35: =I35-N35 -> 0
A36: 01/01/2026 | B36: TG-KS01254 | C36: G-MASTER NƯỚNG | D36: TG-AA20733 | E36: I100132 | F36: Lá cây nhíp (lá mè) | G36: Kg | H36: 4 | I36: 95000 | J36: =H36*I36 -> 380000 | L36: =+VLOOKUP(E36,mã!$B$2:$F$229,2,0) -> NL300080 | M36: =+VLOOKUP(T36,Sheet2!$B$2:$P$372,10,0) -> 4 | N36: =+VLOOKUP(L36,mã!$C$2:$F$229,4,0) -> 95000 | O36: =M36*N36 -> 380000 | P36: =J36-O36 -> 0 | Q36: =IF(U36=0," ","SAI SL NHẬN") | R36: =+VLOOKUP(T36,Sheet2!$B$2:$P$372,13,0) -> 380000 | S36: =O36-R36 -> 0 | T36: =A36&L36 -> 01/01/2026NL300080 | U36: =H36-M36 -> 0 | V36: =I36-N36 -> 0
A37: 01/01/2026 | B37: TG-KS01254 | C37: G-MASTER NƯỚNG | D37: TG-AA20733 | E37: I100236 | F37: Nấm đông cô tươi | G37: Kg | H37: 7 | I37: 145000 | J37: =H37*I37 -> 1015000 | L37: =+VLOOKUP(E37,mã!$B$2:$F$229,2,0) -> NL300090 | M37: =+VLOOKUP(T37,Sheet2!$B$2:$P$372,10,0) -> 7 | N37: =+VLOOKUP(L37,mã!$C$2:$F$229,4,0) -> 145000 | O37: =M37*N37 -> 1015000 | P37: =J37-O37 -> 0 | Q37: =IF(U37=0," ","SAI SL NHẬN") | R37: =+VLOOKUP(T37,Sheet2!$B$2:$P$372,13,0) -> 1015000 | S37: =O37-R37 -> 0 | T37: =A37&L37 -> 01/01/2026NL300090 | U37: =H37-M37 -> 0 | V37: =I37-N37 -> 0
A38: 01/01/2026 | B38: TG-KS01254 | C38: G-MASTER NƯỚNG | D38: TG-AA20733 | E38: I100237 | F38: Nấm đùi gà | G38: Kg | H38: 2 | I38: 47000 | J38: =H38*I38 -> 94000 | L38: =+VLOOKUP(E38,mã!$B$2:$F$229,2,0) -> NL300091 | M38: =+VLOOKUP(T38,Sheet2!$B$2:$P$372,10,0) -> 2 | N38: =+VLOOKUP(L38,mã!$C$2:$F$229,4,0) -> 47000 | O38: =M38*N38 -> 94000 | P38: =J38-O38 -> 0 | Q38: =IF(U38=0," ","SAI SL NHẬN") | R38: =+VLOOKUP(T38,Sheet2!$B$2:$P$372,13,0) -> 94000 | S38: =O38-R38 -> 0 | T38: =A38&L38 -> 01/01/2026NL300091 | U38: =H38-M38 -> 0 | V38: =I38-N38 -> 0
A39: 01/01/2026 | B39: TG-KS01254 | C39: G-MASTER NƯỚNG | D39: TG-AA20733 | E39: I100634 | F39: Nấm hải sản (kg) | G39: Kg | H39: 2 | I39: 80000 | J39: =H39*I39 -> 160000 | L39: =+VLOOKUP(E39,mã!$B$2:$F$229,2,0) -> NL300094 | M39: 0 | N39: =+VLOOKUP(L39,mã!$C$2:$F$229,4,0) -> 80000 | O39: =M39*N39 -> 0 | P39: =J39-O39 -> 160000 | Q39: =IF(U39=0," ","SAI SL NHẬN") -> SAI SL NHẬN | R39: 0 | S39: =O39-R39 -> 0 | T39: =A39&L39 -> 01/01/2026NL300094 | U39: =H39-M39 -> 2 | V39: =I39-N39 -> 0
A40: 01/01/2026 | B40: TG-KS01254 | C40: G-MASTER NƯỚNG | D40: TG-AA20733 | E40: I100240 | F40: Nấm kim châm tươi | G40: Kg | H40: 1 | I40: 45000 | J40: =H40*I40 -> 45000 | L40: =+VLOOKUP(E40,mã!$B$2:$F$229,2,0) -> NL300096 | M40: =+VLOOKUP(T40,Sheet2!$B$2:$P$372,10,0) -> 1 | N40: =+VLOOKUP(L40,mã!$C$2:$F$229,4,0) -> 45000 | O40: =M40*N40 -> 45000 | P40: =J40-O40 -> 0 | Q40: =IF(U40=0," ","SAI SL NHẬN") | R40: =+VLOOKUP(T40,Sheet2!$B$2:$P$372,13,0) -> 45000 | S40: =O40-R40 -> 0 | T40: =A40&L40 -> 01/01/2026NL300096 | U40: =H40-M40 -> 0 | V40: =I40-N40 -> 0
A41: 01/01/2026 | B41: TG-KS01254 | C41: G-MASTER NƯỚNG | D41: TG-AA20733 | E41: I100156 | F41: Ngò rí | G41: Kg | H41: 0.1 | I41: 45000 | J41: =H41*I41 -> 4500 | L41: =+VLOOKUP(E41,mã!$B$2:$F$229,2,0) -> NL300085 | M41: =+VLOOKUP(T41,Sheet2!$B$2:$P$372,10,0) -> 0.1 | N41: =+VLOOKUP(L41,mã!$C$2:$F$229,4,0) -> 45000 | O41: =M41*N41 -> 4500 | P41: =J41-O41 -> 0 | Q41: =IF(U41=0," ","SAI SL NHẬN") | R41: =+VLOOKUP(T41,Sheet2!$B$2:$P$372,13,0) -> 4500 | S41: =O41-R41 -> 0 | T41: =A41&L41 -> 01/01/2026NL300085 | U41: =H41-M41 -> 0 | V41: =I41-N41 -> 0
A42: 01/01/2026 | B42: TG-KS01254 | C42: G-MASTER NƯỚNG | D42: TG-AA20733 | E42: I100160 | F42: Ngò tây | G42: Kg | H42: 0.5 | I42: 70000 | J42: =H42*I42 -> 35000 | L42: =+VLOOKUP(E42,mã!$B$2:$F$229,2,0) -> NL300126 | M42: =+VLOOKUP(T42,Sheet2!$B$2:$P$372,10,0) -> 0.5 | N42: =+VLOOKUP(L42,mã!$C$2:$F$229,4,0) -> 70000 | O42: =M42*N42 -> 35000 | P42: =J42-O42 -> 0 | Q42: =IF(U42=0," ","SAI SL NHẬN") | R42: =+VLOOKUP(T42,Sheet2!$B$2:$P$372,13,0) -> 35000 | S42: =O42-R42 -> 0 | T42: =A42&L42 -> 01/01/2026NL300126 | U42: =H42-M42 -> 0 | V42: =I42-N42 -> 0
A43: 01/01/2026 | B43: TG-KS01254 | C43: G-MASTER NƯỚNG | D43: TG-AA20733 | E43: I100167 | F43: Ớt hiểm đỏ | G43: Kg | H43: 1 | I43: 145000 | J43: =H43*I43 -> 145000 | L43: =+VLOOKUP(E43,mã!$B$2:$F$229,2,0) -> NL300113 | M43: =+VLOOKUP(T43,Sheet2!$B$2:$P$372,10,0) -> 1 | N43: =+VLOOKUP(L43,mã!$C$2:$F$229,4,0) -> 145000 | O43: =M43*N43 -> 145000 | P43: =J43-O43 -> 0 | Q43: =IF(U43=0," ","SAI SL NHẬN") | R43: =+VLOOKUP(T43,Sheet2!$B$2:$P$372,13,0) -> 145000 | S43: =O43-R43 -> 0 | T43: =A43&L43 -> 01/01/2026NL300113 | U43: =H43-M43 -> 0 | V43: =I43-N43 -> 0
A44: 01/01/2026 | B44: TG-KS01254 | C44: G-MASTER NƯỚNG | D44: TG-AA20733 | E44: I100216 | F44: Tắc trái | G44: Kg | H44: 2.5 | I44: 21000 | J44: =H44*I44 -> 52500 | L44: =+VLOOKUP(E44,mã!$B$2:$F$229,2,0) -> NL300119 | M44: =+VLOOKUP(T44,Sheet2!$B$2:$P$372,10,0) -> 1.7 | N44: =+VLOOKUP(L44,mã!$C$2:$F$229,4,0) -> 21000 | O44: =M44*N44 -> 35700 | P44: =J44-O44 -> 16800 | Q44: =IF(U44=0," ","SAI SL NHẬN") -> SAI SL NHẬN | R44: =+VLOOKUP(T44,Sheet2!$B$2:$P$372,13,0) -> 35700 | S44: =O44-R44 -> 0 | T44: =A44&L44 -> 01/01/2026NL300119 | U44: =H44-M44 -> 0.8 | V44: =I44-N44 -> 0
A45: 01/01/2026 | B45: TG-KS01254 | C45: G-MASTER NƯỚNG | D45: TG-AA20733 | E45: I100229 | F45: Tỏi lột | G45: Kg | H45: 0.5 | I45: 50000 | J45: =H45*I45 -> 25000 | L45: =+VLOOKUP(E45,mã!$B$2:$F$229,2,0) -> NL300142 | M45: =+VLOOKUP(T45,Sheet2!$B$2:$P$372,10,0) -> 0.5 | N45: =+VLOOKUP(L45,mã!$C$2:$F$229,4,0) -> 50000 | O45: =M45*N45 -> 25000 | P45: =J45-O45 -> 0 | Q45: =IF(U45=0," ","SAI SL NHẬN") | R45: =+VLOOKUP(T45,Sheet2!$B$2:$P$372,13,0) -> 25000 | S45: =O45-R45 -> 0 | T45: =A45&L45 -> 01/01/2026NL300142 | U45: =H45-M45 -> 0 | V45: =I45-N45 -> 0
A46: 01/01/2026 | B46: TG-KS01254 | C46: G-MASTER NƯỚNG | D46: TG-AA20733 | E46: I100203 | F46: Xà lách búp mỹ | G46: Kg | H46: 1 | I46: 65000 | J46: =H46*I46 -> 65000 | L46: =+VLOOKUP(E46,mã!$B$2:$F$229,2,0) -> NL300146 | M46: =+VLOOKUP(T46,Sheet2!$B$2:$P$372,10,0) -> 1 | N46: =+VLOOKUP(L46,mã!$C$2:$F$229,4,0) -> 65000 | O46: =M46*N46 -> 65000 | P46: =J46-O46 -> 0 | Q46: =IF(U46=0," ","SAI SL NHẬN") | R46: =+VLOOKUP(T46,Sheet2!$B$2:$P$372,13,0) -> 65000 | S46: =O46-R46 -> 0 | T46: =A46&L46 -> 01/01/2026NL300146 | U46: =H46-M46 -> 0 | V46: =I46-N46 -> 0
...

Sheet Sheet2
A1: Ngày ct | B1: Mã ct | C1: Số ct | D1: Áp giá | E1: Mã ncc | F1: Tên ncc | G1: Diễn giải | H1: Mã hàng | I1: Tên mặt hàng | J1: Đvt | K1: Số lượng | L1: Giá | M1: Giá báo | N1: =SUBTOTAL(9,N2:N372) -> 23526920 | O1: Thuế suất | P1: Chênh lệch giá | Q1: Kho hàng | R1: Mã nx | S1: Vụ việc | T1: Bộ phận | U1: Hợp đồng | V1: Người tạo | W1: Người sửa
A2: 46023 | B2: ="0"&DAY(A2)&"/01/2026"&H2 -> 01/01/2026NL300004 | C2: GSG012601007 | D2: 1 | E2: NCC100186 | F2: CÔNG TY TNHH NÔNG SẢN THỰC PHẨM TRẦN GIA | G2: GSG01 - Nhập hàng mua ngày 01/01/2026 | H2: NL300004 | I2: Bắp cải trắng | J2: kg | K2: 4.6 | L2: 19000 | M2: 0 | N2: =L2*K2 -> 87400 | O2: 0 | P2: 19000 | Q2: GSG.01 | R2: 3311 | T2: GSG01 | V2: TRANNTB | W2: TRANNTB
A3: 46023 | B3: ="0"&DAY(A3)&"/01/2026"&H3 -> 01/01/2026NL300107 | C3: GSG012601007 | D3: 1 | E3: NCC100186 | F3: CÔNG TY TNHH NÔNG SẢN THỰC PHẨM TRẦN GIA | G3: GSG01 - Nhập hàng mua ngày 01/01/2026 | H3: NL300107 | I3: Ngô ngọt ( Bắp trái) | J3: Cái | K3: 20 | L3: 8500 | M3: 0 | N3: =L3*K3 -> 170000 | O3: 0 | P3: 8500 | Q3: GSG.01 | R3: 3311 | T3: GSG01 | V3: TRANNTB | W3: TRANNTB
A4: 46023 | B4: ="0"&DAY(A4)&"/01/2026"&H4 -> 01/01/2026NL300007 | C4: GSG012601007 | D4: 1 | E4: NCC100186 | F4: CÔNG TY TNHH NÔNG SẢN THỰC PHẨM TRẦN GIA | G4: GSG01 - Nhập hàng mua ngày 01/01/2026 | H4: NL300007 | I4: Bí đỏ | J4: kg | K4: 2.9 | L4: 30000 | M4: 0 | N4: =L4*K4 -> 87000 | O4: 0 | P4: 30000 | Q4: GSG.01 | R4: 3311 | T4: GSG01 | V4: TRANNTB | W4: TRANNTB
A5: 46023 | B5: ="0"&DAY(A5)&"/01/2026"&H5 -> 01/01/2026NL300008 | C5: GSG012601007 | D5: 1 | E5: NCC100186 | F5: CÔNG TY TNHH NÔNG SẢN THỰC PHẨM TRẦN GIA | G5: GSG01 - Nhập hàng mua ngày 01/01/2026 | H5: NL300008 | I5: Bí ngòi | J5: kg | K5: 3.1 | L5: 40000 | M5: 0 | N5: =L5*K5 -> 124000 | O5: 0 | P5: 40000 | Q5: GSG.01 | R5: 3311 | T5: GSG01 | V5: TRANNTB | W5: TRANNTB
A6: 46023 | B6: ="0"&DAY(A6)&"/01/2026"&H6 -> 01/01/2026NL300013 | C6: GSG012601007 | D6: 1 | E6: NCC100186 | F6: CÔNG TY TNHH NÔNG SẢN THỰC PHẨM TRẦN GIA | G6: GSG01 - Nhập hàng mua ngày 01/01/2026 | H6: NL300013 | I6: Cà chua | J6: kg | K6: 1 | L6: 50000 | M6: 0 | N6: =L6*K6 -> 50000 | O6: 0 | P6: 50000 | Q6: GSG.01 | R6: 3311 | T6: GSG01 | V6: TRANNTB | W6: TRANNTB
A7: 46023 | B7: ="0"&DAY(A7)&"/01/2026"&H7 -> 01/01/2026NL300014 | C7: GSG012601007 | D7: 1 | E7: NCC100186 | F7: CÔNG TY TNHH NÔNG SẢN THỰC PHẨM TRẦN GIA | G7: GSG01 - Nhập hàng mua ngày 01/01/2026 | H7: NL300014 | I7: Cà chua bi | J7: kg | K7: 1 | L7: 55000 | M7: 0 | N7: =L7*K7 -> 55000 | O7: 0 | P7: 55000 | Q7: GSG.01 | R7: 3311 | T7: GSG01 | V7: TRANNTB | W7: TRANNTB
A8: 46023 | B8: ="0"&DAY(A8)&"/01/2026"&H8 -> 01/01/2026NL300027 | C8: GSG012601007 | D8: 1 | E8: NCC100186 | F8: CÔNG TY TNHH NÔNG SẢN THỰC PHẨM TRẦN GIA | G8: GSG01 - Nhập hàng mua ngày 01/01/2026 | H8: NL300027 | I8: Cà rốt | J8: kg | K8: 3 | L8: 18000 | M8: 0 | N8: =L8*K8 -> 54000 | O8: 0 | P8: 18000 | Q8: GSG.01 | R8: 3311 | T8: GSG01 | V8: TRANNTB | W8: TRANNTB
A9: 46023 | B9: ="0"&DAY(A9)&"/01/2026"&H9 -> 01/01/2026NL300230 | C9: GSG012601007 | D9: 1 | E9: NCC100186 | F9: CÔNG TY TNHH NÔNG SẢN THỰC PHẨM TRẦN GIA | G9: GSG01 - Nhập hàng mua ngày 01/01/2026 | H9: NL300230 | I9: Cải Mầm | J9: kg | K9: 0.1 | L9: 80000 | M9: 0 | N9: =L9*K9 -> 8000 | O9: 0 | P9: 80000 | Q9: GSG.01 | R9: 3311 | T9: GSG01 | V9: TRANNTB | W9: TRANNTB
A10: 46023 | B10: ="0"&DAY(A10)&"/01/2026"&H10 -> 01/01/2026NL300034 | C10: GSG012601007 | D10: 1 | E10: NCC100186 | F10: CÔNG TY TNHH NÔNG SẢN THỰC PHẨM TRẦN GIA | G10: GSG01 - Nhập hàng mua ngày 01/01/2026 | H10: NL300034 | I10: Củ cải đỏ | J10: kg | K10: 0.2 | L10: 40000 | M10: 0 | N10: =L10*K10 -> 8000 | O10: 0 | P10: 40000 | Q10: GSG.01 | R10: 3311 | T10: GSG01 | V10: TRANNTB | W10: TRANNTB
A11: 46023 | B11: ="0"&DAY(A11)&"/01/2026"&H11 -> 01/01/2026NL300033 | C11: GSG012601007 | D11: 1 | E11: NCC100186 | F11: CÔNG TY TNHH NÔNG SẢN THỰC PHẨM TRẦN GIA | G11: GSG01 - Nhập hàng mua ngày 01/01/2026 | H11: NL300033 | I11: Củ cải trắng | J11: kg | K11: 4 | L11: 13000 | M11: 0 | N11: =L11*K11 -> 52000 | O11: 0 | P11: 13000 | Q11: GSG.01 | R11: 3311 | T11: GSG01 | V11: TRANNTB | W11: TRANNTB
A12: 46023 | B12: ="0"&DAY(A12)&"/01/2026"&H12 -> 01/01/2026NL300053 | C12: GSG012601007 | D12: 1 | E12: NCC100186 | F12: CÔNG TY TNHH NÔNG SẢN THỰC PHẨM TRẦN GIA | G12: GSG01 - Nhập hàng mua ngày 01/01/2026 | H12: NL300053 | I12: Gừng ta | J12: kg | K12: 0.5 | L12: 30000 | M12: 0 | N12: =L12*K12 -> 15000 | O12: 0 | P12: 30000 | Q12: GSG.01 | R12: 3311 | T12: GSG01 | V12: TRANNTB | W12: TRANNTB
A13: 46023 | B13: ="0"&DAY(A13)&"/01/2026"&H13 -> 01/01/2026NL600004 | C13: GSG012601007 | D13: 1 | E13: NCC100186 | F13: CÔNG TY TNHH NÔNG SẢN THỰC PHẨM TRẦN GIA | G13: GSG01 - Nhập hàng mua ngày 01/01/2026 | H13: NL600004 | I13: Dưa hấu | J13: kg | K13: 21 | L13: 18000 | M13: 0 | N13: =L13*K13 -> 378000 | O13: 0 | P13: 18000 | Q13: GSG.01 | R13: 3311 | T13: GSG01 | V13: TRANNTB | W13: TRANNTB
... A219: 46031 | B219: ="0"&DAY(A219)&"/01/2026"&H219 -> 09/01/2026NL300048 | C219: 2601GSG01045 | D219: 1 | E219: NCC100186 | F219: CÔNG TY TNHH NÔNG SẢN THỰC PHẨM TRẦN GIA | G219: GSG01 - Nhập hàng mua ngày 09/01/2026 | H219: NL300048 | I219: Dưa chuột | J219: kg | K219: 0.6 | L219: 18000 | M219: 0 | N219: =L219*K219 -> 10800 | O219: 0 | P219: 18000 | Q219: GSG.01 | R219: 3311 | T219: GSG01 | V219: TRANNTB | W219: TRANNTB
A220: 46032 | B220: =""&DAY(A220)&"/01/2026"&H220 -> 10/01/2026NL300008 | C220: 2601GSG01077 | D220: 1 | E220: NCC100186 | F220: CÔNG TY TNHH NÔNG SẢN THỰC PHẨM TRẦN GIA | G220: GSG01 - Nhập hàng mua ngày 10/01/2026 | H220: NL300008 | I220: Bí ngòi | J220: kg | K220: 2.1 | L220: 40000 | M220: 0 | N220: =L220*K220 -> 84000 | O220: 0 | P220: 40000 | Q220: GSG.01 | R220: 3311 | T220: GSG01 | V220: TRANNTB | W220: TRANNTB
A221: 46032 | B221: =""&DAY(A221)&"/01/2026"&H221 -> 10/01/2026NL300107 | C221: 2601GSG01077 | D221: 1 | E221: NCC100186 | F221: CÔNG TY TNHH NÔNG SẢN THỰC PHẨM TRẦN GIA | G221: GSG01 - Nhập hàng mua ngày 10/01/2026 | H221: NL300107 | I221: Ngô ngọt ( Bắp trái) | J221: Cái | K221: 12 | L221: 8500 | M221: 0 | N221: =L221*K221 -> 102000 | O221: 0 | P221: 8500 | Q221: GSG.01 | R221: 3311 | T221: GSG01 | V221: TRANNTB | W221: TRANNTB
A222: 46032 | B222: =""&DAY(A222)&"/01/2026"&H222 -> 10/01/2026NL300059 | C222: 2601GSG01077 | D222: 1 | E222: NCC100186 | F222: CÔNG TY TNHH NÔNG SẢN THỰC PHẨM TRẦN GIA | G222: GSG01 - Nhập hàng mua ngày 10/01/2026 | H222: NL300059 | I222: Hành tây | J222: kg | K222: 2 | L222: 13000 | M222: 0 | N222: =L222*K222 -> 26000 | O222: 0 | P222: 13000 | Q222: GSG.01 | R222: 3311 | T222: GSG01 | V222: TRANNTB | W222: TRANNTB
A223: 46032 | B223: =""&DAY(A223)&"/01/2026"&H223 -> 10/01/2026NL300038 | C223: 2601GSG01077 | D223: 1 | E223: NCC100186 | F223: CÔNG TY TNHH NÔNG SẢN THỰC PHẨM TRẦN GIA | G223: GSG01 - Nhập hàng mua ngày 10/01/2026 | H223: NL300038 | I223: Đậu bắp | J223: kg | K223: 2.5 | L223: 32000 | M223: 0 | N223: =L223*K223 -> 80000 | O223: 0 | P223: 32000 | Q223: GSG.01 | R223: 3311 | T223: GSG01 | V223: TRANNTB | W223: TRANNTB
A224: 46032 | B224: =""&DAY(A224)&"/01/2026"&H224 -> 10/01/2026NL300090 | C224: 2601GSG01077 | D224: 1 | E224: NCC100186 | F224: CÔNG TY TNHH NÔNG SẢN THỰC PHẨM TRẦN GIA | G224: GSG01 - Nhập hàng mua ngày 10/01/2026 | H224: NL300090 | I224: Nấm đông cô tươi | J224: kg | K224: 2 | L224: 145000 | M224: 0 | N224: =L224*K224 -> 290000 | O224: 0 | P224: 145000 | Q224: GSG.01 | R224: 3311 | T224: GSG01 | V224: TRANNTB | W224: TRANNTB
A225: 46032 | B225: =""&DAY(A225)&"/01/2026"&H225 -> 10/01/2026NL300027 | C225: 2601GSG01077 | D225: 1 | E225: NCC100186 | F225: CÔNG TY TNHH NÔNG SẢN THỰC PHẨM TRẦN GIA | G225: GSG01 - Nhập hàng mua ngày 10/01/2026 | H225: NL300027 | I225: Cà rốt | J225: kg | K225: 2 | L225: 18000 | M225: 0 | N225: =L225*K225 -> 36000 | O225: 0 | P225: 18000 | Q225: GSG.01 | R225: 3311 | T225: GSG01 | V225: TRANNTB | W225: TRANNTB
A226: 46032 | B226: =""&DAY(A226)&"/01/2026"&H226 -> 10/01/2026NL300061 | C226: 2601GSG01077 | D226: 1 | E226: NCC100186 | F226: CÔNG TY TNHH NÔNG SẢN THỰC PHẨM TRẦN GIA | G226: GSG01 - Nhập hàng mua ngày 10/01/2026 | H226: NL300061 | I226: Hành Paro (Hành Baro) | J226: kg | K226: 1.1 | L226: 38000 | M226: 0 | N226: =L226*K226 -> 41800 | O226: 0 | P226: 38000 | Q226: GSG.01 | R226: 3311 | T226: GSG01 | V226: TRANNTB | W226: TRANNTB
A227: 46032 | B227: =""&DAY(A227)&"/01/2026"&H227 -> 10/01/2026NL300048 | C227: 2601GSG01077 | D227: 1 | E227: NCC100186 | F227: CÔNG TY TNHH NÔNG SẢN THỰC PHẨM TRẦN GIA | G227: GSG01 - Nhập hàng mua ngày 10/01/2026 | H227: NL300048 | I227: Dưa chuột | J227: kg | K227: 2.2 | L227: 18000 | M227: 0 | N227: =L227*K227 -> 39600 | O227: 0 | P227: 18000 | Q227: GSG.01 | R227: 3311 | T227: GSG01 | V227: TRANNTB | W227: TRANNTB
A228: 46032 | B228: =""&DAY(A228)&"/01/2026"&H228 -> 10/01/2026NL300033 | C228: 2601GSG01077 | D228: 1 | E228: NCC100186 | F228: CÔNG TY TNHH NÔNG SẢN THỰC PHẨM TRẦN GIA | G228: GSG01 - Nhập hàng mua ngày 10/01/2026 | H228: NL300033 | I228: Củ cải trắng | J228: kg | K228: 2 | L228: 13000 | M228: 0 | N228: =L228*K228 -> 26000 | O228: 0 | P228: 13000 | Q228: GSG.01 | R228: 3311 | T228: GSG01 | V228: TRANNTB | W228: TRANNTB
A229: 46032 | B229: =""&DAY(A229)&"/01/2026"&H229 -> 10/01/2026NL300142 | C229: 2601GSG01077 | D229: 1 | E229: NCC100186 | F229: CÔNG TY TNHH NÔNG SẢN THỰC PHẨM TRẦN GIA | G229: GSG01 - Nhập hàng mua ngày 10/01/2026 | H229: NL300142 | I229: Tỏi bóc | J229: kg | K229: 0.6 | L229: 50000 | M229: 0 | N229: =L229*K229 -> 30000 | O229: 0 | P229: 50000 | Q229: GSG.01 | R229: 3311 | T229: GSG01 | V229: TRANNTB | W229: TRANNTB
A230: 46032 | B230: =""&DAY(A230)&"/01/2026"&H230 -> 10/01/2026NL300145 | C230: 2601GSG01077 | D230: 1 | E230: NCC100186 | F230: CÔNG TY TNHH NÔNG SẢN THỰC PHẨM TRẦN GIA | G230: GSG01 - Nhập hàng mua ngày 10/01/2026 | H230: NL300145 | I230: Xà lách | J230: kg | K230: 10 | L230: 38000 | M230: 0 | N230: =L230*K230 -> 380000 | O230: 0 | P230: 38000 | Q230: GSG.01 | R230: 3311 | T230: GSG01 | V230: TRANNTB | W230: TRANNTB
A231: 46032 | B231: =""&DAY(A231)&"/01/2026"&H231 -> 10/01/2026NL300080 | C231: 2601GSG01077 | D231: 1 | E231: NCC100186 | F231: CÔNG TY TNHH NÔNG SẢN THỰC PHẨM TRẦN GIA | G231: GSG01 - Nhập hàng mua ngày 10/01/2026 | H231: NL300080 | I231: Lá vừng Hàn Quốc - Lá kê nhíp | J231: kg | K231: 1 | L231: 95000 | M231: 0 | N231: =L231*K231 -> 95000 | O231: 0 | P231: 95000 | Q231: GSG.01 | R231: 3311 | T231: GSG01 | V231: TRANNTB | W231: TRANNTB
... A281: 46033 | B281: =""&DAY(A281)&"/01/2026"&H281 -> 11/01/2026NL300147 | C281: 2601GSG01050 | D281: 1 | E281: NCC100186 | F281: CÔNG TY TNHH NÔNG SẢN THỰC PHẨM TRẦN GIA | G281: GSG01 - Nhập hàng mua ngày 11/01/2026 | H281: NL300147 | I281: Xà lách Roman | J281: kg | K281: 1 | L281: 62000 | M281: 0 | N281: =L281*K281 -> 62000 | O281: 0 | P281: 62000 | Q281: GSG.01 | R281: 3311 | T281: GSG01 | V281: TRANNTB | W281: TRANNTB
A282: 46034 | B282: =""&DAY(A282)&"/01/2026"&H282 -> 12/01/2026NL300048 | C282: 2601GSG01056 | D282: 1 | E282: NCC100186 | F282: CÔNG TY TNHH NÔNG SẢN THỰC PHẨM TRẦN GIA | G282: GSG01 - Nhập hàng mua ngày 12/01/2026 | H282: NL300048 | I282: Dưa chuột | J282: kg | K282: 1.7 | L282: 18000 | N282: =L282*K282 -> 30600 | O282: 0 | P282: 18000 | Q282: GSG.01 | R282: 3311 | T282: GSG01 | V282: TRANNTB | W282: TRANNTB
A283: 46034 | B283: =""&DAY(A283)&"/01/2026"&H283 -> 12/01/2026NL300033 | C283: 2601GSG01056 | D283: 1 | E283: NCC100186 | F283: CÔNG TY TNHH NÔNG SẢN THỰC PHẨM TRẦN GIA | G283: GSG01 - Nhập hàng mua ngày 12/01/2026 | H283: NL300033 | I283: Củ cải trắng | J283: kg | K283: 2 | L283: 13000 | N283: =L283*K283 -> 26000 | O283: 0 | P283: 13000 | Q283: GSG.01 | R283: 3311 | T283: GSG01 | V283: TRANNTB | W283: TRANNTB
A284: 46034 | B284: =""&DAY(A284)&"/01/2026"&H284 -> 12/01/2026NL300145 | C284: 2601GSG01056 | D284: 1 | E284: NCC100186 | F284: CÔNG TY TNHH NÔNG SẢN THỰC PHẨM TRẦN GIA | G284: GSG01 - Nhập hàng mua ngày 12/01/2026 | H284: NL300145 | I284: Xà lách | J284: kg | K284: 3 | L284: 38000 | N284: =L284*K284 -> 114000 | O284: 0 | P284: 38000 | Q284: GSG.01 | R284: 3311 | T284: GSG01 | V284: TRANNTB | W284: TRANNTB
A285: 46034 | B285: =""&DAY(A285)&"/01/2026"&H285 -> 12/01/2026NL300113 | C285: 2601GSG01056 | D285: 1 | E285: NCC100186 | F285: CÔNG TY TNHH NÔNG SẢN THỰC PHẨM TRẦN GIA | G285: GSG01 - Nhập hàng mua ngày 12/01/2026 | H285: NL300113 | I285: Ớt hiểm đỏ | J285: kg | K285: 0.3 | L285: 145000 | N285: =L285*K285 -> 43500 | O285: 0 | P285: 145000 | Q285: GSG.01 | R285: 3311 | T285: GSG01 | V285: TRANNTB | W285: TRANNTB
A286: 46034 | B286: =""&DAY(A286)&"/01/2026"&H286 -> 12/01/2026NL300119 | C286: 2601GSG01056 | D286: 1 | E286: NCC100186 | F286: CÔNG TY TNHH NÔNG SẢN THỰC PHẨM TRẦN GIA | G286: GSG01 - Nhập hàng mua ngày 12/01/2026 | H286: NL300119 | I286: Quất ( Tắc trái ) | J286: kg | K286: 0.4 | L286: 21000 | N286: =L286*K286 -> 8400 | O286: 0 | P286: 21000 | Q286: GSG.01 | R286: 3311 | T286: GSG01 | V286: TRANNTB | W286: TRANNTB
A287: 46034 | B287: =""&DAY(A287)&"/01/2026"&H287 -> 12/01/2026NL300008 | C287: 2601GSG01056 | D287: 1 | E287: NCC100186 | F287: CÔNG TY TNHH NÔNG SẢN THỰC PHẨM TRẦN GIA | G287: GSG01 - Nhập hàng mua ngày 12/01/2026 | H287: NL300008 | I287: Bí ngòi | J287: kg | K287: 0.9 | L287: 40000 | N287: =L287*K287 -> 36000 | O287: 0 | P287: 40000 | Q287: GSG.01 | R287: 3311 | T287: GSG01 | V287: TRANNTB | W287: TRANNTB
A288: 46034 | B288: =""&DAY(A288)&"/01/2026"&H288 -> 12/01/2026NL300107 | C288: 2601GSG01056 | D288: 1 | E288: NCC100186 | F288: CÔNG TY TNHH NÔNG SẢN THỰC PHẨM TRẦN GIA | G288: GSG01 - Nhập hàng mua ngày 12/01/2026 | H288: NL300107 | I288: Ngô ngọt ( Bắp trái) | J288: Cái | K288: 9 | L288: 8500 | N288: =L288*K288 -> 76500 | O288: 0 | P288: 8500 | Q288: GSG.01 | R288: 3311 | T288: GSG01 | V288: TRANNTB | W288: TRANNTB
A289: 46034 | B289: =""&DAY(A289)&"/01/2026"&H289 -> 12/01/2026NL300059 | C289: 2601GSG01056 | D289: 1 | E289: NCC100186 | F289: CÔNG TY TNHH NÔNG SẢN THỰC PHẨM TRẦN GIA | G289: GSG01 - Nhập hàng mua ngày 12/01/2026 | H289: NL300059 | I289: Hành tây | J289: kg | K289: 0.9 | L289: 13000 | N289: =L289*K289 -> 11700 | O289: 0 | P289: 13000 | Q289: GSG.01 | R289: 3311 | T289: GSG01 | V289: TRANNTB | W289: TRANNTB
A290: 46034 | B290: =""&DAY(A290)&"/01/2026"&H290 -> 12/01/2026NL300090 | C290: 2601GSG01056 | D290: 1 | E290: NCC100186 | F290: CÔNG TY TNHH NÔNG SẢN THỰC PHẨM TRẦN GIA | G290: GSG01 - Nhập hàng mua ngày 12/01/2026 | H290: NL300090 | I290: Nấm đông cô tươi | J290: kg | K290: 1 | L290: 145000 | N290: =L290*K290 -> 145000 | O290: 0 | P290: 145000 | Q290: GSG.01 | R290: 3311 | T290: GSG01 | V290: TRANNTB | W290: TRANNTB
A291: 46034 | B291: =""&DAY(A291)&"/01/2026"&H291 -> 12/01/2026NL300027 | C291: 2601GSG01056 | D291: 1 | E291: NCC100186 | F291: CÔNG TY TNHH NÔNG SẢN THỰC PHẨM TRẦN GIA | G291: GSG01 - Nhập hàng mua ngày 12/01/2026 | H291: NL300027 | I291: Cà rốt | J291: kg | K291: 0.8 | L291: 18000 | N291: =L291*K291 -> 14400 | O291: 0 | P291: 18000 | Q291: GSG.01 | R291: 3311 | T291: GSG01 | V291: TRANNTB | W291: TRANNTB
A292: 46034 | B292: =""&DAY(A292)&"/01/2026"&H292 -> 12/01/2026NL300061 | C292: 2601GSG01056 | D292: 1 | E292: NCC100186 | F292: CÔNG TY TNHH NÔNG SẢN THỰC PHẨM TRẦN GIA | G292: GSG01 - Nhập hàng mua ngày 12/01/2026 | H292: NL300061 | I292: Hành Paro (Hành Baro) | J292: kg | K292: 0.3 | L292: 38000 | N292: =L292*K292 -> 11400 | O292: 0 | P292: 38000 | Q292: GSG.01 | R292: 3311 | T292: GSG01 | V292: TRANNTB | W292: TRANNTB
A293: 46034 | B293: =""&DAY(A293)&"/01/2026"&H293 -> 12/01/2026NL300004 | C293: 2601GSG01056 | D293: 1 | E293: NCC100186 | F293: CÔNG TY TNHH NÔNG SẢN THỰC PHẨM TRẦN GIA | G293: GSG01 - Nhập hàng mua ngày 12/01/2026 | H293: NL300004 | I293: Bắp cải trắng | J293: kg | K293: 2.8 | L293: 19000 | N293: =L293*K293 -> 53200 | O293: 0 | P293: 19000 | Q293: GSG.01 | R293: 3311 | T293: GSG01 | V293: TRANNTB | W293: TRANNTB
... A303: 46034 | B303: =""&DAY(A303)&"/01/2026"&H303 -> 12/01/2026NL300096 | C303: 2601GSG01063 | D303: 1 | E303: NCC100186 | F303: CÔNG TY TNHH NÔNG SẢN THỰC PHẨM TRẦN GIA | G303: GSG01 - Nhập hàng mua ngày 12/01/2026 | H303: NL300096 | I303: Nấm kim châm tươi | J303: kg | K303: 0.5 | L303: 45000 | N303: =L303*K303 -> 22500 | O303: 0 | P303: 45000 | Q303: GSG.01 | R303: 3311 | T303: GSG01 | V303: TRANNTB | W303: TRANNTB
...

Sheet mã
A1: STT | B1: Mã TG | C1: Mã hàng | D1: Tên mặt hàng | E1: Đvt | F1: GIÁ CHỐT
A2: 1 | B2: I100258 | C2: NL430151 | D2: Bánh canh NV | E2: kg | F2: =+VLOOKUP(C2,[1]Sheet1!A$2:D$168,4,0) -> 20000
A3: 2 | B3: I100252 | C3: NL300002 | D3: Bánh phở | E3: kg | F3: =+VLOOKUP(C3,[1]Sheet1!A$2:D$168,4,0) -> 16000
A4: 3 | B4: I100002 | C4: NL300003 | D4: Bắp cải tím | E4: kg | F4: =+VLOOKUP(C4,[1]Sheet1!A$2:D$168,4,0) -> 26000
A5: 4 | B5: I100003 | C5: NL300004 | D5: Bắp cải trắng | E5: kg | F5: =+VLOOKUP(C5,[1]Sheet1!A$2:D$168,4,0) -> 19000
A6: 5 | B6: I100010 | C6: NL300174 | D6: Bầu | E6: kg | F6: =+VLOOKUP(C6,[1]Sheet1!A$2:D$168,4,0) -> 24000
A7: 6 | B7: I100010 | C7: NL430005 | D7: Bầu NV | E7: kg | F7: =+VLOOKUP(C7,[1]Sheet1!A$2:D$168,4,0) -> #N/A
A8: 7 | B8: I100017 | C8: NL430006 | D8: Bí bao tử NV | E8: kg | F8: =+VLOOKUP(C8,[1]Sheet1!A$2:D$168,4,0) -> #N/A
A9: 8 | B9: I100012 | C9: NL300007 | D9: Bí đỏ | E9: kg | F9: =+VLOOKUP(C9,[1]Sheet1!A$2:D$168,4,0) -> 30000
A10: 9 | B10: I100016 | C10: NL300008 | D10: Bí ngòi | E10: kg | F10: =+VLOOKUP(C10,[1]Sheet1!A$2:D$168,4,0) -> 40000
A11: 10 | B11: I100017 | C11: NL300009 | D11: Bí nụ | E11: kg | F11: =+VLOOKUP(C11,[1]Sheet1!A$2:D$168,4,0) -> #N/A
A12: 11 | B12: I100011 | C12: NL430009 | D12: Bí xanh NV | E12: kg | F12: =+VLOOKUP(C12,[1]Sheet1!A$2:D$168,4,0) -> 28000
A13: 12 | B13: I100025 | C13: NL300015 | D13: Bông cải xanh Baby | E13: kg | F13: =+VLOOKUP(C13,[1]Sheet1!A$2:D$168,4,0) -> #N/A
... A125: 125 | B125: I100565 | C125: NL410042 | D125: gà nhân viên | E125: kg | F125: =+VLOOKUP(C125,[1]Sheet1!A$2:D$168,4,0) -> #N/A
A126: 126 | B126: #N/A | C126: NL430061 | D126: húng chó | E126: kg | F126: =+VLOOKUP(C126,[1]Sheet1!A$2:D$168,4,0) -> 65000
A127: 127 | B127: #N/A | C127: NL410099 | D127: tim gà | E127: kg | F127: =+VLOOKUP(C127,[1]Sheet1!A$2:D$168,4,0) -> #N/A
A128: 128 | B128: #N/A | C128: NL410051 | D128: lòng già | E128: kg | F128: =+VLOOKUP(C128,[1]Sheet1!A$2:D$168,4,0) -> #N/A
A129: 129 | B129: I100604 | C129: NL410053 | D129: Lòng mề gà NV | E129: kg | F129: =+VLOOKUP(C129,[1]Sheet1!A$2:D$168,4,0) -> #N/A
A130: 130 | B130: I100145 | C130: NL430082 | D130: Măng củ NV | E130: kg | F130: =+VLOOKUP(C130,[1]Sheet1!A$2:D$168,4,0) -> #N/A
A131: 131 | B131: I100143 | C131: NL430083 | D131: Măng lá NV | E131: kg | F131: =+VLOOKUP(C131,[1]Sheet1!A$2:D$168,4,0) -> #N/A
A132: 132 | B132: I100359 | C132: NL430081 | D132: Mắm tôm | E132: lọ | F132: =+VLOOKUP(C132,[1]Sheet1!A$2:D$168,4,0) -> #N/A
A133: 133 | B133: I100358 | C133: NL430080 | D133: Mắm ruốc | E133: lọ | F133: =+VLOOKUP(C133,[1]Sheet1!A$2:D$168,4,0) -> #N/A
A134: 134 | B134: I100761 | C134: NL300175 | D134: Mẻ chua | E134: kg | F134: =+VLOOKUP(C134,[1]Sheet1!A$2:D$168,4,0) -> #N/A
A135: 135 | B135: I100147 | C135: NL420028 | D135: Me vàng NV | E135: kg | F135: =+VLOOKUP(C135,[1]Sheet1!A$2:D$168,4,0) -> #N/A
A136: 136 | B136: I100150 | C136: NL300084 | D136: Mồng tơi nhặt | E136: kg | F136: =+VLOOKUP(C136,[1]Sheet1!A$2:D$168,4,0) -> 22000
A137: 137 | B137: I100156 | C137: NL300085 | D137: Mùi ta ( Ngò rí ) | E137: kg | F137: =+VLOOKUP(C137,[1]Sheet1!A$2:D$168,4,0) -> 45000
A138: 138 | B138: I100243 | C138: NL420030 | D138: Mộc nhĩ NV | E138: kg | F138: =+VLOOKUP(C138,[1]Sheet1!A$2:D$168,4,0) -> #N/A
A139: 139 | B139: I100154 | C139: NL300086 | D139: Mùi tàu ( Ngò gai ) | E139: kg | F139: =+VLOOKUP(C139,[1]Sheet1!A$2:D$168,4,0) -> 33000
A140: 140 | B140: I100118 | C140: NL430092 | D140: Mướp đắng NV ( Khổ qua NV ) | E140: kg | F140: =+VLOOKUP(C140,[1]Sheet1!A$2:D$168,4,0) -> 30000
... A220: 219 | B220: I100206 | C220: NL300148 | D220: Xà lách tím | E220: kg | F220: =+VLOOKUP(C220,[1]Sheet1!A$2:D$168,4,0) -> 65000
B221: I100024 | C221: NL300137 | D221: Súp lơ xanh | E221: kg | F221: =+VLOOKUP(C221,[1]Sheet1!A$2:D$168,4,0) -> 52000
B222: I100653 | C222: NL300230 | D222: Cải Mầm | E222: kg | F222: =+VLOOKUP(C222,[1]Sheet1!A$2:D$168,4,0) -> 80000
B223: I100094 | C223: NL300050 | D223: Giá đỗ | E223: kg | F223: =+VLOOKUP(C223,[1]Sheet1!A$2:D$168,4,0) -> 9000
C224: NL300071 | D224: Khoai tây củ | E224: kg | F224: =+VLOOKUP(C224,[1]Sheet1!A$2:D$168,4,0) -> 20000
C225: NL300232 | D225: Xà lách thủy tinh | E225: kg | F225: 68000
