Workbook

Sheet LW3
D2: CÔNG TY TNHH NÔNG SẢN THỰC PHẨM TRẦN GIA HTX: Ấp Lộc Tiến, Xã Mỹ Lộc, Huyện Cần Giuộc, Tỉnh Long An VP: Tòa nhà An Phú Plaza, 117-119 Lý Chính Thắng, P.7. Q.3, TP.HCM Kho sơ chế: 30 Kha Vạn Cân, P. Hiệp Bình Chánh, TP.Thủ Đức, TP.HCM Kho Đà Lạt: 69 Trần Thủ Độ, TT Liên Nghĩa, Huyện Đức Trọng, Tỉnh Lâm Đồng. Website: rausachtrangia.com - Hotline: 090.245.8081
A4: CHI TIẾT ĐỐI CHIẾU CÔNG NỢ
A6: Từ ngày 1 tháng 01 đến ngày 15 tháng 01 năm 2026
A8: Tên Khách hàng: LONGWANG 3
A10: Địa chỉ:
A12: Người liên hệ: Email: | N12: =SUBTOTAL(9,N15:N465) -> 1854.22 | P12: =SUBTOTAL(9,P15:P465) -> 45597950
J13: =SUBTOTAL(9,J15:J465) -> 55453150
A14: NGÀY | B14: MÃ KHÁCH HÀNG | C14: TÊN KHÁCH HÀNG | D14: MÃ ĐƠN HÀNG | E14: MÃ HÀNG | F14: TÊN HÀNG | G14: ĐVT | H14: SỐ LƯỢNG | I14: ĐƠN GIÁ | J14: THÀNH TIỀN | K14: GHI CHÚ | N14: THỰC NHẬN | O14: ĐƠN GIÁ | P14: THÀNH TIỀN | Q14: LỆCH SL | R14: LỆCH ĐG | S14: NOTE
A15: 01/01/2026 | B15: TG-KS00286 | C15: LONGWANG 3 | D15: TG-AA20662 | E15: I100008 | F15: Bắp mỹ trái (Loại 1) | G15: Trái | H15: 25 | I15: 8500 | J15: =H15*I15 -> 212500 | L15: =IFERROR(VLOOKUP(F15,MÃ!$A:$B,2,0),0) -> NL300107 | M15: ="0"&DAY(A15)&"/01/2026"&L15 -> 01/01/2026NL300107 | N15: =IFERROR(VLOOKUP(M15,'WS3'!$B$2:$Q$437,11,0),0) -> 24 | O15: =IFERROR(VLOOKUP(M15,'WS3'!$B$2:$Q$437,12,0),0) -> 8500 | P15: =N15*O15 -> 204000 | Q15: =H15-N15 -> 1 | R15: =I15-O15 -> 0 | S15: SAI SL
A16: 01/01/2026 | B16: TG-KS00286 | C16: LONGWANG 3 | D16: TG-AA20662 | E16: I100012 | F16: Bí đỏ hồ lô | G16: Kg | H16: 4.8 | I16: 30000 | J16: =H16*I16 -> 144000 | L16: =IFERROR(VLOOKUP(F16,MÃ!$A:$B,2,0),0) -> NL300007 | M16: ="0"&DAY(A16)&"/01/2026"&L16 -> 01/01/2026NL300007 | N16: =IFERROR(VLOOKUP(M16,'WS3'!$B$2:$Q$437,11,0),0) -> 4.8 | O16: =IFERROR(VLOOKUP(M16,'WS3'!$B$2:$Q$437,12,0),0) -> 30000 | P16: =N16*O16 -> 144000 | Q16: =H16-N16 -> 0 | R16: =I16-O16 -> 0
A17: 01/01/2026 | B17: TG-KS00286 | C17: LONGWANG 3 | D17: TG-AA20662 | E17: I100016 | F17: Bí ngòi xanh | G17: Kg | H17: 15 | I17: 40000 | J17: =H17*I17 -> 600000 | L17: =IFERROR(VLOOKUP(F17,MÃ!$A:$B,2,0),0) -> NL300008 | M17: ="0"&DAY(A17)&"/01/2026"&L17 -> 01/01/2026NL300008 | N17: =IFERROR(VLOOKUP(M17,'WS3'!$B$2:$Q$437,11,0),0) -> 10 | O17: =IFERROR(VLOOKUP(M17,'WS3'!$B$2:$Q$437,12,0),0) -> 40000 | P17: =N17*O17 -> 400000 | Q17: =H17-N17 -> 5 | R17: =I17-O17 -> 0 | S17: SAI SL
A18: 01/01/2026 | B18: TG-KS00286 | C18: LONGWANG 3 | D18: TG-AA20662 | E18: I100024 | F18: Bông cải xanh | G18: Kg | H18: 7 | I18: 52000 | J18: =H18*I18 -> 364000 | L18: =IFERROR(VLOOKUP(F18,MÃ!$A:$B,2,0),0) -> NL300137 | M18: ="0"&DAY(A18)&"/01/2026"&L18 -> 01/01/2026NL300137 | N18: =IFERROR(VLOOKUP(M18,'WS3'!$B$2:$Q$437,11,0),0) -> 5 | O18: =IFERROR(VLOOKUP(M18,'WS3'!$B$2:$Q$437,12,0),0) -> 52000 | P18: =N18*O18 -> 260000 | Q18: =H18-N18 -> 2 | R18: =I18-O18 -> 0 | S18: SAI SL
A19: 01/01/2026 | B19: TG-KS00286 | C19: LONGWANG 3 | D19: TG-AA20662 | E19: I100040 | F19: Cà rốt baby | G19: Kg | H19: 0.5 | I19: 75000 | J19: =H19*I19 -> 37500 | L19: =IFERROR(VLOOKUP(F19,MÃ!$A:$B,2,0),0) -> NL300028 | M19: ="0"&DAY(A19)&"/01/2026"&L19 -> 01/01/2026NL300028 | N19: =IFERROR(VLOOKUP(M19,'WS3'!$B$2:$Q$437,11,0),0) -> 0.5 | O19: =IFERROR(VLOOKUP(M19,'WS3'!$B$2:$Q$437,12,0),0) -> 75000 | P19: =N19*O19 -> 37500 | Q19: =H19-N19 -> 0 | R19: =I19-O19 -> 0
A20: 01/01/2026 | B20: TG-KS00286 | C20: LONGWANG 3 | D20: TG-AA20662 | E20: I100045 | F20: Cải Hongkong(Cai ngong) | G20: Kg | H20: 5 | I20: 30000 | J20: =H20*I20 -> 150000 | L20: =IFERROR(VLOOKUP(F20,MÃ!$A:$B,2,0),0) -> NL300020 | M20: ="0"&DAY(A20)&"/01/2026"&L20 -> 01/01/2026NL300020 | N20: =IFERROR(VLOOKUP(M20,'WS3'!$B$2:$Q$437,11,0),0) -> 3 | O20: =IFERROR(VLOOKUP(M20,'WS3'!$B$2:$Q$437,12,0),0) -> 30000 | P20: =N20*O20 -> 90000 | Q20: =H20-N20 -> 2 | R20: =I20-O20 -> 0 | S20: SAI SL
A21: 01/01/2026 | B21: TG-KS00286 | C21: LONGWANG 3 | D21: TG-AA20662 | E21: I100057 | F21: Cần tây | G21: Kg | H21: 2.2 | I21: 44000 | J21: =H21*I21 -> 96800 | L21: =IFERROR(VLOOKUP(F21,MÃ!$A:$B,2,0),0) -> NL300025 | M21: ="0"&DAY(A21)&"/01/2026"&L21 -> 01/01/2026NL300025 | N21: =IFERROR(VLOOKUP(M21,'WS3'!$B$2:$Q$437,11,0),0) -> 2.2 | O21: =IFERROR(VLOOKUP(M21,'WS3'!$B$2:$Q$437,12,0),0) -> 44000 | P21: =N21*O21 -> 96800 | Q21: =H21-N21 -> 0 | R21: =I21-O21 -> 0
A22: 01/01/2026 | B22: TG-KS00286 | C22: LONGWANG 3 | D22: TG-AA20662 | E22: I100097 | F22: Củ Gừng | G22: Kg | H22: 2 | I22: 38000 | J22: =H22*I22 -> 76000 | L22: =IFERROR(VLOOKUP(F22,MÃ!$A:$B,2,0),0) -> NL300054 | M22: ="0"&DAY(A22)&"/01/2026"&L22 -> 01/01/2026NL300054 | N22: =IFERROR(VLOOKUP(M22,'WS3'!$B$2:$Q$437,11,0),0) -> 2 | O22: =IFERROR(VLOOKUP(M22,'WS3'!$B$2:$Q$437,12,0),0) -> 38000 | P22: =N22*O22 -> 76000 | Q22: =H22-N22 -> 0 | R22: =I22-O22 -> 0
A23: 01/01/2026 | B23: TG-KS00286 | C23: LONGWANG 3 | D23: TG-AA20662 | E23: I100072 | F23: Củ riềng | G23: Kg | H23: 0.15 | I23: 25000 | J23: =H23*I23 -> 3750 | L23: =IFERROR(VLOOKUP(F23,MÃ!$A:$B,2,0),0) -> NL300035 | M23: ="0"&DAY(A23)&"/01/2026"&L23 -> 01/01/2026NL300035 | N23: =IFERROR(VLOOKUP(M23,'WS3'!$B$2:$Q$437,11,0),0) -> 0.15 | O23: =IFERROR(VLOOKUP(M23,'WS3'!$B$2:$Q$437,12,0),0) -> 25000 | P23: =N23*O23 -> 3750 | Q23: =H23-N23 -> 0 | R23: =I23-O23 -> 0
A24: 01/01/2026 | B24: TG-KS00286 | C24: LONGWANG 3 | D24: TG-AA20662 | E24: I100074 | F24: Củ sen | G24: Kg | H24: 1 | I24: 47000 | J24: =H24*I24 -> 47000 | L24: =IFERROR(VLOOKUP(F24,MÃ!$A:$B,2,0),0) -> NL300036 | M24: ="0"&DAY(A24)&"/01/2026"&L24 -> 01/01/2026NL300036 | N24: =IFERROR(VLOOKUP(M24,'WS3'!$B$2:$Q$437,11,0),0) -> 1 | O24: =IFERROR(VLOOKUP(M24,'WS3'!$B$2:$Q$437,12,0),0) -> 47000 | P24: =N24*O24 -> 47000 | Q24: =H24-N24 -> 0 | R24: =I24-O24 -> 0
A25: 01/01/2026 | B25: TG-KS00286 | C25: LONGWANG 3 | D25: TG-AA20662 | E25: I100075 | F25: Đậu bắp | G25: Kg | H25: 5 | I25: 32000 | J25: =H25*I25 -> 160000 | L25: =IFERROR(VLOOKUP(F25,MÃ!$A:$B,2,0),0) -> NL300038 | M25: ="0"&DAY(A25)&"/01/2026"&L25 -> 01/01/2026NL300038 | N25: =IFERROR(VLOOKUP(M25,'WS3'!$B$2:$Q$437,11,0),0) -> 5 | O25: =IFERROR(VLOOKUP(M25,'WS3'!$B$2:$Q$437,12,0),0) -> 32000 | P25: =N25*O25 -> 160000 | Q25: =H25-N25 -> 0 | R25: =I25-O25 -> 0
A26: 01/01/2026 | B26: TG-KS00286 | C26: LONGWANG 3 | D26: TG-AA20662 | E26: I100883 | F26: Đậu hủ trứng CP 220gr | G26: Cây | H26: 9 | I26: 15000 | J26: =H26*I26 -> 135000 | L26: =IFERROR(VLOOKUP(F26,MÃ!$A:$B,2,0),0) -> NL300041 | M26: ="0"&DAY(A26)&"/01/2026"&L26 -> 01/01/2026NL300041 | N26: =IFERROR(VLOOKUP(M26,'WS3'!$B$2:$Q$437,11,0),0) -> 9 | O26: =IFERROR(VLOOKUP(M26,'WS3'!$B$2:$Q$437,12,0),0) -> 15000 | P26: =N26*O26 -> 135000 | Q26: =H26-N26 -> 0 | R26: =I26-O26 -> 0
A27: 01/01/2026 | B27: TG-KS00286 | C27: LONGWANG 3 | D27: TG-AA20662 | E27: I100479 | F27: Dưa hấu | G27: Kg | H27: 47 | I27: 18000 | J27: =H27*I27 -> 846000 | L27: =IFERROR(VLOOKUP(F27,MÃ!$A:$B,2,0),0) -> NL600004 | M27: ="0"&DAY(A27)&"/01/2026"&L27 -> 01/01/2026NL600004 | N27: =IFERROR(VLOOKUP(M27,'WS3'!$B$2:$Q$437,11,0),0) -> 47 | O27: =IFERROR(VLOOKUP(M27,'WS3'!$B$2:$Q$437,12,0),0) -> 18000 | P27: =N27*O27 -> 846000 | Q27: =H27-N27 -> 0 | R27: =I27-O27 -> 0
A28: 01/01/2026 | B28: TG-KS00286 | C28: LONGWANG 3 | D28: TG-AA20662 | E28: I100098 | F28: Hành lá | G28: Kg | H28: 6 | I28: 55000 | J28: =H28*I28 -> 330000 | L28: =IFERROR(VLOOKUP(F28,MÃ!$A:$B,2,0),0) -> NL300058 | M28: ="0"&DAY(A28)&"/01/2026"&L28 -> 01/01/2026NL300058 | N28: =IFERROR(VLOOKUP(M28,'WS3'!$B$2:$Q$437,11,0),0) -> 4.5 | O28: =IFERROR(VLOOKUP(M28,'WS3'!$B$2:$Q$437,12,0),0) -> 55000 | P28: =N28*O28 -> 247500 | Q28: =H28-N28 -> 1.5 | R28: =I28-O28 -> 0 | S28: SAI SL
A29: 01/01/2026 | B29: TG-KS00286 | C29: LONGWANG 3 | D29: TG-AA20662 | E29: I100101 | F29: Hành tây | G29: Kg | H29: 0.6 | I29: 13000 | J29: =H29*I29 -> 7800 | L29: =IFERROR(VLOOKUP(F29,MÃ!$A:$B,2,0),0) -> NL300059 | M29: ="0"&DAY(A29)&"/01/2026"&L29 -> 01/01/2026NL300059 | N29: =IFERROR(VLOOKUP(M29,'WS3'!$B$2:$Q$437,11,0),0) -> 0.6 | O29: =IFERROR(VLOOKUP(M29,'WS3'!$B$2:$Q$437,12,0),0) -> 13000 | P29: =N29*O29 -> 7800 | Q29: =H29-N29 -> 0 | R29: =I29-O29 -> 0
A30: 01/01/2026 | B30: TG-KS00286 | C30: LONGWANG 3 | D30: TG-AA20662 | E30: I100730 | F30: Hành tím bắc lột | G30: Kg | H30: 0.5 | I30: 80000 | J30: =H30*I30 -> 40000 | L30: =IFERROR(VLOOKUP(F30,MÃ!$A:$B,2,0),0) -> NL300055 | M30: ="0"&DAY(A30)&"/01/2026"&L30 -> 01/01/2026NL300055 | N30: =IFERROR(VLOOKUP(M30,'WS3'!$B$2:$Q$437,11,0),0) -> 0.5 | O30: =IFERROR(VLOOKUP(M30,'WS3'!$B$2:$Q$437,12,0),0) -> 80000 | P30: =N30*O30 -> 40000 | Q30: =H30-N30 -> 0 | R30: =I30-O30 -> 0
A31: 01/01/2026 | B31: TG-KS00286 | C31: LONGWANG 3 | D31: TG-AA20662 | E31: I100136 | F31: Lá dứa | G31: Kg | H31: 0.5 | I31: 18000 | J31: =H31*I31 -> 9000 | L31: =IFERROR(VLOOKUP(F31,MÃ!$A:$B,2,0),0) -> NL300184 | M31: ="0"&DAY(A31)&"/01/2026"&L31 -> 01/01/2026NL300184 | N31: =IFERROR(VLOOKUP(M31,'WS3'!$B$2:$Q$437,11,0),0) -> 0.5 | O31: =IFERROR(VLOOKUP(M31,'WS3'!$B$2:$Q$437,12,0),0) -> 18000 | P31: =N31*O31 -> 9000 | Q31: =H31-N31 -> 0 | R31: =I31-O31 -> 0
A32: 01/01/2026 | B32: TG-KS00286 | C32: LONGWANG 3 | D32: TG-AA20662 | E32: I100151 | F32: Mướp hương | G32: Kg | H32: 14 | I32: 27000 | J32: =H32*I32 -> 378000 | L32: =IFERROR(VLOOKUP(F32,MÃ!$A:$B,2,0),0) -> NL300088 | M32: ="0"&DAY(A32)&"/01/2026"&L32 -> 01/01/2026NL300088 | N32: =IFERROR(VLOOKUP(M32,'WS3'!$B$2:$Q$437,11,0),0) -> 7 | O32: =IFERROR(VLOOKUP(M32,'WS3'!$B$2:$Q$437,12,0),0) -> 27000 | P32: =N32*O32 -> 189000 | Q32: =H32-N32 -> 7 | R32: =I32-O32 -> 0 | S32: SAI SL
A33: 01/01/2026 | B33: TG-KS00286 | C33: LONGWANG 3 | D33: TG-AA20662 | E33: I100236 | F33: Nấm đông cô tươi | G33: Kg | H33: 7 | I33: 145000 | J33: =H33*I33 -> 1015000 | L33: =IFERROR(VLOOKUP(F33,MÃ!$A:$B,2,0),0) -> NL300090 | M33: ="0"&DAY(A33)&"/01/2026"&L33 -> 01/01/2026NL300090 | N33: =IFERROR(VLOOKUP(M33,'WS3'!$B$2:$Q$437,11,0),0) -> 6.7 | O33: =IFERROR(VLOOKUP(M33,'WS3'!$B$2:$Q$437,12,0),0) -> 145000 | P33: =N33*O33 -> 971500 | Q33: =H33-N33 -> 0.3 | R33: =I33-O33 -> 0 | S33: SAI SL
A34: 01/01/2026 | B34: TG-KS00286 | C34: LONGWANG 3 | D34: TG-AA20662 | E34: I100237 | F34: Nấm đùi gà | G34: Kg | H34: 5 | I34: 47000 | J34: =H34*I34 -> 235000 | L34: =IFERROR(VLOOKUP(F34,MÃ!$A:$B,2,0),0) -> NL300091 | M34: ="0"&DAY(A34)&"/01/2026"&L34 -> 01/01/2026NL300091 | N34: =IFERROR(VLOOKUP(M34,'WS3'!$B$2:$Q$437,11,0),0) -> 5 | O34: =IFERROR(VLOOKUP(M34,'WS3'!$B$2:$Q$437,12,0),0) -> 47000 | P34: =N34*O34 -> 235000 | Q34: =H34-N34 -> 0 | R34: =I34-O34 -> 0
A35: 01/01/2026 | B35: TG-KS00286 | C35: LONGWANG 3 | D35: TG-AA20662 | E35: I100650 | F35: Nấm đùi gà baby | G35: Kg | H35: 3 | I35: 90000 | J35: =H35*I35 -> 270000 | L35: =IFERROR(VLOOKUP(F35,MÃ!$A:$B,2,0),0) -> NL300092 | M35: ="0"&DAY(A35)&"/01/2026"&L35 -> 01/01/2026NL300092 | N35: =IFERROR(VLOOKUP(M35,'WS3'!$B$2:$Q$437,11,0),0) -> 2.8 | O35: =IFERROR(VLOOKUP(M35,'WS3'!$B$2:$Q$437,12,0),0) -> 90000 | P35: =N35*O35 -> 252000 | Q35: =H35-N35 -> 0.2 | R35: =I35-O35 -> 0 | S35: SAI SL
A36: 01/01/2026 | B36: TG-KS00286 | C36: LONGWANG 3 | D36: TG-AA20662 | E36: I100634 | F36: Nấm hải sản (kg) | G36: Kg | H36: 1 | I36: 80000 | J36: =H36*I36 -> 80000 | L36: =IFERROR(VLOOKUP(F36,MÃ!$A:$B,2,0),0) -> NL300094 | M36: ="0"&DAY(A36)&"/01/2026"&L36 -> 01/01/2026NL300094 | N36: =IFERROR(VLOOKUP(M36,'WS3'!$B$2:$Q$437,11,0),0) -> 0.8 | O36: =IFERROR(VLOOKUP(M36,'WS3'!$B$2:$Q$437,12,0),0) -> 80000 | P36: =N36*O36 -> 64000 | Q36: =H36-N36 -> 0.2 | R36: =I36-O36 -> 0 | S36: SAI SL
A37: 01/01/2026 | B37: TG-KS00286 | C37: LONGWANG 3 | D37: TG-AA20662 | E37: I100240 | F37: Nấm kim châm tươi | G37: Kg | H37: 8 | I37: 45000 | J37: =H37*I37 -> 360000 | L37: =IFERROR(VLOOKUP(F37,MÃ!$A:$B,2,0),0) -> NL300096 | M37: ="0"&DAY(A37)&"/01/2026"&L37 -> 01/01/2026NL300096 | N37: =IFERROR(VLOOKUP(M37,'WS3'!$B$2:$Q$437,11,0),0) -> 7.6 | O37: =IFERROR(VLOOKUP(M37,'WS3'!$B$2:$Q$437,12,0),0) -> 45000 | P37: =N37*O37 -> 342000 | Q37: =H37-N37 -> 0.4 | R37: =I37-O37 -> 0 | S37: SAI SL
A38: 01/01/2026 | B38: TG-KS00286 | C38: LONGWANG 3 | D38: TG-AA20662 | E38: I100635 | F38: Nấm linh chi nâu (kg) | G38: Kg | H38: 1 | I38: 90000 | J38: =H38*I38 -> 90000 | L38: =IFERROR(VLOOKUP(F38,MÃ!$A:$B,2,0),0) -> NL300097 | M38: ="0"&DAY(A38)&"/01/2026"&L38 -> 01/01/2026NL300097 | N38: =IFERROR(VLOOKUP(M38,'WS3'!$B$2:$Q$437,11,0),0) -> 1 | O38: =IFERROR(VLOOKUP(M38,'WS3'!$B$2:$Q$437,12,0),0) -> 90000 | P38: =N38*O38 -> 90000 | Q38: =H38-N38 -> 0 | R38: =I38-O38 -> 0
A39: 01/01/2026 | B39: TG-KS00286 | C39: LONGWANG 3 | D39: TG-AA20662 | E39: I100156 | F39: Ngò rí | G39: Kg | H39: 4 | I39: 45000 | J39: =H39*I39 -> 180000 | L39: =IFERROR(VLOOKUP(F39,MÃ!$A:$B,2,0),0) -> NL300085 | M39: ="0"&DAY(A39)&"/01/2026"&L39 -> 01/01/2026NL300085 | N39: =IFERROR(VLOOKUP(M39,'WS3'!$B$2:$Q$437,11,0),0) -> 2.5 | O39: =IFERROR(VLOOKUP(M39,'WS3'!$B$2:$Q$437,12,0),0) -> 45000 | P39: =N39*O39 -> 112500 | Q39: =H39-N39 -> 1.5 | R39: =I39-O39 -> 0 | S39: SAI SL
A40: 01/01/2026 | B40: TG-KS00286 | C40: LONGWANG 3 | D40: TG-AA20662 | E40: I100160 | F40: Ngò tây | G40: Kg | H40: 0.1 | I40: 70000 | J40: =H40*I40 -> 7000 | L40: =IFERROR(VLOOKUP(F40,MÃ!$A:$B,2,0),0) -> NL300126 | M40: ="0"&DAY(A40)&"/01/2026"&L40 -> 01/01/2026NL300126 | N40: =IFERROR(VLOOKUP(M40,'WS3'!$B$2:$Q$437,11,0),0) -> 0.1 | O40: =IFERROR(VLOOKUP(M40,'WS3'!$B$2:$Q$437,12,0),0) -> 70000 | P40: =N40*O40 -> 7000 | Q40: =H40-N40 -> 0 | R40: =I40-O40 -> 0
A41: 01/01/2026 | B41: TG-KS00286 | C41: LONGWANG 3 | D41: TG-AA20662 | E41: I100167 | F41: Ớt hiểm đỏ | G41: Kg | H41: 2 | I41: 145000 | J41: =H41*I41 -> 290000 | L41: =IFERROR(VLOOKUP(F41,MÃ!$A:$B,2,0),0) -> NL300113 | M41: ="0"&DAY(A41)&"/01/2026"&L41 -> 01/01/2026NL300113 | N41: =IFERROR(VLOOKUP(M41,'WS3'!$B$2:$Q$437,11,0),0) -> 2 | O41: =IFERROR(VLOOKUP(M41,'WS3'!$B$2:$Q$437,12,0),0) -> 145000 | P41: =N41*O41 -> 290000 | Q41: =H41-N41 -> 0 | R41: =I41-O41 -> 0
A42: 01/01/2026 | B42: TG-KS00286 | C42: LONGWANG 3 | D42: TG-AA20662 | E42: I100170 | F42: Ớt sừng đỏ | G42: Kg | H42: 0.3 | I42: 148000 | J42: =H42*I42 -> 44400 | L42: =IFERROR(VLOOKUP(F42,MÃ!$A:$B,2,0),0) -> NL300116 | M42: ="0"&DAY(A42)&"/01/2026"&L42 -> 01/01/2026NL300116 | N42: =IFERROR(VLOOKUP(M42,'WS3'!$B$2:$Q$437,11,0),0) -> 0.3 | O42: =IFERROR(VLOOKUP(M42,'WS3'!$B$2:$Q$437,12,0),0) -> 148000 | P42: =N42*O42 -> 44400 | Q42: =H42-N42 -> 0 | R42: =I42-O42 -> 0
A43: 01/01/2026 | B43: TG-KS00286 | C43: LONGWANG 3 | D43: TG-AA20662 | E43: I100626 | F43: Rau má nhỏ | G43: Kg | H43: 1 | I43: 42000 | J43: =H43*I43 -> 42000 | L43: =IFERROR(VLOOKUP(F43,MÃ!$A:$B,2,0),0) -> NL300125 | M43: ="0"&DAY(A43)&"/01/2026"&L43 -> 01/01/2026NL300125 | N43: =IFERROR(VLOOKUP(M43,'WS3'!$B$2:$Q$437,11,0),0) -> 1 | O43: =IFERROR(VLOOKUP(M43,'WS3'!$B$2:$Q$437,12,0),0) -> 42000 | P43: =N43*O43 -> 42000 | Q43: =H43-N43 -> 0 | R43: =I43-O43 -> 0
A44: 01/01/2026 | B44: TG-KS00286 | C44: LONGWANG 3 | D44: TG-AA20662 | E44: I100189 | F44: Rau răm | G44: Kg | H44: 0.1 | I44: 22000 | J44: =H44*I44 -> 2200 | L44: =IFERROR(VLOOKUP(F44,MÃ!$A:$B,2,0),0) -> NL300121 | M44: ="0"&DAY(A44)&"/01/2026"&L44 -> 01/01/2026NL300121 | N44: =IFERROR(VLOOKUP(M44,'WS3'!$B$2:$Q$437,11,0),0) -> 0.1 | O44: =IFERROR(VLOOKUP(M44,'WS3'!$B$2:$Q$437,12,0),0) -> 22000 | P44: =N44*O44 -> 2200 | Q44: =H44-N44 -> 0 | R44: =I44-O44 -> 0
A45: 01/01/2026 | B45: TG-KS00286 | C45: LONGWANG 3 | D45: TG-AA20662 | E45: I100194 | F45: Rau tía tô | G45: Kg | H45: 1 | I45: 36000 | J45: =H45*I45 -> 36000 | L45: =IFERROR(VLOOKUP(F45,MÃ!$A:$B,2,0),0) -> NL300140 | M45: ="0"&DAY(A45)&"/01/2026"&L45 -> 01/01/2026NL300140 | N45: =IFERROR(VLOOKUP(M45,'WS3'!$B$2:$Q$437,11,0),0) -> 1 | O45: =IFERROR(VLOOKUP(M45,'WS3'!$B$2:$Q$437,12,0),0) -> 36000 | P45: =N45*O45 -> 36000 | Q45: =H45-N45 -> 0 | R45: =I45-O45 -> 0
A46: 01/01/2026 | B46: TG-KS00286 | C46: LONGWANG 3 | D46: TG-AA20662 | E46: I100198 | F46: Sả cây | G46: Kg | H46: 1 | I46: 12000 | J46: =H46*I46 -> 12000 | L46: =IFERROR(VLOOKUP(F46,MÃ!$A:$B,2,0),0) -> NL300132 | M46: ="0"&DAY(A46)&"/01/2026"&L46 -> 01/01/2026NL300132 | N46: =IFERROR(VLOOKUP(M46,'WS3'!$B$2:$Q$437,11,0),0) -> 1 | O46: =IFERROR(VLOOKUP(M46,'WS3'!$B$2:$Q$437,12,0),0) -> 12000 | P46: =N46*O46 -> 12000 | Q46: =H46-N46 -> 0 | R46: =I46-O46 -> 0
...

Sheet WS3
A1: Ngày ct | B1: Mã ct | C1: Số ct | D1: Số hđ | E1: Áp giá | F1: Mã ncc | G1: Tên ncc | H1: Diễn giải | I1: Mã hàng | J1: Tên mặt hàng | K1: Đvt | L1: =SUBTOTAL(9,L2:L437) -> 99.7 | M1: Giá | N1: Giá báo | O1: =SUBTOTAL(9,O2:O437) -> 1840600 | P1: Thuế suất | Q1: Chênh lệch giá | R1: Kho hàng | S1: Mã nx | T1: Vụ việc | U1: Bộ phận | V1: Hợp đồng | W1: Người tạo | X1: Người sửa
A2: 46023 | B2: ="0"&DAY(A2)&"/01/2026"&I2 -> 01/01/2026NL100101 | C2: 2601WSG03004 | E2: 1 | F2: NCC100186 | G2: CÔNG TY TNHH NÔNG SẢN THỰC PHẨM TRẦN GIA | H2: WSG03 - Nhập hàng mua ngày 01/01/2026 | I2: NL100101 | J2: Trứng vịt muối | K2: quả | L2: 35 | M2: 5000 | N2: 0 | O2: 175000 | P2: 0 | Q2: 5000 | R2: WSG.03 | S2: 3311 | U2: WSG03 | W2: NHUNTQ | X2: NHUNTQ
A3: 46023 | B3: ="0"&DAY(A3)&"/01/2026"&I3 -> 01/01/2026NL100279 | C3: 2601WSG03004 | E3: 1 | F3: NCC100186 | G3: CÔNG TY TNHH NÔNG SẢN THỰC PHẨM TRẦN GIA | H3: WSG03 - Nhập hàng mua ngày 01/01/2026 | I3: NL100279 | J3: Trứng Bắc Thảo | K3: Quả | L3: 50 | M3: 9000 | N3: 0 | O3: 450000 | P3: 0 | Q3: 9000 | R3: WSG.03 | S3: 3311 | U3: WSG03 | W3: NHUNTQ | X3: NHUNTQ
A4: 46023 | B4: ="0"&DAY(A4)&"/01/2026"&I4 -> 01/01/2026NL300142 | C4: 2601WSG03004 | E4: 1 | F4: NCC100186 | G4: CÔNG TY TNHH NÔNG SẢN THỰC PHẨM TRẦN GIA | H4: WSG03 - Nhập hàng mua ngày 01/01/2026 | I4: NL300142 | J4: Tỏi bóc | K4: kg | L4: 2 | M4: 50000 | N4: 0 | O4: 100000 | P4: 0 | Q4: 50000 | R4: WSG.03 | S4: 3311 | U4: WSG03 | W4: NHUNTQ | X4: NHUNTQ
A5: 46023 | B5: ="0"&DAY(A5)&"/01/2026"&I5 -> 01/01/2026NL300097 | C5: 2601WSG03004 | E5: 1 | F5: NCC100186 | G5: CÔNG TY TNHH NÔNG SẢN THỰC PHẨM TRẦN GIA | H5: WSG03 - Nhập hàng mua ngày 01/01/2026 | I5: NL300097 | J5: Nấm Linh Chi nâu | K5: kg | L5: 1 | M5: 90000 | N5: 0 | O5: 90000 | P5: 0 | Q5: 90000 | R5: WSG.03 | S5: 3311 | U5: WSG03 | W5: NHUNTQ | X5: NHUNTQ
A6: 46023 | B6: ="0"&DAY(A6)&"/01/2026"&I6 -> 01/01/2026NL300007 | C6: 2601WSG03004 | E6: 1 | F6: NCC100186 | G6: CÔNG TY TNHH NÔNG SẢN THỰC PHẨM TRẦN GIA | H6: WSG03 - Nhập hàng mua ngày 01/01/2026 | I6: NL300007 | J6: Bí đỏ | K6: kg | L6: 4.8 | M6: 30000 | N6: 0 | O6: 144000 | P6: 0 | Q6: 30000 | R6: WSG.03 | S6: 3311 | U6: WSG03 | W6: NHUNTQ | X6: NHUNTQ
A7: 46023 | B7: ="0"&DAY(A7)&"/01/2026"&I7 -> 01/01/2026NL300008 | C7: 2601WSG03004 | E7: 1 | F7: NCC100186 | G7: CÔNG TY TNHH NÔNG SẢN THỰC PHẨM TRẦN GIA | H7: WSG03 - Nhập hàng mua ngày 01/01/2026 | I7: NL300008 | J7: Bí ngòi | K7: kg | L7: 10 | M7: 40000 | N7: 0 | O7: 400000 | P7: 0 | Q7: 40000 | R7: WSG.03 | S7: 3311 | U7: WSG03 | W7: NHUNTQ | X7: NHUNTQ
A8: 46023 | B8: ="0"&DAY(A8)&"/01/2026"&I8 -> 01/01/2026NL300020 | C8: 2601WSG03004 | E8: 1 | F8: NCC100186 | G8: CÔNG TY TNHH NÔNG SẢN THỰC PHẨM TRẦN GIA | H8: WSG03 - Nhập hàng mua ngày 01/01/2026 | I8: NL300020 | J8: Cải ngồng | K8: kg | L8: 3 | M8: 30000 | N8: 0 | O8: 90000 | P8: 0 | Q8: 30000 | R8: WSG.03 | S8: 3311 | U8: WSG03 | W8: NHUNTQ | X8: NHUNTQ
A9: 46023 | B9: ="0"&DAY(A9)&"/01/2026"&I9 -> 01/01/2026NL300025 | C9: 2601WSG03004 | E9: 1 | F9: NCC100186 | G9: CÔNG TY TNHH NÔNG SẢN THỰC PHẨM TRẦN GIA | H9: WSG03 - Nhập hàng mua ngày 01/01/2026 | I9: NL300025 | J9: Rau cần tây | K9: kg | L9: 2.2 | M9: 44000 | N9: 0 | O9: 96800 | P9: 0 | Q9: 44000 | R9: WSG.03 | S9: 3311 | U9: WSG03 | W9: NHUNTQ | X9: NHUNTQ
A10: 46023 | B10: ="0"&DAY(A10)&"/01/2026"&I10 -> 01/01/2026NL300028 | C10: 2601WSG03004 | E10: 1 | F10: NCC100186 | G10: CÔNG TY TNHH NÔNG SẢN THỰC PHẨM TRẦN GIA | H10: WSG03 - Nhập hàng mua ngày 01/01/2026 | I10: NL300028 | J10: Cà rốt baby | K10: kg | L10: 0.5 | M10: 75000 | N10: 0 | O10: 37500 | P10: 0 | Q10: 75000 | R10: WSG.03 | S10: 3311 | U10: WSG03 | W10: NHUNTQ | X10: NHUNTQ
A11: 46023 | B11: ="0"&DAY(A11)&"/01/2026"&I11 -> 01/01/2026NL300035 | C11: 2601WSG03004 | E11: 1 | F11: NCC100186 | G11: CÔNG TY TNHH NÔNG SẢN THỰC PHẨM TRẦN GIA | H11: WSG03 - Nhập hàng mua ngày 01/01/2026 | I11: NL300035 | J11: Riềng củ | K11: kg | L11: 0.15 | M11: 25000 | N11: 0 | O11: 3750 | P11: 0 | Q11: 25000 | R11: WSG.03 | S11: 3311 | U11: WSG03 | W11: NHUNTQ | X11: NHUNTQ
A12: 46023 | B12: ="0"&DAY(A12)&"/01/2026"&I12 -> 01/01/2026NL300036 | C12: 2601WSG03004 | E12: 1 | F12: NCC100186 | G12: CÔNG TY TNHH NÔNG SẢN THỰC PHẨM TRẦN GIA | H12: WSG03 - Nhập hàng mua ngày 01/01/2026 | I12: NL300036 | J12: Củ sen | K12: kg | L12: 1 | M12: 47000 | N12: 0 | O12: 47000 | P12: 0 | Q12: 47000 | R12: WSG.03 | S12: 3311 | U12: WSG03 | W12: NHUNTQ | X12: NHUNTQ
A13: 46023 | B13: ="0"&DAY(A13)&"/01/2026"&I13 -> 01/01/2026NL300038 | C13: 2601WSG03004 | E13: 1 | F13: NCC100186 | G13: CÔNG TY TNHH NÔNG SẢN THỰC PHẨM TRẦN GIA | H13: WSG03 - Nhập hàng mua ngày 01/01/2026 | I13: NL300038 | J13: Đậu bắp | K13: kg | L13: 5 | M13: 32000 | N13: 0 | O13: 160000 | P13: 0 | Q13: 32000 | R13: WSG.03 | S13: 3311 | U13: WSG03 | W13: NHUNTQ | X13: NHUNTQ
... A257: 46031 | B257: ="0"&DAY(A257)&"/01/2026"&I257 -> 09/01/2026NL100279 | C257: 2601WSG03059 | E257: 1 | F257: NCC100186 | G257: CÔNG TY TNHH NÔNG SẢN THỰC PHẨM TRẦN GIA | H257: WSG03 - Nhập hàng mua ngày 09/01/2026 | I257: NL100279 | J257: Trứng Bắc Thảo | K257: Quả | L257: 50 | M257: 9000 | N257: 0 | O257: 450000 | P257: 0 | Q257: 9000 | R257: WSG.03 | S257: 3311 | U257: WSG03 | W257: NHUNTQ | X257: NHUNTQ
A258: 46032 | B258: =""&DAY(A258)&"/01/2026"&I258 -> 10/01/2026NL600004 | C258: 2601WSG03140 | E258: 1 | F258: NCC100186 | G258: CÔNG TY TNHH NÔNG SẢN THỰC PHẨM TRẦN GIA | H258: WSG03 - Nhập hàng mua ngày 10/01/2026 | I258: NL600004 | J258: Dưa hấu | K258: kg | L258: 18.5 | M258: 18000 | N258: 0 | O258: 333000 | P258: 0 | Q258: 18000 | R258: WSG.03 | S258: 3311 | U258: WSG03 | W258: NHUNTQ | X258: NHUNTQ
A259: 46032 | B259: =""&DAY(A259)&"/01/2026"&I259 -> 10/01/2026NL600068 | C259: 2601WSG03140 | E259: 1 | F259: NCC100186 | G259: CÔNG TY TNHH NÔNG SẢN THỰC PHẨM TRẦN GIA | H259: WSG03 - Nhập hàng mua ngày 10/01/2026 | I259: NL600068 | J259: Chanh vàng | K259: kg | L259: 0.3 | M259: 95000 | N259: 0 | O259: 28500 | P259: 0 | Q259: 95000 | R259: WSG.03 | S259: 3311 | U259: WSG03 | W259: NHUNTQ | X259: NHUNTQ
A260: 46032 | B260: =""&DAY(A260)&"/01/2026"&I260 -> 10/01/2026NL300131 | C260: 2601WSG03140 | E260: 1 | F260: NCC100186 | G260: CÔNG TY TNHH NÔNG SẢN THỰC PHẨM TRẦN GIA | H260: WSG03 - Nhập hàng mua ngày 10/01/2026 | I260: NL300131 | J260: Xà lách Rocket | K260: kg | L260: 0.3 | M260: 220000 | N260: 0 | O260: 66000 | P260: 0 | Q260: 220000 | R260: WSG.03 | S260: 3311 | U260: WSG03 | W260: NHUNTQ | X260: NHUNTQ
A261: 46032 | B261: =""&DAY(A261)&"/01/2026"&I261 -> 10/01/2026NL300030 | C261: 2601WSG03140 | E261: 1 | F261: NCC100186 | G261: CÔNG TY TNHH NÔNG SẢN THỰC PHẨM TRẦN GIA | H261: WSG03 - Nhập hàng mua ngày 10/01/2026 | I261: NL300030 | J261: Chanh dây (chanh leo) | K261: kg | L261: 1.2 | M261: 34000 | N261: 0 | O261: 40800 | P261: 0 | Q261: 34000 | R261: WSG.03 | S261: 3311 | U261: WSG03 | W261: NHUNTQ | X261: NHUNTQ
A262: 46032 | B262: =""&DAY(A262)&"/01/2026"&I262 -> 10/01/2026NL300062 | C262: 2601WSG03140 | E262: 1 | F262: NCC100186 | G262: CÔNG TY TNHH NÔNG SẢN THỰC PHẨM TRẦN GIA | H262: WSG03 - Nhập hàng mua ngày 10/01/2026 | I262: NL300062 | J262: Húng Bạc Hà | K262: kg | L262: 0.1 | M262: 65000 | N262: 0 | O262: 6500 | P262: 0 | Q262: 65000 | R262: WSG.03 | S262: 3311 | U262: WSG03 | W262: NHUNTQ | X262: NHUNTQ
A263: 46032 | B263: =""&DAY(A263)&"/01/2026"&I263 -> 10/01/2026NL300125 | C263: 2601WSG03140 | E263: 1 | F263: NCC100186 | G263: CÔNG TY TNHH NÔNG SẢN THỰC PHẨM TRẦN GIA | H263: WSG03 - Nhập hàng mua ngày 10/01/2026 | I263: NL300125 | J263: Rau má | K263: kg | L263: 0.5 | M263: 42000 | N263: 0 | O263: 21000 | P263: 0 | Q263: 42000 | R263: WSG.03 | S263: 3311 | U263: WSG03 | W263: NHUNTQ | X263: NHUNTQ
A264: 46032 | B264: =""&DAY(A264)&"/01/2026"&I264 -> 10/01/2026NL600067 | C264: 2601WSG03140 | E264: 1 | F264: NCC100186 | G264: CÔNG TY TNHH NÔNG SẢN THỰC PHẨM TRẦN GIA | H264: WSG03 - Nhập hàng mua ngày 10/01/2026 | I264: NL600067 | J264: Cam vàng | K264: kg | L264: 0.8 | M264: 75000 | N264: 0 | O264: 60000 | P264: 0 | Q264: 75000 | R264: WSG.03 | S264: 3311 | U264: WSG03 | W264: NHUNTQ | X264: NHUNTQ
A265: 46032 | B265: =""&DAY(A265)&"/01/2026"&I265 -> 10/01/2026NL300184 | C265: 2601WSG03140 | E265: 1 | F265: NCC100186 | G265: CÔNG TY TNHH NÔNG SẢN THỰC PHẨM TRẦN GIA | H265: WSG03 - Nhập hàng mua ngày 10/01/2026 | I265: NL300184 | J265: Lá Dứa (lá nếp) | K265: kg | L265: 0.3 | M265: 18000 | N265: 0 | O265: 5400 | P265: 0 | Q265: 18000 | R265: WSG.03 | S265: 3311 | U265: WSG03 | W265: NHUNTQ | X265: NHUNTQ
A266: 46032 | B266: =""&DAY(A266)&"/01/2026"&I266 -> 10/01/2026NL100101 | C266: 2601WSG03140 | E266: 1 | F266: NCC100186 | G266: CÔNG TY TNHH NÔNG SẢN THỰC PHẨM TRẦN GIA | H266: WSG03 - Nhập hàng mua ngày 10/01/2026 | I266: NL100101 | J266: Trứng vịt muối | K266: quả | L266: 47 | M266: 5000 | N266: 0 | O266: 235000 | P266: 0 | Q266: 5000 | R266: WSG.03 | S266: 3311 | U266: WSG03 | W266: NHUNTQ | X266: NHUNTQ
A267: 46032 | B267: =""&DAY(A267)&"/01/2026"&I267 -> 10/01/2026NL300097 | C267: 2601WSG03140 | E267: 1 | F267: NCC100186 | G267: CÔNG TY TNHH NÔNG SẢN THỰC PHẨM TRẦN GIA | H267: WSG03 - Nhập hàng mua ngày 10/01/2026 | I267: NL300097 | J267: Nấm Linh Chi nâu | K267: kg | L267: 0.5 | M267: 90000 | N267: 0 | O267: 45000 | P267: 0 | Q267: 90000 | R267: WSG.03 | S267: 3311 | U267: WSG03 | W267: NHUNTQ | X267: NHUNTQ
A268: 46032 | B268: =""&DAY(A268)&"/01/2026"&I268 -> 10/01/2026NL300007 | C268: 2601WSG03140 | E268: 1 | F268: NCC100186 | G268: CÔNG TY TNHH NÔNG SẢN THỰC PHẨM TRẦN GIA | H268: WSG03 - Nhập hàng mua ngày 10/01/2026 | I268: NL300007 | J268: Bí đỏ | K268: kg | L268: 4.1 | M268: 30000 | N268: 0 | O268: 123000 | P268: 0 | Q268: 30000 | R268: WSG.03 | S268: 3311 | U268: WSG03 | W268: NHUNTQ | X268: NHUNTQ
A269: 46032 | B269: =""&DAY(A269)&"/01/2026"&I269 -> 10/01/2026NL300008 | C269: 2601WSG03140 | E269: 1 | F269: NCC100186 | G269: CÔNG TY TNHH NÔNG SẢN THỰC PHẨM TRẦN GIA | H269: WSG03 - Nhập hàng mua ngày 10/01/2026 | I269: NL300008 | J269: Bí ngòi | K269: kg | L269: 4 | M269: 40000 | N269: 0 | O269: 160000 | P269: 0 | Q269: 40000 | R269: WSG.03 | S269: 3311 | U269: WSG03 | W269: NHUNTQ | X269: NHUNTQ
... A437: 46037 | B437: =""&DAY(A437)&"/01/2026"&I437 -> 15/01/2026NL300119 | C437: 2601WSG03184 | E437: 1 | F437: NCC100186 | G437: CÔNG TY TNHH NÔNG SẢN THỰC PHẨM TRẦN GIA | H437: WSG03 - Nhập hàng mua ngày 15/01/2026 | I437: NL300119 | J437: Quất ( Tắc trái ) | K437: kg | L437: 1 | M437: 21000 | N437: 0 | O437: 21000 | P437: 0 | Q437: 21000 | R437: WSG.03 | S437: 3311 | U437: WSG03 | W437: NHUNTQ | X437: NHUNTQ

Sheet MÃ
A1: Row Labels | B1: Count of Mã hàng
A2: Bắp cải tím | B2: NL300003
A3: Bắp cải trắng | B3: NL300004
A4: Bắp mỹ trái (Loại 1) | B4: NL300107
A5: Bầu xanh | B5: NL300174
A6: Bông cải xanh | B6: NL300137
A7: Bún nhỏ | B7: NL300012
A8: Cà chua | B8: NL300013
A9: Cà chua bi | B9: NL300014
A10: Cà rốt | B10: NL300027
A11: Cải chua nguyên cây | B11: NL300155
A12: Cải thảo | B12: NL300022
... A146: Trứng bắc thảo | B146: NL100279

Sheet LW11
D2: CÔNG TY TNHH NÔNG SẢN THỰC PHẨM TRẦN GIA HTX: Ấp Lộc Tiến, Xã Mỹ Lộc, Huyện Cần Giuộc, Tỉnh Long An VP: Tòa nhà An Phú Plaza, 117-119 Lý Chính Thắng, P.7. Q.3, TP.HCM Kho sơ chế: 30 Kha Vạn Cân, P. Hiệp Bình Chánh, TP.Thủ Đức, TP.HCM Kho Đà Lạt: 69 Trần Thủ Độ, TT Liên Nghĩa, Huyện Đức Trọng, Tỉnh Lâm Đồng. Website: rausachtrangia.com - Hotline: 090.245.8081
A4: CHI TIẾT ĐỐI CHIẾU CÔNG NỢ
A6: Từ ngày 1 tháng 01 đến ngày 15 tháng 01 năm 2026
A8: Tên Khách hàng: LONGWANG 11
A10: Địa chỉ:
A12: Người liên hệ: Email: | N12: =SUBTOTAL(9,N15:N501) -> 1428.65 | P12: =SUBTOTAL(9,P15:P501) -> 36061660
J13: =SUBTOTAL(9,J15:J498) -> 49135400
A14: NGÀY | B14: MÃ KHÁCH HÀNG | C14: TÊN KHÁCH HÀNG | D14: MÃ ĐƠN HÀNG | E14: MÃ HÀNG | F14: TÊN HÀNG | G14: ĐVT | H14: SỐ LƯỢNG | I14: ĐƠN GIÁ | J14: THÀNH TIỀN | K14: GHI CHÚ | N14: THỰC NHẬN | O14: ĐƠN GIÁ | P14: THÀNH TIỀN | Q14: LỆCH SL | R14: LỆCH ĐG | S14: NOTE
A15: 01/01/2026 | B15: TG-KS00546 | C15: LONGWANG 11 | D15: TG-AA20664 | E15: I100253 | F15: Bánh ướt | G15: Kg | H15: 2.8 | I15: 15000 | J15: =H15*I15 -> 42000 | L15: =IFERROR(VLOOKUP(F15,MÃ!$A:$B,2,0),0) -> NL300189 | M15: ="0"&DAY(A15)&"/01/2026"&L15 -> 01/01/2026NL300189 | N15: =IFERROR(VLOOKUP(M15,'WS11'!$B$2:$Q$475,11,0),0) -> 1 | O15: =IFERROR(VLOOKUP(M15,'WS11'!$B$2:$Q$475,12,0),0) -> 15000 | P15: =N15*O15 -> 15000 | Q15: =H15-N15 -> 1.8 | R15: =I15-O15 -> 0 | S15: SAI SL
A16: 01/01/2026 | B16: TG-KS00546 | C16: LONGWANG 11 | D16: TG-AA20664 | E16: I100008 | F16: Bắp mỹ trái (Loại 1) | G16: Trái | H16: 12 | I16: 8500 | J16: =H16*I16 -> 102000 | L16: =IFERROR(VLOOKUP(F16,MÃ!$A:$B,2,0),0) -> NL300107 | M16: ="0"&DAY(A16)&"/01/2026"&L16 -> 01/01/2026NL300107 | N16: =IFERROR(VLOOKUP(M16,'WS11'!$B$2:$Q$475,11,0),0) -> 10 | O16: =IFERROR(VLOOKUP(M16,'WS11'!$B$2:$Q$475,12,0),0) -> 8500 | P16: =N16*O16 -> 85000 | Q16: =H16-N16 -> 2 | R16: =I16-O16 -> 0 | S16: SAI SL
A17: 01/01/2026 | B17: TG-KS00546 | C17: LONGWANG 11 | D17: TG-AA20664 | E17: I100012 | F17: Bí đỏ hồ lô | G17: Kg | H17: 5.1 | I17: 30000 | J17: =H17*I17 -> 153000 | L17: =IFERROR(VLOOKUP(F17,MÃ!$A:$B,2,0),0) -> NL300007 | M17: ="0"&DAY(A17)&"/01/2026"&L17 -> 01/01/2026NL300007 | N17: =IFERROR(VLOOKUP(M17,'WS11'!$B$2:$Q$475,11,0),0) -> 3 | O17: =IFERROR(VLOOKUP(M17,'WS11'!$B$2:$Q$475,12,0),0) -> 30000 | P17: =N17*O17 -> 90000 | Q17: =H17-N17 -> 2.1 | R17: =I17-O17 -> 0 | S17: SAI SL
A18: 01/01/2026 | B18: TG-KS00546 | C18: LONGWANG 11 | D18: TG-AA20664 | E18: I100016 | F18: Bí ngòi xanh | G18: Kg | H18: 9.5 | I18: 40000 | J18: =H18*I18 -> 380000 | L18: =IFERROR(VLOOKUP(F18,MÃ!$A:$B,2,0),0) -> NL300008 | M18: ="0"&DAY(A18)&"/01/2026"&L18 -> 01/01/2026NL300008 | N18: =IFERROR(VLOOKUP(M18,'WS11'!$B$2:$Q$475,11,0),0) -> 6 | O18: =IFERROR(VLOOKUP(M18,'WS11'!$B$2:$Q$475,12,0),0) -> 40000 | P18: =N18*O18 -> 240000 | Q18: =H18-N18 -> 3.5 | R18: =I18-O18 -> 0 | S18: SAI SL
A19: 01/01/2026 | B19: TG-KS00546 | C19: LONGWANG 11 | D19: TG-AA20664 | E19: I100024 | F19: Bông cải xanh | G19: Kg | H19: 4.2 | I19: 52000 | J19: =H19*I19 -> 218400 | L19: =IFERROR(VLOOKUP(F19,MÃ!$A:$B,2,0),0) -> NL300137 | M19: ="0"&DAY(A19)&"/01/2026"&L19 -> 01/01/2026NL300137 | N19: =IFERROR(VLOOKUP(M19,'WS11'!$B$2:$Q$475,11,0),0) -> 3 | O19: =IFERROR(VLOOKUP(M19,'WS11'!$B$2:$Q$475,12,0),0) -> 52000 | P19: =N19*O19 -> 156000 | Q19: =H19-N19 -> 1.2 | R19: =I19-O19 -> 0 | S19: SAI SL
A20: 01/01/2026 | B20: TG-KS00546 | C20: LONGWANG 11 | D20: TG-AA20664 | E20: I100045 | F20: Cải Hongkong(Cai ngong) | G20: Kg | H20: 2.9 | I20: 30000 | J20: =H20*I20 -> 87000 | L20: =IFERROR(VLOOKUP(F20,MÃ!$A:$B,2,0),0) -> NL300020 | M20: ="0"&DAY(A20)&"/01/2026"&L20 -> 01/01/2026NL300020 | N20: =IFERROR(VLOOKUP(M20,'WS11'!$B$2:$Q$475,11,0),0) -> 2 | O20: =IFERROR(VLOOKUP(M20,'WS11'!$B$2:$Q$475,12,0),0) -> 30000 | P20: =N20*O20 -> 60000 | Q20: =H20-N20 -> 0.9 | R20: =I20-O20 -> 0 | S20: SAI SL
A21: 01/01/2026 | B21: TG-KS00546 | C21: LONGWANG 11 | D21: TG-AA20664 | E21: I100057 | F21: Cần tây | G21: Kg | H21: 1.1 | I21: 44000 | J21: =H21*I21 -> 48400 | L21: =IFERROR(VLOOKUP(F21,MÃ!$A:$B,2,0),0) -> NL300025 | M21: ="0"&DAY(A21)&"/01/2026"&L21 -> 01/01/2026NL300025 | N21: =IFERROR(VLOOKUP(M21,'WS11'!$B$2:$Q$475,11,0),0) -> 0.7 | O21: =IFERROR(VLOOKUP(M21,'WS11'!$B$2:$Q$475,12,0),0) -> 44000 | P21: =N21*O21 -> 30800 | Q21: =H21-N21 -> 0.4 | R21: =I21-O21 -> 0 | S21: SAI SL
A22: 01/01/2026 | B22: TG-KS00546 | C22: LONGWANG 11 | D22: TG-AA20664 | E22: I100474 | F22: Chanh Dây | G22: Kg | H22: 0.6 | I22: 34000 | J22: =H22*I22 -> 20400 | L22: =IFERROR(VLOOKUP(F22,MÃ!$A:$B,2,0),0) -> NL300030 | M22: ="0"&DAY(A22)&"/01/2026"&L22 -> 01/01/2026NL300030 | N22: =IFERROR(VLOOKUP(M22,'WS11'!$B$2:$Q$475,11,0),0) -> 0.6 | O22: =IFERROR(VLOOKUP(M22,'WS11'!$B$2:$Q$475,12,0),0) -> 34000 | P22: =N22*O22 -> 20400 | Q22: =H22-N22 -> 0 | R22: =I22-O22 -> 0
A23: 01/01/2026 | B23: TG-KS00546 | C23: LONGWANG 11 | D23: TG-AA20664 | E23: I100060 | F23: Chanh không hạt | G23: Kg | H23: 1 | I23: 22000 | J23: =H23*I23 -> 22000 | L23: =IFERROR(VLOOKUP(F23,MÃ!$A:$B,2,0),0) -> NL300029 | M23: ="0"&DAY(A23)&"/01/2026"&L23 -> 01/01/2026NL300029 | N23: =IFERROR(VLOOKUP(M23,'WS11'!$B$2:$Q$475,11,0),0) -> 1 | O23: =IFERROR(VLOOKUP(M23,'WS11'!$B$2:$Q$475,12,0),0) -> 22000 | P23: =N23*O23 -> 22000 | Q23: =H23-N23 -> 0 | R23: =I23-O23 -> 0
A24: 01/01/2026 | B24: TG-KS00546 | C24: LONGWANG 11 | D24: TG-AA20664 | E24: I100062 | F24: Chanh vàng | G24: Kg | H24: 0.5 | I24: 95000 | J24: =H24*I24 -> 47500 | L24: =IFERROR(VLOOKUP(F24,MÃ!$A:$B,2,0),0) -> NL600068 | M24: ="0"&DAY(A24)&"/01/2026"&L24 -> 01/01/2026NL600068 | N24: =IFERROR(VLOOKUP(M24,'WS11'!$B$2:$Q$475,11,0),0) -> 0.5 | O24: =IFERROR(VLOOKUP(M24,'WS11'!$B$2:$Q$475,12,0),0) -> 95000 | P24: =N24*O24 -> 47500 | Q24: =H24-N24 -> 0 | R24: =I24-O24 -> 0
A25: 01/01/2026 | B25: TG-KS00546 | C25: LONGWANG 11 | D25: TG-AA20664 | E25: I100097 | F25: Củ Gừng | G25: Kg | H25: 1.2 | I25: 38000 | J25: =H25*I25 -> 45600 | L25: =IFERROR(VLOOKUP(F25,MÃ!$A:$B,2,0),0) -> NL300054 | M25: ="0"&DAY(A25)&"/01/2026"&L25 -> 01/01/2026NL300054 | N25: =IFERROR(VLOOKUP(M25,'WS11'!$B$2:$Q$475,11,0),0) -> 1 | O25: =IFERROR(VLOOKUP(M25,'WS11'!$B$2:$Q$475,12,0),0) -> 38000 | P25: =N25*O25 -> 38000 | Q25: =H25-N25 -> 0.2 | R25: =I25-O25 -> 0 | S25: SAI SL
A26: 01/01/2026 | B26: TG-KS00546 | C26: LONGWANG 11 | D26: TG-AA20664 | E26: I100074 | F26: Củ sen | G26: Kg | H26: 2.5 | I26: 47000 | J26: =H26*I26 -> 117500 | L26: =IFERROR(VLOOKUP(F26,MÃ!$A:$B,2,0),0) -> NL300036 | M26: ="0"&DAY(A26)&"/01/2026"&L26 -> 01/01/2026NL300036 | N26: =IFERROR(VLOOKUP(M26,'WS11'!$B$2:$Q$475,11,0),0) -> 2 | O26: =IFERROR(VLOOKUP(M26,'WS11'!$B$2:$Q$475,12,0),0) -> 47000 | P26: =N26*O26 -> 94000 | Q26: =H26-N26 -> 0.5 | R26: =I26-O26 -> 0 | S26: SAI SL
A27: 01/01/2026 | B27: TG-KS00546 | C27: LONGWANG 11 | D27: TG-AA20664 | E27: I100075 | F27: Đậu bắp | G27: Kg | H27: 4 | I27: 32000 | J27: =H27*I27 -> 128000 | L27: =IFERROR(VLOOKUP(F27,MÃ!$A:$B,2,0),0) -> NL300038 | M27: ="0"&DAY(A27)&"/01/2026"&L27 -> 01/01/2026NL300038 | N27: =IFERROR(VLOOKUP(M27,'WS11'!$B$2:$Q$475,11,0),0) -> 2.5 | O27: =IFERROR(VLOOKUP(M27,'WS11'!$B$2:$Q$475,12,0),0) -> 32000 | P27: =N27*O27 -> 80000 | Q27: =H27-N27 -> 1.5 | R27: =I27-O27 -> 0 | S27: SAI SL
A28: 01/01/2026 | B28: TG-KS00546 | C28: LONGWANG 11 | D28: TG-AA20664 | E28: I100883 | F28: Đậu hủ trứng CP 220gr | G28: Cây | H28: 5 | I28: 15000 | J28: =H28*I28 -> 75000 | L28: =IFERROR(VLOOKUP(F28,MÃ!$A:$B,2,0),0) -> NL300041 | M28: ="0"&DAY(A28)&"/01/2026"&L28 -> 01/01/2026NL300041 | N28: =IFERROR(VLOOKUP(M28,'WS11'!$B$2:$Q$475,11,0),0) -> 5 | O28: =IFERROR(VLOOKUP(M28,'WS11'!$B$2:$Q$475,12,0),0) -> 15000 | P28: =N28*O28 -> 75000 | Q28: =H28-N28 -> 0 | R28: =I28-O28 -> 0
A29: 01/01/2026 | B29: TG-KS00546 | C29: LONGWANG 11 | D29: TG-AA20664 | E29: I100479 | F29: Dưa hấu | G29: Kg | H29: 20 | I29: 18000 | J29: =H29*I29 -> 360000 | L29: =IFERROR(VLOOKUP(F29,MÃ!$A:$B,2,0),0) -> NL600004 | M29: ="0"&DAY(A29)&"/01/2026"&L29 -> 01/01/2026NL600004 | N29: =IFERROR(VLOOKUP(M29,'WS11'!$B$2:$Q$475,11,0),0) -> 20 | O29: =IFERROR(VLOOKUP(M29,'WS11'!$B$2:$Q$475,12,0),0) -> 18000 | P29: =N29*O29 -> 360000 | Q29: =H29-N29 -> 0 | R29: =I29-O29 -> 0
A30: 01/01/2026 | B30: TG-KS00546 | C30: LONGWANG 11 | D30: TG-AA20664 | E30: I100098 | F30: Hành lá | G30: Kg | H30: 3 | I30: 55000 | J30: =H30*I30 -> 165000 | L30: =IFERROR(VLOOKUP(F30,MÃ!$A:$B,2,0),0) -> NL300058 | M30: ="0"&DAY(A30)&"/01/2026"&L30 -> 01/01/2026NL300058 | N30: =IFERROR(VLOOKUP(M30,'WS11'!$B$2:$Q$475,11,0),0) -> 1.5 | O30: =IFERROR(VLOOKUP(M30,'WS11'!$B$2:$Q$475,12,0),0) -> 55000 | P30: =N30*O30 -> 82500 | Q30: =H30-N30 -> 1.5 | R30: =I30-O30 -> 0 | S30: SAI SL
A31: 01/01/2026 | B31: TG-KS00546 | C31: LONGWANG 11 | D31: TG-AA20664 | E31: I100101 | F31: Hành tây | G31: Kg | H31: 0.6 | I31: 13000 | J31: =H31*I31 -> 7800 | L31: =IFERROR(VLOOKUP(F31,MÃ!$A:$B,2,0),0) -> NL300059 | M31: ="0"&DAY(A31)&"/01/2026"&L31 -> 01/01/2026NL300059 | N31: =IFERROR(VLOOKUP(M31,'WS11'!$B$2:$Q$475,11,0),0) -> 0.5 | O31: =IFERROR(VLOOKUP(M31,'WS11'!$B$2:$Q$475,12,0),0) -> 13000 | P31: =N31*O31 -> 6500 | Q31: =H31-N31 -> 0.1 | R31: =I31-O31 -> 0 | S31: SAI SL
A32: 01/01/2026 | B32: TG-KS00546 | C32: LONGWANG 11 | D32: TG-AA20664 | E32: I100121 | F32: Khoai lang nhật | G32: Kg | H32: 0.7 | I32: 23000 | J32: =H32*I32 -> 16100 | L32: =IFERROR(VLOOKUP(F32,MÃ!$A:$B,2,0),0) -> NL300070 | M32: ="0"&DAY(A32)&"/01/2026"&L32 -> 01/01/2026NL300070 | N32: =IFERROR(VLOOKUP(M32,'WS11'!$B$2:$Q$475,11,0),0) -> 0.5 | O32: =IFERROR(VLOOKUP(M32,'WS11'!$B$2:$Q$475,12,0),0) -> 23000 | P32: =N32*O32 -> 11500 | Q32: =H32-N32 -> 0.2 | R32: =I32-O32 -> 0 | S32: SAI SL
A33: 01/01/2026 | B33: TG-KS00546 | C33: LONGWANG 11 | D33: TG-AA20664 | E33: I100136 | F33: Lá dứa | G33: Kg | H33: 3.8 | I33: 18000 | J33: =H33*I33 -> 68400 | L33: =IFERROR(VLOOKUP(F33,MÃ!$A:$B,2,0),0) -> NL300184 | M33: ="0"&DAY(A33)&"/01/2026"&L33 -> 01/01/2026NL300184 | N33: =IFERROR(VLOOKUP(M33,'WS11'!$B$2:$Q$475,11,0),0) -> 3.8 | O33: =IFERROR(VLOOKUP(M33,'WS11'!$B$2:$Q$475,12,0),0) -> 18000 | P33: =N33*O33 -> 68400 | Q33: =H33-N33 -> 0 | R33: =I33-O33 -> 0
A34: 01/01/2026 | B34: TG-KS00546 | C34: LONGWANG 11 | D34: TG-AA20664 | E34: I100151 | F34: Mướp hương | G34: Kg | H34: 3.2 | I34: 27000 | J34: =H34*I34 -> 86400 | L34: =IFERROR(VLOOKUP(F34,MÃ!$A:$B,2,0),0) -> NL300088 | M34: ="0"&DAY(A34)&"/01/2026"&L34 -> 01/01/2026NL300088 | N34: =IFERROR(VLOOKUP(M34,'WS11'!$B$2:$Q$475,11,0),0) -> 2 | O34: =IFERROR(VLOOKUP(M34,'WS11'!$B$2:$Q$475,12,0),0) -> 27000 | P34: =N34*O34 -> 54000 | Q34: =H34-N34 -> 1.2 | R34: =I34-O34 -> 0 | S34: SAI SL
A35: 01/01/2026 | B35: TG-KS00546 | C35: LONGWANG 11 | D35: TG-AA20664 | E35: I100236 | F35: Nấm đông cô tươi | G35: Kg | H35: 3 | I35: 145000 | J35: =H35*I35 -> 435000 | L35: =IFERROR(VLOOKUP(F35,MÃ!$A:$B,2,0),0) -> NL300090 | M35: ="0"&DAY(A35)&"/01/2026"&L35 -> 01/01/2026NL300090 | N35: =IFERROR(VLOOKUP(M35,'WS11'!$B$2:$Q$475,11,0),0) -> 2 | O35: =IFERROR(VLOOKUP(M35,'WS11'!$B$2:$Q$475,12,0),0) -> 145000 | P35: =N35*O35 -> 290000 | Q35: =H35-N35 -> 1 | R35: =I35-O35 -> 0 | S35: SAI SL
A36: 01/01/2026 | B36: TG-KS00546 | C36: LONGWANG 11 | D36: TG-AA20664 | E36: I100237 | F36: Nấm đùi gà | G36: Kg | H36: 1 | I36: 47000 | J36: =H36*I36 -> 47000 | L36: =IFERROR(VLOOKUP(F36,MÃ!$A:$B,2,0),0) -> NL300091 | M36: ="0"&DAY(A36)&"/01/2026"&L36 -> 01/01/2026NL300091 | N36: =IFERROR(VLOOKUP(M36,'WS11'!$B$2:$Q$475,11,0),0) -> 0.9 | O36: =IFERROR(VLOOKUP(M36,'WS11'!$B$2:$Q$475,12,0),0) -> 47000 | P36: =N36*O36 -> 42300 | Q36: =H36-N36 -> 0.1 | R36: =I36-O36 -> 0 | S36: SAI SL
A37: 01/01/2026 | B37: TG-KS00546 | C37: LONGWANG 11 | D37: TG-AA20664 | E37: I100650 | F37: Nấm đùi gà baby | G37: Kg | H37: 2 | I37: 90000 | J37: =H37*I37 -> 180000 | L37: =IFERROR(VLOOKUP(F37,MÃ!$A:$B,2,0),0) -> NL300092 | M37: ="0"&DAY(A37)&"/01/2026"&L37 -> 01/01/2026NL300092 | N37: =IFERROR(VLOOKUP(M37,'WS11'!$B$2:$Q$475,11,0),0) -> 1.6 | O37: =IFERROR(VLOOKUP(M37,'WS11'!$B$2:$Q$475,12,0),0) -> 90000 | P37: =N37*O37 -> 144000 | Q37: =H37-N37 -> 0.4 | R37: =I37-O37 -> 0 | S37: SAI SL
A38: 01/01/2026 | B38: TG-KS00546 | C38: LONGWANG 11 | D38: TG-AA20664 | E38: I100634 | F38: Nấm hải sản (kg) | G38: Kg | H38: 1.5 | I38: 80000 | J38: =H38*I38 -> 120000 | L38: =IFERROR(VLOOKUP(F38,MÃ!$A:$B,2,0),0) -> NL300094 | M38: ="0"&DAY(A38)&"/01/2026"&L38 -> 01/01/2026NL300094 | N38: =IFERROR(VLOOKUP(M38,'WS11'!$B$2:$Q$475,11,0),0) -> 1.3 | O38: =IFERROR(VLOOKUP(M38,'WS11'!$B$2:$Q$475,12,0),0) -> 80000 | P38: =N38*O38 -> 104000 | Q38: =H38-N38 -> 0.2 | R38: =I38-O38 -> 0 | S38: SAI SL
A39: 01/01/2026 | B39: TG-KS00546 | C39: LONGWANG 11 | D39: TG-AA20664 | E39: I100240 | F39: Nấm kim châm tươi | G39: Kg | H39: 5.1 | I39: 45000 | J39: =H39*I39 -> 229500 | L39: =IFERROR(VLOOKUP(F39,MÃ!$A:$B,2,0),0) -> NL300096 | M39: ="0"&DAY(A39)&"/01/2026"&L39 -> 01/01/2026NL300096 | N39: =IFERROR(VLOOKUP(M39,'WS11'!$B$2:$Q$475,11,0),0) -> 4 | O39: =IFERROR(VLOOKUP(M39,'WS11'!$B$2:$Q$475,12,0),0) -> 45000 | P39: =N39*O39 -> 180000 | Q39: =H39-N39 -> 1.1 | R39: =I39-O39 -> 0 | S39: SAI SL
A40: 01/01/2026 | B40: TG-KS00546 | C40: LONGWANG 11 | D40: TG-AA20664 | E40: I100635 | F40: Nấm linh chi nâu (kg) | G40: Kg | H40: 1.6 | I40: 90000 | J40: =H40*I40 -> 144000 | L40: =IFERROR(VLOOKUP(F40,MÃ!$A:$B,2,0),0) -> NL300097 | M40: ="0"&DAY(A40)&"/01/2026"&L40 -> 01/01/2026NL300097 | N40: =IFERROR(VLOOKUP(M40,'WS11'!$B$2:$Q$475,11,0),0) -> 1.4 | O40: =IFERROR(VLOOKUP(M40,'WS11'!$B$2:$Q$475,12,0),0) -> 90000 | P40: =N40*O40 -> 126000 | Q40: =H40-N40 -> 0.2 | R40: =I40-O40 -> 0 | S40: SAI SL
A41: 01/01/2026 | B41: TG-KS00546 | C41: LONGWANG 11 | D41: TG-AA20664 | E41: I100156 | F41: Ngò rí | G41: Kg | H41: 2.9 | I41: 45000 | J41: =H41*I41 -> 130500 | L41: =IFERROR(VLOOKUP(F41,MÃ!$A:$B,2,0),0) -> NL300085 | M41: ="0"&DAY(A41)&"/01/2026"&L41 -> 01/01/2026NL300085 | N41: =IFERROR(VLOOKUP(M41,'WS11'!$B$2:$Q$475,11,0),0) -> 2 | O41: =IFERROR(VLOOKUP(M41,'WS11'!$B$2:$Q$475,12,0),0) -> 45000 | P41: =N41*O41 -> 90000 | Q41: =H41-N41 -> 0.9 | R41: =I41-O41 -> 0 | S41: SAI SL
A42: 01/01/2026 | B42: TG-KS00546 | C42: LONGWANG 11 | D42: TG-AA20664 | E42: I100160 | F42: Ngò tây | G42: Kg | H42: 0.3 | I42: 70000 | J42: =H42*I42 -> 21000 | L42: =IFERROR(VLOOKUP(F42,MÃ!$A:$B,2,0),0) -> NL300126 | M42: ="0"&DAY(A42)&"/01/2026"&L42 -> 01/01/2026NL300126 | N42: =IFERROR(VLOOKUP(M42,'WS11'!$B$2:$Q$475,11,0),0) -> 0.3 | O42: =IFERROR(VLOOKUP(M42,'WS11'!$B$2:$Q$475,12,0),0) -> 70000 | P42: =N42*O42 -> 21000 | Q42: =H42-N42 -> 0 | R42: =I42-O42 -> 0
A43: 01/01/2026 | B43: TG-KS00546 | C43: LONGWANG 11 | D43: TG-AA20664 | E43: I100167 | F43: Ớt hiểm đỏ | G43: Kg | H43: 1.5 | I43: 145000 | J43: =H43*I43 -> 217500 | L43: =IFERROR(VLOOKUP(F43,MÃ!$A:$B,2,0),0) -> NL300113 | M43: ="0"&DAY(A43)&"/01/2026"&L43 -> 01/01/2026NL300113 | N43: =IFERROR(VLOOKUP(M43,'WS11'!$B$2:$Q$475,11,0),0) -> 1.2 | O43: =IFERROR(VLOOKUP(M43,'WS11'!$B$2:$Q$475,12,0),0) -> 145000 | P43: =N43*O43 -> 174000 | Q43: =H43-N43 -> 0.3 | R43: =I43-O43 -> 0 | S43: SAI SL
A44: 01/01/2026 | B44: TG-KS00546 | C44: LONGWANG 11 | D44: TG-AA20664 | E44: I100168 | F44: Ớt hiểm xanh | G44: Kg | H44: 0.1 | I44: 185000 | J44: =H44*I44 -> 18500 | L44: =IFERROR(VLOOKUP(F44,MÃ!$A:$B,2,0),0) -> NL300111 | M44: ="0"&DAY(A44)&"/01/2026"&L44 -> 01/01/2026NL300111 | N44: =IFERROR(VLOOKUP(M44,'WS11'!$B$2:$Q$475,11,0),0) -> 0.1 | O44: =IFERROR(VLOOKUP(M44,'WS11'!$B$2:$Q$475,12,0),0) -> 185000 | P44: =N44*O44 -> 18500 | Q44: =H44-N44 -> 0 | R44: =I44-O44 -> 0
A45: 01/01/2026 | B45: TG-KS00546 | C45: LONGWANG 11 | D45: TG-AA20664 | E45: I100170 | F45: Ớt sừng đỏ | G45: Kg | H45: 0.5 | I45: 148000 | J45: =H45*I45 -> 74000 | L45: =IFERROR(VLOOKUP(F45,MÃ!$A:$B,2,0),0) -> NL300116 | M45: ="0"&DAY(A45)&"/01/2026"&L45 -> 01/01/2026NL300116 | N45: =IFERROR(VLOOKUP(M45,'WS11'!$B$2:$Q$475,11,0),0) -> 0 | O45: =IFERROR(VLOOKUP(M45,'WS11'!$B$2:$Q$475,12,0),0) -> 0 | P45: =N45*O45 -> 0 | Q45: =H45-N45 -> 0.5 | R45: =I45-O45 -> 148000 | S45: ĐƠN KHÔNG NHẬN
A46: 01/01/2026 | B46: TG-KS00546 | C46: LONGWANG 11 | D46: TG-AA20664 | E46: I100626 | F46: Rau má nhỏ | G46: Kg | H46: 0.4 | I46: 42000 | J46: =H46*I46 -> 16800 | L46: =IFERROR(VLOOKUP(F46,MÃ!$A:$B,2,0),0) -> NL300125 | M46: ="0"&DAY(A46)&"/01/2026"&L46 -> 01/01/2026NL300125 | N46: =IFERROR(VLOOKUP(M46,'WS11'!$B$2:$Q$475,11,0),0) -> 0.4 | O46: =IFERROR(VLOOKUP(M46,'WS11'!$B$2:$Q$475,12,0),0) -> 42000 | P46: =N46*O46 -> 16800 | Q46: =H46-N46 -> 0 | R46: =I46-O46 -> 0
...

Sheet WS11
A1: Ngày ct | B1: Mã ct | C1: Số ct | D1: Số hđ | E1: Áp giá | F1: Mã ncc | G1: Tên ncc | H1: Diễn giải | I1: Mã hàng | J1: Tên mặt hàng | K1: Đvt | L1: =SUBTOTAL(9,L2:L499) -> 1428.65 | M1: Giá | N1: Giá báo | O1: =SUBTOTAL(9,O2:O499) -> 36061660 | P1: Thuế suất | Q1: Chênh lệch giá | R1: Kho hàng | S1: Mã nx | T1: Vụ việc | U1: Bộ phận | V1: Hợp đồng | W1: Người tạo | X1: Người sửa
A2: 46023 | B2: ="0"&DAY(A2)&"/01/2026"&I2 -> 01/01/2026NL300007 | C2: 2601WSG11005 | E2: 1 | F2: NCC100186 | G2: CÔNG TY TNHH NÔNG SẢN THỰC PHẨM TRẦN GIA | H2: WSG11 - Nhập hàng mua ngày 01/01/2026 | I2: NL300007 | J2: Bí đỏ | K2: kg | L2: 3 | M2: 30000 | N2: 0 | O2: 90000 | P2: 0 | Q2: 30000 | R2: WSG.11 | S2: 3311 | U2: WSG11 | W2: NHUNTQ | X2: NHUNTQ
A3: 46023 | B3: ="0"&DAY(A3)&"/01/2026"&I3 -> 01/01/2026NL300008 | C3: 2601WSG11005 | E3: 1 | F3: NCC100186 | G3: CÔNG TY TNHH NÔNG SẢN THỰC PHẨM TRẦN GIA | H3: WSG11 - Nhập hàng mua ngày 01/01/2026 | I3: NL300008 | J3: Bí ngòi | K3: kg | L3: 6 | M3: 40000 | N3: 0 | O3: 240000 | P3: 0 | Q3: 40000 | R3: WSG.11 | S3: 3311 | U3: WSG11 | W3: NHUNTQ | X3: NHUNTQ
A4: 46023 | B4: ="0"&DAY(A4)&"/01/2026"&I4 -> 01/01/2026NL300020 | C4: 2601WSG11005 | E4: 1 | F4: NCC100186 | G4: CÔNG TY TNHH NÔNG SẢN THỰC PHẨM TRẦN GIA | H4: WSG11 - Nhập hàng mua ngày 01/01/2026 | I4: NL300020 | J4: Cải ngồng | K4: kg | L4: 2 | M4: 30000 | N4: 0 | O4: 60000 | P4: 0 | Q4: 30000 | R4: WSG.11 | S4: 3311 | U4: WSG11 | W4: NHUNTQ | X4: NHUNTQ
A5: 46023 | B5: ="0"&DAY(A5)&"/01/2026"&I5 -> 01/01/2026NL300038 | C5: 2601WSG11005 | E5: 1 | F5: NCC100186 | G5: CÔNG TY TNHH NÔNG SẢN THỰC PHẨM TRẦN GIA | H5: WSG11 - Nhập hàng mua ngày 01/01/2026 | I5: NL300038 | J5: Đậu bắp | K5: kg | L5: 2.5 | M5: 32000 | N5: 0 | O5: 80000 | P5: 0 | Q5: 32000 | R5: WSG.11 | S5: 3311 | U5: WSG11 | W5: NHUNTQ | X5: NHUNTQ
A6: 46023 | B6: ="0"&DAY(A6)&"/01/2026"&I6 -> 01/01/2026NL300054 | C6: 2601WSG11005 | E6: 1 | F6: NCC100186 | G6: CÔNG TY TNHH NÔNG SẢN THỰC PHẨM TRẦN GIA | H6: WSG11 - Nhập hàng mua ngày 01/01/2026 | I6: NL300054 | J6: Gừng tàu | K6: kg | L6: 1 | M6: 38000 | N6: 0 | O6: 38000 | P6: 0 | Q6: 38000 | R6: WSG.11 | S6: 3311 | U6: WSG11 | W6: NHUNTQ | X6: NHUNTQ
A7: 46023 | B7: ="0"&DAY(A7)&"/01/2026"&I7 -> 01/01/2026NL300058 | C7: 2601WSG11005 | E7: 1 | F7: NCC100186 | G7: CÔNG TY TNHH NÔNG SẢN THỰC PHẨM TRẦN GIA | H7: WSG11 - Nhập hàng mua ngày 01/01/2026 | I7: NL300058 | J7: Hành lá | K7: kg | L7: 1.5 | M7: 55000 | N7: 0 | O7: 82500 | P7: 0 | Q7: 55000 | R7: WSG.11 | S7: 3311 | U7: WSG11 | W7: NHUNTQ | X7: NHUNTQ
A8: 46023 | B8: ="0"&DAY(A8)&"/01/2026"&I8 -> 01/01/2026NL300059 | C8: 2601WSG11005 | E8: 1 | F8: NCC100186 | G8: CÔNG TY TNHH NÔNG SẢN THỰC PHẨM TRẦN GIA | H8: WSG11 - Nhập hàng mua ngày 01/01/2026 | I8: NL300059 | J8: Hành tây | K8: kg | L8: 0.5 | M8: 13000 | N8: 0 | O8: 6500 | P8: 0 | Q8: 13000 | R8: WSG.11 | S8: 3311 | U8: WSG11 | W8: NHUNTQ | X8: NHUNTQ
A9: 46023 | B9: ="0"&DAY(A9)&"/01/2026"&I9 -> 01/01/2026NL300085 | C9: 2601WSG11005 | E9: 1 | F9: NCC100186 | G9: CÔNG TY TNHH NÔNG SẢN THỰC PHẨM TRẦN GIA | H9: WSG11 - Nhập hàng mua ngày 01/01/2026 | I9: NL300085 | J9: Mùi ta ( Ngò rí ) | K9: kg | L9: 2 | M9: 45000 | N9: 0 | O9: 90000 | P9: 0 | Q9: 45000 | R9: WSG.11 | S9: 3311 | U9: WSG11 | W9: NHUNTQ | X9: NHUNTQ
A10: 46023 | B10: ="0"&DAY(A10)&"/01/2026"&I10 -> 01/01/2026NL300091 | C10: 2601WSG11005 | E10: 1 | F10: NCC100186 | G10: CÔNG TY TNHH NÔNG SẢN THỰC PHẨM TRẦN GIA | H10: WSG11 - Nhập hàng mua ngày 01/01/2026 | I10: NL300091 | J10: Nấm đùi gà | K10: kg | L10: 0.9 | M10: 47000 | N10: 0 | O10: 42300 | P10: 0 | Q10: 47000 | R10: WSG.11 | S10: 3311 | U10: WSG11 | W10: NHUNTQ | X10: NHUNTQ
A11: 46023 | B11: ="0"&DAY(A11)&"/01/2026"&I11 -> 01/01/2026NL300092 | C11: 2601WSG11005 | E11: 1 | F11: NCC100186 | G11: CÔNG TY TNHH NÔNG SẢN THỰC PHẨM TRẦN GIA | H11: WSG11 - Nhập hàng mua ngày 01/01/2026 | I11: NL300092 | J11: Nấm đùi gà baby | K11: kg | L11: 1.6 | M11: 90000 | N11: 0 | O11: 144000 | P11: 0 | Q11: 90000 | R11: WSG.11 | S11: 3311 | U11: WSG11 | W11: NHUNTQ | X11: NHUNTQ
A12: 46023 | B12: ="0"&DAY(A12)&"/01/2026"&I12 -> 01/01/2026NL300094 | C12: 2601WSG11005 | E12: 1 | F12: NCC100186 | G12: CÔNG TY TNHH NÔNG SẢN THỰC PHẨM TRẦN GIA | H12: WSG11 - Nhập hàng mua ngày 01/01/2026 | I12: NL300094 | J12: Nấm hải sản | K12: kg | L12: 1.3 | M12: 80000 | N12: 0 | O12: 104000 | P12: 0 | Q12: 80000 | R12: WSG.11 | S12: 3311 | U12: WSG11 | W12: NHUNTQ | X12: NHUNTQ
A13: 46023 | B13: ="0"&DAY(A13)&"/01/2026"&I13 -> 01/01/2026NL300096 | C13: 2601WSG11005 | E13: 1 | F13: NCC100186 | G13: CÔNG TY TNHH NÔNG SẢN THỰC PHẨM TRẦN GIA | H13: WSG11 - Nhập hàng mua ngày 01/01/2026 | I13: NL300096 | J13: Nấm kim châm tươi | K13: kg | L13: 4 | M13: 45000 | N13: 0 | O13: 180000 | P13: 0 | Q13: 45000 | R13: WSG.11 | S13: 3311 | U13: WSG11 | W13: NHUNTQ | X13: NHUNTQ
... A276: 46031 | B276: ="0"&DAY(A276)&"/01/2026"&I276 -> 09/01/2026NL300147 | C276: 2601WSG11056 | E276: 1 | F276: NCC100186 | G276: CÔNG TY TNHH NÔNG SẢN THỰC PHẨM TRẦN GIA | H276: WSG11 - Nhập hàng mua ngày 09/01/2026 | I276: NL300147 | J276: Xà lách Roman | K276: kg | L276: 2 | M276: 62000 | N276: 0 | O276: 124000 | P276: 0 | Q276: 62000 | R276: WSG.11 | S276: 3311 | U276: WSG11 | W276: NHUNTQ | X276: NHUNTQ
A277: 46032 | B277: =""&DAY(A277)&"/01/2026"&I277 -> 10/01/2026NL300061 | C277: 2601WSG11101 | E277: 1 | F277: NCC100186 | G277: CÔNG TY TNHH NÔNG SẢN THỰC PHẨM TRẦN GIA | H277: WSG11 - Nhập hàng mua ngày 10/01/2026 | I277: NL300061 | J277: Hành Paro (Hành Baro) | K277: kg | L277: 0.5 | M277: 38000 | N277: 0 | O277: 19000 | P277: 0 | Q277: 38000 | R277: WSG.11 | S277: 3311 | U277: WSG11 | W277: NHUNTQ | X277: NHUNTQ
A278: 46032 | B278: =""&DAY(A278)&"/01/2026"&I278 -> 10/01/2026NL300088 | C278: 2601WSG11101 | E278: 1 | F278: NCC100186 | G278: CÔNG TY TNHH NÔNG SẢN THỰC PHẨM TRẦN GIA | H278: WSG11 - Nhập hàng mua ngày 10/01/2026 | I278: NL300088 | J278: Mướp hương | K278: kg | L278: 1.5 | M278: 27000 | N278: 0 | O278: 40500 | P278: 0 | Q278: 27000 | R278: WSG.11 | S278: 3311 | U278: WSG11 | W278: NHUNTQ | X278: NHUNTQ
A279: 46032 | B279: =""&DAY(A279)&"/01/2026"&I279 -> 10/01/2026NL300107 | C279: 2601WSG11101 | E279: 1 | F279: NCC100186 | G279: CÔNG TY TNHH NÔNG SẢN THỰC PHẨM TRẦN GIA | H279: WSG11 - Nhập hàng mua ngày 10/01/2026 | I279: NL300107 | J279: Ngô ngọt ( Bắp trái) | K279: Cái | L279: 10 | M279: 8500 | N279: 0 | O279: 85000 | P279: 0 | Q279: 8500 | R279: WSG.11 | S279: 3311 | U279: WSG11 | W279: NHUNTQ | X279: NHUNTQ
A280: 46032 | B280: =""&DAY(A280)&"/01/2026"&I280 -> 10/01/2026NL300041 | C280: 2601WSG11101 | E280: 1 | F280: NCC100186 | G280: CÔNG TY TNHH NÔNG SẢN THỰC PHẨM TRẦN GIA | H280: WSG11 - Nhập hàng mua ngày 10/01/2026 | I280: NL300041 | J280: Đậu hủ non trứng | K280: Cái | L280: 5 | M280: 15000 | N280: 0 | O280: 75000 | P280: 0 | Q280: 15000 | R280: WSG.11 | S280: 3311 | U280: WSG11 | W280: NHUNTQ | X280: NHUNTQ
A281: 46032 | B281: =""&DAY(A281)&"/01/2026"&I281 -> 10/01/2026NL300090 | C281: 2601WSG11101 | E281: 1 | F281: NCC100186 | G281: CÔNG TY TNHH NÔNG SẢN THỰC PHẨM TRẦN GIA | H281: WSG11 - Nhập hàng mua ngày 10/01/2026 | I281: NL300090 | J281: Nấm đông cô tươi | K281: kg | L281: 3 | M281: 145000 | N281: 0 | O281: 435000 | P281: 0 | Q281: 145000 | R281: WSG.11 | S281: 3311 | U281: WSG11 | W281: NHUNTQ | X281: NHUNTQ
A282: 46032 | B282: =""&DAY(A282)&"/01/2026"&I282 -> 10/01/2026NL300116 | C282: 2601WSG11101 | E282: 1 | F282: NCC100186 | G282: CÔNG TY TNHH NÔNG SẢN THỰC PHẨM TRẦN GIA | H282: WSG11 - Nhập hàng mua ngày 10/01/2026 | I282: NL300116 | J282: Ớt sừng | K282: kg | L282: 0.4 | M282: 148000 | N282: 0 | O282: 59200 | P282: 0 | Q282: 148000 | R282: WSG.11 | S282: 3311 | U282: WSG11 | W282: NHUNTQ | X282: NHUNTQ
A283: 46032 | B283: =""&DAY(A283)&"/01/2026"&I283 -> 10/01/2026NL300025 | C283: 2601WSG11101 | E283: 1 | F283: NCC100186 | G283: CÔNG TY TNHH NÔNG SẢN THỰC PHẨM TRẦN GIA | H283: WSG11 - Nhập hàng mua ngày 10/01/2026 | I283: NL300025 | J283: Rau cần tây | K283: kg | L283: 1.8 | M283: 44000 | N283: 0 | O283: 79200 | P283: 0 | Q283: 44000 | R283: WSG.11 | S283: 3311 | U283: WSG11 | W283: NHUNTQ | X283: NHUNTQ
A284: 46032 | B284: =""&DAY(A284)&"/01/2026"&I284 -> 10/01/2026NL300101 | C284: 2601WSG11101 | E284: 1 | F284: NCC100186 | G284: CÔNG TY TNHH NÔNG SẢN THỰC PHẨM TRẦN GIA | H284: WSG11 - Nhập hàng mua ngày 10/01/2026 | I284: NL300101 | J284: Nấm Mối | K284: kg | L284: 0.7 | M284: 195000 | N284: 0 | O284: 136500 | P284: 0 | Q284: 195000 | R284: WSG.11 | S284: 3311 | U284: WSG11 | W284: NHUNTQ | X284: NHUNTQ
A285: 46032 | B285: =""&DAY(A285)&"/01/2026"&I285 -> 10/01/2026NL300070 | C285: 2601WSG11101 | E285: 1 | F285: NCC100186 | G285: CÔNG TY TNHH NÔNG SẢN THỰC PHẨM TRẦN GIA | H285: WSG11 - Nhập hàng mua ngày 10/01/2026 | I285: NL300070 | J285: Khoai lang Nhật | K285: kg | L285: 0.5 | M285: 23000 | N285: 0 | O285: 11500 | P285: 0 | Q285: 23000 | R285: WSG.11 | S285: 3311 | U285: WSG11 | W285: NHUNTQ | X285: NHUNTQ
A286: 46032 | B286: =""&DAY(A286)&"/01/2026"&I286 -> 10/01/2026NL100101 | C286: 2601WSG11101 | E286: 1 | F286: NCC100186 | G286: CÔNG TY TNHH NÔNG SẢN THỰC PHẨM TRẦN GIA | H286: WSG11 - Nhập hàng mua ngày 10/01/2026 | I286: NL100101 | J286: Trứng vịt muối | K286: quả | L286: 60 | M286: 5000 | N286: 0 | O286: 300000 | P286: 0 | Q286: 5000 | R286: WSG.11 | S286: 3311 | U286: WSG11 | W286: NHUNTQ | X286: NHUNTQ
A287: 46032 | B287: =""&DAY(A287)&"/01/2026"&I287 -> 10/01/2026NL600004 | C287: 2601WSG11101 | E287: 1 | F287: NCC100186 | G287: CÔNG TY TNHH NÔNG SẢN THỰC PHẨM TRẦN GIA | H287: WSG11 - Nhập hàng mua ngày 10/01/2026 | I287: NL600004 | J287: Dưa hấu | K287: kg | L287: 19 | M287: 18000 | N287: 0 | O287: 342000 | P287: 0 | Q287: 18000 | R287: WSG.11 | S287: 3311 | U287: WSG11 | W287: NHUNTQ | X287: NHUNTQ
A288: 46032 | B288: =""&DAY(A288)&"/01/2026"&I288 -> 10/01/2026NL300131 | C288: 2601WSG11101 | E288: 1 | F288: NCC100186 | G288: CÔNG TY TNHH NÔNG SẢN THỰC PHẨM TRẦN GIA | H288: WSG11 - Nhập hàng mua ngày 10/01/2026 | I288: NL300131 | J288: Xà lách Rocket | K288: kg | L288: 0.1 | M288: 220000 | N288: 0 | O288: 22000 | P288: 0 | Q288: 220000 | R288: WSG.11 | S288: 3311 | U288: WSG11 | W288: NHUNTQ | X288: NHUNTQ
... A475: 46037 | B475: =""&DAY(A475)&"/01/2026"&I475 -> 15/01/2026NL100101 | C475: WSG112601025 | E475: 1 | F475: NCC100186 | G475: CÔNG TY TNHH NÔNG SẢN THỰC PHẨM TRẦN GIA | H475: WSG11 - Nhập hàng mua ngày 15/01/2026 | I475: NL100101 | J475: Trứng vịt muối | K475: quả | L475: 15 | M475: 5000 | N475: 0 | O475: 75000 | P475: 0 | Q475: 5000 | R475: WSG.11 | S475: 3311 | U475: WSG11 | W475: NHUNTQ | X475: NHUNTQ
