Workbook

Sheet BÒ BÌNH THẠNH
D2: CÔNG TY TNHH NÔNG SẢN THỰC PHẨM TRẦN GIA HTX: Ấp Lộc Tiến, Xã Mỹ Lộc, Huyện Cần Giuộc, Tỉnh Long An VP: Tòa nhà An Phú Plaza, 117-119 Lý Chính Thắng, P.7. Q.3, TP.HCM Kho sơ chế: 30 Kha Vạn Cân, P. Hiệp Bình Chánh, TP.Thủ Đức, TP.HCM Kho Đà Lạt: 69 Trần Thủ Độ, TT Liên Nghĩa, Huyện Đức Trọng, Tỉnh Lâm Đồng. Website: rausachtrangia.com - Hotline: 090.245.8081
A4: CHI TIẾT ĐỐI CHIẾU CÔNG NỢ
A6: Từ ngày 1 tháng 01 đến ngày 15 tháng 01 năm 2026
A8: Tên Khách hàng: BÒ TƠ BÌNH THẠNH
A10: Địa chỉ:
A12: Người liên hệ: Email:
J13: =SUBTOTAL(9,J15:J757) -> 40653170 | N13: =SUBTOTAL(9,N15:N987) -> 1209.11 | O13: =N13-Sheet3!M5 -> 0 | Q13: =SUBTOTAL(9,Q15:Q987) -> 28479250 | R13: =Q13-Sheet3!P5 -> 0
A14: NGÀY | B14: MÃ KHÁCH HÀNG | C14: TÊN KHÁCH HÀNG | D14: MÃ ĐƠN HÀNG | E14: MÃ HÀNG | F14: TÊN HÀNG | G14: ĐVT | H14: SỐ LƯỢNG | I14: ĐƠN GIÁ | J14: THÀNH TIỀN | K14: GHI CHÚ | N14: Thực nhận | O14: lệch | P14: Giá chốt | Q14: Tổng | R14: Lệch
A15: 01/01/2026 | B15: TG-KS00197 | C15: BÒ TƠ BÌNH THẠNH | D15: TG-AA20656 | E15: I100002 | F15: Bắp cải tím | G15: Kg | H15: 3.7 | I15: 26000 | J15: =H15*I15 -> 96200 | L15: =VLOOKUP(F15,[1]Sheet1!$D:$J,7,0) -> NL300003 | M15: =A15&L15 -> 01/01/2026NL300003 | N15: =VLOOKUP(M15,Sheet3!I:P,5,0) -> 3.4 | O15: =H15-N15 -> 0.3 | P15: =VLOOKUP(L15,[2]Sheet1!$I:$M,5,0) -> 26000 | Q15: =N15*P15 -> 88400 | R15: =J15-Q15 -> 7800
A16: 01/01/2026 | B16: TG-KS00197 | C16: BÒ TƠ BÌNH THẠNH | D16: TG-AA20656 | E16: I100003 | F16: Bắp cải trắng | G16: Kg | H16: 4.2 | I16: 19000 | J16: =H16*I16 -> 79800 | L16: =VLOOKUP(F16,[1]Sheet1!$D:$J,7,0) -> NL300004 | M16: =A16&L16 -> 01/01/2026NL300004 | N16: =VLOOKUP(M16,Sheet3!I:P,5,0) -> 4 | O16: =H16-N16 -> 0.2 | P16: =VLOOKUP(L16,[2]Sheet1!$I:$M,5,0) -> 19000 | Q16: =N16*P16 -> 76000 | R16: =J16-Q16 -> 3800
A17: 01/01/2026 | B17: TG-KS00197 | C17: BÒ TƠ BÌNH THẠNH | D17: TG-AA20656 | E17: I100004 | F17: Bắp chuối bào | G17: Kg | H17: 0.5 | I17: 33000 | J17: =H17*I17 -> 16500 | L17: =VLOOKUP(F17,[1]Sheet1!$D:$J,7,0) -> NL300060 | M17: =A17&L17 -> 01/01/2026NL300060 | N17: =VLOOKUP(M17,Sheet3!I:P,5,0) -> 0.5 | O17: =H17-N17 -> 0 | P17: =VLOOKUP(L17,[2]Sheet1!$I:$M,5,0) -> 33000 | Q17: =N17*P17 -> 16500 | R17: =J17-Q17 -> 0
A18: 01/01/2026 | B18: TG-KS00197 | C18: BÒ TƠ BÌNH THẠNH | D18: TG-AA20738 | E18: I100004 | F18: Bắp chuối bào | G18: Kg | H18: 0.2 | I18: 33000 | J18: =H18*I18 -> 6600 | L18: =VLOOKUP(F18,[1]Sheet1!$D:$J,7,0) -> NL300060 | M18: =A18&L18 -> 01/01/2026NL300060 | N18: 0.2 | O18: =H18-N18 -> 0 | P18: =VLOOKUP(L18,[2]Sheet1!$I:$M,5,0) -> 33000 | Q18: =N18*P18 -> 6600 | R18: =J18-Q18 -> 0
A19: 01/01/2026 | B19: TG-KS00197 | C19: BÒ TƠ BÌNH THẠNH | D19: TG-AA20656 | E19: I100008 | F19: Bắp mỹ trái (Loại 1) | G19: Trái | H19: 4 | I19: 8500 | J19: =H19*I19 -> 34000 | L19: =VLOOKUP(F19,[1]Sheet1!$D:$J,7,0) -> NL300107 | M19: =A19&L19 -> 01/01/2026NL300107 | N19: =VLOOKUP(M19,Sheet3!I:P,5,0) -> 4 | O19: =H19-N19 -> 0 | P19: =VLOOKUP(L19,[2]Sheet1!$I:$M,5,0) -> 8500 | Q19: =N19*P19 -> 34000 | R19: =J19-Q19 -> 0
A20: 01/01/2026 | B20: TG-KS00197 | C20: BÒ TƠ BÌNH THẠNH | D20: TG-AA20738 | E20: I100008 | F20: Bắp mỹ trái (Loại 1) | G20: Trái | H20: 4 | I20: 8500 | J20: =H20*I20 -> 34000 | L20: =VLOOKUP(F20,[1]Sheet1!$D:$J,7,0) -> NL300107 | M20: =A20&L20 -> 01/01/2026NL300107 | N20: =VLOOKUP(M20,Sheet3!I:P,5,0) -> 4 | O20: =H20-N20 -> 0 | P20: =VLOOKUP(L20,[2]Sheet1!$I:$M,5,0) -> 8500 | Q20: =N20*P20 -> 34000 | R20: =J20-Q20 -> 0
A21: 01/01/2026 | B21: TG-KS00197 | C21: BÒ TƠ BÌNH THẠNH | D21: TG-AA20656 | E21: I100010 | F21: Bầu xanh | G21: Kg | H21: 7.2 | I21: 24000 | J21: =H21*I21 -> 172800 | L21: =VLOOKUP(F21,[1]Sheet1!$D:$J,7,0) -> NL300174 | M21: =A21&L21 -> 01/01/2026NL300174 | N21: =VLOOKUP(M21,Sheet3!I:P,5,0) -> 7 | O21: =H21-N21 -> 0.2 | P21: =VLOOKUP(L21,[2]Sheet1!$I:$M,5,0) -> 24000 | Q21: =N21*P21 -> 168000 | R21: =J21-Q21 -> 4800
A22: 01/01/2026 | B22: TG-KS00197 | C22: BÒ TƠ BÌNH THẠNH | D22: TG-AA20656 | E22: I100018 | F22: Bó xôi (Nhà Lồng) | G22: Kg | H22: 6 | I22: 45000 | J22: =H22*I22 -> 270000 | L22: =VLOOKUP(F22,[1]Sheet1!$D:$J,7,0) -> NL300203 | M22: =A22&L22 -> 01/01/2026NL300203 | N22: =VLOOKUP(M22,Sheet3!I:P,5,0) -> 6 | O22: =H22-N22 -> 0 | P22: =VLOOKUP(L22,[2]Sheet1!$I:$M,5,0) -> 45000 | Q22: =N22*P22 -> 270000 | R22: =J22-Q22 -> 0
A23: 01/01/2026 | B23: TG-KS00197 | C23: BÒ TƠ BÌNH THẠNH | D23: TG-AA20656 | E23: I100024 | F23: Bông cải xanh | G23: Kg | H23: 3 | I23: 52000 | J23: =H23*I23 -> 156000 | L23: =VLOOKUP(F23,[1]Sheet1!$D:$J,7,0) -> NL300137 | M23: =A23&L23 -> 01/01/2026NL300137 | N23: =VLOOKUP(M23,Sheet3!I:P,5,0) -> 3 | O23: =H23-N23 -> 0 | P23: =VLOOKUP(L23,[2]Sheet1!$I:$M,5,0) -> 52000 | Q23: =N23*P23 -> 156000 | R23: =J23-Q23 -> 0
A24: 01/01/2026 | B24: TG-KS00197 | C24: BÒ TƠ BÌNH THẠNH | D24: TG-AA20656 | E24: I100031 | F24: Bông súng | G24: Kg | H24: 0.8 | I24: 17000 | J24: =H24*I24 -> 13600 | L24: =VLOOKUP(F24,[1]Sheet1!$D:$J,7,0) -> NL300011 | M24: =A24&L24 -> 01/01/2026NL300011 | N24: =VLOOKUP(M24,Sheet3!I:P,5,0) -> 0.8 | O24: =H24-N24 -> 0 | P24: =VLOOKUP(L24,[2]Sheet1!$I:$M,5,0) -> 17000 | Q24: =N24*P24 -> 13600 | R24: =J24-Q24 -> 0
A25: 01/01/2026 | B25: TG-KS00197 | C25: BÒ TƠ BÌNH THẠNH | D25: TG-AA20656 | E25: I100034 | F25: Cà chua | G25: Kg | H25: 5 | I25: 50000 | J25: =H25*I25 -> 250000 | L25: =VLOOKUP(F25,[1]Sheet1!$D:$J,7,0) -> NL300013 | M25: =A25&L25 -> 01/01/2026NL300013 | N25: 0 | O25: =H25-N25 -> 5 | P25: =VLOOKUP(L25,[2]Sheet1!$I:$M,5,0) -> 50000 | Q25: =N25*P25 -> 0 | R25: =J25-Q25 -> 250000
A26: 01/01/2026 | B26: TG-KS00197 | C26: BÒ TƠ BÌNH THẠNH | D26: TG-AA20656 | E26: I100033 | F26: Cà chua bi | G26: Kg | H26: 1.5 | I26: 55000 | J26: =H26*I26 -> 82500 | L26: =VLOOKUP(F26,[1]Sheet1!$D:$J,7,0) -> NL300014 | M26: =A26&L26 -> 01/01/2026NL300014 | N26: =VLOOKUP(M26,Sheet3!I:P,5,0) -> 1.4 | O26: =H26-N26 -> 0.1 | P26: =VLOOKUP(L26,[2]Sheet1!$I:$M,5,0) -> 55000 | Q26: =N26*P26 -> 77000 | R26: =J26-Q26 -> 5500
A27: 01/01/2026 | B27: TG-KS00197 | C27: BÒ TƠ BÌNH THẠNH | D27: TG-AA20656 | E27: I100039 | F27: Cà rốt | G27: Kg | H27: 5.5 | I27: 18000 | J27: =H27*I27 -> 99000 | L27: =VLOOKUP(F27,[1]Sheet1!$D:$J,7,0) -> NL300027 | M27: =A27&L27 -> 01/01/2026NL300027 | N27: =VLOOKUP(M27,Sheet3!I:P,5,0) -> 4.8 | O27: =H27-N27 -> 0.7 | P27: =VLOOKUP(L27,[2]Sheet1!$I:$M,5,0) -> 18000 | Q27: =N27*P27 -> 86400 | R27: =J27-Q27 -> 12600
A28: 01/01/2026 | B28: TG-KS00197 | C28: BÒ TƠ BÌNH THẠNH | D28: TG-AA20656 | E28: I100073 | F28: Củ sắn | G28: Kg | H28: 0.5 | I28: 12000 | J28: =H28*I28 -> 6000 | L28: =VLOOKUP(F28,[1]Sheet1!$D:$J,7,0) -> NL300188 | M28: =A28&L28 -> 01/01/2026NL300188 | N28: =VLOOKUP(M28,Sheet3!I:P,5,0) -> 0.4 | O28: =H28-N28 -> 0.1 | P28: =VLOOKUP(L28,[2]Sheet1!$I:$M,5,0) -> 12000 | Q28: =N28*P28 -> 4800 | R28: =J28-Q28 -> 1200
A29: 01/01/2026 | B29: TG-KS00291 | C29: BÒ TƠ BÌNH THẠNH (BAR) | D29: TG-AA20627 | E29: I100060 | F29: Chanh không hạt | G29: Kg | H29: 1.5 | I29: 22000 | J29: =H29*I29 -> 33000 | L29: =VLOOKUP(F29,[1]Sheet1!$D:$J,7,0) -> NL300029 | M29: =A29&L29 -> 01/01/2026NL300029 | N29: 0 | O29: =H29-N29 -> 1.5 | P29: =VLOOKUP(L29,[2]Sheet1!$I:$M,5,0) -> 22000 | Q29: =N29*P29 -> 0 | R29: =J29-Q29 -> 33000
A30: 01/01/2026 | B30: TG-KS00291 | C30: BÒ TƠ BÌNH THẠNH (BAR) | D30: TG-AA20627 | E30: I100479 | F30: Dưa hấu | G30: Kg | H30: 3.3 | I30: 18000 | J30: =H30*I30 -> 59400 | L30: =VLOOKUP(F30,[1]Sheet1!$D:$J,7,0) -> NL600004 | M30: =A30&L30 -> 01/01/2026NL600004 | N30: 0 | O30: =H30-N30 -> 3.3 | P30: =VLOOKUP(L30,[2]Sheet1!$I:$M,5,0) -> 18000 | Q30: =N30*P30 -> 0 | R30: =J30-Q30 -> 59400
A31: 01/01/2026 | B31: TG-KS00197 | C31: BÒ TƠ BÌNH THẠNH | D31: TG-AA20656 | E31: I100089 | F31: Dưa leo | G31: Kg | H31: 5 | I31: 18000 | J31: =H31*I31 -> 90000 | L31: =VLOOKUP(F31,[1]Sheet1!$D:$J,7,0) -> NL300048 | M31: =A31&L31 -> 01/01/2026NL300048 | N31: =VLOOKUP(M31,Sheet3!I:P,5,0) -> 4.8 | O31: =H31-N31 -> 0.2 | P31: =VLOOKUP(L31,[2]Sheet1!$I:$M,5,0) -> 18000 | Q31: =N31*P31 -> 86400 | R31: =J31-Q31 -> 3600
A32: 01/01/2026 | B32: TG-KS00197 | C32: BÒ TƠ BÌNH THẠNH | D32: TG-AA20656 | E32: I100075 | F32: Đậu bắp | G32: Kg | H32: 2 | I32: 32000 | J32: =H32*I32 -> 64000 | L32: =VLOOKUP(F32,[1]Sheet1!$D:$J,7,0) -> NL300038 | M32: =A32&L32 -> 01/01/2026NL300038 | N32: =VLOOKUP(M32,Sheet3!I:P,5,0) -> 1.8 | O32: =H32-N32 -> 0.2 | P32: =VLOOKUP(L32,[2]Sheet1!$I:$M,5,0) -> 32000 | Q32: =N32*P32 -> 57600 | R32: =J32-Q32 -> 6400
A33: 01/01/2026 | B33: TG-KS00197 | C33: BÒ TƠ BÌNH THẠNH | D33: TG-AA20656 | E33: I100077 | F33: Đậu cove Pháp (Nhật) | G33: Kg | H33: 0.1 | I33: 75000 | J33: =H33*I33 -> 7500 | L33: =VLOOKUP(F33,[1]Sheet1!$D:$J,7,0) -> NL300156 | M33: =A33&L33 -> 01/01/2026NL300156 | N33: =VLOOKUP(M33,Sheet3!I:P,5,0) -> 0.1 | O33: =H33-N33 -> 0 | P33: =VLOOKUP(L33,[2]Sheet1!$I:$M,5,0) -> 75000 | Q33: =N33*P33 -> 7500 | R33: =J33-Q33 -> 0
A34: 01/01/2026 | B34: TG-KS00197 | C34: BÒ TƠ BÌNH THẠNH | D34: TG-AA20656 | E34: I100260 | F34: Đậu hủ miếng trắng | G34: Miếng | H34: 60 | I34: 4000 | J34: =H34*I34 -> 240000 | L34: =VLOOKUP(F34,[1]Sheet1!$D:$J,7,0) -> NL300037 | M34: =A34&L34 -> 01/01/2026NL300037 | N34: =VLOOKUP(M34,Sheet3!I:P,5,0) -> 60 | O34: =H34-N34 -> 0 | P34: =VLOOKUP(L34,[2]Sheet1!$I:$M,5,0) -> 4000 | Q34: =N34*P34 -> 240000 | R34: =J34-Q34 -> 0
A35: 01/01/2026 | B35: TG-KS00197 | C35: BÒ TƠ BÌNH THẠNH | D35: TG-AA20656 | E35: I100088 | F35: Đu đủ trái xanh | G35: Kg | H35: 2 | I35: 9000 | J35: =H35*I35 -> 18000 | L35: =VLOOKUP(F35,[1]Sheet1!$D:$J,7,0) -> NL300049 | M35: =A35&L35 -> 01/01/2026NL300049 | N35: =VLOOKUP(M35,Sheet3!I:P,5,0) -> 1.9 | O35: =H35-N35 -> 0.1 | P35: =VLOOKUP(L35,[2]Sheet1!$I:$M,5,0) -> 9000 | Q35: =N35*P35 -> 17100 | R35: =J35-Q35 -> 900
A36: 01/01/2026 | B36: TG-KS00197 | C36: BÒ TƠ BÌNH THẠNH | D36: TG-AA20656 | E36: I100098 | F36: Hành lá | G36: Kg | H36: 1.1 | I36: 55000 | J36: =H36*I36 -> 60500 | L36: =VLOOKUP(F36,[1]Sheet1!$D:$J,7,0) -> NL300058 | M36: =A36&L36 -> 01/01/2026NL300058 | N36: =VLOOKUP(M36,Sheet3!I:P,5,0) -> 1 | O36: =H36-N36 -> 0.1 | P36: =VLOOKUP(L36,[2]Sheet1!$I:$M,5,0) -> 55000 | Q36: =N36*P36 -> 55000 | R36: =J36-Q36 -> 5500
A37: 01/01/2026 | B37: TG-KS00197 | C37: BÒ TƠ BÌNH THẠNH | D37: TG-AA20656 | E37: I100101 | F37: Hành tây | G37: Kg | H37: 2.2 | I37: 13000 | J37: =H37*I37 -> 28600 | L37: =VLOOKUP(F37,[1]Sheet1!$D:$J,7,0) -> NL300059 | M37: =A37&L37 -> 01/01/2026NL300059 | N37: =VLOOKUP(M37,Sheet3!I:P,5,0) -> 2 | O37: =H37-N37 -> 0.2 | P37: =VLOOKUP(L37,[2]Sheet1!$I:$M,5,0) -> 13000 | Q37: =N37*P37 -> 26000 | R37: =J37-Q37 -> 2600
A38: 01/01/2026 | B38: TG-KS00197 | C38: BÒ TƠ BÌNH THẠNH | D38: TG-AA20656 | E38: I100730 | F38: Hành tím bắc lột | G38: Kg | H38: 2 | I38: 80000 | J38: =H38*I38 -> 160000 | L38: =VLOOKUP(F38,[1]Sheet1!$D:$J,7,0) -> NL300055 | M38: =A38&L38 -> 01/01/2026NL300055 | N38: =VLOOKUP(M38,Sheet3!I:P,5,0) -> 2 | O38: =H38-N38 -> 0 | P38: =VLOOKUP(L38,[2]Sheet1!$I:$M,5,0) -> 80000 | Q38: =N38*P38 -> 160000 | R38: =J38-Q38 -> 0
A39: 01/01/2026 | B39: TG-KS00197 | C39: BÒ TƠ BÌNH THẠNH | D39: TG-AA20656 | E39: I100111 | F39: Hẹ lá | G39: Kg | H39: 1.3 | I39: 38000 | J39: =H39*I39 -> 49400 | L39: =VLOOKUP(F39,[1]Sheet1!$D:$J,7,0) -> NL300076 | M39: =A39&L39 -> 01/01/2026NL300076 | N39: =VLOOKUP(M39,Sheet3!I:P,5,0) -> 1 | O39: =H39-N39 -> 0.3 | P39: =VLOOKUP(L39,[2]Sheet1!$I:$M,5,0) -> 38000 | Q39: =N39*P39 -> 38000 | R39: =J39-Q39 -> 11400
A40: 01/01/2026 | B40: TG-KS00197 | C40: BÒ TƠ BÌNH THẠNH | D40: TG-AA20656 | E40: I100112 | F40: Húng cây | G40: Kg | H40: 2.8 | I40: 48000 | J40: =H40*I40 -> 134400 | L40: =VLOOKUP(F40,[1]Sheet1!$D:$J,7,0) -> NL300063 | M40: =A40&L40 -> 01/01/2026NL300063 | N40: =VLOOKUP(M40,Sheet3!I:P,5,0) -> 2.8 | O40: =H40-N40 -> 0 | P40: =VLOOKUP(L40,[2]Sheet1!$I:$M,5,0) -> 48000 | Q40: =N40*P40 -> 134400 | R40: =J40-Q40 -> 0
A41: 01/01/2026 | B41: TG-KS00197 | C41: BÒ TƠ BÌNH THẠNH | D41: TG-AA20738 | E41: I100112 | F41: Húng cây | G41: Kg | H41: 2.4 | I41: 48000 | J41: =H41*I41 -> 115200 | L41: =VLOOKUP(F41,[1]Sheet1!$D:$J,7,0) -> NL300063 | M41: =A41&L41 -> 01/01/2026NL300063 | N41: 1.8 | O41: =H41-N41 -> 0.6 | P41: =VLOOKUP(L41,[2]Sheet1!$I:$M,5,0) -> 48000 | Q41: =N41*P41 -> 86400 | R41: =J41-Q41 -> 28800
A42: 01/01/2026 | B42: TG-KS00197 | C42: BÒ TƠ BÌNH THẠNH | D42: TG-AA20738 | E42: I100113 | F42: Húng lũi | G42: Kg | H42: 1 | I42: 65000 | J42: =H42*I42 -> 65000 | L42: =VLOOKUP(F42,[1]Sheet1!$D:$J,7,0) -> NL300062 | M42: =A42&L42 -> 01/01/2026NL300062 | N42: =VLOOKUP(M42,Sheet3!I:P,5,0) -> 0.9 | O42: =H42-N42 -> 0.1 | P42: =VLOOKUP(L42,[2]Sheet1!$I:$M,5,0) -> 65000 | Q42: =N42*P42 -> 58500 | R42: =J42-Q42 -> 6500
A43: 01/01/2026 | B43: TG-KS00291 | C43: BÒ TƠ BÌNH THẠNH (BAR) | D43: TG-AA20627 | E43: I100113 | F43: Húng lũi | G43: Kg | H43: 1 | I43: 65000 | J43: =H43*I43 -> 65000 | L43: =VLOOKUP(F43,[1]Sheet1!$D:$J,7,0) -> NL300062 | M43: =A43&L43 -> 01/01/2026NL300062 | N43: 0 | O43: =H43-N43 -> 1 | P43: =VLOOKUP(L43,[2]Sheet1!$I:$M,5,0) -> 65000 | Q43: =N43*P43 -> 0 | R43: =J43-Q43 -> 65000
A44: 01/01/2026 | B44: TG-KS00197 | C44: BÒ TƠ BÌNH THẠNH | D44: TG-AA20656 | E44: I100115 | F44: Kèo nèo | G44: Kg | H44: 0.7 | I44: 25000 | J44: =H44*I44 -> 17500 | L44: =VLOOKUP(F44,[1]Sheet1!$D:$J,7,0) -> NL300067 | M44: =A44&L44 -> 01/01/2026NL300067 | N44: =VLOOKUP(M44,Sheet3!I:P,5,0) -> 0.7 | O44: =H44-N44 -> 0 | P44: =VLOOKUP(L44,[2]Sheet1!$I:$M,5,0) -> 25000 | Q44: =N44*P44 -> 17500 | R44: =J44-Q44 -> 0
A45: 01/01/2026 | B45: TG-KS00197 | C45: BÒ TƠ BÌNH THẠNH | D45: TG-AA20738 | E45: I100115 | F45: Kèo nèo | G45: Kg | H45: 0.9 | I45: 25000 | J45: =H45*I45 -> 22500 | L45: =VLOOKUP(F45,[1]Sheet1!$D:$J,7,0) -> NL300067 | M45: =A45&L45 -> 01/01/2026NL300067 | N45: 0.8 | O45: =H45-N45 -> 0.1 | P45: =VLOOKUP(L45,[2]Sheet1!$I:$M,5,0) -> 25000 | Q45: =N45*P45 -> 20000 | R45: =J45-Q45 -> 2500
A46: 01/01/2026 | B46: TG-KS00197 | C46: BÒ TƠ BÌNH THẠNH | D46: TG-AA20656 | E46: I100116 | F46: Khế xanh | G46: Kg | H46: 0.3 | I46: 35000 | J46: =H46*I46 -> 10500 | L46: =VLOOKUP(F46,[1]Sheet1!$D:$J,7,0) -> NL300068 | M46: =A46&L46 -> 01/01/2026NL300068 | N46: 0 | O46: =H46-N46 -> 0.3 | P46: =VLOOKUP(L46,[2]Sheet1!$I:$M,5,0) -> 35000 | Q46: =N46*P46 -> 0 | R46: =J46-Q46 -> 10500
...

Sheet Sheet3
A3: Bảng kê hóa đơn mua hàng
A4: Từ ngày 01/01/2026 đến ngày 15/01/2026...
M5: =SUBTOTAL(9,M7:M824) -> 1209.11 | N5: =M5-'BÒ BÌNH THẠNH'!N13 -> 0 | P5: =SUBTOTAL(9,P7:P824) -> 28479250 | Q5: =P5-'BÒ BÌNH THẠNH'!Q13 -> 0
A6: Ngày ct | B6: Mã ct | C6: Số ct | D6: Số hđ | E6: Áp giá | F6: Mã ncc | G6: Tên ncc | H6: Diễn giải | J6: Mã hàng | K6: Tên mặt hàng | L6: Đvt | M6: Số lượng | N6: Giá | O6: Giá báo | P6: Tiền | Q6: Thuế suất | R6: Chênh lệch giá | S6: Kho hàng | T6: Mã nx | U6: Vụ việc | V6: Bộ phận | W6: Hợp đồng | X6: Người tạo | Y6: Người sửa
I7: =TEXT(A7,"dd/mm/yyyy")&J7
A8: 46023 | B8: HD | C8: 2601BSG07003 | E8: 1 | F8: NCC100186 | G8: CÔNG TY TNHH NÔNG SẢN THỰC PHẨM TRẦN GIA | H8: BSG07 - Nhập hàng mua ngày 01/01/2026 | I8: =TEXT(A8,"dd/mm/yyyy")&J8 -> 01/01/2026NL300003 | J8: NL300003 | K8: Bắp cải tím | L8: kg | M8: 3.4 | N8: =VLOOKUP(J8,[2]Sheet1!$I:$M,5,0) -> 26000 | O8: 0 | P8: =M8*N8 -> 88400 | Q8: 0 | R8: 26000 | S8: BSG.07 | T8: 3311 | V8: BSG07 | X8: PHATLT | Y8: PHATLT
A9: 46023 | B9: HD | C9: 2601BSG07003 | E9: 1 | F9: NCC100186 | G9: CÔNG TY TNHH NÔNG SẢN THỰC PHẨM TRẦN GIA | H9: BSG07 - Nhập hàng mua ngày 01/01/2026 | I9: =TEXT(A9,"dd/mm/yyyy")&J9 -> 01/01/2026NL300004 | J9: NL300004 | K9: Bắp cải trắng | L9: kg | M9: 4 | N9: =VLOOKUP(J9,[2]Sheet1!$I:$M,5,0) -> 19000 | O9: 0 | P9: =M9*N9 -> 76000 | Q9: 0 | R9: 19000 | S9: BSG.07 | T9: 3311 | V9: BSG07 | X9: PHATLT | Y9: PHATLT
A10: 46023 | B10: HD | C10: 2601BSG07003 | E10: 1 | F10: NCC100186 | G10: CÔNG TY TNHH NÔNG SẢN THỰC PHẨM TRẦN GIA | H10: BSG07 - Nhập hàng mua ngày 01/01/2026 | I10: =TEXT(A10,"dd/mm/yyyy")&J10 -> 01/01/2026NL300174 | J10: NL300174 | K10: Bầu | L10: kg | M10: 7 | N10: =VLOOKUP(J10,[2]Sheet1!$I:$M,5,0) -> 24000 | O10: 0 | P10: =M10*N10 -> 168000 | Q10: 0 | R10: 24000 | S10: BSG.07 | T10: 3311 | V10: BSG07 | X10: PHATLT | Y10: PHATLT
A11: 46023 | B11: HD | C11: 2601BSG07003 | E11: 1 | F11: NCC100186 | G11: CÔNG TY TNHH NÔNG SẢN THỰC PHẨM TRẦN GIA | H11: BSG07 - Nhập hàng mua ngày 01/01/2026 | I11: =TEXT(A11,"dd/mm/yyyy")&J11 -> 01/01/2026NL300011 | J11: NL300011 | K11: Bông súng | L11: kg | M11: 0.8 | N11: =VLOOKUP(J11,[2]Sheet1!$I:$M,5,0) -> 17000 | O11: 0 | P11: =M11*N11 -> 13600 | Q11: 0 | R11: 17000 | S11: BSG.07 | T11: 3311 | V11: BSG07 | X11: PHATLT | Y11: PHATLT
A12: 46023 | B12: HD | C12: 2601BSG07003 | E12: 1 | F12: NCC100186 | G12: CÔNG TY TNHH NÔNG SẢN THỰC PHẨM TRẦN GIA | H12: BSG07 - Nhập hàng mua ngày 01/01/2026 | I12: =TEXT(A12,"dd/mm/yyyy")&J12 -> 01/01/2026NL300014 | J12: NL300014 | K12: Cà chua bi | L12: kg | M12: 1.4 | N12: =VLOOKUP(J12,[2]Sheet1!$I:$M,5,0) -> 55000 | O12: 0 | P12: =M12*N12 -> 77000 | Q12: 0 | R12: 55000 | S12: BSG.07 | T12: 3311 | V12: BSG07 | X12: PHATLT | Y12: PHATLT
A13: 46023 | B13: HD | C13: 2601BSG07003 | E13: 1 | F13: NCC100186 | G13: CÔNG TY TNHH NÔNG SẢN THỰC PHẨM TRẦN GIA | H13: BSG07 - Nhập hàng mua ngày 01/01/2026 | I13: =TEXT(A13,"dd/mm/yyyy")&J13 -> 01/01/2026NL300027 | J13: NL300027 | K13: Cà rốt | L13: kg | M13: 4.8 | N13: =VLOOKUP(J13,[2]Sheet1!$I:$M,5,0) -> 18000 | O13: 0 | P13: =M13*N13 -> 86400 | Q13: 0 | R13: 18000 | S13: BSG.07 | T13: 3311 | V13: BSG07 | X13: PHATLT | Y13: PHATLT
A14: 46023 | B14: HD | C14: 2601BSG07003 | E14: 1 | F14: NCC100186 | G14: CÔNG TY TNHH NÔNG SẢN THỰC PHẨM TRẦN GIA | H14: BSG07 - Nhập hàng mua ngày 01/01/2026 | I14: =TEXT(A14,"dd/mm/yyyy")&J14 -> 01/01/2026NL300203 | J14: NL300203 | K14: Cải bó xôi | L14: kg | M14: 6 | N14: =VLOOKUP(J14,[2]Sheet1!$I:$M,5,0) -> 45000 | O14: 0 | P14: =M14*N14 -> 270000 | Q14: 0 | R14: 45000 | S14: BSG.07 | T14: 3311 | V14: BSG07 | X14: PHATLT | Y14: PHATLT
A15: 46023 | B15: HD | C15: 2601BSG07003 | E15: 1 | F15: NCC100186 | G15: CÔNG TY TNHH NÔNG SẢN THỰC PHẨM TRẦN GIA | H15: BSG07 - Nhập hàng mua ngày 01/01/2026 | I15: =TEXT(A15,"dd/mm/yyyy")&J15 -> 01/01/2026NL300188 | J15: NL300188 | K15: Củ Sắn ( Bếp) | L15: kg | M15: 0.4 | N15: =VLOOKUP(J15,[2]Sheet1!$I:$M,5,0) -> 12000 | O15: 0 | P15: =M15*N15 -> 4800 | Q15: 0 | R15: 12000 | S15: BSG.07 | T15: 3311 | V15: BSG07 | X15: PHATLT | Y15: PHATLT
A16: 46023 | B16: HD | C16: 2601BSG07003 | E16: 1 | F16: NCC100186 | G16: CÔNG TY TNHH NÔNG SẢN THỰC PHẨM TRẦN GIA | H16: BSG07 - Nhập hàng mua ngày 01/01/2026 | I16: =TEXT(A16,"dd/mm/yyyy")&J16 -> 01/01/2026NL300048 | J16: NL300048 | K16: Dưa chuột | L16: kg | M16: 4.8 | N16: =VLOOKUP(J16,[2]Sheet1!$I:$M,5,0) -> 18000 | O16: 0 | P16: =M16*N16 -> 86400 | Q16: 0 | R16: 18000 | S16: BSG.07 | T16: 3311 | V16: BSG07 | X16: PHATLT | Y16: PHATLT
A17: 46023 | B17: HD | C17: 2601BSG07003 | E17: 1 | F17: NCC100186 | G17: CÔNG TY TNHH NÔNG SẢN THỰC PHẨM TRẦN GIA | H17: BSG07 - Nhập hàng mua ngày 01/01/2026 | I17: =TEXT(A17,"dd/mm/yyyy")&J17 -> 01/01/2026NL300038 | J17: NL300038 | K17: Đậu bắp | L17: kg | M17: 1.8 | N17: =VLOOKUP(J17,[2]Sheet1!$I:$M,5,0) -> 32000 | O17: 0 | P17: =M17*N17 -> 57600 | Q17: 0 | R17: 32000 | S17: BSG.07 | T17: 3311 | V17: BSG07 | X17: PHATLT | Y17: PHATLT
A18: 46023 | B18: HD | C18: 2601BSG07003 | E18: 1 | F18: NCC100186 | G18: CÔNG TY TNHH NÔNG SẢN THỰC PHẨM TRẦN GIA | H18: BSG07 - Nhập hàng mua ngày 01/01/2026 | I18: =TEXT(A18,"dd/mm/yyyy")&J18 -> 01/01/2026NL300156 | J18: NL300156 | K18: Đậu cove Pháp | L18: kg | M18: 0.1 | N18: =VLOOKUP(J18,[2]Sheet1!$I:$M,5,0) -> 75000 | O18: 0 | P18: =M18*N18 -> 7500 | Q18: 0 | R18: 75000 | S18: BSG.07 | T18: 3311 | V18: BSG07 | X18: PHATLT | Y18: PHATLT
A19: 46023 | B19: HD | C19: 2601BSG07003 | E19: 1 | F19: NCC100186 | G19: CÔNG TY TNHH NÔNG SẢN THỰC PHẨM TRẦN GIA | H19: BSG07 - Nhập hàng mua ngày 01/01/2026 | I19: =TEXT(A19,"dd/mm/yyyy")&J19 -> 01/01/2026NL300037 | J19: NL300037 | K19: Đậu phụ ( đậu hủ miếng trắng ) | L19: miếng | M19: 60 | N19: =VLOOKUP(J19,[2]Sheet1!$I:$M,5,0) -> 4000 | O19: 0 | P19: =M19*N19 -> 240000 | Q19: 0 | R19: 4000 | S19: BSG.07 | T19: 3311 | V19: BSG07 | X19: PHATLT | Y19: PHATLT
... A348: 46031 | B348: HD | C348: 2601BSG07063 | E348: 1 | F348: NCC100186 | G348: CÔNG TY TNHH NÔNG SẢN THỰC PHẨM TRẦN GIA | H348: BSG07 - Nhập hàng mua ngày 09/01/2026 | I348: =TEXT(A348,"dd/mm/yyyy")&J348 -> 09/01/2026NL300209 | J348: NL300209 | K348: Khoai môn | L348: kg | M348: 0.8 | N348: =VLOOKUP(J348,[2]Sheet1!$I:$M,5,0) -> 30000 | O348: 0 | P348: =M348*N348 -> 24000 | Q348: 0 | R348: 30000 | S348: BSG.07 | T348: 3311 | V348: BSG07 | X348: PHATLT | Y348: PHATLT
A349: 46031 | B349: HD | C349: 2601BSG07063 | E349: 1 | F349: NCC100186 | G349: CÔNG TY TNHH NÔNG SẢN THỰC PHẨM TRẦN GIA | H349: BSG07 - Nhập hàng mua ngày 09/01/2026 | I349: =TEXT(A349,"dd/mm/yyyy")&J349 -> 09/01/2026NL300105 | J349: NL300105 | K349: Nghệ | L349: kg | M349: 0.2 | N349: 36000 | O349: 0 | P349: =M349*N349 -> 7200 | Q349: 0 | R349: 36000 | S349: BSG.07 | T349: 3311 | V349: BSG07 | X349: PHATLT | Y349: PHATLT
A350: 46031 | B350: HD | C350: 2601BSG07063 | E350: 1 | F350: NCC100186 | G350: CÔNG TY TNHH NÔNG SẢN THỰC PHẨM TRẦN GIA | H350: BSG07 - Nhập hàng mua ngày 09/01/2026 | I350: =TEXT(A350,"dd/mm/yyyy")&J350 -> 09/01/2026NL300119 | J350: NL300119 | K350: Quất ( Tắc trái ) | L350: kg | M350: 1 | N350: =VLOOKUP(J350,[2]Sheet1!$I:$M,5,0) -> 21000 | O350: 0 | P350: =M350*N350 -> 21000 | Q350: 0 | R350: 21000 | S350: BSG.07 | T350: 3311 | V350: BSG07 | X350: PHATLT | Y350: PHATLT
A351: 46031 | B351: HD | C351: 2601BSG07063 | E351: 1 | F351: NCC100186 | G351: CÔNG TY TNHH NÔNG SẢN THỰC PHẨM TRẦN GIA | H351: BSG07 - Nhập hàng mua ngày 09/01/2026 | I351: =TEXT(A351,"dd/mm/yyyy")&J351 -> 09/01/2026NL300132 | J351: NL300132 | K351: Sả cây | L351: kg | M351: 0.3 | N351: =VLOOKUP(J351,[2]Sheet1!$I:$M,5,0) -> 12000 | O351: 0 | P351: =M351*N351 -> 3600 | Q351: 0 | R351: 12000 | S351: BSG.07 | T351: 3311 | V351: BSG07 | X351: PHATLT | Y351: PHATLT
A352: 46031 | B352: HD | C352: 2601BSG07063 | E352: 1 | F352: NCC100186 | G352: CÔNG TY TNHH NÔNG SẢN THỰC PHẨM TRẦN GIA | H352: BSG07 - Nhập hàng mua ngày 09/01/2026 | I352: =TEXT(A352,"dd/mm/yyyy")&J352 -> 09/01/2026NL300062 | J352: NL300062 | K352: Húng Bạc Hà | L352: kg | M352: 0.2 | N352: =VLOOKUP(J352,[2]Sheet1!$I:$M,5,0) -> 65000 | O352: 0 | P352: =M352*N352 -> 13000 | Q352: 0 | R352: 65000 | S352: BSG.07 | T352: 3311 | V352: BSG07 | X352: PHATLT | Y352: PHATLT
A353: 46031 | B353: HD | C353: 2601BSG07063 | E353: 1 | F353: NCC100186 | G353: CÔNG TY TNHH NÔNG SẢN THỰC PHẨM TRẦN GIA | H353: BSG07 - Nhập hàng mua ngày 09/01/2026 | I353: =TEXT(A353,"dd/mm/yyyy")&J353 -> 09/01/2026NL300141 | J353: NL300141 | K353: Tiêu xanh | L353: kg | M353: 0.2 | N353: =VLOOKUP(J353,[2]Sheet1!$I:$M,5,0) -> 92000 | O353: 0 | P353: =M353*N353 -> 18400 | Q353: 0 | R353: 92000 | S353: BSG.07 | T353: 3311 | V353: BSG07 | X353: PHATLT | Y353: PHATLT
A354: 46031 | B354: HD | C354: 2601BSG07063 | E354: 1 | F354: NCC100186 | G354: CÔNG TY TNHH NÔNG SẢN THỰC PHẨM TRẦN GIA | H354: BSG07 - Nhập hàng mua ngày 09/01/2026 | I354: =TEXT(A354,"dd/mm/yyyy")&J354 -> 09/01/2026NL300137 | J354: NL300137 | K354: Súp lơ xanh | L354: kg | M354: 0.7 | N354: =VLOOKUP(J354,[2]Sheet1!$I:$M,5,0) -> 52000 | O354: 0 | P354: =M354*N354 -> 36400 | Q354: 0 | R354: 52000 | S354: BSG.07 | T354: 3311 | V354: BSG07 | X354: PHATLT | Y354: PHATLT
A355: 46031 | B355: HD | C355: 2601BSG07063 | E355: 1 | F355: NCC100186 | G355: CÔNG TY TNHH NÔNG SẢN THỰC PHẨM TRẦN GIA | H355: BSG07 - Nhập hàng mua ngày 09/01/2026 | I355: =TEXT(A355,"dd/mm/yyyy")&J355 -> 09/01/2026NL300153 | J355: NL300153 | K355: Ớt xanh Đà Lạt | L355: kg | M355: 0.2 | N355: =VLOOKUP(J355,[2]Sheet1!$I:$M,5,0) -> 46000 | O355: 0 | P355: =M355*N355 -> 9200 | Q355: 0 | R355: 46000 | S355: BSG.07 | T355: 3311 | V355: BSG07 | X355: PHATLT | Y355: PHATLT
A356: 46031 | B356: HD | C356: 2601BSG07063 | E356: 1 | F356: NCC100186 | G356: CÔNG TY TNHH NÔNG SẢN THỰC PHẨM TRẦN GIA | H356: BSG07 - Nhập hàng mua ngày 09/01/2026 | I356: =TEXT(A356,"dd/mm/yyyy")&J356 -> 09/01/2026NL300107 | J356: NL300107 | K356: Ngô ngọt ( Bắp trái) | L356: Cái | M356: 2 | N356: =VLOOKUP(J356,[2]Sheet1!$I:$M,5,0) -> 8500 | O356: 0 | P356: =M356*N356 -> 17000 | Q356: 0 | R356: 8500 | S356: BSG.07 | T356: 3311 | V356: BSG07 | X356: PHATLT | Y356: PHATLT
A357: 46031 | B357: HD | C357: 2601BSG07063 | E357: 1 | F357: NCC100186 | G357: CÔNG TY TNHH NÔNG SẢN THỰC PHẨM TRẦN GIA | H357: BSG07 - Nhập hàng mua ngày 09/01/2026 | I357: =TEXT(A357,"dd/mm/yyyy")&J357 -> 09/01/2026NL300076 | J357: NL300076 | K357: Lá hẹ | L357: kg | M357: 0.2 | N357: =VLOOKUP(J357,[2]Sheet1!$I:$M,5,0) -> 38000 | O357: 0 | P357: =M357*N357 -> 7600 | Q357: 0 | R357: 38000 | S357: BSG.07 | T357: 3311 | V357: BSG07 | X357: PHATLT | Y357: PHATLT
A358: 46031 | B358: HD | C358: 2601BSG07063 | E358: 1 | F358: NCC100186 | G358: CÔNG TY TNHH NÔNG SẢN THỰC PHẨM TRẦN GIA | H358: BSG07 - Nhập hàng mua ngày 09/01/2026 | I358: =TEXT(A358,"dd/mm/yyyy")&J358 -> 09/01/2026NL300055 | J358: NL300055 | K358: Hành bóc | L358: kg | M358: 1 | N358: =VLOOKUP(J358,[2]Sheet1!$I:$M,5,0) -> 80000 | O358: 0 | P358: =M358*N358 -> 80000 | Q358: 0 | R358: 80000 | S358: BSG.07 | T358: 3311 | V358: BSG07 | X358: PHATLT | Y358: PHATLT
A359: 46031 | B359: HD | C359: 2601BSG07063 | E359: 1 | F359: NCC100186 | G359: CÔNG TY TNHH NÔNG SẢN THỰC PHẨM TRẦN GIA | H359: BSG07 - Nhập hàng mua ngày 09/01/2026 | I359: =TEXT(A359,"dd/mm/yyyy")&J359 -> 09/01/2026NL300037 | J359: NL300037 | K359: Đậu phụ ( đậu hủ miếng trắng ) | L359: miếng | M359: 10 | N359: =VLOOKUP(J359,[2]Sheet1!$I:$M,5,0) -> 4000 | O359: 0 | P359: =M359*N359 -> 40000 | Q359: 0 | R359: 4000 | S359: BSG.07 | T359: 3311 | V359: BSG07 | X359: PHATLT | Y359: PHATLT
A360: 46031 | B360: HD | C360: 2601BSG07063 | E360: 1 | F360: NCC100186 | G360: CÔNG TY TNHH NÔNG SẢN THỰC PHẨM TRẦN GIA | H360: BSG07 - Nhập hàng mua ngày 09/01/2026 | I360: =TEXT(A360,"dd/mm/yyyy")&J360 -> 09/01/2026NL300048 | J360: NL300048 | K360: Dưa chuột | L360: kg | M360: 1.7 | N360: =VLOOKUP(J360,[2]Sheet1!$I:$M,5,0) -> 18000 | O360: 0 | P360: =M360*N360 -> 30600 | Q360: 0 | R360: 18000 | S360: BSG.07 | T360: 3311 | V360: BSG07 | X360: PHATLT | Y360: PHATLT
A361: 46031 | B361: HD | C361: 2601BSG07063 | E361: 1 | F361: NCC100186 | G361: CÔNG TY TNHH NÔNG SẢN THỰC PHẨM TRẦN GIA | H361: BSG07 - Nhập hàng mua ngày 09/01/2026 | I361: =TEXT(A361,"dd/mm/yyyy")&J361 -> 09/01/2026NL300027 | J361: NL300027 | K361: Cà rốt | L361: kg | M361: 1.9 | N361: =VLOOKUP(J361,[2]Sheet1!$I:$M,5,0) -> 18000 | O361: 0 | P361: =M361*N361 -> 34200 | Q361: 0 | R361: 18000 | S361: BSG.07 | T361: 3311 | V361: BSG07 | X361: PHATLT | Y361: PHATLT
... A651: 46023 | B651: HD | C651: 2601BSG07003 | E651: 1 | F651: NCC100186 | G651: CÔNG TY TNHH NÔNG SẢN THỰC PHẨM TRẦN GIA | H651: BSG07 - Nhập hàng mua ngày 01/01/2026 | I651: =TEXT(A651,"dd/mm/yyyy")&J651 -> 01/01/2026NL300148 | J651: NL300148 | K651: Xà lách tím | L651: kg | M651: 0.5 | N651: =VLOOKUP(J651,[2]Sheet1!$I:$M,5,0) -> 65000 | O651: 0 | P651: =M651*N651 -> 32500 | Q651: 0 | R651: 65000 | S651: BSG.07 | T651: 3311 | V651: BSG07 | X651: PHATLT | Y651: PHATLT

Sheet Q7
D2: CÔNG TY TNHH NÔNG SẢN THỰC PHẨM TRẦN GIA HTX: Ấp Lộc Tiến, Xã Mỹ Lộc, Huyện Cần Giuộc, Tỉnh Long An VP: Tòa nhà An Phú Plaza, 117-119 Lý Chính Thắng, P.7. Q.3, TP.HCM Kho sơ chế: 30 Kha Vạn Cân, P. Hiệp Bình Chánh, TP.Thủ Đức, TP.HCM Kho Đà Lạt: 69 Trần Thủ Độ, TT Liên Nghĩa, Huyện Đức Trọng, Tỉnh Lâm Đồng. Website: rausachtrangia.com - Hotline: 090.245.8081
A4: CHI TIẾT ĐỐI CHIẾU CÔNG NỢ
A6: Từ ngày 1 tháng 01 đến ngày 15 tháng 01 năm 2026
A8: Tên Khách hàng: BÒ TƠ Q7
A10: Địa chỉ:
A12: Người liên hệ: Email:
J13: =SUBTOTAL(9,J15:J860) -> 51467020 | N13: =SUBTOTAL(9,N15:N987) -> 2055.17 | O13: =N13-Sheet4!M5 -> 0 | Q13: =SUBTOTAL(9,Q15:Q987) -> 45897840 | R13: =Q13-Sheet4!P5 -> 0
A14: NGÀY | B14: MÃ KHÁCH HÀNG | C14: TÊN KHÁCH HÀNG | D14: MÃ ĐƠN HÀNG | E14: MÃ HÀNG | F14: TÊN HÀNG | G14: ĐVT | H14: SỐ LƯỢNG | I14: ĐƠN GIÁ | J14: THÀNH TIỀN | K14: GHI CHÚ | N14: Thực nhận | O14: lệch | P14: Giá chốt | Q14: Tổng | R14: Lệch
A15: 01/01/2026 | B15: TG-KS00056 | C15: BÒ TƠ Q7 | D15: TG-AA20659 | E15: I100002 | F15: Bắp cải tím | G15: Kg | H15: 2.3 | I15: 26000 | J15: =H15*I15 -> 59800 | L15: =VLOOKUP(F15,[1]Sheet1!$D:$J,7,0) -> NL300003 | M15: =A15&L15 -> 01/01/2026NL300003 | N15: =VLOOKUP(M15,Sheet4!I:P,5,0) -> 2 | O15: =H15-N15 -> 0.3 | P15: =VLOOKUP(L15,[2]Sheet1!$I:$M,5,0) -> 26000 | Q15: =N15*P15 -> 52000 | R15: =J15-Q15 -> 7800
A16: 01/01/2026 | B16: TG-KS00056 | C16: BÒ TƠ Q7 | D16: TG-AA20659 | E16: I100003 | F16: Bắp cải trắng | G16: Kg | H16: 3.5 | I16: 19000 | J16: =H16*I16 -> 66500 | L16: =VLOOKUP(F16,[1]Sheet1!$D:$J,7,0) -> NL300004 | M16: =A16&L16 -> 01/01/2026NL300004 | N16: =VLOOKUP(M16,Sheet4!I:P,5,0) -> 3 | O16: =H16-N16 -> 0.5 | P16: =VLOOKUP(L16,[2]Sheet1!$I:$M,5,0) -> 19000 | Q16: =N16*P16 -> 57000 | R16: =J16-Q16 -> 9500
A17: 01/01/2026 | B17: TG-KS00056 | C17: BÒ TƠ Q7 | D17: TG-AA20659 | E17: I100004 | F17: Bắp chuối bào | G17: Kg | H17: 0.5 | I17: 33000 | J17: =H17*I17 -> 16500 | L17: =VLOOKUP(F17,[1]Sheet1!$D:$J,7,0) -> NL300060 | M17: =A17&L17 -> 01/01/2026NL300060 | N17: =VLOOKUP(M17,Sheet4!I:P,5,0) -> 0.5 | O17: =H17-N17 -> 0 | P17: =VLOOKUP(L17,[2]Sheet1!$I:$M,5,0) -> 33000 | Q17: =N17*P17 -> 16500 | R17: =J17-Q17 -> 0
A18: 01/01/2026 | B18: TG-KS00056 | C18: BÒ TƠ Q7 | D18: TG-AA20659 | E18: I100008 | F18: Bắp mỹ trái (Loại 1) | G18: Trái | H18: 4 | I18: 8500 | J18: =H18*I18 -> 34000 | L18: =VLOOKUP(F18,[1]Sheet1!$D:$J,7,0) -> NL300107 | M18: =A18&L18 -> 01/01/2026NL300107 | N18: =VLOOKUP(M18,Sheet4!I:P,5,0) -> 4 | O18: =H18-N18 -> 0 | P18: =VLOOKUP(L18,[2]Sheet1!$I:$M,5,0) -> 8500 | Q18: =N18*P18 -> 34000 | R18: =J18-Q18 -> 0
A19: 01/01/2026 | B19: TG-KS00056 | C19: BÒ TƠ Q7 | D19: TG-AA20659 | E19: I100010 | F19: Bầu xanh | G19: Kg | H19: 3.8 | I19: 24000 | J19: =H19*I19 -> 91200 | L19: =VLOOKUP(F19,[1]Sheet1!$D:$J,7,0) -> NL300174 | M19: =A19&L19 -> 01/01/2026NL300174 | N19: =VLOOKUP(M19,Sheet4!I:P,5,0) -> 3.8 | O19: =H19-N19 -> 0 | P19: =VLOOKUP(L19,[2]Sheet1!$I:$M,5,0) -> 24000 | Q19: =N19*P19 -> 91200 | R19: =J19-Q19 -> 0
A20: 01/01/2026 | B20: TG-KS00056 | C20: BÒ TƠ Q7 | D20: TG-AA20659 | E20: I100018 | F20: Bó xôi (Nhà Lồng) | G20: Kg | H20: 6 | I20: 45000 | J20: =H20*I20 -> 270000 | L20: =VLOOKUP(F20,[1]Sheet1!$D:$J,7,0) -> NL300203 | M20: =A20&L20 -> 01/01/2026NL300203 | N20: =VLOOKUP(M20,Sheet4!I:P,5,0) -> 5 | O20: =H20-N20 -> 1 | P20: =VLOOKUP(L20,[2]Sheet1!$I:$M,5,0) -> 45000 | Q20: =N20*P20 -> 225000 | R20: =J20-Q20 -> 45000
A21: 01/01/2026 | B21: TG-KS00056 | C21: BÒ TƠ Q7 | D21: TG-AA20659 | E21: I100024 | F21: Bông cải xanh | G21: Kg | H21: 4 | I21: 52000 | J21: =H21*I21 -> 208000 | L21: =VLOOKUP(F21,[1]Sheet1!$D:$J,7,0) -> NL300137 | M21: =A21&L21 -> 01/01/2026NL300137 | N21: =VLOOKUP(M21,Sheet4!I:P,5,0) -> 3.5 | O21: =H21-N21 -> 0.5 | P21: =VLOOKUP(L21,[2]Sheet1!$I:$M,5,0) -> 52000 | Q21: =N21*P21 -> 182000 | R21: =J21-Q21 -> 26000
A22: 01/01/2026 | B22: TG-KS00056 | C22: BÒ TƠ Q7 | D22: TG-AA20659 | E22: I100034 | F22: Cà chua | G22: Kg | H22: 5 | I22: 50000 | J22: =H22*I22 -> 250000 | L22: =VLOOKUP(F22,[1]Sheet1!$D:$J,7,0) -> NL300013 | M22: =A22&L22 -> 01/01/2026NL300013 | N22: =VLOOKUP(M22,Sheet4!I:P,5,0) -> 5 | O22: =H22-N22 -> 0 | P22: =VLOOKUP(L22,[2]Sheet1!$I:$M,5,0) -> 50000 | Q22: =N22*P22 -> 250000 | R22: =J22-Q22 -> 0
A23: 01/01/2026 | B23: TG-KS00056 | C23: BÒ TƠ Q7 | D23: TG-AA20659 | E23: I100033 | F23: Cà chua bi | G23: Kg | H23: 1.3 | I23: 55000 | J23: =H23*I23 -> 71500 | L23: =VLOOKUP(F23,[1]Sheet1!$D:$J,7,0) -> NL300014 | M23: =A23&L23 -> 01/01/2026NL300014 | N23: =VLOOKUP(M23,Sheet4!I:P,5,0) -> 1 | O23: =H23-N23 -> 0.3 | P23: =VLOOKUP(L23,[2]Sheet1!$I:$M,5,0) -> 55000 | Q23: =N23*P23 -> 55000 | R23: =J23-Q23 -> 16500
A24: 01/01/2026 | B24: TG-KS00056 | C24: BÒ TƠ Q7 | D24: TG-AA20659 | E24: I100039 | F24: Cà rốt | G24: Kg | H24: 7 | I24: 18000 | J24: =H24*I24 -> 126000 | L24: =VLOOKUP(F24,[1]Sheet1!$D:$J,7,0) -> NL300027 | M24: =A24&L24 -> 01/01/2026NL300027 | N24: =VLOOKUP(M24,Sheet4!I:P,5,0) -> 6 | O24: =H24-N24 -> 1 | P24: =VLOOKUP(L24,[2]Sheet1!$I:$M,5,0) -> 18000 | Q24: =N24*P24 -> 108000 | R24: =J24-Q24 -> 18000
A25: 01/01/2026 | B25: TG-KS00056 | C25: BÒ TƠ Q7 | D25: TG-AA20659 | E25: I100064 | F25: Củ cải đỏ (Radis) | G25: Kg | H25: 0.2 | I25: 40000 | J25: =H25*I25 -> 8000 | L25: =VLOOKUP(F25,[1]Sheet1!$D:$J,7,0) -> NL300034 | M25: =A25&L25 -> 01/01/2026NL300034 | N25: =VLOOKUP(M25,Sheet4!I:P,5,0) -> 0.2 | O25: =H25-N25 -> 0 | P25: =VLOOKUP(L25,[2]Sheet1!$I:$M,5,0) -> 40000 | Q25: =N25*P25 -> 8000 | R25: =J25-Q25 -> 0
A26: 01/01/2026 | B26: TG-KS00056 | C26: BÒ TƠ Q7 | D26: TG-AA20659 | E26: I100067 | F26: Củ cải trắng (Loại 1) | G26: Kg | H26: 3.1 | I26: 13000 | J26: =H26*I26 -> 40300 | L26: =VLOOKUP(F26,[1]Sheet1!$D:$J,7,0) -> NL300033 | M26: =A26&L26 -> 01/01/2026NL300033 | N26: =VLOOKUP(M26,Sheet4!I:P,5,0) -> 3 | O26: =H26-N26 -> 0.1 | P26: =VLOOKUP(L26,[2]Sheet1!$I:$M,5,0) -> 13000 | Q26: =N26*P26 -> 39000 | R26: =J26-Q26 -> 1300
... A72: 01/01/2026 | B72: TG-KS00056 | C72: BÒ TƠ Q7 | D72: TG-AA20659 | E72: I100207 | F72: Xà lách lolo xanh | G72: Kg | H72: 15 | I72: 38000 | J72: =H72*I72 -> 570000 | L72: =VLOOKUP(F72,[1]Sheet1!$D:$J,7,0) -> NL300145 | M72: =A72&L72 -> 01/01/2026NL300145 | N72: =VLOOKUP(M72,Sheet4!I:P,5,0) -> 11 | O72: =H72-N72 -> 4 | P72: =VLOOKUP(L72,[2]Sheet1!$I:$M,5,0) -> 38000 | Q72: =N72*P72 -> 418000 | R72: =J72-Q72 -> 152000
A73: 01/01/2026 | B73: TG-KS00056 | C73: BÒ TƠ Q7 | D73: TG-AA20749 | E73: I100033 | F73: Cà chua bi | G73: Kg | H73: 1 | I73: 55000 | J73: =H73*I73 -> 55000 | L73: =VLOOKUP(F73,[1]Sheet1!$D:$J,7,0) -> NL300014 | M73: =A73&L73 -> 01/01/2026NL300014 | N73: 0 | O73: =H73-N73 -> 1 | P73: =VLOOKUP(L73,[2]Sheet1!$I:$M,5,0) -> 55000 | Q73: =N73*P73 -> 0 | R73: =J73-Q73 -> 55000
A74: 02/01/2026 | B74: TG-KS00066 | C74: BÒ TƠ Q7 (NV) | D74: TG-AA20833 | E74: I100001 | F74: Bạc hà | G74: Kg | H74: 0.47 | I74: 17000 | J74: =H74*I74 -> 7990 | L74: NL430043 | M74: =A74&L74 -> 02/01/2026NL430043 | N74: =VLOOKUP(M74,Sheet4!I:P,5,0) -> 0.47 | O74: =H74-N74 -> 0 | P74: =VLOOKUP(L74,[2]Sheet1!$I:$M,5,0) -> 17000 | Q74: =N74*P74 -> 7990 | R74: =J74-Q74 -> 0
A75: 02/01/2026 | B75: TG-KS00056 | C75: BÒ TƠ Q7 | D75: TG-AA20858 | E75: I100002 | F75: Bắp cải tím | G75: Kg | H75: 2 | I75: 26000 | J75: =H75*I75 -> 52000 | L75: =VLOOKUP(F75,[1]Sheet1!$D:$J,7,0) -> NL300003 | M75: =A75&L75 -> 02/01/2026NL300003 | N75: =VLOOKUP(M75,Sheet4!I:P,5,0) -> 2 | O75: =H75-N75 -> 0 | P75: =VLOOKUP(L75,[2]Sheet1!$I:$M,5,0) -> 26000 | Q75: =N75*P75 -> 52000 | R75: =J75-Q75 -> 0
A76: 02/01/2026 | B76: TG-KS00056 | C76: BÒ TƠ Q7 | D76: TG-AA20858 | E76: I100003 | F76: Bắp cải trắng | G76: Kg | H76: 2.9 | I76: 19000 | J76: =H76*I76 -> 55100 | L76: =VLOOKUP(F76,[1]Sheet1!$D:$J,7,0) -> NL300004 | M76: =A76&L76 -> 02/01/2026NL300004 | N76: =VLOOKUP(M76,Sheet4!I:P,5,0) -> 2.9 | O76: =H76-N76 -> 0 | P76: =VLOOKUP(L76,[2]Sheet1!$I:$M,5,0) -> 19000 | Q76: =N76*P76 -> 55100 | R76: =J76-Q76 -> 0
A77: 02/01/2026 | B77: TG-KS00056 | C77: BÒ TƠ Q7 | D77: TG-AA20858 | E77: I100004 | F77: Bắp chuối bào | G77: Kg | H77: 0.5 | I77: 33000 | J77: =H77*I77 -> 16500 | L77: =VLOOKUP(F77,[1]Sheet1!$D:$J,7,0) -> NL300060 | M77: =A77&L77 -> 02/01/2026NL300060 | N77: =VLOOKUP(M77,Sheet4!I:P,5,0) -> 0.5 | O77: =H77-N77 -> 0 | P77: =VLOOKUP(L77,[2]Sheet1!$I:$M,5,0) -> 33000 | Q77: =N77*P77 -> 16500 | R77: =J77-Q77 -> 0
A78: 02/01/2026 | B78: TG-KS00056 | C78: BÒ TƠ Q7 | D78: TG-AA20866 | E78: I100007 | F78: Bắp mỹ kg Lột Vỏ | G78: Kg | H78: 1.1 | I78: 32000 | J78: =H78*I78 -> 35200 | L78: NL300107 | M78: =A78&L78 -> 02/01/2026NL300107 | N78: 1 | O78: =H78-N78 -> 0.1 | P78: =VLOOKUP(L78,[2]Sheet1!$I:$M,5,0) -> 8500 | Q78: =N78*P78 -> 8500 | R78: =J78-Q78 -> 26700
A79: 02/01/2026 | B79: TG-KS00056 | C79: BÒ TƠ Q7 | D79: TG-AA20858 | E79: I100008 | F79: Bắp mỹ trái (Loại 1) | G79: Trái | H79: 4 | I79: 8500 | J79: =H79*I79 -> 34000 | L79: =VLOOKUP(F79,[1]Sheet1!$D:$J,7,0) -> NL300107 | M79: =A79&L79 -> 02/01/2026NL300107 | N79: 4 | O79: =H79-N79 -> 0 | P79: =VLOOKUP(L79,[2]Sheet1!$I:$M,5,0) -> 8500 | Q79: =N79*P79 -> 34000 | R79: =J79-Q79 -> 0
A80: 02/01/2026 | B80: TG-KS00056 | C80: BÒ TƠ Q7 | D80: TG-AA20858 | E80: I100010 | F80: Bầu xanh | G80: Kg | H80: 7.5 | I80: 24000 | J80: =H80*I80 -> 180000 | L80: =VLOOKUP(F80,[1]Sheet1!$D:$J,7,0) -> NL300174 | M80: =A80&L80 -> 02/01/2026NL300174 | N80: =VLOOKUP(M80,Sheet4!I:P,5,0) -> 7 | O80: =H80-N80 -> 0.5 | P80: =VLOOKUP(L80,[2]Sheet1!$I:$M,5,0) -> 24000 | Q80: =N80*P80 -> 168000 | R80: =J80-Q80 -> 12000
A81: 02/01/2026 | B81: TG-KS00056 | C81: BÒ TƠ Q7 | D81: TG-AA20866 | E81: I100016 | F81: Bí ngòi xanh | G81: Kg | H81: 1.2 | I81: 40000 | J81: =H81*I81 -> 48000 | L81: NL300008 | M81: =A81&L81 -> 02/01/2026NL300008 | N81: =VLOOKUP(M81,Sheet4!I:P,5,0) -> 1 | O81: =H81-N81 -> 0.2 | P81: =VLOOKUP(L81,[2]Sheet1!$I:$M,5,0) -> 40000 | Q81: =N81*P81 -> 40000 | R81: =J81-Q81 -> 8000
A82: 02/01/2026 | B82: TG-KS00056 | C82: BÒ TƠ Q7 | D82: TG-AA20858 | E82: I100018 | F82: Bó xôi (Nhà Lồng) | G82: Kg | H82: 5 | I82: 45000 | J82: =H82*I82 -> 225000 | L82: =VLOOKUP(F82,[1]Sheet1!$D:$J,7,0) -> NL300203 | M82: =A82&L82 -> 02/01/2026NL300203 | N82: =VLOOKUP(M82,Sheet4!I:P,5,0) -> 4 | O82: =H82-N82 -> 1 | P82: =VLOOKUP(L82,[2]Sheet1!$I:$M,5,0) -> 45000 | Q82: =N82*P82 -> 180000 | R82: =J82-Q82 -> 45000
A83: 02/01/2026 | B83: TG-KS00056 | C83: BÒ TƠ Q7 | D83: TG-AA20858 | E83: I100024 | F83: Bông cải xanh | G83: Kg | H83: 3.1 | I83: 52000 | J83: =H83*I83 -> 161200 | L83: =VLOOKUP(F83,[1]Sheet1!$D:$J,7,0) -> NL300137 | M83: =A83&L83 -> 02/01/2026NL300137 | N83: =VLOOKUP(M83,Sheet4!I:P,5,0) -> 3 | O83: =H83-N83 -> 0.1 | P83: =VLOOKUP(L83,[2]Sheet1!$I:$M,5,0) -> 52000 | Q83: =N83*P83 -> 156000 | R83: =J83-Q83 -> 5200
A84: 02/01/2026 | B84: TG-KS00066 | C84: BÒ TƠ Q7 (NV) | D84: TG-AA20833 | E84: I100410 | F84: Cá Ba sa | G84: Kg | H84: 3 | I84: 82000 | J84: =H84*I84 -> 246000 | L84: =VLOOKUP(F84,[1]Sheet1!$D:$J,7,0) -> NL410018 | M84: =A84&L84 -> 02/01/2026NL410018 | N84: =VLOOKUP(M84,Sheet4!I:P,5,0) -> 2.9 | O84: =H84-N84 -> 0.1 | P84: =VLOOKUP(L84,[2]Sheet1!$I:$M,5,0) -> 82000 | Q84: =N84*P84 -> 237800 | R84: =J84-Q84 -> 8200
A85: 02/01/2026 | B85: TG-KS00056 | C85: BÒ TƠ Q7 | D85: TG-AA20858 | E85: I100034 | F85: Cà chua | G85: Kg | H85: 7 | I85: 50000 | J85: =H85*I85 -> 350000 | L85: =VLOOKUP(F85,[1]Sheet1!$D:$J,7,0) -> NL300013 | M85: =A85&L85 -> 02/01/2026NL300013 | N85: =VLOOKUP(M85,Sheet4!I:P,5,0) -> 6 | O85: =H85-N85 -> 1 | P85: =VLOOKUP(L85,[2]Sheet1!$I:$M,5,0) -> 50000 | Q85: =N85*P85 -> 300000 | R85: =J85-Q85 -> 50000
A86: 02/01/2026 | B86: TG-KS00056 | C86: BÒ TƠ Q7 | D86: TG-AA20858 | E86: I100033 | F86: Cà chua bi | G86: Kg | H86: 1.2 | I86: 55000 | J86: =H86*I86 -> 66000 | L86: =VLOOKUP(F86,[1]Sheet1!$D:$J,7,0) -> NL300014 | M86: =A86&L86 -> 02/01/2026NL300014 | N86: =VLOOKUP(M86,Sheet4!I:P,5,0) -> 1 | O86: =H86-N86 -> 0.2 | P86: =VLOOKUP(L86,[2]Sheet1!$I:$M,5,0) -> 55000 | Q86: =N86*P86 -> 55000 | R86: =J86-Q86 -> 11000
A87: 02/01/2026 | B87: TG-KS00056 | C87: BÒ TƠ Q7 | D87: TG-AA20858 | E87: I100039 | F87: Cà rốt | G87: Kg | H87: 7 | I87: 18000 | J87: =H87*I87 -> 126000 | L87: =VLOOKUP(F87,[1]Sheet1!$D:$J,7,0) -> NL300027 | M87: =A87&L87 -> 02/01/2026NL300027 | N87: =VLOOKUP(M87,Sheet4!I:P,5,0) -> 7 | O87: =H87-N87 -> 0 | P87: =VLOOKUP(L87,[2]Sheet1!$I:$M,5,0) -> 18000 | Q87: =N87*P87 -> 126000 | R87: =J87-Q87 -> 0
A88: 02/01/2026 | B88: TG-KS00056 | C88: BÒ TƠ Q7 | D88: TG-AA20866 | E88: I100042 | F88: Cà tím | G88: Kg | H88: 1.15 | I88: 33000 | J88: =H88*I88 -> 37950 | L88: NL300233 | M88: =A88&L88 -> 02/01/2026NL300233 | N88: =VLOOKUP(M88,Sheet4!I:P,5,0) -> 1.15 | O88: =H88-N88 -> 0 | P88: =VLOOKUP(L88,[2]Sheet1!$I:$M,5,0) -> 33000 | Q88: =N88*P88 -> 37950 | R88: =J88-Q88 -> 0
A89: 02/01/2026 | B89: TG-KS00066 | C89: BÒ TƠ Q7 (NV) | D89: TG-AA20833 | E89: I100580 | F89: Cải bẹ xanh nước | G89: Kg | H89: 2 | I89: 28000 | J89: =H89*I89 -> 56000 | L89: NL430021 | M89: =A89&L89 -> 02/01/2026NL430021 | N89: =VLOOKUP(M89,Sheet4!I:P,5,0) -> 2 | O89: =H89-N89 -> 0 | P89: =VLOOKUP(L89,[2]Sheet1!$I:$M,5,0) -> 28000 | Q89: =N89*P89 -> 56000 | R89: =J89-Q89 -> 0
A90: 02/01/2026 | B90: TG-KS00056 | C90: BÒ TƠ Q7 | D90: TG-AA20866 | E90: I100051 | F90: Cải thảo | G90: Kg | H90: 1.2 | I90: 18000 | J90: =H90*I90 -> 21600 | L90: NL300022 | M90: =A90&L90 -> 02/01/2026NL300022 | N90: =VLOOKUP(M90,Sheet4!I:P,5,0) -> 1.2 | O90: =H90-N90 -> 0 | P90: =VLOOKUP(L90,[2]Sheet1!$I:$M,5,0) -> 18000 | Q90: =N90*P90 -> 21600 | R90: =J90-Q90 -> 0
A91: 02/01/2026 | B91: TG-KS00056 | C91: BÒ TƠ Q7 | D91: TG-AA20858 | E91: I100067 | F91: Củ cải trắng (Loại 1) | G91: Kg | H91: 2 | I91: 13000 | J91: =H91*I91 -> 26000 | L91: =VLOOKUP(F91,[1]Sheet1!$D:$J,7,0) -> NL300033 | M91: =A91&L91 -> 02/01/2026NL300033 | N91: =VLOOKUP(M91,Sheet4!I:P,5,0) -> 2 | O91: =H91-N91 -> 0 | P91: =VLOOKUP(L91,[2]Sheet1!$I:$M,5,0) -> 13000 | Q91: =N91*P91 -> 26000 | R91: =J91-Q91 -> 0
...

Sheet Sheet4
A3: Bảng kê hóa đơn mua hàng
A4: Từ ngày 01/01/2026 đến ngày 15/01/2026...
M5: =SUBTOTAL(9,M7:M830) -> 2055.17 | N5: =M5-'Q7'!N13 -> 0 | P5: =SUBTOTAL(9,P7:P830) -> 45897840 | Q5: =P5-'Q7'!Q13 -> 0
A6: Ngày ct | B6: Mã ct | C6: Số ct | D6: Số hđ | E6: Áp giá | F6: Mã ncc | G6: Tên ncc | H6: Diễn giải | J6: Mã hàng | K6: Tên mặt hàng | L6: Đvt | M6: Số lượng | N6: Giá | O6: Giá báo | P6: Tiền | Q6: Thuế suất | R6: Chênh lệch giá | S6: Kho hàng | T6: Mã nx | U6: Vụ việc | V6: Bộ phận | W6: Hợp đồng | X6: Người tạo | Y6: Người sửa
A7: 46023 | B7: HD | C7: 2601BSG01002 | E7: 1 | F7: NCC100186 | G7: CÔNG TY TNHH NÔNG SẢN THỰC PHẨM TRẦN GIA | H7: BSG01 - Nhập hàng mua ngày 01/01/2026 | I7: =TEXT(A7,"dd/mm/yyyy")&J7 -> 01/01/2026NL300174 | J7: NL300174 | K7: Bầu | L7: kg | M7: 3.8 | N7: =VLOOKUP(J7,[2]Sheet1!$I:$M,5,0) -> 24000 | O7: 0 | P7: =M7*N7 -> 91200 | Q7: 0 | R7: 24000 | S7: BSG.01 | T7: 3311 | V7: BSG01 | X7: MINHDL | Y7: PHATLT
A8: 46023 | B8: HD | C8: 2601BSG01002 | E8: 1 | F8: NCC100186 | G8: CÔNG TY TNHH NÔNG SẢN THỰC PHẨM TRẦN GIA | H8: BSG01 - Nhập hàng mua ngày 01/01/2026 | I8: =TEXT(A8,"dd/mm/yyyy")&J8 -> 01/01/2026NL300003 | J8: NL300003 | K8: Bắp cải tím | L8: kg | M8: 2 | N8: =VLOOKUP(J8,[2]Sheet1!$I:$M,5,0) -> 26000 | O8: 0 | P8: =M8*N8 -> 52000 | Q8: 0 | R8: 26000 | S8: BSG.01 | T8: 3311 | V8: BSG01 | X8: MINHDL | Y8: PHATLT
A9: 46023 | B9: HD | C9: 2601BSG01002 | E9: 1 | F9: NCC100186 | G9: CÔNG TY TNHH NÔNG SẢN THỰC PHẨM TRẦN GIA | H9: BSG01 - Nhập hàng mua ngày 01/01/2026 | I9: =TEXT(A9,"dd/mm/yyyy")&J9 -> 01/01/2026NL300004 | J9: NL300004 | K9: Bắp cải trắng | L9: kg | M9: 3 | N9: =VLOOKUP(J9,[2]Sheet1!$I:$M,5,0) -> 19000 | O9: 0 | P9: =M9*N9 -> 57000 | Q9: 0 | R9: 19000 | S9: BSG.01 | T9: 3311 | V9: BSG01 | X9: MINHDL | Y9: PHATLT
A10: 46023 | B10: HD | C10: 2601BSG01002 | E10: 1 | F10: NCC100186 | G10: CÔNG TY TNHH NÔNG SẢN THỰC PHẨM TRẦN GIA | H10: BSG01 - Nhập hàng mua ngày 01/01/2026 | I10: =TEXT(A10,"dd/mm/yyyy")&J10 -> 01/01/2026NL300013 | J10: NL300013 | K10: Cà chua | L10: kg | M10: 5 | N10: =VLOOKUP(J10,[2]Sheet1!$I:$M,5,0) -> 50000 | O10: 0 | P10: =M10*N10 -> 250000 | Q10: 0 | R10: 50000 | S10: BSG.01 | T10: 3311 | V10: BSG01 | X10: MINHDL | Y10: PHATLT
A11: 46023 | B11: HD | C11: 2601BSG01002 | E11: 1 | F11: NCC100186 | G11: CÔNG TY TNHH NÔNG SẢN THỰC PHẨM TRẦN GIA | H11: BSG01 - Nhập hàng mua ngày 01/01/2026 | I11: =TEXT(A11,"dd/mm/yyyy")&J11 -> 01/01/2026NL300014 | J11: NL300014 | K11: Cà chua bi | L11: kg | M11: 1 | N11: =VLOOKUP(J11,[2]Sheet1!$I:$M,5,0) -> 55000 | O11: 0 | P11: =M11*N11 -> 55000 | Q11: 0 | R11: 55000 | S11: BSG.01 | T11: 3311 | V11: BSG01 | X11: MINHDL | Y11: PHATLT
A12: 46023 | B12: HD | C12: 2601BSG01002 | E12: 1 | F12: NCC100186 | G12: CÔNG TY TNHH NÔNG SẢN THỰC PHẨM TRẦN GIA | H12: BSG01 - Nhập hàng mua ngày 01/01/2026 | I12: =TEXT(A12,"dd/mm/yyyy")&J12 -> 01/01/2026NL300027 | J12: NL300027 | K12: Cà rốt | L12: kg | M12: 6 | N12: =VLOOKUP(J12,[2]Sheet1!$I:$M,5,0) -> 18000 | O12: 0 | P12: =M12*N12 -> 108000 | Q12: 0 | R12: 18000 | S12: BSG.01 | T12: 3311 | V12: BSG01 | X12: MINHDL | Y12: PHATLT
A13: 46023 | B13: HD | C13: 2601BSG01002 | E13: 1 | F13: NCC100186 | G13: CÔNG TY TNHH NÔNG SẢN THỰC PHẨM TRẦN GIA | H13: BSG01 - Nhập hàng mua ngày 01/01/2026 | I13: =TEXT(A13,"dd/mm/yyyy")&J13 -> 01/01/2026NL300203 | J13: NL300203 | K13: Cải bó xôi | L13: kg | M13: 5 | N13: =VLOOKUP(J13,[2]Sheet1!$I:$M,5,0) -> 45000 | O13: 0 | P13: =M13*N13 -> 225000 | Q13: 0 | R13: 45000 | S13: BSG.01 | T13: 3311 | V13: BSG01 | X13: MINHDL | Y13: PHATLT
A14: 46023 | B14: HD | C14: 2601BSG01002 | E14: 1 | F14: NCC100186 | G14: CÔNG TY TNHH NÔNG SẢN THỰC PHẨM TRẦN GIA | H14: BSG01 - Nhập hàng mua ngày 01/01/2026 | I14: =TEXT(A14,"dd/mm/yyyy")&J14 -> 01/01/2026NL300033 | J14: NL300033 | K14: Củ cải trắng | L14: kg | M14: 3 | N14: =VLOOKUP(J14,[2]Sheet1!$I:$M,5,0) -> 13000 | O14: 0 | P14: =M14*N14 -> 39000 | Q14: 0 | R14: 13000 | S14: BSG.01 | T14: 3311 | V14: BSG01 | X14: MINHDL | Y14: PHATLT
A15: 46023 | B15: HD | C15: 2601BSG01002 | E15: 1 | F15: NCC100186 | G15: CÔNG TY TNHH NÔNG SẢN THỰC PHẨM TRẦN GIA | H15: BSG01 - Nhập hàng mua ngày 01/01/2026 | I15: =TEXT(A15,"dd/mm/yyyy")&J15 -> 01/01/2026NL300034 | J15: NL300034 | K15: Củ cải đỏ | L15: kg | M15: 0.2 | N15: =VLOOKUP(J15,[2]Sheet1!$I:$M,5,0) -> 40000 | O15: 0 | P15: =M15*N15 -> 8000 | Q15: 0 | R15: 40000 | S15: BSG.01 | T15: 3311 | V15: BSG01 | X15: MINHDL | Y15: PHATLT
A16: 46023 | B16: HD | C16: 2601BSG01002 | E16: 1 | F16: NCC100186 | G16: CÔNG TY TNHH NÔNG SẢN THỰC PHẨM TRẦN GIA | H16: BSG01 - Nhập hàng mua ngày 01/01/2026 | I16: =TEXT(A16,"dd/mm/yyyy")&J16 -> 01/01/2026NL300188 | J16: NL300188 | K16: Củ Sắn ( Bếp) | L16: kg | M16: 0.5 | N16: =VLOOKUP(J16,[2]Sheet1!$I:$M,5,0) -> 12000 | O16: 0 | P16: =M16*N16 -> 6000 | Q16: 0 | R16: 12000 | S16: BSG.01 | T16: 3311 | V16: BSG01 | X16: MINHDL | Y16: PHATLT
A17: 46023 | B17: HD | C17: 2601BSG01002 | E17: 1 | F17: NCC100186 | G17: CÔNG TY TNHH NÔNG SẢN THỰC PHẨM TRẦN GIA | H17: BSG01 - Nhập hàng mua ngày 01/01/2026 | I17: =TEXT(A17,"dd/mm/yyyy")&J17 -> 01/01/2026NL300038 | J17: NL300038 | K17: Đậu bắp | L17: kg | M17: 2.5 | N17: =VLOOKUP(J17,[2]Sheet1!$I:$M,5,0) -> 32000 | O17: 0 | P17: =M17*N17 -> 80000 | Q17: 0 | R17: 32000 | S17: BSG.01 | T17: 3311 | V17: BSG01 | X17: MINHDL | Y17: PHATLT
A18: 46023 | B18: HD | C18: 2601BSG01002 | E18: 1 | F18: NCC100186 | G18: CÔNG TY TNHH NÔNG SẢN THỰC PHẨM TRẦN GIA | H18: BSG01 - Nhập hàng mua ngày 01/01/2026 | I18: =TEXT(A18,"dd/mm/yyyy")&J18 -> 01/01/2026NL300156 | J18: NL300156 | K18: Đậu cove Pháp | L18: kg | M18: 0.3 | N18: =VLOOKUP(J18,[2]Sheet1!$I:$M,5,0) -> 75000 | O18: 0 | P18: =M18*N18 -> 22500 | Q18: 0 | R18: 75000 | S18: BSG.01 | T18: 3311 | V18: BSG01 | X18: MINHDL | Y18: PHATLT
... A70: 46023 | B70: HD | C70: 2601BSG01005 | E70: 1 | F70: NCC100186 | G70: CÔNG TY TNHH NÔNG SẢN THỰC PHẨM TRẦN GIA | H70: BSG01 - Nhập hàng mua ngày 01/01/2026 | I70: =TEXT(A70,"dd/mm/yyyy")&J70 -> 01/01/2026NL300029 | J70: NL300029 | K70: Chanh | L70: kg | M70: 3 | N70: =VLOOKUP(J70,[2]Sheet1!$I:$M,5,0) -> 22000 | O70: 0 | P70: =M70*N70 -> 66000 | Q70: 0 | R70: 22000 | S70: BSG.01 | T70: 3311 | V70: BSG01 | X70: MINHDL | Y70: PHATLT
I71: =TEXT(A71,"dd/mm/yyyy")&J71
A72: 46024 | B72: HD | C72: 2601BSG01018 | E72: 1 | F72: NCC100186 | G72: CÔNG TY TNHH NÔNG SẢN THỰC PHẨM TRẦN GIA | H72: BSG01 - Nhập hàng mua ngày 02/01/2026 | I72: =TEXT(A72,"dd/mm/yyyy")&J72 -> 02/01/2026NL300002 | J72: NL300002 | K72: Bánh phở | L72: kg | M72: 0 | O72: 0 | P72: =M72*N72 -> 0 | Q72: 0 | R72: 16000 | S72: BSG.01 | T72: 3311 | V72: BSG01 | X72: MINHDL | Y72: PHATLT
A73: 46024 | B73: HD | C73: 2601BSG01007 | E73: 1 | F73: NCC100186 | G73: CÔNG TY TNHH NÔNG SẢN THỰC PHẨM TRẦN GIA | H73: BSG01 - Nhập hàng mua ngày 02/01/2026 | I73: =TEXT(A73,"dd/mm/yyyy")&J73 -> 02/01/2026NL300003 | J73: NL300003 | K73: Bắp cải tím | L73: kg | M73: 2 | N73: =VLOOKUP(J73,[2]Sheet1!$I:$M,5,0) -> 26000 | O73: 0 | P73: =M73*N73 -> 52000 | Q73: 0 | R73: 26000 | S73: BSG.01 | T73: 3311 | V73: BSG01 | X73: MINHDL | Y73: PHATLT
A74: 46024 | B74: HD | C74: 2601BSG01007 | E74: 1 | F74: NCC100186 | G74: CÔNG TY TNHH NÔNG SẢN THỰC PHẨM TRẦN GIA | H74: BSG01 - Nhập hàng mua ngày 02/01/2026 | I74: =TEXT(A74,"dd/mm/yyyy")&J74 -> 02/01/2026NL300004 | J74: NL300004 | K74: Bắp cải trắng | L74: kg | M74: 2.9 | N74: =VLOOKUP(J74,[2]Sheet1!$I:$M,5,0) -> 19000 | O74: 0 | P74: =M74*N74 -> 55100 | Q74: 0 | R74: 19000 | S74: BSG.01 | T74: 3311 | V74: BSG01 | X74: MINHDL | Y74: PHATLT
A75: 46024 | B75: HD | C75: 2601BSG01007 | E75: 1 | F75: NCC100186 | G75: CÔNG TY TNHH NÔNG SẢN THỰC PHẨM TRẦN GIA | H75: BSG01 - Nhập hàng mua ngày 02/01/2026 | I75: =TEXT(A75,"dd/mm/yyyy")&J75 -> 02/01/2026NL300174 | J75: NL300174 | K75: Bầu | L75: kg | M75: 7 | N75: =VLOOKUP(J75,[2]Sheet1!$I:$M,5,0) -> 24000 | O75: 0 | P75: =M75*N75 -> 168000 | Q75: 0 | R75: 24000 | S75: BSG.01 | T75: 3311 | V75: BSG01 | X75: MINHDL | Y75: PHATLT
A76: 46024 | B76: HD | C76: 2601BSG01.01 | E76: 1 | F76: NCC100186 | G76: CÔNG TY TNHH NÔNG SẢN THỰC PHẨM TRẦN GIA | H76: BSG01 - Nhập hàng mua ngày 02/01/2026 | I76: =TEXT(A76,"dd/mm/yyyy")&J76 -> 02/01/2026NL300008 | J76: NL300008 | K76: Bí ngòi | L76: kg | M76: 1 | N76: =VLOOKUP(J76,[2]Sheet1!$I:$M,5,0) -> 40000 | O76: 0 | P76: =M76*N76 -> 40000 | Q76: 0 | R76: 40000 | S76: BSG.01 | T76: 3311 | V76: BSG01 | X76: PHATLT | Y76: PHATLT
A77: 46024 | B77: HD | C77: 2601BSG01007 | E77: 1 | F77: NCC100186 | G77: CÔNG TY TNHH NÔNG SẢN THỰC PHẨM TRẦN GIA | H77: BSG01 - Nhập hàng mua ngày 02/01/2026 | I77: =TEXT(A77,"dd/mm/yyyy")&J77 -> 02/01/2026NL300013 | J77: NL300013 | K77: Cà chua | L77: kg | M77: 6 | N77: =VLOOKUP(J77,[2]Sheet1!$I:$M,5,0) -> 50000 | O77: 0 | P77: =M77*N77 -> 300000 | Q77: 0 | R77: 50000 | S77: BSG.01 | T77: 3311 | V77: BSG01 | X77: MINHDL | Y77: PHATLT
A78: 46024 | B78: HD | C78: 2601BSG01007 | E78: 1 | F78: NCC100186 | G78: CÔNG TY TNHH NÔNG SẢN THỰC PHẨM TRẦN GIA | H78: BSG01 - Nhập hàng mua ngày 02/01/2026 | I78: =TEXT(A78,"dd/mm/yyyy")&J78 -> 02/01/2026NL300014 | J78: NL300014 | K78: Cà chua bi | L78: kg | M78: 1 | N78: =VLOOKUP(J78,[2]Sheet1!$I:$M,5,0) -> 55000 | O78: 0 | P78: =M78*N78 -> 55000 | Q78: 0 | R78: 55000 | S78: BSG.01 | T78: 3311 | V78: BSG01 | X78: MINHDL | Y78: PHATLT
A79: 46024 | B79: HD | C79: 2601BSG01007 | E79: 1 | F79: NCC100186 | G79: CÔNG TY TNHH NÔNG SẢN THỰC PHẨM TRẦN GIA | H79: BSG01 - Nhập hàng mua ngày 02/01/2026 | I79: =TEXT(A79,"dd/mm/yyyy")&J79 -> 02/01/2026NL300027 | J79: NL300027 | K79: Cà rốt | L79: kg | M79: 7 | N79: =VLOOKUP(J79,[2]Sheet1!$I:$M,5,0) -> 18000 | O79: 0 | P79: =M79*N79 -> 126000 | Q79: 0 | R79: 18000 | S79: BSG.01 | T79: 3311 | V79: BSG01 | X79: MINHDL | Y79: PHATLT
A80: 46024 | B80: HD | C80: 2601BSG01.01 | E80: 1 | F80: NCC100186 | G80: CÔNG TY TNHH NÔNG SẢN THỰC PHẨM TRẦN GIA | H80: BSG01 - Nhập hàng mua ngày 02/01/2026 | I80: =TEXT(A80,"dd/mm/yyyy")&J80 -> 02/01/2026NL300233 | J80: NL300233 | K80: Cà Tím | L80: kg | M80: 1.15 | N80: =VLOOKUP(J80,[2]Sheet1!$I:$M,5,0) -> 33000 | O80: 0 | P80: =M80*N80 -> 37950 | Q80: 0 | R80: 33000 | S80: BSG.01 | T80: 3311 | V80: BSG01 | X80: PHATLT | Y80: PHATLT
A81: 46024 | B81: HD | C81: 2601BSG01007 | E81: 1 | F81: NCC100186 | G81: CÔNG TY TNHH NÔNG SẢN THỰC PHẨM TRẦN GIA | H81: BSG01 - Nhập hàng mua ngày 02/01/2026 | I81: =TEXT(A81,"dd/mm/yyyy")&J81 -> 02/01/2026NL410018 | J81: NL410018 | K81: Cá tra NV ( Cá basa NV ) | L81: kg | M81: 2.9 | N81: =VLOOKUP(J81,[2]Sheet1!$I:$M,5,0) -> 82000 | O81: 0 | P81: =M81*N81 -> 237800 | Q81: 0 | R81: 82000 | S81: BSG.01 | T81: 3311 | V81: BSG01 | X81: MINHDL | Y81: PHATLT
A82: 46024 | B82: HD | C82: 2601BSG01007 | E82: 1 | F82: NCC100186 | G82: CÔNG TY TNHH NÔNG SẢN THỰC PHẨM TRẦN GIA | H82: BSG01 - Nhập hàng mua ngày 02/01/2026 | I82: =TEXT(A82,"dd/mm/yyyy")&J82 -> 02/01/2026NL300203 | J82: NL300203 | K82: Cải bó xôi | L82: kg | M82: 4 | N82: =VLOOKUP(J82,[2]Sheet1!$I:$M,5,0) -> 45000 | O82: 0 | P82: =M82*N82 -> 180000 | Q82: 0 | R82: 45000 | S82: BSG.01 | T82: 3311 | V82: BSG01 | X82: MINHDL | Y82: PHATLT
A83: 46024 | B83: HD | C83: 2601BSG01.01 | E83: 1 | F83: NCC100186 | G83: CÔNG TY TNHH NÔNG SẢN THỰC PHẨM TRẦN GIA | H83: BSG01 - Nhập hàng mua ngày 02/01/2026 | I83: =TEXT(A83,"dd/mm/yyyy")&J83 -> 02/01/2026NL300022 | J83: NL300022 | K83: Cải thảo | L83: kg | M83: 1.2 | N83: =VLOOKUP(J83,[2]Sheet1!$I:$M,5,0) -> 18000 | O83: 0 | P83: =M83*N83 -> 21600 | Q83: 0 | R83: 18000 | S83: BSG.01 | T83: 3311 | V83: BSG01 | X83: PHATLT | Y83: PHATLT
A84: 46024 | B84: HD | C84: 2601BSG01007 | E84: 1 | F84: NCC100186 | G84: CÔNG TY TNHH NÔNG SẢN THỰC PHẨM TRẦN GIA | H84: BSG01 - Nhập hàng mua ngày 02/01/2026 | I84: =TEXT(A84,"dd/mm/yyyy")&J84 -> 02/01/2026NL430021 | J84: NL430021 | K84: Cải xanh NV | L84: kg | M84: 2 | N84: =VLOOKUP(J84,[2]Sheet1!$I:$M,5,0) -> 28000 | O84: 0 | P84: =M84*N84 -> 56000 | Q84: 0 | R84: 28000 | S84: BSG.01 | T84: 3311 | V84: BSG01 | X84: MINHDL | Y84: PHATLT
... A145: 46024 | B145: HD | C145: 2601BSG01007 | E145: 1 | F145: NCC100186 | G145: CÔNG TY TNHH NÔNG SẢN THỰC PHẨM TRẦN GIA | H145: BSG01 - Nhập hàng mua ngày 02/01/2026 | I145: =TEXT(A145,"dd/mm/yyyy")&J145 -> 02/01/2026NL300144 | J145: NL300144 | K145: Tỏi ta | L145: kg | M145: 0.2 | N145: =VLOOKUP(J145,[2]Sheet1!$I:$M,5,0) -> 90000 | O145: 0 | P145: =M145*N145 -> 18000 | Q145: 0 | R145: 90000 | S145: BSG.01 | T145: 3311 | V145: BSG01 | X145: MINHDL | Y145: PHATLT
A146: 46024 | B146: HD | C146: 2601BSG01018 | E146: 1 | F146: NCC100186 | G146: CÔNG TY TNHH NÔNG SẢN THỰC PHẨM TRẦN GIA | H146: BSG01 - Nhập hàng mua ngày 02/01/2026 | I146: =TEXT(A146,"dd/mm/yyyy")&J146 -> 02/01/2026NL100100 | J146: NL100100 | K146: Trứng gà | L146: quả | M146: 0 | O146: 0 | P146: =M146*N146 -> 0 | Q146: 0 | R146: 3500 | S146: BSG.01 | T146: 3311 | V146: BSG01 | X146: MINHDL | Y146: PHATLT
A147: 46024 | B147: HD | C147: 2601BSG01007 | E147: 1 | F147: NCC100186 | G147: CÔNG TY TNHH NÔNG SẢN THỰC PHẨM TRẦN GIA | H147: BSG01 - Nhập hàng mua ngày 02/01/2026 | I147: =TEXT(A147,"dd/mm/yyyy")&J147 -> 02/01/2026NL300145 | J147: NL300145 | K147: Xà lách | L147: kg | M147: 15 | N147: =VLOOKUP(J147,[2]Sheet1!$I:$M,5,0) -> 38000 | O147: 0 | P147: =M147*N147 -> 570000 | Q147: 0 | R147: 38000 | S147: BSG.01 | T147: 3311 | V147: BSG01 | X147: MINHDL | Y147: PHATLT
A148: 46025 | B148: HD | C148: 2601BSG01011 | E148: 1 | F148: NCC100186 | G148: CÔNG TY TNHH NÔNG SẢN THỰC PHẨM TRẦN GIA | H148: BSG01 - Nhập hàng mua ngày 03/01/2026 | I148: =TEXT(A148,"dd/mm/yyyy")&J148 -> 03/01/2026NL300174 | J148: NL300174 | K148: Bầu | L148: kg | M148: 3.8 | N148: =VLOOKUP(J148,[2]Sheet1!$I:$M,5,0) -> 24000 | O148: 0 | P148: =M148*N148 -> 91200 | Q148: 0 | R148: 24000 | S148: BSG.01 | T148: 3311 | V148: BSG01 | X148: MINHDL | Y148: PHATLT
A149: 46025 | B149: HD | C149: 2601BSG01011 | E149: 1 | F149: NCC100186 | G149: CÔNG TY TNHH NÔNG SẢN THỰC PHẨM TRẦN GIA | H149: BSG01 - Nhập hàng mua ngày 03/01/2026 | I149: =TEXT(A149,"dd/mm/yyyy")&J149 -> 03/01/2026NL300003 | J149: NL300003 | K149: Bắp cải tím | L149: kg | M149: 0.7 | N149: =VLOOKUP(J149,[2]Sheet1!$I:$M,5,0) -> 26000 | O149: 0 | P149: =M149*N149 -> 18200 | Q149: 0 | R149: 26000 | S149: BSG.01 | T149: 3311 | V149: BSG01 | X149: MINHDL | Y149: PHATLT
A150: 46025 | B150: HD | C150: 2601BSG01011 | E150: 1 | F150: NCC100186 | G150: CÔNG TY TNHH NÔNG SẢN THỰC PHẨM TRẦN GIA | H150: BSG01 - Nhập hàng mua ngày 03/01/2026 | I150: =TEXT(A150,"dd/mm/yyyy")&J150 -> 03/01/2026NL300004 | J150: NL300004 | K150: Bắp cải trắng | L150: kg | M150: 1.9 | N150: =VLOOKUP(J150,[2]Sheet1!$I:$M,5,0) -> 19000 | O150: 0 | P150: =M150*N150 -> 36100 | Q150: 0 | R150: 19000 | S150: BSG.01 | T150: 3311 | V150: BSG01 | X150: MINHDL | Y150: PHATLT
A151: 46025 | B151: HD | C151: 2601BSG01011 | E151: 1 | F151: NCC100186 | G151: CÔNG TY TNHH NÔNG SẢN THỰC PHẨM TRẦN GIA | H151: BSG01 - Nhập hàng mua ngày 03/01/2026 | I151: =TEXT(A151,"dd/mm/yyyy")&J151 -> 03/01/2026NL300011 | J151: NL300011 | K151: Bông súng | L151: kg | M151: 0.5 | N151: =VLOOKUP(J151,[2]Sheet1!$I:$M,5,0) -> 17000 | O151: 0 | P151: =M151*N151 -> 8500 | Q151: 0 | R151: 17000 | S151: BSG.01 | T151: 3311 | V151: BSG01 | X151: MINHDL | Y151: PHATLT
A152: 46025 | B152: HD | C152: 2601BSG01011 | E152: 1 | F152: NCC100186 | G152: CÔNG TY TNHH NÔNG SẢN THỰC PHẨM TRẦN GIA | H152: BSG01 - Nhập hàng mua ngày 03/01/2026 | I152: =TEXT(A152,"dd/mm/yyyy")&J152 -> 03/01/2026NL300013 | J152: NL300013 | K152: Cà chua | L152: kg | M152: 3 | N152: =VLOOKUP(J152,[2]Sheet1!$I:$M,5,0) -> 50000 | O152: 0 | P152: =M152*N152 -> 150000 | Q152: 0 | R152: 50000 | S152: BSG.01 | T152: 3311 | V152: BSG01 | X152: MINHDL | Y152: PHATLT
A153: 46025 | B153: HD | C153: 2601BSG01011 | E153: 1 | F153: NCC100186 | G153: CÔNG TY TNHH NÔNG SẢN THỰC PHẨM TRẦN GIA | H153: BSG01 - Nhập hàng mua ngày 03/01/2026 | I153: =TEXT(A153,"dd/mm/yyyy")&J153 -> 03/01/2026NL300014 | J153: NL300014 | K153: Cà chua bi | L153: kg | M153: 1 | N153: =VLOOKUP(J153,[2]Sheet1!$I:$M,5,0) -> 55000 | O153: 0 | P153: =M153*N153 -> 55000 | Q153: 0 | R153: 55000 | S153: BSG.01 | T153: 3311 | V153: BSG01 | X153: MINHDL | Y153: PHATLT
...

Sheet Q3
D2: CÔNG TY TNHH NÔNG SẢN THỰC PHẨM TRẦN GIA HTX: Ấp Lộc Tiến, Xã Mỹ Lộc, Huyện Cần Giuộc, Tỉnh Long An VP: Tòa nhà An Phú Plaza, 117-119 Lý Chính Thắng, P.7. Q.3, TP.HCM Kho sơ chế: 30 Kha Vạn Cân, P. Hiệp Bình Chánh, TP.Thủ Đức, TP.HCM Kho Đà Lạt: 69 Trần Thủ Độ, TT Liên Nghĩa, Huyện Đức Trọng, Tỉnh Lâm Đồng. Website: rausachtrangia.com - Hotline: 090.245.8081
A4: CHI TIẾT ĐỐI CHIẾU CÔNG NỢ
A6: Từ ngày 1 tháng 01 đến ngày 15 tháng 01 năm 2026
A8: Tên Khách hàng: BÒ TƠ Q3
A10: Địa chỉ:
A12: Người liên hệ: Email:
J13: =SUBTOTAL(9,J15:J767) -> 58579700 | N13: =SUBTOTAL(9,N15:N987) -> 2224.95 | O13: =N13-Sheet5!M5 -> 0 | Q13: =SUBTOTAL(9,Q15:Q987) -> 49032800 | R13: =Q13-Sheet5!P5 -> 0
A14: NGÀY | B14: MÃ KHÁCH HÀNG | C14: TÊN KHÁCH HÀNG | D14: MÃ ĐƠN HÀNG | E14: MÃ HÀNG | F14: TÊN HÀNG | G14: ĐVT | H14: SỐ LƯỢNG | I14: ĐƠN GIÁ | J14: THÀNH TIỀN | K14: GHI CHÚ | N14: Thực nhận | O14: lệch | P14: Giá chốt | Q14: Tổng | R14: Lệch
A15: 01/01/2026 | B15: TG-KS00058 | C15: BÒ TƠ Q3 | D15: TG-AA20658 | E15: I100002 | F15: Bắp cải tím | G15: Kg | H15: 1 | I15: 26000 | J15: =I15*H15 -> 26000 | L15: =VLOOKUP(F15,[1]Sheet1!$D:$J,7,0) -> NL300003 | M15: =A15&L15 -> 01/01/2026NL300003 | N15: =VLOOKUP(M15,Sheet5!I:P,5,0) -> 1 | O15: =H15-N15 -> 0 | P15: =VLOOKUP(L15,[2]Sheet1!$I:$M,5,0) -> 26000 | Q15: =N15*P15 -> 26000 | R15: =J15-Q15 -> 0
A16: 01/01/2026 | B16: TG-KS00058 | C16: BÒ TƠ Q3 | D16: TG-AA20658 | E16: I100003 | F16: Bắp cải trắng | G16: Kg | H16: 2 | I16: 19000 | J16: =I16*H16 -> 38000 | L16: =VLOOKUP(F16,[1]Sheet1!$D:$J,7,0) -> NL300004 | M16: =A16&L16 -> 01/01/2026NL300004 | N16: =VLOOKUP(M16,Sheet5!I:P,5,0) -> 2 | O16: =H16-N16 -> 0 | P16: =VLOOKUP(L16,[2]Sheet1!$I:$M,5,0) -> 19000 | Q16: =N16*P16 -> 38000 | R16: =J16-Q16 -> 0
A17: 01/01/2026 | B17: TG-KS00058 | C17: BÒ TƠ Q3 | D17: TG-AA20658 | E17: I100004 | F17: Bắp chuối bào | G17: Kg | H17: 0.6 | I17: 33000 | J17: =I17*H17 -> 19800 | L17: =VLOOKUP(F17,[1]Sheet1!$D:$J,7,0) -> NL300060 | M17: =A17&L17 -> 01/01/2026NL300060 | N17: =VLOOKUP(M17,Sheet5!I:P,5,0) -> 0.6 | O17: =H17-N17 -> 0 | P17: =VLOOKUP(L17,[2]Sheet1!$I:$M,5,0) -> 33000 | Q17: =N17*P17 -> 19800 | R17: =J17-Q17 -> 0
A18: 01/01/2026 | B18: TG-KS00058 | C18: BÒ TƠ Q3 | D18: TG-AA20658 | E18: I100008 | F18: Bắp mỹ trái (Loại 1) | G18: Trái | H18: 6 | I18: 8500 | J18: =I18*H18 -> 51000 | L18: =VLOOKUP(F18,[1]Sheet1!$D:$J,7,0) -> NL300107 | M18: =A18&L18 -> 01/01/2026NL300107 | N18: =VLOOKUP(M18,Sheet5!I:P,5,0) -> 6 | O18: =H18-N18 -> 0 | P18: =VLOOKUP(L18,[2]Sheet1!$I:$M,5,0) -> 8500 | Q18: =N18*P18 -> 51000 | R18: =J18-Q18 -> 0
