Workbook

Sheet LW13
E2: CÔNG TY TNHH NÔNG SẢN THỰC PHẨM TRẦN GIA HTX: Ấp Lộc Tiến, Xã Mỹ Lộc, Huyện Cần Giuộc, Tỉnh Long An VP: Tòa nhà An Phú Plaza, 117-119 Lý Chính Thắng, P.7. Q.3, TP.HCM Kho sơ chế: 30 Kha Vạn Cân, P. Hiệp Bình Chánh, TP.Thủ Đức, TP.HCM Kho Đà Lạt: 69 Trần Thủ Độ, TT Liên Nghĩa, Huyện Đức Trọng, Tỉnh Lâm Đồng. Website: rausachtrangia.com - Hotline: 090.245.8081
B4: CHI TIẾT ĐỐI CHIẾU CÔNG NỢ
B8: Tên Khách hàng: LONGWANG 18 | X8: sheet fast | Y8: =FAST!M5 -> 2023.16 | AA8: =FAST!P5 -> 49683590
B10: Địa chỉ: Land Mark 81 | X10: lệch sheet fast | Y10: =Y12-Y8 -> 0 | AA10: =AA12-AA8 -> 0 | AB10: lệch SL với ncc | AD10: lệch TT với ncc
B12: Người liên hệ: Email: | X12: sum vlookup | Y12: =SUBTOTAL(9,Y13:Y482) -> 2023.16 | AA12: =SUBTOTAL(9,AA13:AA800) -> 49683590 | AB12: =SUBTOTAL(9,AB13:AB1001) -> -107.2 | AD12: =SUBTOTAL(9,AD13:AD5001) -> -2932400
L13: =SUBTOTAL(9,L15:L5000) -> 2130.36 | N13: =SUBTOTAL(9,N15:N5001) -> 52615990
B14: MÃ ĐƠN HÀNG | C14: NGÀY | D14: MÃ KH | E14: TÊN KH | F14: Line ID | G14: Barcode | H14: MÃ KHO | I14: MÃ HÀNG | J14: TÊN HÀNG | K14: ĐVT | L14: SL | M14: ĐƠN GIÁ | N14: THÀNH TIỀN | P14: GHI CHÚ | Q14: Booklet No | R14: Custom5 | S14: Price List Id | T14: Doc Type | Y14: Thực nhận | Z14: đơn giá | AA14: thành tiền | AB14: lệch số lượng | AC14: lệch đơn giá | AD14: lệch tổng tiền
C15: 01/01/2026 | D15: TG-KS00392 | E15: LONGWANG 7 | F15: TG-AA12453 | G15: I100253 | H15: Bánh ướt | I15: Kg | J15: Bánh ướt | K15: Kg | L15: 1.5 | M15: 15000 | N15: 22500 | Q15: SOTG00110145428 | T15: AdjDO | U15: =VLOOKUP(J15,Sheet1!$A$2:$D$200,4,0) -> NL300189 | V15: =VLOOKUP(U15,Sheet1!$D$2:$E$200,2,0) -> Bánh ướt | W15: =DAY(C15)&MONTH(C15)&U15 -> 11NL300189 | X15: =COUNTIF($R$15:W15,W15)&W15 -> 111NL300189 | Y15: =IFERROR(VLOOKUP(X15,FAST!$B$7:$M$9722,12,0),"0") -> 1.5 | Z15: =IFERROR(VLOOKUP(X15,FAST!$B$7:$N$9722,13,0),"0") -> 15000 | AA15: =Y15*Z15 -> 22500 | AB15: =Y15-L15 -> 0 | AC15: =Z15-M15 -> 0 | AD15: =AA15-N15 -> 0
C16: 01/01/2026 | D16: TG-KS00392 | E16: LONGWANG 7 | F16: TG-AA12453 | G16: I100003 | H16: Bắp cải trắng | I16: Kg | J16: Bắp cải trắng | K16: Kg | L16: 1.5 | M16: 19000 | N16: 28500 | Q16: SOTG00110145428 | T16: AdjDO | U16: =VLOOKUP(J16,Sheet1!$A$2:$D$200,4,0) -> NL300004 | V16: =VLOOKUP(U16,Sheet1!$D$2:$E$200,2,0) -> Bắp cải trắng | W16: =DAY(C16)&MONTH(C16)&U16 -> 11NL300004 | X16: =COUNTIF($R$15:W16,W16)&W16 -> 111NL300004 | Y16: =IFERROR(VLOOKUP(X16,FAST!$B$7:$M$9722,12,0),"0") -> 1.5 | Z16: =IFERROR(VLOOKUP(X16,FAST!$B$7:$N$9722,13,0),"0") -> 19000 | AA16: =Y16*Z16 -> 28500 | AB16: =Y16-L16 -> 0 | AC16: =Z16-M16 -> 0 | AD16: =AA16-N16 -> 0
C17: 01/01/2026 | D17: TG-KS00392 | E17: LONGWANG 7 | F17: TG-AA12453 | G17: I100008 | H17: Bắp mỹ trái (Loại 1) | I17: Trái | J17: Bắp mỹ trái (Loại 1) | K17: Trái | L17: 20 | M17: 8500 | N17: 170000 | Q17: SOTG00110145428 | T17: AdjDO | U17: =VLOOKUP(J17,Sheet1!$A$2:$D$200,4,0) -> NL300107 | V17: =VLOOKUP(U17,Sheet1!$D$2:$E$200,2,0) -> Ngô ngọt ( Bắp trái) | W17: =DAY(C17)&MONTH(C17)&U17 -> 11NL300107 | X17: =COUNTIF($R$15:W17,W17)&W17 -> 111NL300107 | Y17: =IFERROR(VLOOKUP(X17,FAST!$B$7:$M$9722,12,0),"0") -> 20 | Z17: =IFERROR(VLOOKUP(X17,FAST!$B$7:$N$9722,13,0),"0") -> 8500 | AA17: =Y17*Z17 -> 170000 | AB17: =Y17-L17 -> 0 | AC17: =Z17-M17 -> 0 | AD17: =AA17-N17 -> 0
C18: 01/01/2026 | D18: TG-KS00392 | E18: LONGWANG 7 | F18: TG-AA12453 | G18: I100012 | H18: Bí đỏ hồ lô | I18: Kg | J18: Bí đỏ hồ lô | K18: Kg | L18: 4 | M18: 30000 | N18: 120000 | Q18: SOTG00110145428 | T18: AdjDO | U18: =VLOOKUP(J18,Sheet1!$A$2:$D$200,4,0) -> NL300007 | V18: =VLOOKUP(U18,Sheet1!$D$2:$E$200,2,0) -> Bí đỏ | W18: =DAY(C18)&MONTH(C18)&U18 -> 11NL300007 | X18: =COUNTIF($R$15:W18,W18)&W18 -> 111NL300007 | Y18: =IFERROR(VLOOKUP(X18,FAST!$B$7:$M$9722,12,0),"0") -> 4 | Z18: =IFERROR(VLOOKUP(X18,FAST!$B$7:$N$9722,13,0),"0") -> 30000 | AA18: =Y18*Z18 -> 120000 | AB18: =Y18-L18 -> 0 | AC18: =Z18-M18 -> 0 | AD18: =AA18-N18 -> 0
C19: 01/01/2026 | D19: TG-KS00392 | E19: LONGWANG 7 | F19: TG-AA12453 | G19: I100016 | H19: Bí ngòi xanh | I19: Kg | J19: Bí ngòi xanh | K19: Kg | L19: 15 | M19: 40000 | N19: 600000 | Q19: SOTG00110145428 | T19: AdjDO | U19: =VLOOKUP(J19,Sheet1!$A$2:$D$200,4,0) -> NL300008 | V19: =VLOOKUP(U19,Sheet1!$D$2:$E$200,2,0) -> Bí ngòi | W19: =DAY(C19)&MONTH(C19)&U19 -> 11NL300008 | X19: =COUNTIF($R$15:W19,W19)&W19 -> 111NL300008 | Y19: =IFERROR(VLOOKUP(X19,FAST!$B$7:$M$9722,12,0),"0") -> 15 | Z19: =IFERROR(VLOOKUP(X19,FAST!$B$7:$N$9722,13,0),"0") -> 40000 | AA19: =Y19*Z19 -> 600000 | AB19: =Y19-L19 -> 0 | AC19: =Z19-M19 -> 0 | AD19: =AA19-N19 -> 0
C20: 01/01/2026 | D20: TG-KS00392 | E20: LONGWANG 7 | F20: TG-AA12453 | G20: I100024 | H20: Bông cải xanh | I20: Kg | J20: Bông cải xanh | K20: Kg | L20: 6.5 | M20: 52000 | N20: 338000 | Q20: SOTG00110145428 | T20: AdjDO | U20: =VLOOKUP(J20,Sheet1!$A$2:$D$200,4,0) -> NL300137 | V20: =VLOOKUP(U20,Sheet1!$D$2:$E$200,2,0) -> Súp lơ xanh | W20: =DAY(C20)&MONTH(C20)&U20 -> 11NL300137 | X20: =COUNTIF($R$15:W20,W20)&W20 -> 111NL300137 | Y20: =IFERROR(VLOOKUP(X20,FAST!$B$7:$M$9722,12,0),"0") -> 6.5 | Z20: =IFERROR(VLOOKUP(X20,FAST!$B$7:$N$9722,13,0),"0") -> 52000 | AA20: =Y20*Z20 -> 338000 | AB20: =Y20-L20 -> 0 | AC20: =Z20-M20 -> 0 | AD20: =AA20-N20 -> 0
C21: 01/01/2026 | D21: TG-KS00392 | E21: LONGWANG 7 | F21: TG-AA12453 | G21: I100040 | H21: Cà rốt baby | I21: Kg | J21: Cà rốt baby | K21: Kg | L21: 0.3 | M21: 75000 | N21: 22500 | Q21: SOTG00110145428 | T21: AdjDO | U21: =VLOOKUP(J21,Sheet1!$A$2:$D$200,4,0) -> NL300028 | V21: =VLOOKUP(U21,Sheet1!$D$2:$E$200,2,0) -> Cà rốt baby | W21: =DAY(C21)&MONTH(C21)&U21 -> 11NL300028 | X21: =COUNTIF($R$15:W21,W21)&W21 -> 111NL300028 | Y21: =IFERROR(VLOOKUP(X21,FAST!$B$7:$M$9722,12,0),"0") -> 0.3 | Z21: =IFERROR(VLOOKUP(X21,FAST!$B$7:$N$9722,13,0),"0") -> 75000 | AA21: =Y21*Z21 -> 22500 | AB21: =Y21-L21 -> 0 | AC21: =Z21-M21 -> 0 | AD21: =AA21-N21 -> 0
C22: 01/01/2026 | D22: TG-KS00392 | E22: LONGWANG 7 | F22: TG-AA12453 | G22: I100045 | H22: Cải Hongkong(Cai ngong) | I22: Kg | J22: Cải Hongkong(Cai ngong) | K22: Kg | L22: 1.5 | M22: 30000 | N22: 45000 | Q22: SOTG00110145428 | T22: AdjDO | U22: =VLOOKUP(J22,Sheet1!$A$2:$D$200,4,0) -> NL300020 | V22: =VLOOKUP(U22,Sheet1!$D$2:$E$200,2,0) -> Cải ngồng | W22: =DAY(C22)&MONTH(C22)&U22 -> 11NL300020 | X22: =COUNTIF($R$15:W22,W22)&W22 -> 111NL300020 | Y22: =IFERROR(VLOOKUP(X22,FAST!$B$7:$M$9722,12,0),"0") -> 1.5 | Z22: =IFERROR(VLOOKUP(X22,FAST!$B$7:$N$9722,13,0),"0") -> 30000 | AA22: =Y22*Z22 -> 45000 | AB22: =Y22-L22 -> 0 | AC22: =Z22-M22 -> 0 | AD22: =AA22-N22 -> 0
C23: 01/01/2026 | D23: TG-KS00392 | E23: LONGWANG 7 | F23: TG-AA12453 | G23: I100057 | H23: Cần tây | I23: Kg | J23: Cần tây | K23: Kg | L23: 1 | M23: 44000 | N23: 44000 | Q23: SOTG00110145428 | T23: AdjDO | U23: =VLOOKUP(J23,Sheet1!$A$2:$D$200,4,0) -> NL300025 | V23: =VLOOKUP(U23,Sheet1!$D$2:$E$200,2,0) -> Rau cần tây | W23: =DAY(C23)&MONTH(C23)&U23 -> 11NL300025 | X23: =COUNTIF($R$15:W23,W23)&W23 -> 111NL300025 | Y23: =IFERROR(VLOOKUP(X23,FAST!$B$7:$M$9722,12,0),"0") -> 1 | Z23: =IFERROR(VLOOKUP(X23,FAST!$B$7:$N$9722,13,0),"0") -> 44000 | AA23: =Y23*Z23 -> 44000 | AB23: =Y23-L23 -> 0 | AC23: =Z23-M23 -> 0 | AD23: =AA23-N23 -> 0
C24: 01/01/2026 | D24: TG-KS00392 | E24: LONGWANG 7 | F24: TG-AA12453 | G24: I100060 | H24: Chanh không hạt | I24: Kg | J24: Chanh không hạt | K24: Kg | L24: 3 | M24: 22000 | N24: 66000 | Q24: SOTG00110145428 | T24: AdjDO | U24: =VLOOKUP(J24,Sheet1!$A$2:$D$200,4,0) -> NL300029 | V24: =VLOOKUP(U24,Sheet1!$D$2:$E$200,2,0) -> Chanh | W24: =DAY(C24)&MONTH(C24)&U24 -> 11NL300029 | X24: =COUNTIF($R$15:W24,W24)&W24 -> 111NL300029 | Y24: =IFERROR(VLOOKUP(X24,FAST!$B$7:$M$9722,12,0),"0") -> 3 | Z24: =IFERROR(VLOOKUP(X24,FAST!$B$7:$N$9722,13,0),"0") -> 22000 | AA24: =Y24*Z24 -> 66000 | AB24: =Y24-L24 -> 0 | AC24: =Z24-M24 -> 0 | AD24: =AA24-N24 -> 0
C25: 01/01/2026 | D25: TG-KS00392 | E25: LONGWANG 7 | F25: TG-AA12453 | G25: I100097 | H25: Củ Gừng | I25: Kg | J25: Củ Gừng | K25: Kg | L25: 2 | M25: 38000 | N25: 76000 | Q25: SOTG00110145428 | T25: AdjDO | U25: =VLOOKUP(J25,Sheet1!$A$2:$D$200,4,0) -> NL300054 | V25: =VLOOKUP(U25,Sheet1!$D$2:$E$200,2,0) -> Gừng tàu | W25: =DAY(C25)&MONTH(C25)&U25 -> 11NL300054 | X25: =COUNTIF($R$15:W25,W25)&W25 -> 111NL300054 | Y25: =IFERROR(VLOOKUP(X25,FAST!$B$7:$M$9722,12,0),"0") -> 2 | Z25: =IFERROR(VLOOKUP(X25,FAST!$B$7:$N$9722,13,0),"0") -> 38000 | AA25: =Y25*Z25 -> 76000 | AB25: =Y25-L25 -> 0 | AC25: =Z25-M25 -> 0 | AD25: =AA25-N25 -> 0
C26: 01/01/2026 | D26: TG-KS00392 | E26: LONGWANG 7 | F26: TG-AA12453 | G26: I100074 | H26: Củ sen | I26: Kg | J26: Củ sen | K26: Kg | L26: 0.7 | M26: 47000 | N26: 32900 | Q26: SOTG00110145428 | T26: AdjDO | U26: =VLOOKUP(J26,Sheet1!$A$2:$D$200,4,0) -> NL300036 | V26: =VLOOKUP(U26,Sheet1!$D$2:$E$200,2,0) -> Củ sen | W26: =DAY(C26)&MONTH(C26)&U26 -> 11NL300036 | X26: =COUNTIF($R$15:W26,W26)&W26 -> 111NL300036 | Y26: =IFERROR(VLOOKUP(X26,FAST!$B$7:$M$9722,12,0),"0") -> 0.7 | Z26: =IFERROR(VLOOKUP(X26,FAST!$B$7:$N$9722,13,0),"0") -> 47000 | AA26: =Y26*Z26 -> 32900 | AB26: =Y26-L26 -> 0 | AC26: =Z26-M26 -> 0 | AD26: =AA26-N26 -> 0
... C215: 07/01/2026 | D215: TG-KS00392 | E215: LONGWANG 7 | F215: TG-AA13632 | G215: I100060 | H215: Chanh không hạt | I215: Kg | J215: Ớt sừng đỏ | K215: Kg | L215: 0.2 | M215: 148000 | N215: 29600 | Q215: SOTG00110145428 | T215: AdjDO | U215: =VLOOKUP(J215,Sheet1!$A$2:$D$200,4,0) -> NL300116 | V215: =VLOOKUP(U215,Sheet1!$D$2:$E$200,2,0) -> Ớt sừng | W215: =DAY(C215)&MONTH(C215)&U215 -> 71NL300116 | X215: =COUNTIF($R$15:W215,W215)&W215 -> 171NL300116 | Y215: =IFERROR(VLOOKUP(X215,FAST!$B$7:$M$9722,12,0),"0") -> 0.2 | Z215: =IFERROR(VLOOKUP(X215,FAST!$B$7:$N$9722,13,0),"0") -> 148000 | AA215: =Y215*Z215 -> 29600 | AB215: =Y215-L215 -> 0 | AC215: =Z215-M215 -> 0 | AD215: =AA215-N215 -> 0
C216: 07/01/2026 | D216: TG-KS00392 | E216: LONGWANG 7 | J216: Rau tía tô | K216: Kg | L216: 0.1 | M216: 36000 | N216: 3600 | U216: =VLOOKUP(J216,Sheet1!$A$2:$D$200,4,0) -> NL300140 | V216: =VLOOKUP(U216,Sheet1!$D$2:$E$200,2,0) -> Tía tô | W216: =DAY(C216)&MONTH(C216)&U216 -> 71NL300140 | X216: =COUNTIF($R$15:W216,W216)&W216 -> 171NL300140 | Y216: =IFERROR(VLOOKUP(X216,FAST!$B$7:$M$9722,12,0),"0") -> 0.1 | Z216: =IFERROR(VLOOKUP(X216,FAST!$B$7:$N$9722,13,0),"0") -> 36000 | AA216: =Y216*Z216 -> 3600 | AB216: =Y216-L216 -> 0 | AC216: =Z216-M216 -> 0 | AD216: =AA216-N216 -> 0
C217: 07/01/2026 | D217: TG-KS00392 | E217: LONGWANG 7 | J217: Tắc trái | K217: Kg | L217: 0.8 | M217: 21000 | N217: 16800 | U217: =VLOOKUP(J217,Sheet1!$A$2:$D$200,4,0) -> NL300119 | V217: =VLOOKUP(U217,Sheet1!$D$2:$E$200,2,0) -> Quất ( Tắc trái ) | W217: =DAY(C217)&MONTH(C217)&U217 -> 71NL300119 | X217: =COUNTIF($R$15:W217,W217)&W217 -> 171NL300119 | Y217: =IFERROR(VLOOKUP(X217,FAST!$B$7:$M$9722,12,0),"0") -> 0.8 | Z217: =IFERROR(VLOOKUP(X217,FAST!$B$7:$N$9722,13,0),"0") -> 21000 | AA217: =Y217*Z217 -> 16800 | AB217: =Y217-L217 -> 0 | AC217: =Z217-M217 -> 0 | AD217: =AA217-N217 -> 0
C218: 07/01/2026 | D218: TG-KS00392 | E218: LONGWANG 7 | J218: Tiêu xanh Tươi | K218: Kg | L218: 0.1 | M218: 92000 | N218: 9200 | U218: =VLOOKUP(J218,Sheet1!$A$2:$D$200,4,0) -> NL300141 | V218: =VLOOKUP(U218,Sheet1!$D$2:$E$200,2,0) -> Tiêu xanh | W218: =DAY(C218)&MONTH(C218)&U218 -> 71NL300141 | X218: =COUNTIF($R$15:W218,W218)&W218 -> 171NL300141 | Y218: =IFERROR(VLOOKUP(X218,FAST!$B$7:$M$9722,12,0),"0") -> 0.1 | Z218: =IFERROR(VLOOKUP(X218,FAST!$B$7:$N$9722,13,0),"0") -> 92000 | AA218: =Y218*Z218 -> 9200 | AB218: =Y218-L218 -> 0 | AC218: =Z218-M218 -> 0 | AD218: =AA218-N218 -> 0
C219: 07/01/2026 | D219: TG-KS00392 | E219: LONGWANG 7 | J219: Trứng vịt muối | K219: Quả | L219: 35 | M219: 5000 | N219: 175000 | U219: =VLOOKUP(J219,Sheet1!$A$2:$D$200,4,0) -> NL100101 | V219: =VLOOKUP(U219,Sheet1!$D$2:$E$200,2,0) -> Trứng vịt muối | W219: =DAY(C219)&MONTH(C219)&U219 -> 71NL100101 | X219: =COUNTIF($R$15:W219,W219)&W219 -> 171NL100101 | Y219: =IFERROR(VLOOKUP(X219,FAST!$B$7:$M$9722,12,0),"0") -> 35 | Z219: =IFERROR(VLOOKUP(X219,FAST!$B$7:$N$9722,13,0),"0") -> 5000 | AA219: =Y219*Z219 -> 175000 | AB219: =Y219-L219 -> 0 | AC219: =Z219-M219 -> 0 | AD219: =AA219-N219 -> 0
C220: 07/01/2026 | D220: TG-KS00392 | E220: LONGWANG 7 | J220: Xà lách Rocket | K220: Kg | L220: 0.2 | M220: 220000 | N220: 44000 | U220: =VLOOKUP(J220,Sheet1!$A$2:$D$200,4,0) -> NL300131 | V220: =VLOOKUP(U220,Sheet1!$D$2:$E$200,2,0) -> Xà lách Rocket | W220: =DAY(C220)&MONTH(C220)&U220 -> 71NL300131 | X220: =COUNTIF($R$15:W220,W220)&W220 -> 171NL300131 | Y220: =IFERROR(VLOOKUP(X220,FAST!$B$7:$M$9722,12,0),"0") -> 0.2 | Z220: =IFERROR(VLOOKUP(X220,FAST!$B$7:$N$9722,13,0),"0") -> 220000 | AA220: =Y220*Z220 -> 44000 | AB220: =Y220-L220 -> 0 | AC220: =Z220-M220 -> 0 | AD220: =AA220-N220 -> 0
C221: 07/01/2026 | D221: TG-KS00392 | E221: LONGWANG 7 | J221: Xà lách romain | K221: Kg | L221: 1.5 | M221: 62000 | N221: 93000 | U221: =VLOOKUP(J221,Sheet1!$A$2:$D$200,4,0) -> NL300147 | V221: =VLOOKUP(U221,Sheet1!$D$2:$E$200,2,0) -> Xà lách Roman | W221: =DAY(C221)&MONTH(C221)&U221 -> 71NL300147 | X221: =COUNTIF($R$15:W221,W221)&W221 -> 171NL300147 | Y221: =IFERROR(VLOOKUP(X221,FAST!$B$7:$M$9722,12,0),"0") -> 1.5 | Z221: =IFERROR(VLOOKUP(X221,FAST!$B$7:$N$9722,13,0),"0") -> 62000 | AA221: =Y221*Z221 -> 93000 | AB221: =Y221-L221 -> 0 | AC221: =Z221-M221 -> 0 | AD221: =AA221-N221 -> 0
C222: 08/01/2026 | D222: TG-KS00392 | E222: LONGWANG 7 | J222: Bánh ướt | K222: Kg | L222: 1.5 | M222: 15000 | N222: 22500 | U222: =VLOOKUP(J222,Sheet1!$A$2:$D$200,4,0) -> NL300189 | V222: =VLOOKUP(U222,Sheet1!$D$2:$E$200,2,0) -> Bánh ướt | W222: =DAY(C222)&MONTH(C222)&U222 -> 81NL300189 | X222: =COUNTIF($R$15:W222,W222)&W222 -> 181NL300189 | Y222: =IFERROR(VLOOKUP(X222,FAST!$B$7:$M$9722,12,0),"0") -> 1.5 | Z222: =IFERROR(VLOOKUP(X222,FAST!$B$7:$N$9722,13,0),"0") -> 15000 | AA222: =Y222*Z222 -> 22500 | AB222: =Y222-L222 -> 0 | AC222: =Z222-M222 -> 0 | AD222: =AA222-N222 -> 0
C223: 08/01/2026 | D223: TG-KS00392 | E223: LONGWANG 7 | J223: Bắp cải trắng | K223: Kg | L223: 1 | M223: 19000 | N223: 19000 | U223: =VLOOKUP(J223,Sheet1!$A$2:$D$200,4,0) -> NL300004 | V223: =VLOOKUP(U223,Sheet1!$D$2:$E$200,2,0) -> Bắp cải trắng | W223: =DAY(C223)&MONTH(C223)&U223 -> 81NL300004 | X223: =COUNTIF($R$15:W223,W223)&W223 -> 181NL300004 | Y223: =IFERROR(VLOOKUP(X223,FAST!$B$7:$M$9722,12,0),"0") -> 1 | Z223: =IFERROR(VLOOKUP(X223,FAST!$B$7:$N$9722,13,0),"0") -> 19000 | AA223: =Y223*Z223 -> 19000 | AB223: =Y223-L223 -> 0 | AC223: =Z223-M223 -> 0 | AD223: =AA223-N223 -> 0
C224: 08/01/2026 | D224: TG-KS00392 | E224: LONGWANG 7 | J224: Bí ngòi xanh | K224: Kg | L224: 3.5 | M224: 40000 | N224: 140000 | U224: =VLOOKUP(J224,Sheet1!$A$2:$D$200,4,0) -> NL300008 | V224: =VLOOKUP(U224,Sheet1!$D$2:$E$200,2,0) -> Bí ngòi | W224: =DAY(C224)&MONTH(C224)&U224 -> 81NL300008 | X224: =COUNTIF($R$15:W224,W224)&W224 -> 181NL300008 | Y224: =IFERROR(VLOOKUP(X224,FAST!$B$7:$M$9722,12,0),"0") -> 3.5 | Z224: =IFERROR(VLOOKUP(X224,FAST!$B$7:$N$9722,13,0),"0") -> 40000 | AA224: =Y224*Z224 -> 140000 | AB224: =Y224-L224 -> 0 | AC224: =Z224-M224 -> 0 | AD224: =AA224-N224 -> 0
C225: 08/01/2026 | D225: TG-KS00392 | E225: LONGWANG 7 | J225: Bông cải xanh | K225: Kg | L225: 1.9 | M225: 52000 | N225: 98800 | U225: =VLOOKUP(J225,Sheet1!$A$2:$D$200,4,0) -> NL300137 | V225: =VLOOKUP(U225,Sheet1!$D$2:$E$200,2,0) -> Súp lơ xanh | W225: =DAY(C225)&MONTH(C225)&U225 -> 81NL300137 | X225: =COUNTIF($R$15:W225,W225)&W225 -> 181NL300137 | Y225: =IFERROR(VLOOKUP(X225,FAST!$B$7:$M$9722,12,0),"0") -> 1.9 | Z225: =IFERROR(VLOOKUP(X225,FAST!$B$7:$N$9722,13,0),"0") -> 52000 | AA225: =Y225*Z225 -> 98800 | AB225: =Y225-L225 -> 0 | AC225: =Z225-M225 -> 0 | AD225: =AA225-N225 -> 0
C226: 08/01/2026 | D226: TG-KS00392 | E226: LONGWANG 7 | J226: Cải Hongkong(Cai ngong) | K226: Kg | L226: 1.8 | M226: 30000 | N226: 54000 | U226: =VLOOKUP(J226,Sheet1!$A$2:$D$200,4,0) -> NL300020 | V226: =VLOOKUP(U226,Sheet1!$D$2:$E$200,2,0) -> Cải ngồng | W226: =DAY(C226)&MONTH(C226)&U226 -> 81NL300020 | X226: =COUNTIF($R$15:W226,W226)&W226 -> 181NL300020 | Y226: =IFERROR(VLOOKUP(X226,FAST!$B$7:$M$9722,12,0),"0") -> 1.8 | Z226: =IFERROR(VLOOKUP(X226,FAST!$B$7:$N$9722,13,0),"0") -> 30000 | AA226: =Y226*Z226 -> 54000 | AB226: =Y226-L226 -> 0 | AC226: =Z226-M226 -> 0 | AD226: =AA226-N226 -> 0
C227: 08/01/2026 | D227: TG-KS00392 | E227: LONGWANG 7 | J227: Cam vàng | K227: Kg | L227: 0.3 | M227: 75000 | N227: 22500 | U227: =VLOOKUP(J227,Sheet1!$A$2:$D$200,4,0) -> NL600067 | V227: =VLOOKUP(U227,Sheet1!$D$2:$E$200,2,0) -> Cam vàng | W227: =DAY(C227)&MONTH(C227)&U227 -> 81NL600067 | X227: =COUNTIF($R$15:W227,W227)&W227 -> 181NL600067 | Y227: =IFERROR(VLOOKUP(X227,FAST!$B$7:$M$9722,12,0),"0") -> 0.3 | Z227: =IFERROR(VLOOKUP(X227,FAST!$B$7:$N$9722,13,0),"0") -> 75000 | AA227: =Y227*Z227 -> 22500 | AB227: =Y227-L227 -> 0 | AC227: =Z227-M227 -> 0 | AD227: =AA227-N227 -> 0
... C460: 15/01/2026 | D460: TG-KS00392 | E460: LONGWANG 7 | J460: Xà lách romain | K460: Kg | L460: 2.5 | M460: 62000 | N460: 155000 | U460: =VLOOKUP(J460,Sheet1!$A$2:$D$200,4,0) -> NL300147 | V460: =VLOOKUP(U460,Sheet1!$D$2:$E$200,2,0) -> Xà lách Roman | W460: =DAY(C460)&MONTH(C460)&U460 -> 151NL300147 | X460: =COUNTIF($R$15:W460,W460)&W460 -> 1151NL300147 | Y460: =IFERROR(VLOOKUP(X460,FAST!$B$7:$M$9722,12,0),"0") -> 2 | Z460: =IFERROR(VLOOKUP(X460,FAST!$B$7:$N$9722,13,0),"0") -> 62000 | AA460: =Y460*Z460 -> 124000 | AB460: =Y460-L460 -> -0.5 | AC460: =Z460-M460 -> 0 | AD460: =AA460-N460 -> -31000

Sheet FAST
M5: =SUBTOTAL(9,M7:M1000) -> 2023.16 | O5: =SUBTOTAL(9,O7:O1000) -> 0 | P5: =SUBTOTAL(9,P7:P1000) -> 49683590
C6: Ngày ct | D6: Mã ct | E6: Số ct | F6: Áp giá | G6: Mã ncc | H6: Tên ncc | I6: Diễn giải | J6: Mã hàng | K6: Tên mặt hàng | L6: Đvt | M6: Số lượng | N6: Giá | O6: Giá báo | P6: Tiền | Q6: Chênh lệch giá | R6: Kho hàng | S6: Mã nx | T6: Vụ việc | U6: Bộ phận | V6: Hợp đồng
A7: =DAY(C7)&MONTH(C7)&J7 -> 11NL300189 | B7: =COUNTIF($A$7:A7,A7)&A7 -> 111NL300189 | C7: 46023 | D7: HD | E7: 2601WSG07005 | F7: 1 | G7: NCC100186 | H7: CÔNG TY TNHH NÔNG SẢN THỰC PHẨM TRẦN GIA | I7: WSG07 - Nhập hàng mua ngày 01/01/2026 | J7: NL300189 | K7: Bánh ướt | L7: kg | M7: 1.5 | N7: 15000 | O7: 0 | P7: 22500 | Q7: 0 | R7: 15000 | S7: WSG.07 | T7: 3311 | V7: WSG07 | W7: =VLOOKUP(B7,'LW13'!$X$15:$Y$501,2,0)-M7 -> 0
A8: =DAY(C8)&MONTH(C8)&J8 -> 11NL300004 | B8: =COUNTIF($A$7:A8,A8)&A8 -> 111NL300004 | C8: 46023 | D8: HD | E8: 2601WSG07005 | F8: 1 | G8: NCC100186 | H8: CÔNG TY TNHH NÔNG SẢN THỰC PHẨM TRẦN GIA | I8: WSG07 - Nhập hàng mua ngày 01/01/2026 | J8: NL300004 | K8: Bắp cải trắng | L8: kg | M8: 1.5 | N8: 19000 | O8: 0 | P8: 28500 | Q8: 0 | R8: 19000 | S8: WSG.07 | T8: 3311 | V8: WSG07 | W8: =VLOOKUP(B8,'LW13'!$X$15:$Y$501,2,0)-M8 -> 0
A9: =DAY(C9)&MONTH(C9)&J9 -> 11NL300007 | B9: =COUNTIF($A$7:A9,A9)&A9 -> 111NL300007 | C9: 46023 | D9: HD | E9: 2601WSG07005 | F9: 1 | G9: NCC100186 | H9: CÔNG TY TNHH NÔNG SẢN THỰC PHẨM TRẦN GIA | I9: WSG07 - Nhập hàng mua ngày 01/01/2026 | J9: NL300007 | K9: Bí đỏ | L9: kg | M9: 4 | N9: 30000 | O9: 0 | P9: 120000 | Q9: 0 | R9: 30000 | S9: WSG.07 | T9: 3311 | V9: WSG07 | W9: =VLOOKUP(B9,'LW13'!$X$15:$Y$501,2,0)-M9 -> 0
A10: =DAY(C10)&MONTH(C10)&J10 -> 11NL300008 | B10: =COUNTIF($A$7:A10,A10)&A10 -> 111NL300008 | C10: 46023 | D10: HD | E10: 2601WSG07005 | F10: 1 | G10: NCC100186 | H10: CÔNG TY TNHH NÔNG SẢN THỰC PHẨM TRẦN GIA | I10: WSG07 - Nhập hàng mua ngày 01/01/2026 | J10: NL300008 | K10: Bí ngòi | L10: kg | M10: 15 | N10: 40000 | O10: 0 | P10: 600000 | Q10: 0 | R10: 40000 | S10: WSG.07 | T10: 3311 | V10: WSG07 | W10: =VLOOKUP(B10,'LW13'!$X$15:$Y$501,2,0)-M10 -> 0
A11: =DAY(C11)&MONTH(C11)&J11 -> 11NL300028 | B11: =COUNTIF($A$7:A11,A11)&A11 -> 111NL300028 | C11: 46023 | D11: HD | E11: 2601WSG07005 | F11: 1 | G11: NCC100186 | H11: CÔNG TY TNHH NÔNG SẢN THỰC PHẨM TRẦN GIA | I11: WSG07 - Nhập hàng mua ngày 01/01/2026 | J11: NL300028 | K11: Cà rốt baby | L11: kg | M11: 0.3 | N11: 75000 | O11: 0 | P11: 22500 | Q11: 0 | R11: 75000 | S11: WSG.07 | T11: 3311 | V11: WSG07 | W11: =VLOOKUP(B11,'LW13'!$X$15:$Y$501,2,0)-M11 -> 0
A12: =DAY(C12)&MONTH(C12)&J12 -> 11NL300020 | B12: =COUNTIF($A$7:A12,A12)&A12 -> 111NL300020 | C12: 46023 | D12: HD | E12: 2601WSG07005 | F12: 1 | G12: NCC100186 | H12: CÔNG TY TNHH NÔNG SẢN THỰC PHẨM TRẦN GIA | I12: WSG07 - Nhập hàng mua ngày 01/01/2026 | J12: NL300020 | K12: Cải ngồng | L12: kg | M12: 1.5 | N12: 30000 | O12: 0 | P12: 45000 | Q12: 0 | R12: 30000 | S12: WSG.07 | T12: 3311 | V12: WSG07 | W12: =VLOOKUP(B12,'LW13'!$X$15:$Y$501,2,0)-M12 -> 0
A13: =DAY(C13)&MONTH(C13)&J13 -> 11NL300036 | B13: =COUNTIF($A$7:A13,A13)&A13 -> 111NL300036 | C13: 46023 | D13: HD | E13: 2601WSG07005 | F13: 1 | G13: NCC100186 | H13: CÔNG TY TNHH NÔNG SẢN THỰC PHẨM TRẦN GIA | I13: WSG07 - Nhập hàng mua ngày 01/01/2026 | J13: NL300036 | K13: Củ sen | L13: kg | M13: 0.7 | N13: 47000 | O13: 0 | P13: 32900 | Q13: 0 | R13: 47000 | S13: WSG.07 | T13: 3311 | V13: WSG07 | W13: =VLOOKUP(B13,'LW13'!$X$15:$Y$501,2,0)-M13 -> 0
A14: =DAY(C14)&MONTH(C14)&J14 -> 11NL300038 | B14: =COUNTIF($A$7:A14,A14)&A14 -> 111NL300038 | C14: 46023 | D14: HD | E14: 2601WSG07005 | F14: 1 | G14: NCC100186 | H14: CÔNG TY TNHH NÔNG SẢN THỰC PHẨM TRẦN GIA | I14: WSG07 - Nhập hàng mua ngày 01/01/2026 | J14: NL300038 | K14: Đậu bắp | L14: kg | M14: 1.5 | N14: 32000 | O14: 0 | P14: 48000 | Q14: 0 | R14: 32000 | S14: WSG.07 | T14: 3311 | V14: WSG07 | W14: =VLOOKUP(B14,'LW13'!$X$15:$Y$501,2,0)-M14 -> 0
A15: =DAY(C15)&MONTH(C15)&J15 -> 11NL300041 | B15: =COUNTIF($A$7:A15,A15)&A15 -> 111NL300041 | C15: 46023 | D15: HD | E15: 2601WSG07005 | F15: 1 | G15: NCC100186 | H15: CÔNG TY TNHH NÔNG SẢN THỰC PHẨM TRẦN GIA | I15: WSG07 - Nhập hàng mua ngày 01/01/2026 | J15: NL300041 | K15: Đậu hủ non trứng | L15: Cái | M15: 7 | N15: 15000 | O15: 0 | P15: 105000 | Q15: 0 | R15: 15000 | S15: WSG.07 | T15: 3311 | V15: WSG07 | W15: =VLOOKUP(B15,'LW13'!$X$15:$Y$501,2,0)-M15 -> 0
A16: =DAY(C16)&MONTH(C16)&J16 -> 11NL300054 | B16: =COUNTIF($A$7:A16,A16)&A16 -> 111NL300054 | C16: 46023 | D16: HD | E16: 2601WSG07005 | F16: 1 | G16: NCC100186 | H16: CÔNG TY TNHH NÔNG SẢN THỰC PHẨM TRẦN GIA | I16: WSG07 - Nhập hàng mua ngày 01/01/2026 | J16: NL300054 | K16: Gừng tàu | L16: kg | M16: 2 | N16: 38000 | O16: 0 | P16: 76000 | Q16: 0 | R16: 38000 | S16: WSG.07 | T16: 3311 | V16: WSG07 | W16: =VLOOKUP(B16,'LW13'!$X$15:$Y$501,2,0)-M16 -> 0
A17: =DAY(C17)&MONTH(C17)&J17 -> 11NL300058 | B17: =COUNTIF($A$7:A17,A17)&A17 -> 111NL300058 | C17: 46023 | D17: HD | E17: 2601WSG07005 | F17: 1 | G17: NCC100186 | H17: CÔNG TY TNHH NÔNG SẢN THỰC PHẨM TRẦN GIA | I17: WSG07 - Nhập hàng mua ngày 01/01/2026 | J17: NL300058 | K17: Hành lá | L17: kg | M17: 4.25 | N17: 55000 | O17: 0 | P17: 233750 | Q17: 0 | R17: 55000 | S17: WSG.07 | T17: 3311 | V17: WSG07 | W17: =VLOOKUP(B17,'LW13'!$X$15:$Y$501,2,0)-M17 -> 0
A18: =DAY(C18)&MONTH(C18)&J18 -> 11NL300061 | B18: =COUNTIF($A$7:A18,A18)&A18 -> 111NL300061 | C18: 46023 | D18: HD | E18: 2601WSG07005 | F18: 1 | G18: NCC100186 | H18: CÔNG TY TNHH NÔNG SẢN THỰC PHẨM TRẦN GIA | I18: WSG07 - Nhập hàng mua ngày 01/01/2026 | J18: NL300061 | K18: Hành Paro (Hành Baro) | L18: kg | M18: 0.5 | N18: 38000 | O18: 0 | P18: 19000 | Q18: 0 | R18: 38000 | S18: WSG.07 | T18: 3311 | V18: WSG07 | W18: =VLOOKUP(B18,'LW13'!$X$15:$Y$501,2,0)-M18 -> 0
... A444: =DAY(C444)&MONTH(C444)&J444 -> 151NL300125 | B444: =COUNTIF($A$7:A444,A444)&A444 -> 1151NL300125 | C444: 46037 | D444: HD | E444: 2601WSG07136 | F444: 1 | G444: NCC100186 | H444: CÔNG TY TNHH NÔNG SẢN THỰC PHẨM TRẦN GIA | I444: WSG07 - Nhập hàng mua ngày 15/01/2026 | J444: NL300125 | K444: Rau má | L444: kg | M444: 1 | N444: 42000 | O444: 0 | P444: 42000 | Q444: 0 | R444: 42000 | S444: WSG.07 | T444: 3311 | V444: WSG07 | W444: =VLOOKUP(B444,'LW13'!$X$15:$Y$501,2,0)-M444 -> 0

Sheet Sheet1
A1: TRẦN GIA | D1: FAST
A2: Trứng gà | D2: NL100100 | E2: =VLOOKUP(D2,[1]FAST!$A$2:$C$4520,2,0) -> Trứng gà | F2: =VLOOKUP(D2,[1]FAST!$A$2:$C$4520,3,0) -> quả
A3: Trứng vịt muối | B3: =VLOOKUP(A3,'[1]BÁO CÁO CÔNG NỢ_KIỂM TRA_ĐIỀU C'!J143:K532,2,0) -> Quả | D3: NL100101 | E3: =VLOOKUP(D3,[1]FAST!$A$2:$C$4520,2,0) -> Trứng vịt muối | F3: =VLOOKUP(D3,[1]FAST!$A$2:$C$4520,3,0) -> quả
A4: Chả lụa chay | D4: NL100153 | E4: =VLOOKUP(D4,[1]FAST!$A$2:$C$4520,2,0) -> Chả Lụa Chay | F4: =VLOOKUP(D4,[1]FAST!$A$2:$C$4520,3,0) -> kg
A5: Hành phi | D5: NL200008 | E5: =VLOOKUP(D5,[1]FAST!$A$2:$C$4520,2,0) -> Hành phi sẵn | F5: =VLOOKUP(D5,[1]FAST!$A$2:$C$4520,3,0) -> kg
A6: Me Vắt | D6: NL200143 | E6: =VLOOKUP(D6,[1]FAST!$A$2:$C$4520,2,0) -> Me vàng | F6: =VLOOKUP(D6,[1]FAST!$A$2:$C$4520,3,0) -> kg
A7: Nấm mèo | D7: NL200147 | E7: =VLOOKUP(D7,[1]FAST!$A$2:$C$4520,2,0) -> Mộc nhĩ ( Nấm mèo) | F7: =VLOOKUP(D7,[1]FAST!$A$2:$C$4520,3,0) -> kg
A8: Đậu Hà Lan | D8: NL200314 | E8: =VLOOKUP(D8,[1]FAST!$A$2:$C$4520,2,0) -> Đậu Hà lan đông lạnh | F8: =VLOOKUP(D8,[1]FAST!$A$2:$C$4520,3,0) -> kg
A9: Miến dong | D9: NL200324 | E9: =VLOOKUP(D9,[1]FAST!$A$2:$C$4520,2,0) -> Miến | F9: =VLOOKUP(D9,[1]FAST!$A$2:$C$4520,3,0) -> kg
A10: Bánh phở | D10: NL300002 | E10: =VLOOKUP(D10,[1]FAST!$A$2:$C$4520,2,0) -> Bánh phở | F10: =VLOOKUP(D10,[1]FAST!$A$2:$C$4520,3,0) -> kg
A11: Bắp cải tím | D11: NL300003 | E11: =VLOOKUP(D11,[1]FAST!$A$2:$C$4520,2,0) -> Bắp cải tím | F11: =VLOOKUP(D11,[1]FAST!$A$2:$C$4520,3,0) -> kg
A12: Bắp cải trắng | B12: =VLOOKUP(A12,'[1]BÁO CÁO CÔNG NỢ_KIỂM TRA_ĐIỀU C'!J17:K406,2,0) -> Kg | D12: NL300004 | E12: =VLOOKUP(D12,[1]FAST!$A$2:$C$4520,2,0) -> Bắp cải trắng | F12: =VLOOKUP(D12,[1]FAST!$A$2:$C$4520,3,0) -> kg
A13: Bí đỏ hồ lô | B13: =VLOOKUP(A13,'[1]BÁO CÁO CÔNG NỢ_KIỂM TRA_ĐIỀU C'!J158:K547,2,0) -> Kg | D13: NL300007 | E13: =VLOOKUP(D13,[1]FAST!$A$2:$C$4520,2,0) -> Bí đỏ | F13: =VLOOKUP(D13,[1]FAST!$A$2:$C$4520,3,0) -> kg
A14: Bí ngòi xanh | B14: =VLOOKUP(A14,'[1]BÁO CÁO CÔNG NỢ_KIỂM TRA_ĐIỀU C'!J126:K515,2,0) -> Kg | D14: NL300008 | E14: =VLOOKUP(D14,[1]FAST!$A$2:$C$4520,2,0) -> Bí ngòi | F14: =VLOOKUP(D14,[1]FAST!$A$2:$C$4520,3,0) -> kg
A15: Bí nụ | D15: NL300009 | E15: =VLOOKUP(D15,[1]FAST!$A$2:$C$4520,2,0) -> Bí nụ | F15: =VLOOKUP(D15,[1]FAST!$A$2:$C$4520,3,0) -> kg
A16: Bún nhỏ | D16: NL300012 | E16: =VLOOKUP(D16,[1]FAST!$A$2:$C$4520,2,0) -> Bún | F16: =VLOOKUP(D16,[1]FAST!$A$2:$C$4520,3,0) -> kg
A17: Cà chua | D17: NL300013 | E17: =VLOOKUP(D17,[1]FAST!$A$2:$C$4520,2,0) -> Cà chua | F17: =VLOOKUP(D17,[1]FAST!$A$2:$C$4520,3,0) -> kg
A18: Cà chua bi | D18: NL300014 | E18: =VLOOKUP(D18,[1]FAST!$A$2:$C$4520,2,0) -> Cà chua bi | F18: =VLOOKUP(D18,[1]FAST!$A$2:$C$4520,3,0) -> kg
A19: Bông cải xanh Baby | D19: NL300015 | E19: =VLOOKUP(D19,[1]FAST!$A$2:$C$4520,2,0) -> Bông cải xanh Baby | F19: =VLOOKUP(D19,[1]FAST!$A$2:$C$4520,3,0) -> kg
A20: Tần ô | D20: NL300018 | E20: =VLOOKUP(D20,[1]FAST!$A$2:$C$4520,2,0) -> Cải cúc | F20: =VLOOKUP(D20,[1]FAST!$A$2:$C$4520,3,0) -> kg
A21: Cải Hongkong(Cai ngong) | B21: =VLOOKUP(A21,'[1]BÁO CÁO CÔNG NỢ_KIỂM TRA_ĐIỀU C'!J130:K519,2,0) -> Kg | D21: NL300020 | E21: =VLOOKUP(D21,[1]FAST!$A$2:$C$4520,2,0) -> Cải ngồng | F21: =VLOOKUP(D21,[1]FAST!$A$2:$C$4520,3,0) -> kg
A22: Cải thảo | D22: NL300022 | E22: =VLOOKUP(D22,[1]FAST!$A$2:$C$4520,2,0) -> Cải thảo | F22: =VLOOKUP(D22,[1]FAST!$A$2:$C$4520,3,0) -> kg
A23: Cần tây | B23: =VLOOKUP(A23,'[1]BÁO CÁO CÔNG NỢ_KIỂM TRA_ĐIỀU C'!J29:K418,2,0) -> Kg | D23: NL300025 | E23: =VLOOKUP(D23,[1]FAST!$A$2:$C$4520,2,0) -> Rau cần tây | F23: =VLOOKUP(D23,[1]FAST!$A$2:$C$4520,3,0) -> kg
A24: Cà rốt | D24: NL300027 | E24: =VLOOKUP(D24,[1]FAST!$A$2:$C$4520,2,0) -> Cà rốt | F24: =VLOOKUP(D24,[1]FAST!$A$2:$C$4520,3,0) -> kg
A25: Cà rốt baby | B25: =VLOOKUP(A25,'[1]BÁO CÁO CÔNG NỢ_KIỂM TRA_ĐIỀU C'!J129:K518,2,0) -> Kg | D25: NL300028 | E25: =VLOOKUP(D25,[1]FAST!$A$2:$C$4520,2,0) -> Cà rốt baby | F25: =VLOOKUP(D25,[1]FAST!$A$2:$C$4520,3,0) -> kg
A26: Chanh không hạt | B26: =VLOOKUP(A26,'[1]BÁO CÁO CÔNG NỢ_KIỂM TRA_ĐIỀU C'!J160:K549,2,0) -> Kg | D26: NL300029 | E26: =VLOOKUP(D26,[1]FAST!$A$2:$C$4520,2,0) -> Chanh | F26: =VLOOKUP(D26,[1]FAST!$A$2:$C$4520,3,0) -> kg
A27: Chanh ko hạt | D27: NL300029 | E27: =VLOOKUP(D27,[1]FAST!$A$2:$C$4520,2,0) -> Chanh | F27: =VLOOKUP(D27,[1]FAST!$A$2:$C$4520,3,0) -> kg
A28: Chanh Dây | B28: =VLOOKUP(A28,'[1]BÁO CÁO CÔNG NỢ_KIỂM TRA_ĐIỀU C'!J96:K485,2,0) -> Kg | D28: NL300030 | E28: =VLOOKUP(D28,[1]FAST!$A$2:$C$4520,2,0) -> Chanh dây (chanh leo) | F28: =VLOOKUP(D28,[1]FAST!$A$2:$C$4520,3,0) -> kg
A29: Củ cải trắng (Loại 1) | D29: NL300033 | E29: =VLOOKUP(D29,[1]FAST!$A$2:$C$4520,2,0) -> Củ cải trắng | F29: =VLOOKUP(D29,[1]FAST!$A$2:$C$4520,3,0) -> kg
A30: Củ cải đỏ (Radis) | D30: NL300034 | E30: =VLOOKUP(D30,[1]FAST!$A$2:$C$4520,2,0) -> Củ cải đỏ | F30: =VLOOKUP(D30,[1]FAST!$A$2:$C$4520,3,0) -> kg
A31: Củ riềng | B31: =VLOOKUP(A31,'[1]BÁO CÁO CÔNG NỢ_KIỂM TRA_ĐIỀU C'!J187:K576,2,0) -> Kg | D31: NL300035 | E31: =VLOOKUP(D31,[1]FAST!$A$2:$C$4520,2,0) -> Củ riềng | F31: =VLOOKUP(D31,[1]FAST!$A$2:$C$4520,3,0) -> kg
A32: Củ sen | B32: =VLOOKUP(A32,'[1]BÁO CÁO CÔNG NỢ_KIỂM TRA_ĐIỀU C'!J183:K572,2,0) -> Kg | D32: NL300036 | E32: =VLOOKUP(D32,[1]FAST!$A$2:$C$4520,2,0) -> Củ sen | F32: =VLOOKUP(D32,[1]FAST!$A$2:$C$4520,3,0) -> kg
A33: Đậu hủ miếng trắng | D33: NL300037 | E33: =VLOOKUP(D33,[1]FAST!$A$2:$C$4520,2,0) -> Đậu phụ | F33: =VLOOKUP(D33,[1]FAST!$A$2:$C$4520,3,0) -> miếng
A34: Đậu bắp | B34: =VLOOKUP(A34,'[1]BÁO CÁO CÔNG NỢ_KIỂM TRA_ĐIỀU C'!J33:K422,2,0) -> Kg | D34: NL300038 | E34: =VLOOKUP(D34,[1]FAST!$A$2:$C$4520,2,0) -> Đậu bắp | F34: =VLOOKUP(D34,[1]FAST!$A$2:$C$4520,3,0) -> kg
A35: Đậu hủ trắng cây Ichiban 220gr | D35: NL300041 | E35: =VLOOKUP(D35,[1]FAST!$A$2:$C$4520,2,0) -> Đậu hủ non trứng | F35: =VLOOKUP(D35,[1]FAST!$A$2:$C$4520,3,0) -> Cái
A36: Đậu hủ trứng cây Ichiban 220gr | D36: NL300041 | E36: =VLOOKUP(D36,[1]FAST!$A$2:$C$4520,2,0) -> Đậu hủ non trứng | F36: =VLOOKUP(D36,[1]FAST!$A$2:$C$4520,3,0) -> Cái
A37: Đậu hủ trứng CP 220gr | B37: =VLOOKUP(A37,'[1]BÁO CÁO CÔNG NỢ_KIỂM TRA_ĐIỀU C'!J36:K425,2,0) -> Cây | D37: NL300041 | E37: =VLOOKUP(D37,[1]FAST!$A$2:$C$4520,2,0) -> Đậu hủ non trứng | F37: =VLOOKUP(D37,[1]FAST!$A$2:$C$4520,3,0) -> Cái
A38: Lá cóc | D38: NL300043 | E38: =VLOOKUP(D38,[1]FAST!$A$2:$C$4520,2,0) -> Đọt cóc | F38: =VLOOKUP(D38,[1]FAST!$A$2:$C$4520,3,0) -> kg
A39: Lá Trâm Ổi | D39: NL300044 | E39: =VLOOKUP(D39,[1]FAST!$A$2:$C$4520,2,0) -> Đọt mọt ( Lá trăm ) | F39: =VLOOKUP(D39,[1]FAST!$A$2:$C$4520,3,0) -> kg
A40: Thơm trái xanh | D40: NL300047 | E40: =VLOOKUP(D40,[1]FAST!$A$2:$C$4520,2,0) -> Dứa chưa gọt vỏ | F40: =VLOOKUP(D40,[1]FAST!$A$2:$C$4520,3,0) -> quả
...

Sheet titan
E2: CÔNG TY TNHH NÔNG SẢN THỰC PHẨM TRẦN GIA HTX: Ấp Lộc Tiến, Xã Mỹ Lộc, Huyện Cần Giuộc, Tỉnh Long An VP: Tòa nhà An Phú Plaza, 117-119 Lý Chính Thắng, P.7. Q.3, TP.HCM Kho sơ chế: 30 Kha Vạn Cân, P. Hiệp Bình Chánh, TP.Thủ Đức, TP.HCM Kho Đà Lạt: 69 Trần Thủ Độ, TT Liên Nghĩa, Huyện Đức Trọng, Tỉnh Lâm Đồng. Website: rausachtrangia.com - Hotline: 090.245.8081
B4: CHI TIẾT ĐỐI CHIẾU CÔNG NỢ
B8: Tên Khách hàng: TIANLONG 01 | X8: sheet fast | Y8: =Sheet4!M5 -> 393 | AA8: =Sheet4!P5 -> 13383700
B10: Địa chỉ: | X10: lệch sheet fast | Y10: =Y12-Y8 -> 0 | AA10: =AA12-AA8 -> 0
B12: Người liên hệ: Email: | X12: sum vlookup | Y12: =SUBTOTAL(9,Y13:Y9718) -> 393 | AA12: =SUBTOTAL(9,AA13:AA9718) -> 13383700 | AB12: =SUBTOTAL(9,AB13:AB9718) -> -104.7 | AC12: =SUBTOTAL(9,AC13:AC9718) -> 136000 | AD12: =SUBTOTAL(9,AD13:AD9718) -> -789000
L13: =SUM(L15:L1048576) -> 497.7 | N13: =SUM(N15:N1048576) -> 14172700
B14: MÃ ĐƠN HÀNG | C14: NGÀY | D14: MÃ KH | E14: TÊN KH | F14: Line ID | G14: Barcode | H14: MÃ KHO | I14: MÃ HÀNG | J14: TÊN HÀNG | K14: ĐVT | L14: SL | M14: ĐƠN GIÁ | N14: THÀNH TIỀN | O14: TỔNG TIỀN | P14: GHI CHÚ | Q14: Booklet No | R14: Custom5 | S14: Price List Id | T14: Doc Type | Y14: sl | Z14: đơn giá | AA14: thành tiền | AB14: lệch số lượng | AC14: lệch đơn giá | AD14: lệch tổng tiền
C15: 26/09/2025 | D15: TG-KS01163 | E15: TIANLONG 01 | J15: Bắp mỹ trái (Loại 1) | K15: Trái | L15: 10 | M15: 8000 | N15: 80000 | O15: =M15*N15 -> 640000000 | Q15: SOTG00110145381 | S15: Pricelist17 | T15: AdjDO | U15: =VLOOKUP(J15,Sheet1!$A$2:$D$200,4,0) -> NL300107 | V15: =VLOOKUP(U15,Sheet1!$D$2:$E$200,2,0) -> Ngô ngọt ( Bắp trái) | W15: =DAY(C15)&MONTH(C15)&U15 -> 269NL300107 | X15: =COUNTIF($R$15:W15,W15)&W15 -> 1269NL300107 | Y15: =IFERROR(VLOOKUP(X15,Sheet4!$B$7:$M$1187,12,0),"0") -> 10 | Z15: =IFERROR(VLOOKUP(X15,Sheet4!$B$7:$N$1187,13,0),"0") -> 8000 | AA15: =Y15*Z15 -> 80000 | AB15: =Y15-L15 -> 0 | AC15: =Z15-M15 -> 0 | AD15: =AA15-N15 -> 0
C16: =C15 -> 26/09/2025 | D16: =D15 -> TG-KS01163 | E16: =E15 -> TIANLONG 01 | J16: Bó xôi (Nhà Lồng) | K16: Kg | L16: 2 | M16: 48000 | N16: 96000 | O16: =M16*N16 -> 4608000000 | Q16: SOTG00110145431 | S16: Pricelist17 | T16: AdjDO | U16: =VLOOKUP(J16,Sheet1!$A$2:$D$200,4,0) -> NL300203 | V16: =VLOOKUP(U16,Sheet1!$D$2:$E$200,2,0) -> Cải bó xôi | W16: =DAY(C16)&MONTH(C16)&U16 -> 269NL300203 | X16: =COUNTIF($R$15:W16,W16)&W16 -> 1269NL300203 | Y16: =IFERROR(VLOOKUP(X16,Sheet4!$B$7:$M$1187,12,0),"0") -> 1.8 | Z16: =IFERROR(VLOOKUP(X16,Sheet4!$B$7:$N$1187,13,0),"0") -> 48000 | AA16: =Y16*Z16 -> 86400 | AB16: =Y16-L16 -> -0.2 | AC16: =Z16-M16 -> 0 | AD16: =AA16-N16 -> -9600
C17: =C16 -> 26/09/2025 | D17: =D16 -> TG-KS01163 | E17: =E16 -> TIANLONG 01 | J17: Cà chua | K17: Kg | L17: 3 | M17: 25000 | N17: 75000 | O17: =M17*N17 -> 1875000000 | Q17: SOTG00110145381 | S17: Pricelist17 | T17: AdjDO | U17: =VLOOKUP(J17,Sheet1!$A$2:$D$200,4,0) -> NL300013 | V17: =VLOOKUP(U17,Sheet1!$D$2:$E$200,2,0) -> Cà chua | W17: =DAY(C17)&MONTH(C17)&U17 -> 269NL300013 | X17: =COUNTIF($R$15:W17,W17)&W17 -> 1269NL300013 | Y17: =IFERROR(VLOOKUP(X17,Sheet4!$B$7:$M$1187,12,0),"0") -> 3 | Z17: =IFERROR(VLOOKUP(X17,Sheet4!$B$7:$N$1187,13,0),"0") -> 25000 | AA17: =Y17*Z17 -> 75000 | AB17: =Y17-L17 -> 0 | AC17: =Z17-M17 -> 0 | AD17: =AA17-N17 -> 0
C18: =C17 -> 26/09/2025 | D18: =D17 -> TG-KS01163 | E18: =E17 -> TIANLONG 01 | J18: Cải thảo | K18: Kg | L18: 10 | M18: 14000 | N18: 140000 | O18: =M18*N18 -> 1960000000 | Q18: SOTG00110145381 | S18: Pricelist17 | T18: AdjDO | U18: =VLOOKUP(J18,Sheet1!$A$2:$D$200,4,0) -> NL300022 | V18: =VLOOKUP(U18,Sheet1!$D$2:$E$200,2,0) -> Cải thảo | W18: =DAY(C18)&MONTH(C18)&U18 -> 269NL300022 | X18: =COUNTIF($R$15:W18,W18)&W18 -> 1269NL300022 | Y18: =IFERROR(VLOOKUP(X18,Sheet4!$B$7:$M$1187,12,0),"0") -> 9 | Z18: =IFERROR(VLOOKUP(X18,Sheet4!$B$7:$N$1187,13,0),"0") -> 14000 | AA18: =Y18*Z18 -> 126000 | AB18: =Y18-L18 -> -1 | AC18: =Z18-M18 -> 0 | AD18: =AA18-N18 -> -14000
C19: =C18 -> 26/09/2025 | D19: =D18 -> TG-KS01163 | E19: =E18 -> TIANLONG 01 | J19: Cam vàng | K19: Kg | L19: 1.1 | M19: 70000 | N19: 77000 | O19: =M19*N19 -> 5390000000 | Q19: SOTG00110145381 | S19: Pricelist17 | T19: AdjDO | U19: =VLOOKUP(J19,Sheet1!$A$2:$D$200,4,0) -> NL600067 | V19: =VLOOKUP(U19,Sheet1!$D$2:$E$200,2,0) -> Cam vàng | W19: =DAY(C19)&MONTH(C19)&U19 -> 269NL600067 | X19: =COUNTIF($R$15:W19,W19)&W19 -> 1269NL600067 | Y19: =IFERROR(VLOOKUP(X19,Sheet4!$B$7:$M$1187,12,0),"0") -> 1.1 | Z19: =IFERROR(VLOOKUP(X19,Sheet4!$B$7:$N$1187,13,0),"0") -> 70000 | AA19: =Y19*Z19 -> 77000 | AB19: =Y19-L19 -> 0 | AC19: =Z19-M19 -> 0 | AD19: =AA19-N19 -> 0
C20: =C19 -> 26/09/2025 | D20: =D19 -> TG-KS01163 | E20: =E19 -> TIANLONG 01 | J20: Chanh không hạt | K20: Kg | L20: 0.5 | M20: 21000 | N20: 10500 | O20: =M20*N20 -> 220500000 | Q20: SOTG00110145381 | S20: Pricelist17 | T20: AdjDO | U20: =VLOOKUP(J20,Sheet1!$A$2:$D$200,4,0) -> NL300029 | V20: =VLOOKUP(U20,Sheet1!$D$2:$E$200,2,0) -> Chanh | W20: =DAY(C20)&MONTH(C20)&U20 -> 269NL300029 | X20: =COUNTIF($R$15:W20,W20)&W20 -> 1269NL300029 | Y20: =IFERROR(VLOOKUP(X20,Sheet4!$B$7:$M$1187,12,0),"0") -> 0.5 | Z20: =IFERROR(VLOOKUP(X20,Sheet4!$B$7:$N$1187,13,0),"0") -> 21000 | AA20: =Y20*Z20 -> 10500 | AB20: =Y20-L20 -> 0 | AD20: =AA20-N20 -> 0
C21: =C20 -> 26/09/2025 | D21: =D20 -> TG-KS01163 | E21: =E20 -> TIANLONG 01 | J21: Củ cải trắng (Loại 1) | K21: Kg | L21: 2 | M21: 11000 | N21: 22000 | O21: =M21*N21 -> 242000000 | Q21: SOTG00110145381 | S21: Pricelist17 | T21: AdjDO | U21: =VLOOKUP(J21,Sheet1!$A$2:$D$200,4,0) -> NL300033 | V21: =VLOOKUP(U21,Sheet1!$D$2:$E$200,2,0) -> Củ cải trắng | W21: =DAY(C21)&MONTH(C21)&U21 -> 269NL300033 | X21: =COUNTIF($R$15:W21,W21)&W21 -> 1269NL300033 | Y21: =IFERROR(VLOOKUP(X21,Sheet4!$B$7:$M$1187,12,0),"0") -> 2 | Z21: =IFERROR(VLOOKUP(X21,Sheet4!$B$7:$N$1187,13,0),"0") -> 11000 | AA21: =Y21*Z21 -> 22000 | AB21: =Y21-L21 -> 0 | AC21: =Z21-M21 -> 0 | AD21: =AA21-N21 -> 0
C22: =C21 -> 26/09/2025 | D22: =D21 -> TG-KS01163 | E22: =E21 -> TIANLONG 01 | J22: Củ sen | K22: Kg | L22: 2.1 | M22: 44000 | N22: 92400 | O22: =M22*N22 -> 4065600000 | Q22: SOTG00110145381 | S22: Pricelist17 | T22: AdjDO | U22: =VLOOKUP(J22,Sheet1!$A$2:$D$200,4,0) -> NL300036 | V22: =VLOOKUP(U22,Sheet1!$D$2:$E$200,2,0) -> Củ sen | W22: =DAY(C22)&MONTH(C22)&U22 -> 269NL300036 | X22: =COUNTIF($R$15:W22,W22)&W22 -> 1269NL300036 | Y22: =IFERROR(VLOOKUP(X22,Sheet4!$B$7:$M$1187,12,0),"0") -> 2 | Z22: =IFERROR(VLOOKUP(X22,Sheet4!$B$7:$N$1187,13,0),"0") -> 44000 | AA22: =Y22*Z22 -> 88000 | AB22: =Y22-L22 -> -0.1 | AD22: =AA22-N22 -> -4400
C23: =C22 -> 26/09/2025 | D23: =D22 -> TG-KS01163 | E23: =E22 -> TIANLONG 01 | J23: Hành lá | K23: Kg | L23: 1 | M23: 31000 | N23: 31000 | O23: =M23*N23 -> 961000000 | Q23: SOTG00110145381 | S23: Pricelist17 | T23: AdjDO | U23: =VLOOKUP(J23,Sheet1!$A$2:$D$200,4,0) -> NL300058 | V23: =VLOOKUP(U23,Sheet1!$D$2:$E$200,2,0) -> Hành lá | W23: =DAY(C23)&MONTH(C23)&U23 -> 269NL300058 | X23: =COUNTIF($R$15:W23,W23)&W23 -> 1269NL300058 | Y23: =IFERROR(VLOOKUP(X23,Sheet4!$B$7:$M$1187,12,0),"0") -> 0.9 | Z23: =IFERROR(VLOOKUP(X23,Sheet4!$B$7:$N$1187,13,0),"0") -> 31000 | AA23: =Y23*Z23 -> 27900 | AB23: =Y23-L23 -> -0.1 | AC23: =Z23-M23 -> 0 | AD23: =AA23-N23 -> -3100
C24: =C23 -> 26/09/2025 | D24: =D23 -> TG-KS01163 | E24: =E23 -> TIANLONG 01 | J24: Mồng tơi | K24: Kg | L24: 5 | M24: 20000 | N24: 100000 | O24: =M24*N24 -> 2000000000 | Q24: SOTG00110145381 | S24: Pricelist17 | T24: AdjDO | U24: =VLOOKUP(J24,Sheet1!$A$2:$D$200,4,0) -> NL300084 | V24: =VLOOKUP(U24,Sheet1!$D$2:$E$200,2,0) -> Mồng tơi nhặt | W24: =DAY(C24)&MONTH(C24)&U24 -> 269NL300084 | X24: =COUNTIF($R$15:W24,W24)&W24 -> 1269NL300084 | Y24: =IFERROR(VLOOKUP(X24,Sheet4!$B$7:$M$1187,12,0),"0") -> 4 | Z24: =IFERROR(VLOOKUP(X24,Sheet4!$B$7:$N$1187,13,0),"0") -> 20000 | AA24: =Y24*Z24 -> 80000 | AB24: =Y24-L24 -> -1 | AD24: =AA24-N24 -> -20000
C25: =C24 -> 26/09/2025 | D25: =D24 -> TG-KS01163 | E25: =E24 -> TIANLONG 01 | J25: Nấm đông cô tươi | K25: Kg | L25: 2 | M25: 138000 | N25: 276000 | O25: =M25*N25 -> 38088000000 | Q25: SOTG00110145381 | S25: Pricelist17 | T25: AdjDO | U25: =VLOOKUP(J25,Sheet1!$A$2:$D$200,4,0) -> NL300090 | V25: =VLOOKUP(U25,Sheet1!$D$2:$E$200,2,0) -> Nấm đông cô tươi | W25: =DAY(C25)&MONTH(C25)&U25 -> 269NL300090 | X25: =COUNTIF($R$15:W25,W25)&W25 -> 1269NL300090 | Y25: =IFERROR(VLOOKUP(X25,Sheet4!$B$7:$M$1187,12,0),"0") -> 2 | Z25: =IFERROR(VLOOKUP(X25,Sheet4!$B$7:$N$1187,13,0),"0") -> 138000 | AA25: =Y25*Z25 -> 276000 | AB25: =Y25-L25 -> 0 | AC25: =Z25-M25 -> 0 | AD25: =AA25-N25 -> 0
C26: =C25 -> 26/09/2025 | D26: =D25 -> TG-KS01163 | E26: =E25 -> TIANLONG 01 | J26: Nấm kim châm gói (200g) | K26: Gói | L26: 15 | M26: 11000 | N26: 165000 | O26: =M26*N26 -> 1815000000 | Q26: SOTG00110145381 | S26: Pricelist17 | T26: AdjDO | U26: =VLOOKUP(J26,Sheet1!$A$2:$D$200,4,0) -> NL300096 | V26: =VLOOKUP(U26,Sheet1!$D$2:$E$200,2,0) -> Nấm kim châm tươi | W26: =DAY(C26)&MONTH(C26)&U26 -> 269NL300096 | X26: =COUNTIF($R$15:W26,W26)&W26 -> 1269NL300096 | Y26: =IFERROR(VLOOKUP(X26,Sheet4!$B$7:$M$1187,12,0),"0") -> 3 | Z26: =IFERROR(VLOOKUP(X26,Sheet4!$B$7:$N$1187,13,0),"0") -> 45000 | AA26: =Y26*Z26 -> 135000 | AB26: =Y26-L26 -> -12 | AC26: =Z26-M26 -> 34000 | AD26: =AA26-N26 -> -30000
C27: =C26 -> 26/09/2025 | D27: =D26 -> TG-KS01163 | E27: =E26 -> TIANLONG 01 | J27: Nấm linh chi trắng (kg) | K27: Kg | L27: 5 | M27: 90000 | N27: 450000 | O27: =M27*N27 -> 40500000000 | Q27: SOTG00110145381 | T27: AdjDO | U27: =VLOOKUP(J27,Sheet1!$A$2:$D$200,4,0) -> NL300098 | V27: =VLOOKUP(U27,Sheet1!$D$2:$E$200,2,0) -> Nấm Linh Chi trắng | W27: =DAY(C27)&MONTH(C27)&U27 -> 269NL300098 | X27: =COUNTIF($R$15:W27,W27)&W27 -> 1269NL300098 | Y27: =IFERROR(VLOOKUP(X27,Sheet4!$B$7:$M$1187,12,0),"0") -> 5 | Z27: =IFERROR(VLOOKUP(X27,Sheet4!$B$7:$N$1187,13,0),"0") -> 90000 | AA27: =Y27*Z27 -> 450000 | AB27: =Y27-L27 -> 0 | AC27: =Z27-M27 -> 0 | AD27: =AA27-N27 -> 0
C28: =C27 -> 26/09/2025 | D28: =D27 -> TG-KS01163 | E28: =E27 -> TIANLONG 01 | J28: Ngò rí | K28: Kg | L28: 1 | M28: 45000 | N28: 45000 | O28: =M28*N28 -> 2025000000 | Q28: SOTG00110145381 | S28: Pricelist17 | T28: AdjDO | U28: =VLOOKUP(J28,Sheet1!$A$2:$D$200,4,0) -> NL300085 | V28: =VLOOKUP(U28,Sheet1!$D$2:$E$200,2,0) -> Mùi ta ( Ngò rí ) | W28: =DAY(C28)&MONTH(C28)&U28 -> 269NL300085 | X28: =COUNTIF($R$15:W28,W28)&W28 -> 1269NL300085 | Y28: =IFERROR(VLOOKUP(X28,Sheet4!$B$7:$M$1187,12,0),"0") -> 0.8 | Z28: =IFERROR(VLOOKUP(X28,Sheet4!$B$7:$N$1187,13,0),"0") -> 45000 | AA28: =Y28*Z28 -> 36000 | AB28: =Y28-L28 -> -0.2 | AC28: =Z28-M28 -> 0 | AD28: =AA28-N28 -> -9000
C29: =C28 -> 26/09/2025 | D29: =D28 -> TG-KS01163 | E29: =E28 -> TIANLONG 01 | J29: Ngò tây | K29: Kg | L29: 0.3 | M29: 90000 | N29: 27000 | O29: =M29*N29 -> 2430000000 | Q29: SOTG00110145381 | S29: Pricelist17 | T29: AdjDO | U29: =VLOOKUP(J29,Sheet1!$A$2:$D$200,4,0) -> NL300126 | V29: =VLOOKUP(U29,Sheet1!$D$2:$E$200,2,0) -> Rau mùi tây | W29: =DAY(C29)&MONTH(C29)&U29 -> 269NL300126 | X29: =COUNTIF($R$15:W29,W29)&W29 -> 1269NL300126 | Y29: =IFERROR(VLOOKUP(X29,Sheet4!$B$7:$M$1187,12,0),"0") -> 0.2 | Z29: =IFERROR(VLOOKUP(X29,Sheet4!$B$7:$N$1187,13,0),"0") -> 90000 | AA29: =Y29*Z29 -> 18000 | AB29: =Y29-L29 -> -0.1 | AC29: =Z29-M29 -> 0 | AD29: =AA29-N29 -> -9000
C30: =C29 -> 26/09/2025 | D30: =D29 -> TG-KS01163 | E30: =E29 -> TIANLONG 01 | J30: Ớt hiểm đỏ | K30: Kg | L30: 1 | M30: 48000 | N30: 48000 | O30: =M30*N30 -> 2304000000 | Q30: SOTG00110145381 | S30: Pricelist17 | T30: AdjDO | U30: =VLOOKUP(J30,Sheet1!$A$2:$D$200,4,0) -> NL300113 | V30: =VLOOKUP(U30,Sheet1!$D$2:$E$200,2,0) -> Ớt hiểm đỏ | W30: =DAY(C30)&MONTH(C30)&U30 -> 269NL300113 | X30: =COUNTIF($R$15:W30,W30)&W30 -> 1269NL300113 | Y30: =IFERROR(VLOOKUP(X30,Sheet4!$B$7:$M$1187,12,0),"0") -> 1 | Z30: =IFERROR(VLOOKUP(X30,Sheet4!$B$7:$N$1187,13,0),"0") -> 48000 | AA30: =Y30*Z30 -> 48000 | AB30: =Y30-L30 -> 0 | AC30: =Z30-M30 -> 0 | AD30: =AA30-N30 -> 0
C31: =C30 -> 26/09/2025 | D31: =D30 -> TG-KS01163 | E31: =E30 -> TIANLONG 01 | J31: Tắc trái | K31: Kg | L31: 5 | M31: 20000 | N31: 100000 | O31: =M31*N31 -> 2000000000 | Q31: SOTG00110145381 | S31: Pricelist17 | T31: AdjDO | U31: =VLOOKUP(J31,Sheet1!$A$2:$D$200,4,0) -> NL300119 | V31: =VLOOKUP(U31,Sheet1!$D$2:$E$200,2,0) -> Quất ( Tắc trái ) | W31: =DAY(C31)&MONTH(C31)&U31 -> 269NL300119 | X31: =COUNTIF($R$15:W31,W31)&W31 -> 1269NL300119 | Y31: =IFERROR(VLOOKUP(X31,Sheet4!$B$7:$M$1187,12,0),"0") -> 4.5 | Z31: =IFERROR(VLOOKUP(X31,Sheet4!$B$7:$N$1187,13,0),"0") -> 20000 | AA31: =Y31*Z31 -> 90000 | AB31: =Y31-L31 -> -0.5 | AC31: =Z31-M31 -> 0 | AD31: =AA31-N31 -> -10000
C32: =C31 -> 26/09/2025 | D32: =D31 -> TG-KS01163 | E32: =E31 -> TIANLONG 01 | J32: Tần ô | K32: Kg | L32: 4 | M32: 31000 | N32: 124000 | O32: =M32*N32 -> 3844000000 | Q32: SOTG00110145381 | S32: Pricelist17 | T32: AdjDO | U32: =VLOOKUP(J32,Sheet1!$A$2:$D$200,4,0) -> NL300018 | V32: =VLOOKUP(U32,Sheet1!$D$2:$E$200,2,0) -> Cải cúc | W32: =DAY(C32)&MONTH(C32)&U32 -> 269NL300018 | X32: =COUNTIF($R$15:W32,W32)&W32 -> 1269NL300018 | Y32: =IFERROR(VLOOKUP(X32,Sheet4!$B$7:$M$1187,12,0),"0") -> 3.5 | Z32: =IFERROR(VLOOKUP(X32,Sheet4!$B$7:$N$1187,13,0),"0") -> 31000 | AA32: =Y32*Z32 -> 108500 | AB32: =Y32-L32 -> -0.5 | AC32: =Z32-M32 -> 0 | AD32: =AA32-N32 -> -15500
C33: =C32 -> 26/09/2025 | D33: =D32 -> TG-KS01163 | E33: =E32 -> TIANLONG 01 | J33: Tỏi lột | K33: Kg | L33: 2 | M33: 55000 | N33: 110000 | O33: =M33*N33 -> 6050000000 | Q33: SOTG00110145381 | S33: Pricelist17 | T33: AdjDO | U33: =VLOOKUP(J33,Sheet1!$A$2:$D$200,4,0) -> NL300142 | V33: =VLOOKUP(U33,Sheet1!$D$2:$E$200,2,0) -> Tỏi bóc | W33: =DAY(C33)&MONTH(C33)&U33 -> 269NL300142 | X33: =COUNTIF($R$15:W33,W33)&W33 -> 1269NL300142 | Y33: =IFERROR(VLOOKUP(X33,Sheet4!$B$7:$M$1187,12,0),"0") -> 2 | Z33: =IFERROR(VLOOKUP(X33,Sheet4!$B$7:$N$1187,13,0),"0") -> 55000 | AA33: =Y33*Z33 -> 110000 | AB33: =Y33-L33 -> 0 | AC33: =Z33-M33 -> 0 | AD33: =AA33-N33 -> 0
C34: =C33 -> 26/09/2025 | D34: =D33 -> TG-KS01163 | E34: =E33 -> TIANLONG 01 | J34: Xà lách romain | K34: Kg | L34: 6 | M34: 55000 | N34: 330000 | O34: =M34*N34 -> 18150000000 | Q34: SOTG00110145382 | S34: Pricelist17 | T34: AdjDO | U34: =VLOOKUP(J34,Sheet1!$A$2:$D$200,4,0) -> NL300147 | V34: =VLOOKUP(U34,Sheet1!$D$2:$E$200,2,0) -> Xà lách Roman | W34: =DAY(C34)&MONTH(C34)&U34 -> 269NL300147 | X34: =COUNTIF($R$15:W34,W34)&W34 -> 1269NL300147 | Y34: =IFERROR(VLOOKUP(X34,Sheet4!$B$7:$M$1187,12,0),"0") -> 6 | Z34: =IFERROR(VLOOKUP(X34,Sheet4!$B$7:$N$1187,13,0),"0") -> 55000 | AA34: =Y34*Z34 -> 330000 | AB34: =Y34-L34 -> 0 | AC34: =Z34-M34 -> 0 | AD34: =AA34-N34 -> 0
C35: =C34 -> 26/09/2025 | D35: =D34 -> TG-KS01163 | E35: =E34 -> TIANLONG 01 | J35: Nấm đùi gà | K35: Kg | L35: 7 | M35: 45000 | N35: 315000 | O35: =M35*N35 -> 14175000000 | Q35: SOTG00110145382 | S35: Pricelist17 | T35: AdjDO | U35: =VLOOKUP(J35,Sheet1!$A$2:$D$200,4,0) -> NL300091 | V35: =VLOOKUP(U35,Sheet1!$D$2:$E$200,2,0) -> Nấm đùi gà | W35: =DAY(C35)&MONTH(C35)&U35 -> 269NL300091 | X35: =COUNTIF($R$15:W35,W35)&W35 -> 1269NL300091 | Y35: =IFERROR(VLOOKUP(X35,Sheet4!$B$7:$M$1187,12,0),"0") -> 7 | Z35: =IFERROR(VLOOKUP(X35,Sheet4!$B$7:$N$1187,13,0),"0") -> 45000 | AA35: =Y35*Z35 -> 315000 | AB35: =Y35-L35 -> 0 | AC35: =Z35-M35 -> 0 | AD35: =AA35-N35 -> 0
C36: 27/09/2025 | D36: =D35 -> TG-KS01163 | E36: =E35 -> TIANLONG 01 | J36: Cà chua | K36: Kg | L36: 2 | M36: 25000 | N36: 50000 | O36: =M36*N36 -> 1250000000 | Q36: SOTG00110145573 | S36: Pricelist17 | T36: AdjDO | U36: =VLOOKUP(J36,Sheet1!$A$2:$D$200,4,0) -> NL300013 | V36: =VLOOKUP(U36,Sheet1!$D$2:$E$200,2,0) -> Cà chua | W36: =DAY(C36)&MONTH(C36)&U36 -> 279NL300013 | X36: =COUNTIF($R$15:W36,W36)&W36 -> 1279NL300013 | Y36: =IFERROR(VLOOKUP(X36,Sheet4!$B$7:$M$1187,12,0),"0") -> 2 | Z36: =IFERROR(VLOOKUP(X36,Sheet4!$B$7:$N$1187,13,0),"0") -> 25000 | AA36: =Y36*Z36 -> 50000 | AB36: =Y36-L36 -> 0 | AC36: =Z36-M36 -> 0 | AD36: =AA36-N36 -> 0
C37: =C36 -> 27/09/2025 | D37: =D36 -> TG-KS01163 | E37: =E36 -> TIANLONG 01 | J37: Cải thảo | K37: Kg | L37: 10 | M37: 14000 | N37: 140000 | O37: =M37*N37 -> 1960000000 | Q37: SOTG00110145573 | S37: Pricelist17 | T37: AdjDO | U37: =VLOOKUP(J37,Sheet1!$A$2:$D$200,4,0) -> NL300022 | V37: =VLOOKUP(U37,Sheet1!$D$2:$E$200,2,0) -> Cải thảo | W37: =DAY(C37)&MONTH(C37)&U37 -> 279NL300022 | X37: =COUNTIF($R$15:W37,W37)&W37 -> 1279NL300022 | Y37: =IFERROR(VLOOKUP(X37,Sheet4!$B$7:$M$1187,12,0),"0") -> 9 | Z37: =IFERROR(VLOOKUP(X37,Sheet4!$B$7:$N$1187,13,0),"0") -> 14000 | AA37: =Y37*Z37 -> 126000 | AB37: =Y37-L37 -> -1 | AC37: =Z37-M37 -> 0 | AD37: =AA37-N37 -> -14000
C38: =C37 -> 27/09/2025 | D38: =D37 -> TG-KS01163 | E38: =E37 -> TIANLONG 01 | J38: Chanh không hạt | K38: Kg | L38: 1 | M38: 21000 | N38: 21000 | O38: =M38*N38 -> 441000000 | Q38: SOTG00110145573 | S38: Pricelist17 | T38: AdjDO | U38: =VLOOKUP(J38,Sheet1!$A$2:$D$200,4,0) -> NL300029 | V38: =VLOOKUP(U38,Sheet1!$D$2:$E$200,2,0) -> Chanh | W38: =DAY(C38)&MONTH(C38)&U38 -> 279NL300029 | X38: =COUNTIF($R$15:W38,W38)&W38 -> 1279NL300029 | Y38: =IFERROR(VLOOKUP(X38,Sheet4!$B$7:$M$1187,12,0),"0") -> 1 | Z38: =IFERROR(VLOOKUP(X38,Sheet4!$B$7:$N$1187,13,0),"0") -> 21000 | AA38: =Y38*Z38 -> 21000 | AB38: =Y38-L38 -> 0 | AC38: =Z38-M38 -> 0 | AD38: =AA38-N38 -> 0
C39: =C38 -> 27/09/2025 | D39: =D38 -> TG-KS01163 | E39: =E38 -> TIANLONG 01 | J39: Dưa hấu | K39: Kg | L39: 21.5 | M39: 16000 | N39: 344000 | O39: =M39*N39 -> 5504000000 | Q39: SOTG00110145573 | S39: Pricelist17 | T39: AdjDO | U39: =VLOOKUP(J39,Sheet1!$A$2:$D$200,4,0) -> NL600004 | V39: =VLOOKUP(U39,Sheet1!$D$2:$E$200,2,0) -> Dưa hấu | W39: =DAY(C39)&MONTH(C39)&U39 -> 279NL600004 | X39: =COUNTIF($R$15:W39,W39)&W39 -> 1279NL600004 | Y39: =IFERROR(VLOOKUP(X39,Sheet4!$B$7:$M$1187,12,0),"0") -> 21.5 | Z39: =IFERROR(VLOOKUP(X39,Sheet4!$B$7:$N$1187,13,0),"0") -> 16000 | AA39: =Y39*Z39 -> 344000 | AB39: =Y39-L39 -> 0 | AC39: =Z39-M39 -> 0 | AD39: =AA39-N39 -> 0
C40: =C39 -> 27/09/2025 | D40: =D39 -> TG-KS01163 | E40: =E39 -> TIANLONG 01 | J40: Hành lá | K40: Kg | L40: 1 | M40: 31000 | N40: 31000 | O40: =M40*N40 -> 961000000 | Q40: SOTG00110145573 | S40: Pricelist17 | T40: AdjDO | U40: =VLOOKUP(J40,Sheet1!$A$2:$D$200,4,0) -> NL300058 | V40: =VLOOKUP(U40,Sheet1!$D$2:$E$200,2,0) -> Hành lá | W40: =DAY(C40)&MONTH(C40)&U40 -> 279NL300058 | X40: =COUNTIF($R$15:W40,W40)&W40 -> 1279NL300058 | Y40: =IFERROR(VLOOKUP(X40,Sheet4!$B$7:$M$1187,12,0),"0") -> 1 | Z40: =IFERROR(VLOOKUP(X40,Sheet4!$B$7:$N$1187,13,0),"0") -> 31000 | AA40: =Y40*Z40 -> 31000 | AB40: =Y40-L40 -> 0 | AC40: =Z40-M40 -> 0 | AD40: =AA40-N40 -> 0
C41: =C40 -> 27/09/2025 | D41: =D40 -> TG-KS01163 | E41: =E40 -> TIANLONG 01 | J41: Húng lũi | K41: Kg | L41: 0.5 | M41: 54000 | N41: 27000 | O41: =M41*N41 -> 1458000000 | Q41: SOTG00110145573 | S41: Pricelist17 | T41: AdjDO | U41: =VLOOKUP(J41,Sheet1!$A$2:$D$200,4,0) -> NL300062 | V41: =VLOOKUP(U41,Sheet1!$D$2:$E$200,2,0) -> Húng Bạc Hà | W41: =DAY(C41)&MONTH(C41)&U41 -> 279NL300062 | X41: =COUNTIF($R$15:W41,W41)&W41 -> 1279NL300062 | Y41: =IFERROR(VLOOKUP(X41,Sheet4!$B$7:$M$1187,12,0),"0") -> 0.5 | Z41: =IFERROR(VLOOKUP(X41,Sheet4!$B$7:$N$1187,13,0),"0") -> 54000 | AA41: =Y41*Z41 -> 27000 | AB41: =Y41-L41 -> 0 | AC41: =Z41-M41 -> 0 | AD41: =AA41-N41 -> 0
C42: =C41 -> 27/09/2025 | D42: =D41 -> TG-KS01163 | E42: =E41 -> TIANLONG 01 | J42: Lá chuối | K42: Kg | L42: 1.1 | M42: 18000 | N42: 19800 | O42: =M42*N42 -> 356400000 | Q42: SOTG00110145573 | S42: Pricelist17 | T42: AdjDO | U42: =VLOOKUP(J42,Sheet1!$A$2:$D$200,4,0) -> NL300074 | V42: =VLOOKUP(U42,Sheet1!$D$2:$E$200,2,0) -> Lá chuối | W42: =DAY(C42)&MONTH(C42)&U42 -> 279NL300074 | X42: =COUNTIF($R$15:W42,W42)&W42 -> 1279NL300074 | Y42: =IFERROR(VLOOKUP(X42,Sheet4!$B$7:$M$1187,12,0),"0") -> 1.1 | Z42: =IFERROR(VLOOKUP(X42,Sheet4!$B$7:$N$1187,13,0),"0") -> 18000 | AA42: =Y42*Z42 -> 19800 | AB42: =Y42-L42 -> 0 | AC42: =Z42-M42 -> 0 | AD42: =AA42-N42 -> 0
C43: =C42 -> 27/09/2025 | D43: =D42 -> TG-KS01163 | E43: =E42 -> TIANLONG 01 | J43: Mồng tơi | K43: Kg | L43: 3.3 | M43: 20000 | N43: 66000 | O43: =M43*N43 -> 1320000000 | Q43: SOTG00110145573 | S43: Pricelist17 | T43: AdjDO | U43: =VLOOKUP(J43,Sheet1!$A$2:$D$200,4,0) -> NL300084 | V43: =VLOOKUP(U43,Sheet1!$D$2:$E$200,2,0) -> Mồng tơi nhặt | W43: =DAY(C43)&MONTH(C43)&U43 -> 279NL300084 | X43: =COUNTIF($R$15:W43,W43)&W43 -> 1279NL300084 | Y43: =IFERROR(VLOOKUP(X43,Sheet4!$B$7:$M$1187,12,0),"0") -> 2.7 | Z43: =IFERROR(VLOOKUP(X43,Sheet4!$B$7:$N$1187,13,0),"0") -> 20000 | AA43: =Y43*Z43 -> 54000 | AB43: =Y43-L43 -> -0.6 | AC43: =Z43-M43 -> 0 | AD43: =AA43-N43 -> -12000
C44: =C43 -> 27/09/2025 | D44: =D43 -> TG-KS01163 | E44: =E43 -> TIANLONG 01 | J44: Nấm đông cô tươi | K44: Kg | L44: 2 | M44: 138000 | N44: 276000 | O44: =M44*N44 -> 38088000000 | Q44: SOTG00110145573 | S44: Pricelist17 | T44: AdjDO | U44: =VLOOKUP(J44,Sheet1!$A$2:$D$200,4,0) -> NL300090 | V44: =VLOOKUP(U44,Sheet1!$D$2:$E$200,2,0) -> Nấm đông cô tươi | W44: =DAY(C44)&MONTH(C44)&U44 -> 279NL300090 | X44: =COUNTIF($R$15:W44,W44)&W44 -> 1279NL300090 | Y44: =IFERROR(VLOOKUP(X44,Sheet4!$B$7:$M$1187,12,0),"0") -> 2 | Z44: =IFERROR(VLOOKUP(X44,Sheet4!$B$7:$N$1187,13,0),"0") -> 138000 | AA44: =Y44*Z44 -> 276000 | AB44: =Y44-L44 -> 0 | AC44: =Z44-M44 -> 0 | AD44: =AA44-N44 -> 0
C45: =C44 -> 27/09/2025 | D45: TG-KS01163 | E45: TIANLONG 01 | J45: Nấm hải sản (kg) | K45: Kg | L45: 1 | M45: 63000 | N45: 63000 | O45: =M45*N45 -> 3969000000 | Q45: SOTG00110145573 | S45: Pricelist17 | T45: AdjDO | U45: =VLOOKUP(J45,Sheet1!$A$2:$D$200,4,0) -> NL300094 | V45: =VLOOKUP(U45,Sheet1!$D$2:$E$200,2,0) -> Nấm hải sản | W45: =DAY(C45)&MONTH(C45)&U45 -> 279NL300094 | X45: =COUNTIF($R$15:W45,W45)&W45 -> 1279NL300094 | Y45: =IFERROR(VLOOKUP(X45,Sheet4!$B$7:$M$1187,12,0),"0") -> 1 | Z45: =IFERROR(VLOOKUP(X45,Sheet4!$B$7:$N$1187,13,0),"0") -> 63000 | AA45: =Y45*Z45 -> 63000 | AB45: =Y45-L45 -> 0 | AC45: =Z45-M45 -> 0 | AD45: =AA45-N45 -> 0
C46: =C45 -> 27/09/2025 | D46: =D45 -> TG-KS01163 | E46: =E45 -> TIANLONG 01 | J46: Nấm kim châm gói (200g) | K46: Gói | L46: 20 | M46: 11000 | N46: 220000 | O46: =M46*N46 -> 2420000000 | Q46: SOTG00110145573 | S46: Pricelist17 | T46: AdjDO | U46: =VLOOKUP(J46,Sheet1!$A$2:$D$200,4,0) -> NL300096 | V46: =VLOOKUP(U46,Sheet1!$D$2:$E$200,2,0) -> Nấm kim châm tươi | W46: =DAY(C46)&MONTH(C46)&U46 -> 279NL300096 | X46: =COUNTIF($R$15:W46,W46)&W46 -> 1279NL300096 | Y46: =IFERROR(VLOOKUP(X46,Sheet4!$B$7:$M$1187,12,0),"0") -> 4 | Z46: =IFERROR(VLOOKUP(X46,Sheet4!$B$7:$N$1187,13,0),"0") -> 45000 | AA46: =Y46*Z46 -> 180000 | AB46: =Y46-L46 -> -16 | AC46: =Z46-M46 -> 34000 | AD46: =AA46-N46 -> -40000
C47: =C46 -> 27/09/2025 | D47: =D46 -> TG-KS01163 | E47: =E46 -> TIANLONG 01 | J47: Nấm linh chi trắng (kg) | K47: Kg | L47: 3 | M47: 90000 | N47: 270000 | O47: =M47*N47 -> 24300000000 | Q47: SOTG00110145573 | S47: Pricelist17 | T47: AdjDO | U47: =VLOOKUP(J47,Sheet1!$A$2:$D$200,4,0) -> NL300098 | V47: =VLOOKUP(U47,Sheet1!$D$2:$E$200,2,0) -> Nấm Linh Chi trắng | W47: =DAY(C47)&MONTH(C47)&U47 -> 279NL300098 | X47: =COUNTIF($R$15:W47,W47)&W47 -> 1279NL300098 | Y47: =IFERROR(VLOOKUP(X47,Sheet4!$B$7:$M$1187,12,0),"0") -> 3 | Z47: =IFERROR(VLOOKUP(X47,Sheet4!$B$7:$N$1187,13,0),"0") -> 90000 | AA47: =Y47*Z47 -> 270000 | AB47: =Y47-L47 -> 0 | AC47: =Z47-M47 -> 0 | AD47: =AA47-N47 -> 0
...

Sheet Sheet4
C3: Bảng kê hóa đơn mua hàng
M5: =SUBTOTAL(9,M7:M687) -> 393 | P5: =SUBTOTAL(9,P7:P687) -> 13383700
C6: Ngày ct | D6: Mã ct | E6: Số ct | F6: Áp giá | G6: Mã ncc | H6: Tên ncc | I6: Diễn giải | J6: Mã hàng | K6: Tên mặt hàng | L6: Đvt | M6: Số lượng | N6: Giá | O6: Giá báo | P6: Tiền | Q6: Chênh lệch giá | R6: Kho hàng | S6: Mã nx | T6: Vụ việc | U6: Bộ phận | V6: Hợp đồng
A7: =DAY(C7)&MONTH(C7)&J7 -> 269NL300013 | B7: =COUNTIF($A$7:A7,A7)&A7 -> 1269NL300013 | C7: 45926 | D7: HD | E7: 2509TSG01100 | F7: 1 | G7: SCC00003 | H7: HCM-NCC rau-CTy TNHH NS TP Trần Gia | I7: TSG01 - Nhập hàng mua ngày 26/09/2025 | J7: NL300013 | K7: Cà chua | L7: kg | M7: 3 | N7: 25000 | O7: 0 | P7: 75000 | Q7: 25000 | R7: TSG.01 | S7: 331801 | U7: TSG01 | W7: =VLOOKUP(B7,titan!$X$15:$Y$718,2,0)-M7 -> 0
A8: =DAY(C8)&MONTH(C8)&J8 -> 269NL300022 | B8: =COUNTIF($A$7:A8,A8)&A8 -> 1269NL300022 | C8: 45926 | D8: HD | E8: 2509TSG01100 | F8: 1 | G8: SCC00003 | H8: HCM-NCC rau-CTy TNHH NS TP Trần Gia | I8: TSG01 - Nhập hàng mua ngày 26/09/2025 | J8: NL300022 | K8: Cải thảo | L8: kg | M8: 9 | N8: 14000 | O8: 0 | P8: 126000 | Q8: 14000 | R8: TSG.01 | S8: 331801 | U8: TSG01 | W8: =VLOOKUP(B8,titan!$X$15:$Y$718,2,0)-M8 -> 0
A9: =DAY(C9)&MONTH(C9)&J9 -> 269NL300033 | B9: =COUNTIF($A$7:A9,A9)&A9 -> 1269NL300033 | C9: 45926 | D9: HD | E9: 2509TSG01100 | F9: 1 | G9: SCC00003 | H9: HCM-NCC rau-CTy TNHH NS TP Trần Gia | I9: TSG01 - Nhập hàng mua ngày 26/09/2025 | J9: NL300033 | K9: Củ cải trắng | L9: kg | M9: 2 | N9: 11000 | O9: 0 | P9: 22000 | Q9: 11000 | R9: TSG.01 | S9: 331801 | U9: TSG01 | W9: =VLOOKUP(B9,titan!$X$15:$Y$718,2,0)-M9 -> 0
A10: =DAY(C10)&MONTH(C10)&J10 -> 269NL300036 | B10: =COUNTIF($A$7:A10,A10)&A10 -> 1269NL300036 | C10: 45926 | D10: HD | E10: 2509TSG01100 | F10: 1 | G10: SCC00003 | H10: HCM-NCC rau-CTy TNHH NS TP Trần Gia | I10: TSG01 - Nhập hàng mua ngày 26/09/2025 | J10: NL300036 | K10: Củ sen | L10: kg | M10: 2 | N10: 44000 | O10: 0 | P10: 88000 | Q10: 44000 | R10: TSG.01 | S10: 331801 | U10: TSG01 | W10: =VLOOKUP(B10,titan!$X$15:$Y$718,2,0)-M10 -> 0
A11: =DAY(C11)&MONTH(C11)&J11 -> 269NL300058 | B11: =COUNTIF($A$7:A11,A11)&A11 -> 1269NL300058 | C11: 45926 | D11: HD | E11: 2509TSG01100 | F11: 1 | G11: SCC00003 | H11: HCM-NCC rau-CTy TNHH NS TP Trần Gia | I11: TSG01 - Nhập hàng mua ngày 26/09/2025 | J11: NL300058 | K11: Hành lá | L11: kg | M11: 0.9 | N11: 31000 | O11: 0 | P11: 27900 | Q11: 31000 | R11: TSG.01 | S11: 331801 | U11: TSG01 | W11: =VLOOKUP(B11,titan!$X$15:$Y$718,2,0)-M11 -> 0
A12: =DAY(C12)&MONTH(C12)&J12 -> 269NL300085 | B12: =COUNTIF($A$7:A12,A12)&A12 -> 1269NL300085 | C12: 45926 | D12: HD | E12: 2509TSG01100 | F12: 1 | G12: SCC00003 | H12: HCM-NCC rau-CTy TNHH NS TP Trần Gia | I12: TSG01 - Nhập hàng mua ngày 26/09/2025 | J12: NL300085 | K12: Mùi ta ( Ngò rí ) | L12: kg | M12: 0.8 | N12: 45000 | O12: 0 | P12: 36000 | Q12: 45000 | R12: TSG.01 | S12: 331801 | U12: TSG01 | W12: =VLOOKUP(B12,titan!$X$15:$Y$718,2,0)-M12 -> 0
A13: =DAY(C13)&MONTH(C13)&J13 -> 269NL300090 | B13: =COUNTIF($A$7:A13,A13)&A13 -> 1269NL300090 | C13: 45926 | D13: HD | E13: 2509TSG01100 | F13: 1 | G13: SCC00003 | H13: HCM-NCC rau-CTy TNHH NS TP Trần Gia | I13: TSG01 - Nhập hàng mua ngày 26/09/2025 | J13: NL300090 | K13: Nấm đông cô tươi | L13: kg | M13: 2 | N13: 138000 | O13: 0 | P13: 276000 | Q13: 138000 | R13: TSG.01 | S13: 331801 | U13: TSG01 | W13: =VLOOKUP(B13,titan!$X$15:$Y$718,2,0)-M13 -> 0
A14: =DAY(C14)&MONTH(C14)&J14 -> 269NL300096 | B14: =COUNTIF($A$7:A14,A14)&A14 -> 1269NL300096 | C14: 45926 | D14: HD | E14: 2509TSG01100 | F14: 1 | G14: SCC00003 | H14: HCM-NCC rau-CTy TNHH NS TP Trần Gia | I14: TSG01 - Nhập hàng mua ngày 26/09/2025 | J14: NL300096 | K14: Nấm kim châm tươi | L14: kg | M14: 3 | N14: 45000 | O14: 0 | P14: 135000 | Q14: 45000 | R14: TSG.01 | S14: 331801 | U14: TSG01 | W14: =VLOOKUP(B14,titan!$X$15:$Y$718,2,0)-M14 -> 0
A15: =DAY(C15)&MONTH(C15)&J15 -> 269NL300098 | B15: =COUNTIF($A$7:A15,A15)&A15 -> 1269NL300098 | C15: 45926 | D15: HD | E15: 2509TSG01100 | F15: 1 | G15: SCC00003 | H15: HCM-NCC rau-CTy TNHH NS TP Trần Gia | I15: TSG01 - Nhập hàng mua ngày 26/09/2025 | J15: NL300098 | K15: Nấm Linh Chi trắng | L15: kg | M15: 5 | N15: 90000 | O15: 0 | P15: 450000 | Q15: 90000 | R15: TSG.01 | S15: 331801 | U15: TSG01 | W15: =VLOOKUP(B15,titan!$X$15:$Y$718,2,0)-M15 -> 0
A16: =DAY(C16)&MONTH(C16)&J16 -> 269NL300107 | B16: =COUNTIF($A$7:A16,A16)&A16 -> 1269NL300107 | C16: 45926 | D16: HD | E16: 2509TSG01100 | F16: 1 | G16: SCC00003 | H16: HCM-NCC rau-CTy TNHH NS TP Trần Gia | I16: TSG01 - Nhập hàng mua ngày 26/09/2025 | J16: NL300107 | K16: Ngô ngọt ( Bắp trái) | L16: Cái | M16: 10 | N16: 8000 | O16: 0 | P16: 80000 | Q16: 8000 | R16: TSG.01 | S16: 331801 | U16: TSG01 | W16: =VLOOKUP(B16,titan!$X$15:$Y$718,2,0)-M16 -> 0
A17: =DAY(C17)&MONTH(C17)&J17 -> 269NL300126 | B17: =COUNTIF($A$7:A17,A17)&A17 -> 1269NL300126 | C17: 45926 | D17: HD | E17: 2509TSG01100 | F17: 1 | G17: SCC00003 | H17: HCM-NCC rau-CTy TNHH NS TP Trần Gia | I17: TSG01 - Nhập hàng mua ngày 26/09/2025 | J17: NL300126 | K17: Rau mùi tây | L17: kg | M17: 0.2 | N17: 90000 | O17: 0 | P17: 18000 | Q17: 90000 | R17: TSG.01 | S17: 331801 | U17: TSG01 | W17: =VLOOKUP(B17,titan!$X$15:$Y$718,2,0)-M17 -> 0
A18: =DAY(C18)&MONTH(C18)&J18 -> 269NL300142 | B18: =COUNTIF($A$7:A18,A18)&A18 -> 1269NL300142 | C18: 45926 | D18: HD | E18: 2509TSG01100 | F18: 1 | G18: SCC00003 | H18: HCM-NCC rau-CTy TNHH NS TP Trần Gia | I18: TSG01 - Nhập hàng mua ngày 26/09/2025 | J18: NL300142 | K18: Tỏi bóc | L18: kg | M18: 2 | N18: 55000 | O18: 0 | P18: 110000 | Q18: 55000 | R18: TSG.01 | S18: 331801 | U18: TSG01 | W18: =VLOOKUP(B18,titan!$X$15:$Y$718,2,0)-M18 -> 0
