Workbook

Sheet TAL 6
D2: CÔNG TY TNHH NÔNG SẢN THỰC PHẨM TRẦN GIA HTX: Ấp Lộc Tiến, Xã Mỹ Lộc, Huyện Cần Giuộc, Tỉnh Long An VP: Tòa nhà An Phú Plaza, 117-119 Lý Chính Thắng, P.7. Q.3, TP.HCM Kho sơ chế: 30 Kha Vạn Cân, P. Hiệp Bình Chánh, TP.Thủ Đức, TP.HCM Kho Đà Lạt: 69 Trần Thủ Độ, TT Liên Nghĩa, Huyện Đức Trọng, Tỉnh Lâm Đồng. Website: rausachtrangia.com - Hotline: 090.245.8081
A4: CHI TIẾT ĐỐI CHIẾU CÔNG NỢ
A6: Từ ngày 01 tháng 01 đến ngày 15 tháng 01 năm 2026
A8: Tên Khách hàng: TIANLONG 06
A10: Địa chỉ:
A12: Người liên hệ: Email:
J13: =SUBTOTAL(9,J15:J330) -> 47186350
A14: NGÀY | B14: MÃ KHÁCH HÀNG | C14: TÊN KHÁCH HÀNG | D14: MÃ ĐƠN HÀNG | E14: MÃ HÀNG | F14: TÊN HÀNG | G14: ĐVT | H14: SỐ LƯỢNG | I14: ĐƠN GIÁ | J14: THÀNH TIỀN | K14: GHI CHÚ
A15: 01/01/2026 | B15: TG-KS01261 | C15: TIANLONG 06 | D15: TG-AA20650 | E15: I100008 | F15: Bắp mỹ trái (Loại 1) | G15: Trái | H15: 10 | I15: 8500 | J15: =H15*I15 -> 85000
A16: 01/01/2026 | B16: TG-KS01261 | C16: TIANLONG 06 | D16: TG-AA20650 | E16: I100012 | F16: Bí đỏ hồ lô | G16: Kg | H16: 1 | I16: 30000 | J16: =H16*I16 -> 30000
A17: 01/01/2026 | B17: TG-KS01261 | C17: TIANLONG 06 | D17: TG-AA20650 | E17: I100018 | F17: Bó xôi (Nhà Lồng) | G17: Kg | H17: 4 | I17: 45000 | J17: =H17*I17 -> 180000
A18: 01/01/2026 | B18: TG-KS01261 | C18: TIANLONG 06 | D18: TG-AA20650 | E18: I100034 | F18: Cà chua | G18: Kg | H18: 1 | I18: 50000 | J18: =H18*I18 -> 50000
A19: 01/01/2026 | B19: TG-KS01261 | C19: TIANLONG 06 | D19: TG-AA20650 | E19: I100051 | F19: Cải thảo | G19: Kg | H19: 16 | I19: 18000 | J19: =H19*I19 -> 288000
A20: 01/01/2026 | B20: TG-KS01261 | C20: TIANLONG 06 | D20: TG-AA20650 | E20: I100469 | F20: Cam vàng | G20: Kg | H20: 0.55 | I20: 75000 | J20: =H20*I20 -> 41250
A21: 01/01/2026 | B21: TG-KS01261 | C21: TIANLONG 06 | D21: TG-AA20650 | E21: I100060 | F21: Chanh không hạt | G21: Kg | H21: 0.5 | I21: 22000 | J21: =H21*I21 -> 11000
A22: 01/01/2026 | B22: TG-KS01261 | C22: TIANLONG 06 | D22: TG-AA20650 | E22: I100067 | F22: Củ cải trắng (Loại 1) | G22: Kg | H22: 3.3 | I22: 13000 | J22: =H22*I22 -> 42900
A23: 01/01/2026 | B23: TG-KS01261 | C23: TIANLONG 06 | D23: TG-AA20650 | E23: I100074 | F23: Củ sen | G23: Kg | H23: 2.1 | I23: 47000 | J23: =H23*I23 -> 98700
A24: 01/01/2026 | B24: TG-KS01261 | C24: TIANLONG 06 | D24: TG-AA20650 | E24: I100479 | F24: Dưa hấu | G24: Kg | H24: 45 | I24: 18000 | J24: =H24*I24 -> 810000
A25: 01/01/2026 | B25: TG-KS01261 | C25: TIANLONG 06 | D25: TG-AA20650 | E25: I100098 | F25: Hành lá | G25: Kg | H25: 2 | I25: 55000 | J25: =H25*I25 -> 110000
A26: 01/01/2026 | B26: TG-KS01261 | C26: TIANLONG 06 | D26: TG-AA20650 | E26: I100923 | F26: Hoa cúc tím | G26: Bó | H26: 1 | I26: 80000 | J26: =H26*I26 -> 80000
... A330: 15/01/2026 | B330: TG-KS01261 | C330: TIANLONG 06 | D330: TG-AA23132 | E330: I100209 | F330: Xà lách romain | G330: Kg | H330: 5 | I330: 62000 | J330: =H330*I330 -> 310000

Sheet TAL 7
D2: CÔNG TY TNHH NÔNG SẢN THỰC PHẨM TRẦN GIA HTX: Ấp Lộc Tiến, Xã Mỹ Lộc, Huyện Cần Giuộc, Tỉnh Long An VP: Tòa nhà An Phú Plaza, 117-119 Lý Chính Thắng, P.7. Q.3, TP.HCM Kho sơ chế: 30 Kha Vạn Cân, P. Hiệp Bình Chánh, TP.Thủ Đức, TP.HCM Kho Đà Lạt: 69 Trần Thủ Độ, TT Liên Nghĩa, Huyện Đức Trọng, Tỉnh Lâm Đồng. Website: rausachtrangia.com - Hotline: 090.245.8081
A4: CHI TIẾT ĐỐI CHIẾU CÔNG NỢ
A6: Từ ngày 01 tháng 01 đến ngày 15 tháng 01 năm 2026
A8: Tên Khách hàng: TIANLONG 07
A10: Địa chỉ:
A12: Người liên hệ: Email:
J13: =SUBTOTAL(9,J15:J301) -> 32444830 | N13: tsg07 | O13: =SUBTOTAL(9,O15:O308) -> 30416030 | Q13: =O13-Sheet2!N1 -> 0
A14: NGÀY | B14: MÃ KHÁCH HÀNG | C14: TÊN KHÁCH HÀNG | D14: MÃ ĐƠN HÀNG | E14: MÃ HÀNG | F14: TÊN HÀNG | G14: ĐVT | H14: SỐ LƯỢNG | I14: ĐƠN GIÁ | J14: THÀNH TIỀN | K14: GHI CHÚ | L14: MÃ | M14: THỰC NHẬN | N14: GIÁ CHỐT | O14: TỔNG | P14: LỆCH | Q14: NOTE | U14: SAI SL | V14: SAI GIÁ CHỐT
A15: 01/01/2026 | B15: TG-KS01259 | C15: TIANLONG 07 | D15: TG-AA20651 | E15: I100008 | F15: Bắp mỹ trái (Loại 1) | G15: Trái | H15: 3 | I15: 8500 | J15: =H15*I15 -> 25500 | L15: =+VLOOKUP(E15,MÃ!$B$2:$F$229,2,0) -> NL300107 | M15: =+VLOOKUP(T15,Sheet2!$B$2:$N$305,10,0) -> 3 | N15: =+VLOOKUP(L15,MÃ!$C$2:$F$226,4,0) -> 8500 | O15: =M15*N15 -> 25500 | P15: =J15-O15 -> 0 | Q15: =IF(U15=0," ","SAI SL NHẬN") | R15: =+VLOOKUP(T15,Sheet2!$B$2:$N$305,13,0) -> 25500 | S15: =O15-R15 -> 0 | T15: =A15&L15 -> 01/01/2026NL300107 | U15: =H15-M15 -> 0 | V15: =I15-N15 -> 0
A16: 01/01/2026 | B16: TG-KS01259 | C16: TIANLONG 07 | D16: TG-AA20651 | E16: I100051 | F16: Cải thảo | G16: Kg | H16: 11.7 | I16: 18000 | J16: =H16*I16 -> 210600 | L16: =+VLOOKUP(E16,MÃ!$B$2:$F$229,2,0) -> NL300022 | M16: =+VLOOKUP(T16,Sheet2!$B$2:$N$305,10,0) -> 10.5 | N16: =+VLOOKUP(L16,MÃ!$C$2:$F$226,4,0) -> 18000 | O16: =M16*N16 -> 189000 | P16: =J16-O16 -> 21600 | Q16: =IF(U16=0," ","SAI SL NHẬN") -> SAI SL NHẬN | R16: =+VLOOKUP(T16,Sheet2!$B$2:$N$305,13,0) -> 189000 | S16: =O16-R16 -> 0 | T16: =A16&L16 -> 01/01/2026NL300022 | U16: =H16-M16 -> 1.2 | V16: =I16-N16 -> 0
A17: 01/01/2026 | B17: TG-KS01259 | C17: TIANLONG 07 | D17: TG-AA20651 | E17: I100067 | F17: Củ cải trắng (Loại 1) | G17: Kg | H17: 0.8 | I17: 13000 | J17: =H17*I17 -> 10400 | L17: =+VLOOKUP(E17,MÃ!$B$2:$F$229,2,0) -> NL300033 | M17: =+VLOOKUP(T17,Sheet2!$B$2:$N$305,10,0) -> 0.8 | N17: =+VLOOKUP(L17,MÃ!$C$2:$F$226,4,0) -> 13000 | O17: =M17*N17 -> 10400 | P17: =J17-O17 -> 0 | Q17: =IF(U17=0," ","SAI SL NHẬN") | R17: =+VLOOKUP(T17,Sheet2!$B$2:$N$305,13,0) -> 10400 | S17: =O17-R17 -> 0 | T17: =A17&L17 -> 01/01/2026NL300033 | U17: =H17-M17 -> 0 | V17: =I17-N17 -> 0
A18: 01/01/2026 | B18: TG-KS01259 | C18: TIANLONG 07 | D18: TG-AA20651 | E18: I100479 | F18: Dưa hấu | G18: Kg | H18: 8.8 | I18: 18000 | J18: =H18*I18 -> 158400 | L18: =+VLOOKUP(E18,MÃ!$B$2:$F$229,2,0) -> NL600004 | M18: =+VLOOKUP(T18,Sheet2!$B$2:$N$305,10,0) -> 8.8 | N18: =+VLOOKUP(L18,MÃ!$C$2:$F$226,4,0) -> 18000 | O18: =M18*N18 -> 158400 | P18: =J18-O18 -> 0 | Q18: =IF(U18=0," ","SAI SL NHẬN") | R18: =+VLOOKUP(T18,Sheet2!$B$2:$N$305,13,0) -> 158400 | S18: =O18-R18 -> 0 | T18: =A18&L18 -> 01/01/2026NL600004 | U18: =H18-M18 -> 0 | V18: =I18-N18 -> 0
A19: 01/01/2026 | B19: TG-KS01259 | C19: TIANLONG 07 | D19: TG-AA20651 | E19: I100098 | F19: Hành lá | G19: Kg | H19: 0.27 | I19: 55000 | J19: =H19*I19 -> 14850 | L19: =+VLOOKUP(E19,MÃ!$B$2:$F$229,2,0) -> NL300058 | M19: =+VLOOKUP(T19,Sheet2!$B$2:$N$305,10,0) -> 0.27 | N19: =+VLOOKUP(L19,MÃ!$C$2:$F$226,4,0) -> 55000 | O19: =M19*N19 -> 14850 | P19: =J19-O19 -> 0 | Q19: =IF(U19=0," ","SAI SL NHẬN") | R19: =+VLOOKUP(T19,Sheet2!$B$2:$N$305,13,0) -> 14850 | S19: =O19-R19 -> 0 | T19: =A19&L19 -> 01/01/2026NL300058 | U19: =H19-M19 -> 0 | V19: =I19-N19 -> 0
A20: 01/01/2026 | B20: TG-KS01259 | C20: TIANLONG 07 | D20: TG-AA20651 | E20: I100125 | F20: Khoai môn cao | G20: Kg | H20: 1.4 | I20: 30000 | J20: =H20*I20 -> 42000 | L20: =+VLOOKUP(E20,MÃ!$B$2:$F$229,2,0) -> NL300209 | M20: =+VLOOKUP(T20,Sheet2!$B$2:$N$305,10,0) -> 1 | N20: =+VLOOKUP(L20,MÃ!$C$2:$F$226,4,0) -> 30000 | O20: =M20*N20 -> 30000 | P20: =J20-O20 -> 12000 | Q20: =IF(U20=0," ","SAI SL NHẬN") -> SAI SL NHẬN | R20: =+VLOOKUP(T20,Sheet2!$B$2:$N$305,13,0) -> 30000 | S20: =O20-R20 -> 0 | T20: =A20&L20 -> 01/01/2026NL300209 | U20: =H20-M20 -> 0.4 | V20: =I20-N20 -> 0
A21: 01/01/2026 | B21: TG-KS01259 | C21: TIANLONG 07 | D21: TG-AA20651 | E21: I100135 | F21: Lá chuối | G21: Kg | H21: 0.7 | I21: 18000 | J21: =H21*I21 -> 12600 | L21: =+VLOOKUP(E21,MÃ!$B$2:$F$229,2,0) -> NL300074 | M21: =+VLOOKUP(T21,Sheet2!$B$2:$N$305,10,0) -> 0.7 | N21: =+VLOOKUP(L21,MÃ!$C$2:$F$226,4,0) -> 18000 | O21: =M21*N21 -> 12600 | P21: =J21-O21 -> 0 | Q21: =IF(U21=0," ","SAI SL NHẬN") | R21: =+VLOOKUP(T21,Sheet2!$B$2:$N$305,13,0) -> 12600 | S21: =O21-R21 -> 0 | T21: =A21&L21 -> 01/01/2026NL300074 | U21: =H21-M21 -> 0 | V21: =I21-N21 -> 0
A22: 01/01/2026 | B22: TG-KS01259 | C22: TIANLONG 07 | D22: TG-AA20651 | E22: I100236 | F22: Nấm đông cô tươi | G22: Kg | H22: 2 | I22: 145000 | J22: =H22*I22 -> 290000 | L22: =+VLOOKUP(E22,MÃ!$B$2:$F$229,2,0) -> NL300090 | M22: =+VLOOKUP(T22,Sheet2!$B$2:$N$305,10,0) -> 2 | N22: =+VLOOKUP(L22,MÃ!$C$2:$F$226,4,0) -> 145000 | O22: =M22*N22 -> 290000 | P22: =J22-O22 -> 0 | Q22: =IF(U22=0," ","SAI SL NHẬN") | R22: =+VLOOKUP(T22,Sheet2!$B$2:$N$305,13,0) -> 290000 | S22: =O22-R22 -> 0 | T22: =A22&L22 -> 01/01/2026NL300090 | U22: =H22-M22 -> 0 | V22: =I22-N22 -> 0
A23: 01/01/2026 | B23: TG-KS01259 | C23: TIANLONG 07 | D23: TG-AA20651 | E23: I100237 | F23: Nấm đùi gà | G23: Kg | H23: 3 | I23: 47000 | J23: =H23*I23 -> 141000 | L23: =+VLOOKUP(E23,MÃ!$B$2:$F$229,2,0) -> NL300091 | M23: =+VLOOKUP(T23,Sheet2!$B$2:$N$305,10,0) -> 3 | N23: =+VLOOKUP(L23,MÃ!$C$2:$F$226,4,0) -> 47000 | O23: =M23*N23 -> 141000 | P23: =J23-O23 -> 0 | Q23: =IF(U23=0," ","SAI SL NHẬN") | R23: =+VLOOKUP(T23,Sheet2!$B$2:$N$305,13,0) -> 141000 | S23: =O23-R23 -> 0 | T23: =A23&L23 -> 01/01/2026NL300091 | U23: =H23-M23 -> 0 | V23: =I23-N23 -> 0
A24: 01/01/2026 | B24: TG-KS01259 | C24: TIANLONG 07 | D24: TG-AA20651 | E24: I100240 | F24: Nấm kim châm tươi | G24: Kg | H24: 3 | I24: 45000 | J24: =H24*I24 -> 135000 | L24: =+VLOOKUP(E24,MÃ!$B$2:$F$229,2,0) -> NL300096 | M24: =+VLOOKUP(T24,Sheet2!$B$2:$N$305,10,0) -> 3 | N24: =+VLOOKUP(L24,MÃ!$C$2:$F$226,4,0) -> 45000 | O24: =M24*N24 -> 135000 | P24: =J24-O24 -> 0 | Q24: =IF(U24=0," ","SAI SL NHẬN") | R24: =+VLOOKUP(T24,Sheet2!$B$2:$N$305,13,0) -> 135000 | S24: =O24-R24 -> 0 | T24: =A24&L24 -> 01/01/2026NL300096 | U24: =H24-M24 -> 0 | V24: =I24-N24 -> 0
A25: 01/01/2026 | B25: TG-KS01259 | C25: TIANLONG 07 | D25: TG-AA20651 | E25: I100921 | F25: Nấm linh chi trắng (kg) | G25: Kg | H25: 2.2 | I25: 95000 | J25: =H25*I25 -> 209000 | L25: =+VLOOKUP(E25,MÃ!$B$2:$F$229,2,0) -> NL300098 | M25: =+VLOOKUP(T25,Sheet2!$B$2:$N$305,10,0) -> 2.2 | N25: =+VLOOKUP(L25,MÃ!$C$2:$F$226,4,0) -> 95000 | O25: =M25*N25 -> 209000 | P25: =J25-O25 -> 0 | Q25: =IF(U25=0," ","SAI SL NHẬN") | R25: =+VLOOKUP(T25,Sheet2!$B$2:$N$305,13,0) -> 209000 | S25: =O25-R25 -> 0 | T25: =A25&L25 -> 01/01/2026NL300098 | U25: =H25-M25 -> 0 | V25: =I25-N25 -> 0
A26: 01/01/2026 | B26: TG-KS01259 | C26: TIANLONG 07 | D26: TG-AA20651 | E26: I100156 | F26: Ngò rí | G26: Kg | H26: 0.5 | I26: 45000 | J26: =H26*I26 -> 22500 | L26: =+VLOOKUP(E26,MÃ!$B$2:$F$229,2,0) -> NL300085 | M26: =+VLOOKUP(T26,Sheet2!$B$2:$N$305,10,0) -> 0.2 | N26: =+VLOOKUP(L26,MÃ!$C$2:$F$226,4,0) -> 45000 | O26: =M26*N26 -> 9000 | P26: =J26-O26 -> 13500 | Q26: =IF(U26=0," ","SAI SL NHẬN") -> SAI SL NHẬN | R26: =+VLOOKUP(T26,Sheet2!$B$2:$N$305,13,0) -> 9000 | S26: =O26-R26 -> 0 | T26: =A26&L26 -> 01/01/2026NL300085 | U26: =H26-M26 -> 0.3 | V26: =I26-N26 -> 0
... A129: 06/01/2026 | B129: TG-KS01259 | C129: TIANLONG 07 | D129: TG-AA21467 | E129: I100216 | F129: Tắc trái | G129: Kg | H129: 2.4 | I129: 21000 | J129: =H129*I129 -> 50400 | L129: =+VLOOKUP(E129,MÃ!$B$2:$F$229,2,0) -> NL300119 | M129: =+VLOOKUP(T129,Sheet2!$B$2:$N$305,10,0) -> 1.4 | N129: =+VLOOKUP(L129,MÃ!$C$2:$F$226,4,0) -> 21000 | O129: =M129*N129 -> 29400 | P129: =J129-O129 -> 21000 | Q129: =IF(U129=0," ","SAI SL NHẬN") -> SAI SL NHẬN | R129: =+VLOOKUP(T129,Sheet2!$B$2:$N$305,13,0) -> 29400 | S129: =O129-R129 -> 0 | T129: =A129&L129 -> 06/01/2026NL300119 | U129: =H129-M129 -> 1 | V129: =I129-N129 -> 0
A130: 06/01/2026 | B130: TG-KS01259 | C130: TIANLONG 07 | D130: TG-AA21467 | E130: I100217 | F130: Tần ô | G130: Kg | H130: 1 | I130: 38000 | J130: =H130*I130 -> 38000 | L130: =+VLOOKUP(E130,MÃ!$B$2:$F$229,2,0) -> NL300018 | M130: 0 | N130: =+VLOOKUP(L130,MÃ!$C$2:$F$226,4,0) -> 38000 | O130: =M130*N130 -> 0 | P130: =J130-O130 -> 38000 | Q130: =IF(U130=0," ","SAI SL NHẬN") -> SAI SL NHẬN | R130: 0 | S130: =O130-R130 -> 0 | T130: =A130&L130 -> 06/01/2026NL300018 | U130: =H130-M130 -> 1 | V130: =I130-N130 -> 0
A131: 07/01/2026 | B131: TG-KS01259 | C131: TIANLONG 07 | D131: TG-AA21639 | E131: I100018 | F131: Bó xôi (Nhà Lồng) | G131: Kg | H131: 1 | I131: 45000 | J131: =H131*I131 -> 45000 | L131: =+VLOOKUP(E131,MÃ!$B$2:$F$229,2,0) -> NL300203 | M131: =+VLOOKUP(T131,Sheet2!$B$2:$N$305,10,0) -> 1 | N131: =+VLOOKUP(L131,MÃ!$C$2:$F$226,4,0) -> 45000 | O131: =M131*N131 -> 45000 | P131: =J131-O131 -> 0 | Q131: =IF(U131=0," ","SAI SL NHẬN") | R131: =+VLOOKUP(T131,Sheet2!$B$2:$N$305,13,0) -> 45000 | S131: =O131-R131 -> 0 | T131: =A131&L131 -> 07/01/2026NL300203 | U131: =H131-M131 -> 0 | V131: =I131-N131 -> 0
A132: 07/01/2026 | B132: TG-KS01259 | C132: TIANLONG 07 | D132: TG-AA21639 | E132: I100051 | F132: Cải thảo | G132: Kg | H132: 10 | I132: 18000 | J132: =H132*I132 -> 180000 | L132: =+VLOOKUP(E132,MÃ!$B$2:$F$229,2,0) -> NL300022 | M132: =+VLOOKUP(T132,Sheet2!$B$2:$N$305,10,0) -> 6.8 | N132: =+VLOOKUP(L132,MÃ!$C$2:$F$226,4,0) -> 18000 | O132: =M132*N132 -> 122400 | P132: =J132-O132 -> 57600 | Q132: =IF(U132=0," ","SAI SL NHẬN") -> SAI SL NHẬN | R132: =+VLOOKUP(T132,Sheet2!$B$2:$N$305,13,0) -> 122400 | S132: =O132-R132 -> 0 | T132: =A132&L132 -> 07/01/2026NL300022 | U132: =H132-M132 -> 3.2 | V132: =I132-N132 -> 0
A133: 07/01/2026 | B133: TG-KS01259 | C133: TIANLONG 07 | D133: TG-AA21639 | E133: I100474 | F133: Chanh Dây | G133: Kg | H133: 0.55 | I133: 34000 | J133: =H133*I133 -> 18700 | L133: =+VLOOKUP(E133,MÃ!$B$2:$F$229,2,0) -> NL300030 | M133: =+VLOOKUP(T133,Sheet2!$B$2:$N$305,10,0) -> 0.55 | N133: =+VLOOKUP(L133,MÃ!$C$2:$F$226,4,0) -> 34000 | O133: =M133*N133 -> 18700 | P133: =J133-O133 -> 0 | Q133: =IF(U133=0," ","SAI SL NHẬN") | R133: =+VLOOKUP(T133,Sheet2!$B$2:$N$305,13,0) -> 18700 | S133: =O133-R133 -> 0 | T133: =A133&L133 -> 07/01/2026NL300030 | U133: =H133-M133 -> 0 | V133: =I133-N133 -> 0
A134: 07/01/2026 | B134: TG-KS01259 | C134: TIANLONG 07 | D134: TG-AA21639 | E134: I100074 | F134: Củ sen | G134: Kg | H134: 0.25 | I134: 47000 | J134: =H134*I134 -> 11750 | L134: =+VLOOKUP(E134,MÃ!$B$2:$F$229,2,0) -> NL300036 | M134: =+VLOOKUP(T134,Sheet2!$B$2:$N$305,10,0) -> 0.25 | N134: =+VLOOKUP(L134,MÃ!$C$2:$F$226,4,0) -> 47000 | O134: =M134*N134 -> 11750 | P134: =J134-O134 -> 0 | Q134: =IF(U134=0," ","SAI SL NHẬN") | R134: =+VLOOKUP(T134,Sheet2!$B$2:$N$305,13,0) -> 11750 | S134: =O134-R134 -> 0 | T134: =A134&L134 -> 07/01/2026NL300036 | U134: =H134-M134 -> 0 | V134: =I134-N134 -> 0
A135: 07/01/2026 | B135: TG-KS01259 | C135: TIANLONG 07 | D135: TG-AA21639 | E135: I100125 | F135: Khoai môn cao | G135: Kg | H135: 1.26 | I135: 30000 | J135: =H135*I135 -> 37800 | L135: =+VLOOKUP(E135,MÃ!$B$2:$F$229,2,0) -> NL300209 | M135: =+VLOOKUP(T135,Sheet2!$B$2:$N$305,10,0) -> 1.26 | N135: =+VLOOKUP(L135,MÃ!$C$2:$F$226,4,0) -> 30000 | O135: =M135*N135 -> 37800 | P135: =J135-O135 -> 0 | Q135: =IF(U135=0," ","SAI SL NHẬN") | R135: =+VLOOKUP(T135,Sheet2!$B$2:$N$305,13,0) -> 37800 | S135: =O135-R135 -> 0 | T135: =A135&L135 -> 07/01/2026NL300209 | U135: =H135-M135 -> 0 | V135: =I135-N135 -> 0
A136: 07/01/2026 | B136: TG-KS01259 | C136: TIANLONG 07 | D136: TG-AA21639 | E136: I100150 | F136: Mồng tơi | G136: Kg | H136: 1 | I136: 22000 | J136: =H136*I136 -> 22000 | L136: =+VLOOKUP(E136,MÃ!$B$2:$F$229,2,0) -> NL300084 | M136: =+VLOOKUP(T136,Sheet2!$B$2:$N$305,10,0) -> 0.8 | N136: =+VLOOKUP(L136,MÃ!$C$2:$F$226,4,0) -> 22000 | O136: =M136*N136 -> 17600 | P136: =J136-O136 -> 4400 | Q136: =IF(U136=0," ","SAI SL NHẬN") -> SAI SL NHẬN | R136: =+VLOOKUP(T136,Sheet2!$B$2:$N$305,13,0) -> 17600 | S136: =O136-R136 -> 0 | T136: =A136&L136 -> 07/01/2026NL300084 | U136: =H136-M136 -> 0.2 | V136: =I136-N136 -> 0
A137: 07/01/2026 | B137: TG-KS01259 | C137: TIANLONG 07 | D137: TG-AA21639 | E137: I100236 | F137: Nấm đông cô tươi | G137: Kg | H137: 2 | I137: 145000 | J137: =H137*I137 -> 290000 | L137: =+VLOOKUP(E137,MÃ!$B$2:$F$229,2,0) -> NL300090 | M137: =+VLOOKUP(T137,Sheet2!$B$2:$N$305,10,0) -> 2 | N137: =+VLOOKUP(L137,MÃ!$C$2:$F$226,4,0) -> 145000 | O137: =M137*N137 -> 290000 | P137: =J137-O137 -> 0 | Q137: =IF(U137=0," ","SAI SL NHẬN") | R137: =+VLOOKUP(T137,Sheet2!$B$2:$N$305,13,0) -> 290000 | S137: =O137-R137 -> 0 | T137: =A137&L137 -> 07/01/2026NL300090 | U137: =H137-M137 -> 0 | V137: =I137-N137 -> 0
A138: 07/01/2026 | B138: TG-KS01259 | C138: TIANLONG 07 | D138: TG-AA21639 | E138: I100237 | F138: Nấm đùi gà | G138: Kg | H138: 3 | I138: 47000 | J138: =H138*I138 -> 141000 | L138: =+VLOOKUP(E138,MÃ!$B$2:$F$229,2,0) -> NL300091 | M138: =+VLOOKUP(T138,Sheet2!$B$2:$N$305,10,0) -> 3 | N138: =+VLOOKUP(L138,MÃ!$C$2:$F$226,4,0) -> 47000 | O138: =M138*N138 -> 141000 | P138: =J138-O138 -> 0 | Q138: =IF(U138=0," ","SAI SL NHẬN") | R138: =+VLOOKUP(T138,Sheet2!$B$2:$N$305,13,0) -> 141000 | S138: =O138-R138 -> 0 | T138: =A138&L138 -> 07/01/2026NL300091 | U138: =H138-M138 -> 0 | V138: =I138-N138 -> 0
A139: 07/01/2026 | B139: TG-KS01259 | C139: TIANLONG 07 | D139: TG-AA21639 | E139: I100240 | F139: Nấm kim châm tươi | G139: Kg | H139: 2 | I139: 45000 | J139: =H139*I139 -> 90000 | L139: =+VLOOKUP(E139,MÃ!$B$2:$F$229,2,0) -> NL300096 | M139: =+VLOOKUP(T139,Sheet2!$B$2:$N$305,10,0) -> 2 | N139: =+VLOOKUP(L139,MÃ!$C$2:$F$226,4,0) -> 45000 | O139: =M139*N139 -> 90000 | P139: =J139-O139 -> 0 | Q139: =IF(U139=0," ","SAI SL NHẬN") | R139: =+VLOOKUP(T139,Sheet2!$B$2:$N$305,13,0) -> 90000 | S139: =O139-R139 -> 0 | T139: =A139&L139 -> 07/01/2026NL300096 | U139: =H139-M139 -> 0 | V139: =I139-N139 -> 0
A140: 07/01/2026 | B140: TG-KS01259 | C140: TIANLONG 07 | D140: TG-AA21639 | E140: I100921 | F140: Nấm linh chi trắng (kg) | G140: Kg | H140: 2 | I140: 95000 | J140: =H140*I140 -> 190000 | L140: =+VLOOKUP(E140,MÃ!$B$2:$F$229,2,0) -> NL300098 | M140: =+VLOOKUP(T140,Sheet2!$B$2:$N$305,10,0) -> 2 | N140: =+VLOOKUP(L140,MÃ!$C$2:$F$226,4,0) -> 95000 | O140: =M140*N140 -> 190000 | P140: =J140-O140 -> 0 | Q140: =IF(U140=0," ","SAI SL NHẬN") | R140: =+VLOOKUP(T140,Sheet2!$B$2:$N$305,13,0) -> 190000 | S140: =O140-R140 -> 0 | T140: =A140&L140 -> 07/01/2026NL300098 | U140: =H140-M140 -> 0 | V140: =I140-N140 -> 0
A141: 07/01/2026 | B141: TG-KS01259 | C141: TIANLONG 07 | D141: TG-AA21639 | E141: I100216 | F141: Tắc trái | G141: Kg | H141: 3 | I141: 21000 | J141: =H141*I141 -> 63000 | L141: =+VLOOKUP(E141,MÃ!$B$2:$F$229,2,0) -> NL300119 | M141: =+VLOOKUP(T141,Sheet2!$B$2:$N$305,10,0) -> 3 | N141: =+VLOOKUP(L141,MÃ!$C$2:$F$226,4,0) -> 21000 | O141: =M141*N141 -> 63000 | P141: =J141-O141 -> 0 | Q141: =IF(U141=0," ","SAI SL NHẬN") | R141: =+VLOOKUP(T141,Sheet2!$B$2:$N$305,13,0) -> 63000 | S141: =O141-R141 -> 0 | T141: =A141&L141 -> 07/01/2026NL300119 | U141: =H141-M141 -> 0 | V141: =I141-N141 -> 0
A142: 07/01/2026 | B142: TG-KS01259 | C142: TIANLONG 07 | D142: TG-AA21639 | E142: I100217 | F142: Tần ô | G142: Kg | H142: 1 | I142: 38000 | J142: =H142*I142 -> 38000 | L142: =+VLOOKUP(E142,MÃ!$B$2:$F$229,2,0) -> NL300018 | M142: =+VLOOKUP(T142,Sheet2!$B$2:$N$305,10,0) -> 0.9 | N142: =+VLOOKUP(L142,MÃ!$C$2:$F$226,4,0) -> 38000 | O142: =M142*N142 -> 34200 | P142: =J142-O142 -> 3800 | Q142: =IF(U142=0," ","SAI SL NHẬN") -> SAI SL NHẬN | R142: =+VLOOKUP(T142,Sheet2!$B$2:$N$305,13,0) -> 34200 | S142: =O142-R142 -> 0 | T142: =A142&L142 -> 07/01/2026NL300018 | U142: =H142-M142 -> 0.1 | V142: =I142-N142 -> 0
... A182: 09/01/2026 | B182: TG-KS01259 | C182: TIANLONG 07 | D182: TG-AA22108 | E182: I100209 | F182: Xà lách romain | G182: Kg | H182: 4 | I182: 62000 | J182: =H182*I182 -> 248000 | L182: =+VLOOKUP(E182,MÃ!$B$2:$F$229,2,0) -> NL300147 | M182: =+VLOOKUP(T182,Sheet2!$B$2:$N$305,10,0) -> 4 | N182: =+VLOOKUP(L182,MÃ!$C$2:$F$226,4,0) -> 62000 | O182: =M182*N182 -> 248000 | P182: =J182-O182 -> 0 | Q182: =IF(U182=0," ","SAI SL NHẬN") | R182: =+VLOOKUP(T182,Sheet2!$B$2:$N$305,13,0) -> 248000 | S182: =O182-R182 -> 0 | T182: =A182&L182 -> 09/01/2026NL300147 | U182: =H182-M182 -> 0 | V182: =I182-N182 -> 0
A183: 09/01/2026 | B183: TG-KS01259 | C183: TIANLONG 07 | D183: TG-AA22140 | E183: I100240 | F183: Nấm kim châm tươi | G183: Kg | H183: 3 | I183: 45000 | J183: =H183*I183 -> 135000 | L183: =+VLOOKUP(E183,MÃ!$B$2:$F$229,2,0) -> NL300096 | M183: 0 | N183: =+VLOOKUP(L183,MÃ!$C$2:$F$226,4,0) -> 45000 | O183: =M183*N183 -> 0 | P183: =J183-O183 -> 135000 | Q183: =IF(U183=0," ","SAI SL NHẬN") -> SAI SL NHẬN | R183: 0 | S183: =O183-R183 -> 0 | T183: =A183&L183 -> 09/01/2026NL300096 | U183: =H183-M183 -> 3 | V183: =I183-N183 -> 0
A184: 09/01/2026 | B184: TG-KS01259 | C184: TIANLONG 07 | D184: TG-AA22140 | E184: I100216 | F184: Tắc trái | G184: Kg | H184: 2 | I184: 21000 | J184: =H184*I184 -> 42000 | L184: =+VLOOKUP(E184,MÃ!$B$2:$F$229,2,0) -> NL300119 | M184: 2 | N184: =+VLOOKUP(L184,MÃ!$C$2:$F$226,4,0) -> 21000 | O184: =M184*N184 -> 42000 | P184: =J184-O184 -> 0 | Q184: =IF(U184=0," ","SAI SL NHẬN") | R184: =+VLOOKUP(T184,Sheet2!$B$2:$N$305,13,0) -> 21000 | S184: =O184-R184 -> 21000 | T184: =A184&L184 -> 09/01/2026NL300119 | U184: =H184-M184 -> 0 | V184: =I184-N184 -> 0
A185: 10/01/2026 | B185: TG-KS01259 | C185: TIANLONG 07 | D185: TG-AA22313 | E185: I100008 | F185: Bắp mỹ trái (Loại 1) | G185: Trái | H185: 3 | I185: 8500 | J185: =H185*I185 -> 25500 | L185: =+VLOOKUP(E185,MÃ!$B$2:$F$229,2,0) -> NL300107 | M185: =+VLOOKUP(T185,Sheet2!$B$2:$N$305,10,0) -> 3 | N185: =+VLOOKUP(L185,MÃ!$C$2:$F$226,4,0) -> 8500 | O185: =M185*N185 -> 25500 | P185: =J185-O185 -> 0 | Q185: =IF(U185=0," ","SAI SL NHẬN") | R185: =+VLOOKUP(T185,Sheet2!$B$2:$N$305,13,0) -> 25500 | S185: =O185-R185 -> 0 | T185: =A185&L185 -> 10/01/2026NL300107 | U185: =H185-M185 -> 0 | V185: =I185-N185 -> 0
A186: 10/01/2026 | B186: TG-KS01259 | C186: TIANLONG 07 | D186: TG-AA22313 | E186: I100012 | F186: Bí đỏ hồ lô | G186: Kg | H186: 1.5 | I186: 30000 | J186: =H186*I186 -> 45000 | L186: =+VLOOKUP(E186,MÃ!$B$2:$F$229,2,0) -> NL300007 | M186: =+VLOOKUP(T186,Sheet2!$B$2:$N$305,10,0) -> 1.5 | N186: =+VLOOKUP(L186,MÃ!$C$2:$F$226,4,0) -> 30000 | O186: =M186*N186 -> 45000 | P186: =J186-O186 -> 0 | Q186: =IF(U186=0," ","SAI SL NHẬN") | R186: =+VLOOKUP(T186,Sheet2!$B$2:$N$305,13,0) -> 45000 | S186: =O186-R186 -> 0 | T186: =A186&L186 -> 10/01/2026NL300007 | U186: =H186-M186 -> 0 | V186: =I186-N186 -> 0
A187: 10/01/2026 | B187: TG-KS01259 | C187: TIANLONG 07 | D187: TG-AA22313 | E187: I100018 | F187: Bó xôi (Nhà Lồng) | G187: Kg | H187: 1 | I187: 45000 | J187: =H187*I187 -> 45000 | L187: =+VLOOKUP(E187,MÃ!$B$2:$F$229,2,0) -> NL300203 | M187: =+VLOOKUP(T187,Sheet2!$B$2:$N$305,10,0) -> 1 | N187: =+VLOOKUP(L187,MÃ!$C$2:$F$226,4,0) -> 45000 | O187: =M187*N187 -> 45000 | P187: =J187-O187 -> 0 | Q187: =IF(U187=0," ","SAI SL NHẬN") | R187: =+VLOOKUP(T187,Sheet2!$B$2:$N$305,13,0) -> 45000 | S187: =O187-R187 -> 0 | T187: =A187&L187 -> 10/01/2026NL300203 | U187: =H187-M187 -> 0 | V187: =I187-N187 -> 0
...

Sheet Sheet2
A1: Ngày ct | B1: Mã ct | C1: Số ct | D1: Áp giá | E1: Mã ncc | F1: Tên ncc | G1: Diễn giải | H1: Mã hàng | I1: Tên mặt hàng | J1: Đvt | K1: Số lượng | L1: Giá | M1: Giá báo | N1: =SUBTOTAL(9,N2:N303) -> 30416030 | O1: Thuế suất | P1: Chênh lệch giá | Q1: Kho hàng | R1: Mã nx | S1: Vụ việc | T1: Bộ phận | U1: Hợp đồng | V1: Người tạo | W1: Người sửa
A2: 46023 | B2: ="0"&DAY(A2)&"/01/2026"&H2 -> 01/01/2026NL300033 | C2: 2601TSG07002 | D2: 1 | E2: NCC100186 | F2: CÔNG TY TNHH NÔNG SẢN THỰC PHẨM TRẦN GIA | G2: TSG07 - Nhập hàng mua ngày 01/01/2026 | H2: NL300033 | I2: Củ cải trắng | J2: kg | K2: 0.8 | L2: 13000 | M2: 0 | N2: =L2*K2 -> 10400 | O2: 0 | P2: 13000 | Q2: TSG.07 | R2: 3311 | T2: TSG07 | V2: TRANNTB | W2: TRANNTB
A3: 46023 | B3: ="0"&DAY(A3)&"/01/2026"&H3 -> 01/01/2026NL300058 | C3: 2601TSG07002 | D3: 1 | E3: NCC100186 | F3: CÔNG TY TNHH NÔNG SẢN THỰC PHẨM TRẦN GIA | G3: TSG07 - Nhập hàng mua ngày 01/01/2026 | H3: NL300058 | I3: Hành lá | J3: kg | K3: 0.27 | L3: 55000 | M3: 0 | N3: =L3*K3 -> 14850 | O3: 0 | P3: 55000 | Q3: TSG.07 | R3: 3311 | T3: TSG07 | V3: TRANNTB | W3: TRANNTB
A4: 46023 | B4: ="0"&DAY(A4)&"/01/2026"&H4 -> 01/01/2026NL300074 | C4: 2601TSG07002 | D4: 1 | E4: NCC100186 | F4: CÔNG TY TNHH NÔNG SẢN THỰC PHẨM TRẦN GIA | G4: TSG07 - Nhập hàng mua ngày 01/01/2026 | H4: NL300074 | I4: Lá chuối | J4: kg | K4: 0.7 | L4: 18000 | M4: 0 | N4: =L4*K4 -> 12600 | O4: 0 | P4: 18000 | Q4: TSG.07 | R4: 3311 | T4: TSG07 | V4: TRANNTB | W4: TRANNTB
A5: 46023 | B5: ="0"&DAY(A5)&"/01/2026"&H5 -> 01/01/2026NL300085 | C5: 2601TSG07002 | D5: 1 | E5: NCC100186 | F5: CÔNG TY TNHH NÔNG SẢN THỰC PHẨM TRẦN GIA | G5: TSG07 - Nhập hàng mua ngày 01/01/2026 | H5: NL300085 | I5: Mùi ta ( Ngò rí ) | J5: kg | K5: 0.2 | L5: 45000 | M5: 0 | N5: =L5*K5 -> 9000 | O5: 0 | P5: 45000 | Q5: TSG.07 | R5: 3311 | T5: TSG07 | V5: TRANNTB | W5: TRANNTB
A6: 46023 | B6: ="0"&DAY(A6)&"/01/2026"&H6 -> 01/01/2026NL300090 | C6: 2601TSG07002 | D6: 1 | E6: NCC100186 | F6: CÔNG TY TNHH NÔNG SẢN THỰC PHẨM TRẦN GIA | G6: TSG07 - Nhập hàng mua ngày 01/01/2026 | H6: NL300090 | I6: Nấm đông cô tươi | J6: kg | K6: 2 | L6: 145000 | M6: 0 | N6: =L6*K6 -> 290000 | O6: 0 | P6: 145000 | Q6: TSG.07 | R6: 3311 | T6: TSG07 | V6: TRANNTB | W6: TRANNTB
A7: 46023 | B7: ="0"&DAY(A7)&"/01/2026"&H7 -> 01/01/2026NL300091 | C7: 2601TSG07002 | D7: 1 | E7: NCC100186 | F7: CÔNG TY TNHH NÔNG SẢN THỰC PHẨM TRẦN GIA | G7: TSG07 - Nhập hàng mua ngày 01/01/2026 | H7: NL300091 | I7: Nấm đùi gà | J7: kg | K7: 3 | L7: 47000 | M7: 0 | N7: =L7*K7 -> 141000 | O7: 0 | P7: 47000 | Q7: TSG.07 | R7: 3311 | T7: TSG07 | V7: TRANNTB | W7: TRANNTB
A8: 46023 | B8: ="0"&DAY(A8)&"/01/2026"&H8 -> 01/01/2026NL300096 | C8: 2601TSG07002 | D8: 1 | E8: NCC100186 | F8: CÔNG TY TNHH NÔNG SẢN THỰC PHẨM TRẦN GIA | G8: TSG07 - Nhập hàng mua ngày 01/01/2026 | H8: NL300096 | I8: Nấm kim châm tươi | J8: kg | K8: 3 | L8: 45000 | M8: 0 | N8: =L8*K8 -> 135000 | O8: 0 | P8: 45000 | Q8: TSG.07 | R8: 3311 | T8: TSG07 | V8: TRANNTB | W8: TRANNTB
A9: 46023 | B9: ="0"&DAY(A9)&"/01/2026"&H9 -> 01/01/2026NL300098 | C9: 2601TSG07002 | D9: 1 | E9: NCC100186 | F9: CÔNG TY TNHH NÔNG SẢN THỰC PHẨM TRẦN GIA | G9: TSG07 - Nhập hàng mua ngày 01/01/2026 | H9: NL300098 | I9: Nấm Linh Chi trắng | J9: kg | K9: 2.2 | L9: 95000 | M9: 0 | N9: =L9*K9 -> 209000 | O9: 0 | P9: 95000 | Q9: TSG.07 | R9: 3311 | T9: TSG07 | V9: TRANNTB | W9: TRANNTB
A10: 46023 | B10: ="0"&DAY(A10)&"/01/2026"&H10 -> 01/01/2026NL300107 | C10: 2601TSG07002 | D10: 1 | E10: NCC100186 | F10: CÔNG TY TNHH NÔNG SẢN THỰC PHẨM TRẦN GIA | G10: TSG07 - Nhập hàng mua ngày 01/01/2026 | H10: NL300107 | I10: Ngô ngọt ( Bắp trái) | J10: Cái | K10: 3 | L10: 8500 | M10: 0 | N10: =L10*K10 -> 25500 | O10: 0 | P10: 8500 | Q10: TSG.07 | R10: 3311 | T10: TSG07 | V10: TRANNTB | W10: TRANNTB
A11: 46023 | B11: ="0"&DAY(A11)&"/01/2026"&H11 -> 01/01/2026NL300142 | C11: 2601TSG07002 | D11: 1 | E11: NCC100186 | F11: CÔNG TY TNHH NÔNG SẢN THỰC PHẨM TRẦN GIA | G11: TSG07 - Nhập hàng mua ngày 01/01/2026 | H11: NL300142 | I11: Tỏi bóc | J11: kg | K11: 0.5 | L11: 50000 | M11: 0 | N11: =L11*K11 -> 25000 | O11: 0 | P11: 50000 | Q11: TSG.07 | R11: 3311 | T11: TSG07 | V11: TRANNTB | W11: TRANNTB
A12: 46023 | B12: ="0"&DAY(A12)&"/01/2026"&H12 -> 01/01/2026NL300147 | C12: 2601TSG07002 | D12: 1 | E12: NCC100186 | F12: CÔNG TY TNHH NÔNG SẢN THỰC PHẨM TRẦN GIA | G12: TSG07 - Nhập hàng mua ngày 01/01/2026 | H12: NL300147 | I12: Xà lách Roman | J12: kg | K12: 7.1 | L12: 62000 | M12: 0 | N12: =L12*K12 -> 440200 | O12: 0 | P12: 62000 | Q12: TSG.07 | R12: 3311 | T12: TSG07 | V12: TRANNTB | W12: TRANNTB
A13: 46023 | B13: ="0"&DAY(A13)&"/01/2026"&H13 -> 01/01/2026NL300119 | C13: 2601TSG07002 | D13: 1 | E13: NCC100186 | F13: CÔNG TY TNHH NÔNG SẢN THỰC PHẨM TRẦN GIA | G13: TSG07 - Nhập hàng mua ngày 01/01/2026 | H13: NL300119 | I13: Quất ( Tắc trái ) | J13: kg | K13: 5.1 | L13: 21000 | M13: 0 | N13: =L13*K13 -> 107100 | O13: 0 | P13: 21000 | Q13: TSG.07 | R13: 3311 | T13: TSG07 | V13: TRANNTB | W13: TRANNTB
... A123: 46028 | B123: ="0"&DAY(A123)&"/01/2026"&H123 -> 06/01/2026NL300098 | C123: TSG072601017 | D123: 1 | E123: NCC100186 | F123: CÔNG TY TNHH NÔNG SẢN THỰC PHẨM TRẦN GIA | G123: TSG07 - Nhập hàng mua ngày 06/01/2026 | H123: NL300098 | I123: Nấm Linh Chi trắng | J123: kg | K123: 2 | L123: 95000 | M123: 0 | N123: =L123*K123 -> 190000 | O123: 0 | P123: 95000 | Q123: TSG.07 | R123: 3311 | T123: TSG07 | V123: TRANNTB | W123: TRANNTB
A124: 46028 | B124: ="0"&DAY(A124)&"/01/2026"&H124 -> 06/01/2026NL300119 | C124: TSG072601017 | D124: 1 | E124: NCC100186 | F124: CÔNG TY TNHH NÔNG SẢN THỰC PHẨM TRẦN GIA | G124: TSG07 - Nhập hàng mua ngày 06/01/2026 | H124: NL300119 | I124: Quất ( Tắc trái ) | J124: kg | K124: 1.4 | L124: 21000 | M124: 0 | N124: =L124*K124 -> 29400
A125: 46028 | B125: ="0"&DAY(A125)&"/01/2026"&H125 -> 06/01/2026NL300022 | C125: TSG072601017 | D125: 1 | E125: NCC100186 | F125: CÔNG TY TNHH NÔNG SẢN THỰC PHẨM TRẦN GIA | G125: TSG07 - Nhập hàng mua ngày 06/01/2026 | H125: NL300022 | I125: Cải thảo | J125: kg | K125: 6 | L125: 18000 | M125: 0 | N125: =L125*K125 -> 108000 | O125: 0 | P125: 21000 | Q125: TSG.07 | R125: 3311 | T125: TSG07 | V125: TRANNTB | W125: TRANNTB
A126: 46029 | B126: ="0"&DAY(A126)&"/01/2026"&H126 -> 07/01/2026NL300036 | C126: 2601TSG07020 | D126: 1 | E126: NCC100186 | F126: CÔNG TY TNHH NÔNG SẢN THỰC PHẨM TRẦN GIA | G126: TSG07 - Nhập hàng mua ngày 07/01/2026 | H126: NL300036 | I126: Củ sen | J126: kg | K126: 0.25 | L126: 47000 | M126: 0 | N126: =L126*K126 -> 11750 | O126: 0 | P126: 47000 | Q126: TSG.07 | R126: 3311 | T126: TSG07 | V126: TRANNTB | W126: TRANNTB
A127: 46029 | B127: ="0"&DAY(A127)&"/01/2026"&H127 -> 07/01/2026NL300084 | C127: 2601TSG07020 | D127: 1 | E127: NCC100186 | F127: CÔNG TY TNHH NÔNG SẢN THỰC PHẨM TRẦN GIA | G127: TSG07 - Nhập hàng mua ngày 07/01/2026 | H127: NL300084 | I127: Mồng tơi nhặt | J127: kg | K127: 0.8 | L127: 22000 | M127: 0 | N127: =L127*K127 -> 17600 | O127: 0 | P127: 22000 | Q127: TSG.07 | R127: 3311 | T127: TSG07 | V127: TRANNTB | W127: TRANNTB
A128: 46029 | B128: ="0"&DAY(A128)&"/01/2026"&H128 -> 07/01/2026NL300091 | C128: 2601TSG07020 | D128: 1 | E128: NCC100186 | F128: CÔNG TY TNHH NÔNG SẢN THỰC PHẨM TRẦN GIA | G128: TSG07 - Nhập hàng mua ngày 07/01/2026 | H128: NL300091 | I128: Nấm đùi gà | J128: kg | K128: 3 | L128: 47000 | M128: 0 | N128: =L128*K128 -> 141000 | O128: 0 | P128: 47000 | Q128: TSG.07 | R128: 3311 | T128: TSG07 | V128: TRANNTB | W128: TRANNTB
A129: 46029 | B129: ="0"&DAY(A129)&"/01/2026"&H129 -> 07/01/2026NL300096 | C129: 2601TSG07020 | D129: 1 | E129: NCC100186 | F129: CÔNG TY TNHH NÔNG SẢN THỰC PHẨM TRẦN GIA | G129: TSG07 - Nhập hàng mua ngày 07/01/2026 | H129: NL300096 | I129: Nấm kim châm tươi | J129: kg | K129: 2 | L129: 45000 | M129: 0 | N129: =L129*K129 -> 90000 | O129: 0 | P129: 45000 | Q129: TSG.07 | R129: 3311 | T129: TSG07 | V129: TRANNTB | W129: TRANNTB
A130: 46029 | B130: ="0"&DAY(A130)&"/01/2026"&H130 -> 07/01/2026NL300098 | C130: 2601TSG07020 | D130: 1 | E130: NCC100186 | F130: CÔNG TY TNHH NÔNG SẢN THỰC PHẨM TRẦN GIA | G130: TSG07 - Nhập hàng mua ngày 07/01/2026 | H130: NL300098 | I130: Nấm Linh Chi trắng | J130: kg | K130: 2 | L130: 95000 | M130: 0 | N130: =L130*K130 -> 190000 | O130: 0 | P130: 95000 | Q130: TSG.07 | R130: 3311 | T130: TSG07 | V130: TRANNTB | W130: TRANNTB
A131: 46029 | B131: ="0"&DAY(A131)&"/01/2026"&H131 -> 07/01/2026NL300147 | C131: 2601TSG07020 | D131: 1 | E131: NCC100186 | F131: CÔNG TY TNHH NÔNG SẢN THỰC PHẨM TRẦN GIA | G131: TSG07 - Nhập hàng mua ngày 07/01/2026 | H131: NL300147 | I131: Xà lách Roman | J131: kg | K131: 4 | L131: 62000 | M131: 0 | N131: =L131*K131 -> 248000 | O131: 0 | P131: 62000 | Q131: TSG.07 | R131: 3311 | T131: TSG07 | V131: TRANNTB | W131: TRANNTB
A132: 46029 | B132: ="0"&DAY(A132)&"/01/2026"&H132 -> 07/01/2026NL300203 | C132: 2601TSG07020 | D132: 1 | E132: NCC100186 | F132: CÔNG TY TNHH NÔNG SẢN THỰC PHẨM TRẦN GIA | G132: TSG07 - Nhập hàng mua ngày 07/01/2026 | H132: NL300203 | I132: Cải bó xôi | J132: kg | K132: 1 | L132: 45000 | M132: 0 | N132: =L132*K132 -> 45000 | O132: 0 | P132: 45000 | Q132: TSG.07 | R132: 3311 | T132: TSG07 | V132: TRANNTB | W132: TRANNTB
A133: 46029 | B133: ="0"&DAY(A133)&"/01/2026"&H133 -> 07/01/2026NL300218 | C133: 2601TSG07020 | D133: 1 | E133: NCC100186 | F133: CÔNG TY TNHH NÔNG SẢN THỰC PHẨM TRẦN GIA | G133: TSG07 - Nhập hàng mua ngày 07/01/2026 | H133: NL300218 | I133: Hoa cúc (decor) bó | J133: Bó | K133: 0 | L133: 40000 | M133: 0 | N133: =L133*K133 -> 0 | O133: 0 | P133: 40000 | Q133: TSG.07 | R133: 3311 | T133: TSG07 | V133: TRANNTB | W133: TRANNTB
A134: 46029 | B134: ="0"&DAY(A134)&"/01/2026"&H134 -> 07/01/2026NL300030 | C134: 2601TSG07020 | D134: 1 | E134: NCC100186 | F134: CÔNG TY TNHH NÔNG SẢN THỰC PHẨM TRẦN GIA | G134: TSG07 - Nhập hàng mua ngày 07/01/2026 | H134: NL300030 | I134: Chanh dây (chanh leo) | J134: kg | K134: 0.55 | L134: 34000 | M134: 0 | N134: =L134*K134 -> 18700 | O134: 0 | P134: 34000 | Q134: TSG.07 | R134: 3311 | T134: TSG07 | V134: TRANNTB | W134: TRANNTB
A135: 46029 | B135: ="0"&DAY(A135)&"/01/2026"&H135 -> 07/01/2026NL300119 | C135: 2601TSG07020 | D135: 1 | E135: NCC100186 | F135: CÔNG TY TNHH NÔNG SẢN THỰC PHẨM TRẦN GIA | G135: TSG07 - Nhập hàng mua ngày 07/01/2026 | H135: NL300119 | I135: Quất ( Tắc trái ) | J135: kg | K135: 3 | L135: 21000 | M135: 0 | N135: =L135*K135 -> 63000 | O135: 0 | P135: 21000 | Q135: TSG.07 | R135: 3311 | T135: TSG07 | V135: TRANNTB | W135: TRANNTB
A136: 46029 | B136: ="0"&DAY(A136)&"/01/2026"&H136 -> 07/01/2026NL300022 | C136: 2601TSG07020 | D136: 1 | E136: NCC100186 | F136: CÔNG TY TNHH NÔNG SẢN THỰC PHẨM TRẦN GIA | G136: TSG07 - Nhập hàng mua ngày 07/01/2026 | H136: NL300022 | I136: Cải thảo | J136: kg | K136: 6.8 | L136: 18000 | M136: 0 | N136: =L136*K136 -> 122400 | O136: 0 | P136: 18000 | Q136: TSG.07 | R136: 3311 | T136: TSG07 | V136: TRANNTB | W136: TRANNTB
... A180: 46031 | B180: ="0"&DAY(A180)&"/01/2026"&H180 -> 09/01/2026NL300119 | C180: TSG072601052 | D180: 1 | E180: NCC100186 | F180: CÔNG TY TNHH NÔNG SẢN THỰC PHẨM TRẦN GIA | G180: TSG07 - Nhập hàng mua ngày 09/01/2026 | H180: NL300119 | I180: Quất ( Tắc trái ) | J180: kg | K180: 2 | L180: 21000 | M180: 0 | N180: =L180*K180 -> 42000 | O180: 0 | P180: 21000 | Q180: TSG.07 | R180: 3311 | T180: TSG07 | V180: TRANNTB | W180: TRANNTB
A181: 46032 | B181: =""&DAY(A181)&"/01/2026"&H181 -> 10/01/2026NL300119 | C181: 2601TSG07029 | D181: 1 | E181: NCC100186 | F181: CÔNG TY TNHH NÔNG SẢN THỰC PHẨM TRẦN GIA | G181: TSG07 - Nhập hàng mua ngày 10/01/2026 | H181: NL300119 | I181: Quất ( Tắc trái ) | J181: kg | K181: 5.3 | L181: 21000 | M181: 0 | N181: =L181*K181 -> 111300 | O181: 0 | P181: 21000 | Q181: TSG.07 | R181: 3311 | T181: TSG07 | V181: TRANNTB | W181: TRANNTB
A182: 46032 | B182: =""&DAY(A182)&"/01/2026"&H182 -> 10/01/2026NL600004 | C182: 2601TSG07029 | D182: 1 | E182: NCC100186 | F182: CÔNG TY TNHH NÔNG SẢN THỰC PHẨM TRẦN GIA | G182: TSG07 - Nhập hàng mua ngày 10/01/2026 | H182: NL600004 | I182: Dưa hấu | J182: kg | K182: 19.5 | L182: 18000 | M182: 0 | N182: =L182*K182 -> 351000 | O182: 0 | P182: 18000 | Q182: TSG.07 | R182: 3311 | T182: TSG07 | V182: TRANNTB | W182: TRANNTB
A183: 46032 | B183: =""&DAY(A183)&"/01/2026"&H183 -> 10/01/2026NL600067 | C183: 2601TSG07029 | D183: 1 | E183: NCC100186 | F183: CÔNG TY TNHH NÔNG SẢN THỰC PHẨM TRẦN GIA | G183: TSG07 - Nhập hàng mua ngày 10/01/2026 | H183: NL600067 | I183: Cam vàng | J183: kg | K183: 0.8 | L183: 75000 | M183: 0 | N183: =L183*K183 -> 60000 | O183: 0 | P183: 75000 | Q183: TSG.07 | R183: 3311 | T183: TSG07 | V183: TRANNTB | W183: TRANNTB
A184: 46032 | B184: =""&DAY(A184)&"/01/2026"&H184 -> 10/01/2026NL300007 | C184: 2601TSG07029 | D184: 1 | E184: NCC100186 | F184: CÔNG TY TNHH NÔNG SẢN THỰC PHẨM TRẦN GIA | G184: TSG07 - Nhập hàng mua ngày 10/01/2026 | H184: NL300007 | I184: Bí đỏ | J184: kg | K184: 1.5 | L184: 30000 | M184: 0 | N184: =L184*K184 -> 45000 | O184: 0 | P184: 30000 | Q184: TSG.07 | R184: 3311 | T184: TSG07 | V184: TRANNTB | W184: TRANNTB
A185: 46032 | B185: =""&DAY(A185)&"/01/2026"&H185 -> 10/01/2026NL300013 | C185: 2601TSG07029 | D185: 1 | E185: NCC100186 | F185: CÔNG TY TNHH NÔNG SẢN THỰC PHẨM TRẦN GIA | G185: TSG07 - Nhập hàng mua ngày 10/01/2026 | H185: NL300013 | I185: Cà chua | J185: kg | K185: 1 | L185: 50000 | M185: 0 | N185: =L185*K185 -> 50000 | O185: 0 | P185: 50000 | Q185: TSG.07 | R185: 3311 | T185: TSG07 | V185: TRANNTB | W185: TRANNTB
A186: 46032 | B186: =""&DAY(A186)&"/01/2026"&H186 -> 10/01/2026NL300018 | C186: 2601TSG07029 | D186: 1 | E186: NCC100186 | F186: CÔNG TY TNHH NÔNG SẢN THỰC PHẨM TRẦN GIA | G186: TSG07 - Nhập hàng mua ngày 10/01/2026 | H186: NL300018 | I186: Cải cúc (Tần Ô) | J186: kg | K186: 1.4 | L186: 38000 | M186: 0 | N186: =L186*K186 -> 53200 | O186: 0 | P186: 38000 | Q186: TSG.07 | R186: 3311 | T186: TSG07 | V186: TRANNTB | W186: TRANNTB
A187: 46032 | B187: =""&DAY(A187)&"/01/2026"&H187 -> 10/01/2026NL300022 | C187: 2601TSG07029 | D187: 1 | E187: NCC100186 | F187: CÔNG TY TNHH NÔNG SẢN THỰC PHẨM TRẦN GIA | G187: TSG07 - Nhập hàng mua ngày 10/01/2026 | H187: NL300022 | I187: Cải thảo | J187: kg | K187: 10 | L187: 18000 | M187: 0 | N187: =L187*K187 -> 180000 | O187: 0 | P187: 18000 | Q187: TSG.07 | R187: 3311 | T187: TSG07 | V187: TRANNTB | W187: TRANNTB
A188: 46032 | B188: =""&DAY(A188)&"/01/2026"&H188 -> 10/01/2026NL300033 | C188: 2601TSG07029 | D188: 1 | E188: NCC100186 | F188: CÔNG TY TNHH NÔNG SẢN THỰC PHẨM TRẦN GIA | G188: TSG07 - Nhập hàng mua ngày 10/01/2026 | H188: NL300033 | I188: Củ cải trắng | J188: kg | K188: 1 | L188: 13000 | M188: 0 | N188: =L188*K188 -> 13000 | O188: 0 | P188: 13000 | Q188: TSG.07 | R188: 3311 | T188: TSG07 | V188: TRANNTB | W188: TRANNTB
A189: 46032 | B189: =""&DAY(A189)&"/01/2026"&H189 -> 10/01/2026NL300036 | C189: 2601TSG07029 | D189: 1 | E189: NCC100186 | F189: CÔNG TY TNHH NÔNG SẢN THỰC PHẨM TRẦN GIA | G189: TSG07 - Nhập hàng mua ngày 10/01/2026 | H189: NL300036 | I189: Củ sen | J189: kg | K189: 0.7 | L189: 47000 | M189: 0 | N189: =L189*K189 -> 32900 | O189: 0 | P189: 47000 | Q189: TSG.07 | R189: 3311 | T189: TSG07 | V189: TRANNTB | W189: TRANNTB
A190: 46032 | B190: =""&DAY(A190)&"/01/2026"&H190 -> 10/01/2026NL300058 | C190: 2601TSG07029 | D190: 1 | E190: NCC100186 | F190: CÔNG TY TNHH NÔNG SẢN THỰC PHẨM TRẦN GIA | G190: TSG07 - Nhập hàng mua ngày 10/01/2026 | H190: NL300058 | I190: Hành lá | J190: kg | K190: 1 | L190: 55000 | M190: 0 | N190: =L190*K190 -> 55000 | O190: 0 | P190: 55000 | Q190: TSG.07 | R190: 3311 | T190: TSG07 | V190: TRANNTB | W190: TRANNTB
A191: 46032 | B191: =""&DAY(A191)&"/01/2026"&H191 -> 10/01/2026NL300074 | C191: 2601TSG07029 | D191: 1 | E191: NCC100186 | F191: CÔNG TY TNHH NÔNG SẢN THỰC PHẨM TRẦN GIA | G191: TSG07 - Nhập hàng mua ngày 10/01/2026 | H191: NL300074 | I191: Lá chuối | J191: kg | K191: 0.6 | L191: 18000 | M191: 0 | N191: =L191*K191 -> 10800 | O191: 0 | P191: 18000 | Q191: TSG.07 | R191: 3311 | T191: TSG07 | V191: TRANNTB | W191: TRANNTB
A192: 46032 | B192: =""&DAY(A192)&"/01/2026"&H192 -> 10/01/2026NL300084 | C192: 2601TSG07029 | D192: 1 | E192: NCC100186 | F192: CÔNG TY TNHH NÔNG SẢN THỰC PHẨM TRẦN GIA | G192: TSG07 - Nhập hàng mua ngày 10/01/2026 | H192: NL300084 | I192: Mồng tơi nhặt | J192: kg | K192: 2 | L192: 22000 | M192: 0 | N192: =L192*K192 -> 44000 | O192: 0 | P192: 22000 | Q192: TSG.07 | R192: 3311 | T192: TSG07 | V192: TRANNTB | W192: TRANNTB
...

Sheet MÃ
A1: STT | B1: Mã TG | C1: Mã hàng | D1: Tên mặt hàng | E1: Đvt
A2: 1 | B2: I100258 | C2: NL430151 | D2: Bánh canh NV | E2: kg | F2: =+VLOOKUP(C2,[1]Sheet1!A$2:E$167,4,0) -> 20000
A3: 2 | B3: I100252 | C3: NL300002 | D3: Bánh phở | E3: kg | F3: =+VLOOKUP(C3,[1]Sheet1!A$2:E$167,4,0) -> 16000
A4: 3 | B4: I100002 | C4: NL300003 | D4: Bắp cải tím | E4: kg | F4: =+VLOOKUP(C4,[1]Sheet1!A$2:E$167,4,0) -> 26000
A5: 4 | B5: I100003 | C5: NL300004 | D5: Bắp cải trắng | E5: kg | F5: =+VLOOKUP(C5,[1]Sheet1!A$2:E$167,4,0) -> 19000
A6: 5 | B6: I100010 | C6: NL300174 | D6: Bầu | E6: kg | F6: =+VLOOKUP(C6,[1]Sheet1!A$2:E$167,4,0) -> 24000
A7: 6 | B7: I100010 | C7: NL430005 | D7: Bầu NV | E7: kg | F7: =+VLOOKUP(C7,[1]Sheet1!A$2:E$167,4,0) -> #N/A
A8: 7 | B8: I100017 | C8: NL430006 | D8: Bí bao tử NV | E8: kg | F8: =+VLOOKUP(C8,[1]Sheet1!A$2:E$167,4,0) -> #N/A
A9: 8 | B9: I100012 | C9: NL300007 | D9: Bí đỏ | E9: kg | F9: =+VLOOKUP(C9,[1]Sheet1!A$2:E$167,4,0) -> 30000
A10: 9 | B10: I100016 | C10: NL300008 | D10: Bí ngòi | E10: kg | F10: =+VLOOKUP(C10,[1]Sheet1!A$2:E$167,4,0) -> 40000
A11: 10 | B11: I100017 | C11: NL300009 | D11: Bí nụ | E11: kg | F11: =+VLOOKUP(C11,[1]Sheet1!A$2:E$167,4,0) -> #N/A
A12: 11 | B12: I100011 | C12: NL430009 | D12: Bí xanh NV | E12: kg | F12: =+VLOOKUP(C12,[1]Sheet1!A$2:E$167,4,0) -> 28000
A13: 12 | B13: I100025 | C13: NL300015 | D13: Bông cải xanh Baby | E13: kg | F13: =+VLOOKUP(C13,[1]Sheet1!A$2:E$167,4,0) -> #N/A
... A63: 62 | B63: I100074 | C63: NL300036 | D63: Củ sen | E63: kg | F63: =+VLOOKUP(C63,[1]Sheet1!A$2:E$167,4,0) -> 47000
A64: 63 | B64: I100078 | D64: đậu cô ve trắng | E64: kg | F64: =+VLOOKUP(C64,[1]Sheet1!A$2:E$167,4,0) -> #N/A
A65: 64 | B65: I100589 | C65: NL410012 | D65: cánh gà | E65: kg | F65: =+VLOOKUP(C65,[1]Sheet1!A$2:E$167,4,0) -> #N/A
A66: 65 | B66: I100600 | C66: NL300047 | D66: dứa nguyên vỏ | E66: trái | F66: =+VLOOKUP(C66,[1]Sheet1!A$2:E$167,4,0) -> 18000
A67: 66 | B67: I100264 | C67: NL430157 | D67: Da hoành thánh NV | E67: kg | F67: =+VLOOKUP(C67,[1]Sheet1!A$2:E$167,4,0) -> #N/A
A68: 67 | B68: I100075 | C68: NL300038 | D68: Đậu bắp | E68: kg | F68: =+VLOOKUP(C68,[1]Sheet1!A$2:E$167,4,0) -> 32000
A69: 68 | B69: I100077 | C69: NL300156 | D69: Đậu cove Pháp | E69: kg | F69: =+VLOOKUP(C69,[1]Sheet1!A$2:E$167,4,0) -> 75000
A70: 69 | B70: I100079 | C70: NL430038 | D70: Đậu đũa NV | E70: kg | F70: =+VLOOKUP(C70,[1]Sheet1!A$2:E$167,4,0) -> 25000
A71: 70 | B71: I100405 | C71: NL200314 | D71: Đậu Hà Lan | E71: Kg | F71: =+VLOOKUP(C71,[1]Sheet1!A$2:E$167,4,0) -> #N/A
A72: 71 | B72: I100883 | C72: NL300041 | D72: Đậu hủ non trứng | E72: Cái | F72: =+VLOOKUP(C72,[1]Sheet1!A$2:E$167,4,0) -> 15000
A73: 72 | B73: I100489 | C73: NL300081 | D73: Lê vàng | E73: kg | F73: =+VLOOKUP(C73,[1]Sheet1!A$2:E$167,4,0) -> #N/A
A74: 73 | B74: I100201 | C74: NL300194 | D74: Rau cải wasabi (Xà Lách Frise) | E74: kg | F74: =+VLOOKUP(C74,[1]Sheet1!A$2:E$167,4,0) -> #N/A
A75: 74 | B75: I100466 | C75: NL300192 | D75: Thanh long ruột đỏ | E75: kg | F75: =+VLOOKUP(C75,[1]Sheet1!A$2:E$167,4,0) -> #N/A
A76: 75 | B76: I100511 | C76: NL300150 | D76: Xoài xanh | E76: kg | F76: =+VLOOKUP(C76,[1]Sheet1!A$2:E$167,4,0) -> 24000
... A110: 109 | B110: I100124 | C110: NL430065 | D110: Khoai mỡ NV | E110: kg | F110: =+VLOOKUP(C110,[1]Sheet1!A$2:E$167,4,0) -> 35000
F111: =+VLOOKUP(C111,[1]Sheet1!A$2:E$167,4,0) -> #N/A
A112: 111 | B112: I100126 | C112: NL430066 | D112: Khoai sọ nv | E112: kg | F112: =+VLOOKUP(C112,[1]Sheet1!A$2:E$167,4,0) -> #N/A
A113: 112 | B113: I100128 | C113: NL430067 | D113: Khoai tây DL NV | E113: kg | F113: =+VLOOKUP(C113,[1]Sheet1!A$2:E$167,4,0) -> #N/A
A114: 113 | B114: I100181 | C114: NL300072 | D114: Kinh giới | E114: kg | F114: =+VLOOKUP(C114,[1]Sheet1!A$2:E$167,4,0) -> 38000
A115: 114 | B115: I100133 | C115: NL300073 | D115: Lá chanh | E115: kg | F115: =+VLOOKUP(C115,[1]Sheet1!A$2:E$167,4,0) -> 42000
A116: 115 | B116: I100135 | C116: NL300074 | D116: Lá chuối | E116: kg | F116: =+VLOOKUP(C116,[1]Sheet1!A$2:E$167,4,0) -> 18000
A117: 116 | B117: I100136 | C117: NL300184 | D117: lá dứa | E117: kg | F117: =+VLOOKUP(C117,[1]Sheet1!A$2:E$167,4,0) -> 18000
A118: 117 | B118: I100683 | C118: NL300206 | D118: lá cách | E118: kg | F118: =+VLOOKUP(C118,[1]Sheet1!A$2:E$167,4,0) -> #N/A
A119: 118 | B119: I100526 | C119: NL300173 | D119: Lá giang | E119: kg | F119: =+VLOOKUP(C119,[1]Sheet1!A$2:E$167,4,0) -> 80000
A120: 119 | B120: I100111 | C120: NL300076 | D120: Lá hẹ | E120: kg | F120: =+VLOOKUP(C120,[1]Sheet1!A$2:E$167,4,0) -> 38000
A121: 120 | B121: I100196 | C121: NL300066 | D121: Lá hương thảo tươi | E121: kg | F121: =+VLOOKUP(C121,[1]Sheet1!A$2:E$167,4,0) -> 220000
A122: 121 | B122: I100139 | C122: NL300077 | D122: Lá lốt (có cuống) | E122: kg | F122: =+VLOOKUP(C122,[1]Sheet1!A$2:E$167,4,0) -> 30000
...

Sheet TAL 8
D2: CÔNG TY TNHH NÔNG SẢN THỰC PHẨM TRẦN GIA HTX: Ấp Lộc Tiến, Xã Mỹ Lộc, Huyện Cần Giuộc, Tỉnh Long An VP: Tòa nhà An Phú Plaza, 117-119 Lý Chính Thắng, P.7. Q.3, TP.HCM Kho sơ chế: 30 Kha Vạn Cân, P. Hiệp Bình Chánh, TP.Thủ Đức, TP.HCM Kho Đà Lạt: 69 Trần Thủ Độ, TT Liên Nghĩa, Huyện Đức Trọng, Tỉnh Lâm Đồng. Website: rausachtrangia.com - Hotline: 090.245.8081
A4: CHI TIẾT ĐỐI CHIẾU CÔNG NỢ
A6: Từ ngày 01 tháng 01 đến ngày 15 tháng 01 năm 2026
A8: Tên Khách hàng: TIANLONG 08
A10: Địa chỉ:
A12: Người liên hệ: Email:
J13: =SUBTOTAL(9,J15:J314) -> 59014170
A14: NGÀY | B14: MÃ KHÁCH HÀNG | C14: TÊN KHÁCH HÀNG | D14: MÃ ĐƠN HÀNG | E14: MÃ HÀNG | F14: TÊN HÀNG | G14: ĐVT | H14: SỐ LƯỢNG | I14: ĐƠN GIÁ | J14: THÀNH TIỀN | K14: GHI CHÚ
A15: 01/01/2026 | B15: TG-KS01269 | C15: TIANLONG 08 | D15: TG-AA20652 | E15: I100008 | F15: Bắp mỹ trái (Loại 1) | G15: Trái | H15: 8 | I15: 8500 | J15: =H15*I15 -> 68000
A16: 01/01/2026 | B16: TG-KS01269 | C16: TIANLONG 08 | D16: TG-AA20652 | E16: I100018 | F16: Bó xôi (Nhà Lồng) | G16: Kg | H16: 2.7 | I16: 45000 | J16: =H16*I16 -> 121500
A17: 01/01/2026 | B17: TG-KS01269 | C17: TIANLONG 08 | D17: TG-AA20652 | E17: I100034 | F17: Cà chua | G17: Kg | H17: 1 | I17: 50000 | J17: =H17*I17 -> 50000
A18: 01/01/2026 | B18: TG-KS01269 | C18: TIANLONG 08 | D18: TG-AA20652 | E18: I100051 | F18: Cải thảo | G18: Kg | H18: 12 | I18: 18000 | J18: =H18*I18 -> 216000
A19: 01/01/2026 | B19: TG-KS01269 | C19: TIANLONG 08 | D19: TG-AA20652 | E19: I100474 | F19: Chanh Dây | G19: Kg | H19: 0.5 | I19: 34000 | J19: =H19*I19 -> 17000
A20: 01/01/2026 | B20: TG-KS01269 | C20: TIANLONG 08 | D20: TG-AA20652 | E20: I100062 | F20: Chanh vàng | G20: Kg | H20: 0.5 | I20: 95000 | J20: =H20*I20 -> 47500
A21: 01/01/2026 | B21: TG-KS01269 | C21: TIANLONG 08 | D21: TG-AA20652 | E21: I100067 | F21: Củ cải trắng (Loại 1) | G21: Kg | H21: 0.9 | I21: 13000 | J21: =H21*I21 -> 11700
A22: 01/01/2026 | B22: TG-KS01269 | C22: TIANLONG 08 | D22: TG-AA20652 | E22: I100074 | F22: Củ sen | G22: Kg | H22: 0.9 | I22: 47000 | J22: =H22*I22 -> 42300
A23: 01/01/2026 | B23: TG-KS01269 | C23: TIANLONG 08 | D23: TG-AA20652 | E23: I100479 | F23: Dưa hấu | G23: Kg | H23: 50 | I23: 18000 | J23: =H23*I23 -> 900000
A24: 01/01/2026 | B24: TG-KS01269 | C24: TIANLONG 08 | D24: TG-AA20652 | E24: I100096 | F24: Gừng còn vỏ VN | G24: Kg | H24: 0.4 | I24: 30000 | J24: =H24*I24 -> 12000
A25: 01/01/2026 | B25: TG-KS01269 | C25: TIANLONG 08 | D25: TG-AA20652 | E25: I100098 | F25: Hành lá | G25: Kg | H25: 2 | I25: 55000 | J25: =H25*I25 -> 110000
A26: 01/01/2026 | B26: TG-KS01269 | C26: TIANLONG 08 | D26: TG-AA20652 | E26: I100125 | F26: Khoai môn cao | G26: Kg | H26: 1.7 | I26: 30000 | J26: =H26*I26 -> 51000
... A314: 15/01/2026 | B314: TG-KS01269 | C314: TIANLONG 08 | D314: TG-AA23143 | E314: I100209 | F314: Xà lách romain | G314: Kg | H314: 10 | I314: 62000 | J314: =H314*I314 -> 620000

Sheet TAL 9
D2: CÔNG TY TNHH NÔNG SẢN THỰC PHẨM TRẦN GIA HTX: Ấp Lộc Tiến, Xã Mỹ Lộc, Huyện Cần Giuộc, Tỉnh Long An VP: Tòa nhà An Phú Plaza, 117-119 Lý Chính Thắng, P.7. Q.3, TP.HCM Kho sơ chế: 30 Kha Vạn Cân, P. Hiệp Bình Chánh, TP.Thủ Đức, TP.HCM Kho Đà Lạt: 69 Trần Thủ Độ, TT Liên Nghĩa, Huyện Đức Trọng, Tỉnh Lâm Đồng. Website: rausachtrangia.com - Hotline: 090.245.8081
A4: CHI TIẾT ĐỐI CHIẾU CÔNG NỢ
A6: Từ ngày 01 tháng 01 đến ngày 15 tháng 01 năm 2026
A8: Tên Khách hàng: TIANLONG 07
A10: Địa chỉ:
A12: Người liên hệ: Email:
J13: =SUBTOTAL(9,J15:J307) -> 39547160
A14: NGÀY | B14: MÃ KHÁCH HÀNG | C14: TÊN KHÁCH HÀNG | D14: MÃ ĐƠN HÀNG | E14: MÃ HÀNG | F14: TÊN HÀNG | G14: ĐVT | H14: SỐ LƯỢNG | I14: ĐƠN GIÁ | J14: THÀNH TIỀN | K14: GHI CHÚ
A15: 01/01/2026 | B15: TG-KS01266 | C15: TIANLONG 09 | D15: TG-AA20653 | E15: I100008 | F15: Bắp mỹ trái (Loại 1) | G15: Trái | H15: 8 | I15: 8500 | J15: =H15*I15 -> 68000
A16: 01/01/2026 | B16: TG-KS01266 | C16: TIANLONG 09 | D16: TG-AA20653 | E16: I100012 | F16: Bí đỏ hồ lô | G16: Kg | H16: 0.6 | I16: 30000 | J16: =H16*I16 -> 18000
A17: 01/01/2026 | B17: TG-KS01266 | C17: TIANLONG 09 | D17: TG-AA20653 | E17: I100018 | F17: Bó xôi (Nhà Lồng) | G17: Kg | H17: 1.5 | I17: 45000 | J17: =H17*I17 -> 67500
A18: 01/01/2026 | B18: TG-KS01266 | C18: TIANLONG 09 | D18: TG-AA20653 | E18: I100034 | F18: Cà chua | G18: Kg | H18: 1 | I18: 50000 | J18: =H18*I18 -> 50000
A19: 01/01/2026 | B19: TG-KS01266 | C19: TIANLONG 09 | D19: TG-AA20653 | E19: I100051 | F19: Cải thảo | G19: Kg | H19: 12 | I19: 18000 | J19: =H19*I19 -> 216000
A20: 01/01/2026 | B20: TG-KS01266 | C20: TIANLONG 09 | D20: TG-AA20653 | E20: I100062 | F20: Chanh vàng | G20: Kg | H20: 0.3 | I20: 95000 | J20: =H20*I20 -> 28500
A21: 01/01/2026 | B21: TG-KS01266 | C21: TIANLONG 09 | D21: TG-AA20653 | E21: I100067 | F21: Củ cải trắng (Loại 1) | G21: Kg | H21: 2 | I21: 13000 | J21: =H21*I21 -> 26000
A22: 01/01/2026 | B22: TG-KS01266 | C22: TIANLONG 09 | D22: TG-AA20653 | E22: I100074 | F22: Củ sen | G22: Kg | H22: 1.4 | I22: 47000 | J22: =H22*I22 -> 65800
A23: 01/01/2026 | B23: TG-KS01266 | C23: TIANLONG 09 | D23: TG-AA20653 | E23: I100479 | F23: Dưa hấu | G23: Kg | H23: 22 | I23: 18000 | J23: =H23*I23 -> 396000
A24: 01/01/2026 | B24: TG-KS01266 | C24: TIANLONG 09 | D24: TG-AA20653 | E24: I100923 | F24: Hoa cúc tím | G24: Bó | H24: 1 | I24: 80000 | J24: =H24*I24 -> 80000
A25: 01/01/2026 | B25: TG-KS01266 | C25: TIANLONG 09 | D25: TG-AA20653 | E25: I100113 | F25: Húng lũi | G25: Kg | H25: 0.3 | I25: 65000 | J25: =H25*I25 -> 19500
A26: 01/01/2026 | B26: TG-KS01266 | C26: TIANLONG 09 | D26: TG-AA20653 | E26: I100125 | F26: Khoai môn cao | G26: Kg | H26: 2 | I26: 30000 | J26: =H26*I26 -> 60000
... A307: 15/01/2026 | B307: TG-KS01266 | C307: TIANLONG 09 | D307: TG-AA23134 | E307: I100209 | F307: Xà lách romain | G307: Kg | H307: 5.7 | I307: 62000 | J307: =H307*I307 -> 353400
