Workbook

Sheet TEMPLATE
A1: Mã Cũ | B1: ItemCode | C1: Mã Hàng | D1: Mô Tả | E1: Đơn vị | F1: Quantity | G1: Remark | H1: TT Xuất hóa đơn | I1: pon
A2: khoqua | B2: =VLOOKUP(A2,'CODE NOTE'!A:B,2,0) -> I100118 | D2: =VLOOKUP(A2,'CODE NOTE'!A:C,3,0) -> Khổ qua | E2: =VLOOKUP(A2,'CODE NOTE'!D:E,2,0) -> Kg | F2: 0.7 | H2: =VLOOKUP(A2,'CODE NOTE'!D:F,3,0) -> 0.3kg/trái | I2: =VLOOKUP(I1,'KHÁCH NOTE'!A:B,2,0) -> CACHUAHUOM, OTHIEMXAY 0.5kg/bịch, MANGTAY, Dưa leo trắng 702, CUHUDUATHAN, OTBATRI hườm, THOMXANH 1.1kg, KHOAITAYDL, CAROT, COCNON = cóc thái, DUDUHUOM, CUCAITRANG, CHANHDL, BAPCHUOI 1.2KG/bắp, SONNHO, MONGTOI, NAMBAONGUXAM, BINU, RAUDENCOM, BIDOHOLO, TỎI XAY 0.5kg/bịch, CANTAU, RAUNHUT, CHUOICHAT, NHOKHONGHAT, NGOSEN, RAURUNG Tây Ninh đủ loại, CAINHUN = cải bẹ dúng, món của nhân viên note NV | J2: RAUDENXANH | K2: BÒ TƠ
A3: bauxanh | B3: =VLOOKUP(A3,'CODE NOTE'!A:B,2,0) -> I100010 | D3: =VLOOKUP(A3,'CODE NOTE'!A:C,3,0) -> Bầu xanh | E3: =VLOOKUP(A3,'CODE NOTE'!D:E,2,0) -> Kg | F3: 2 | H3: =VLOOKUP(A3,'CODE NOTE'!D:F,3,0) -> 0.5kg/trái (0.3-0.5kg/trái) | J3: RAUMANHO | K3: RAU MÁ
A4: cucaitrang | B4: =VLOOKUP(A4,'CODE NOTE'!A:B,2,0) -> I100067 | D4: =VLOOKUP(A4,'CODE NOTE'!A:C,3,0) -> Củ cải trắng (Loại 1) | E4: =VLOOKUP(A4,'CODE NOTE'!D:E,2,0) -> Kg | F4: 1 | H4: =VLOOKUP(A4,'CODE NOTE'!D:F,3,0) -> 0.15-0.3kg/củ | J4: KHOAILANGNHAT | K4: KHOAI LANG
A5: dauhutrang | B5: =VLOOKUP(A5,'CODE NOTE'!A:B,2,0) -> I100260 | D5: =VLOOKUP(A5,'CODE NOTE'!A:C,3,0) -> Đậu hũ miếng trắng | E5: =VLOOKUP(A5,'CODE NOTE'!D:E,2,0) -> Miếng | F5: 8 | H5: =VLOOKUP(A5,'CODE NOTE'!D:F,3,0) -> không xuất được hóa đơn | J5: HANHHUONG | K5: PHỞ
A6: daubap | B6: =VLOOKUP(A6,'CODE NOTE'!A:B,2,0) -> I100075 | D6: =VLOOKUP(A6,'CODE NOTE'!A:C,3,0) -> Đậu bắp | E6: =VLOOKUP(A6,'CODE NOTE'!D:E,2,0) -> Kg | F6: 0.7 | H6: =VLOOKUP(A6,'CODE NOTE'!D:F,3,0) -> 0 | J6: TRUNGGACP | K6: BÒ Q3 LẤY VỈ
A7: bapcaitrang | B7: =VLOOKUP(A7,'CODE NOTE'!A:B,2,0) -> I100003 | D7: =VLOOKUP(A7,'CODE NOTE'!A:C,3,0) -> Bắp cải trắng | E7: =VLOOKUP(A7,'CODE NOTE'!D:E,2,0) -> Kg | F7: 0.5 | H7: =VLOOKUP(A7,'CODE NOTE'!D:F,3,0) -> 0.8kg/bắp (0.5-1.2kg/bắp) | J7: BAPMYTRAI | K7: BÒ TƠ
H8: =VLOOKUP(A8,'CODE NOTE'!D:F,3,0) -> #N/A | J8: K CÓ HANHTAYTRUNG
H9: =VLOOKUP(A9,'CODE NOTE'!D:F,3,0) -> #N/A | J9: CAIMAM | K9: cải xoong mầm/ salad xoong mầm
H10: =VLOOKUP(A10,'CODE NOTE'!D:F,3,0) -> #N/A | J10: SONNHO/SONDL | K10: cải xoong/ cải xoong lớn
H11: =VLOOKUP(A11,'CODE NOTE'!D:F,3,0) -> #N/A | J11: BIDOTRON | K11: bí đỏ
H12: =VLOOKUP(A12,'CODE NOTE'!D:F,3,0) -> #N/A | J12: NAMHAISAN | K12: nấm bạch tuyết
H13: =VLOOKUP(A13,'CODE NOTE'!D:F,3,0) -> #N/A | J13: BANHTRANGPIA | K13: bò pía/ bánh pía
H14: =VLOOKUP(A14,'CODE NOTE'!D:F,3,0) -> #N/A | J14: BANHTRANGPIAKG
H15: =VLOOKUP(A15,'CODE NOTE'!D:F,3,0) -> #N/A | J15: CAINGOTGOC | K15: SƠN THỦY
H16: =VLOOKUP(A16,'CODE NOTE'!D:F,3,0) -> #N/A
H17: =VLOOKUP(A17,'CODE NOTE'!D:F,3,0) -> #N/A
H18: =VLOOKUP(A18,'CODE NOTE'!D:F,3,0) -> #N/A
H19: =VLOOKUP(A19,'CODE NOTE'!D:F,3,0) -> #N/A | J19: CHECK KĨ R LƯU
H20: =VLOOKUP(A20,'CODE NOTE'!D:F,3,0) -> #N/A
H21: =VLOOKUP(A21,'CODE NOTE'!D:F,3,0) -> #N/A
H22: =VLOOKUP(A22,'CODE NOTE'!D:F,3,0) -> #N/A
H23: =VLOOKUP(A23,'CODE NOTE'!D:F,3,0) -> #N/A
H24: =VLOOKUP(A24,'CODE NOTE'!D:F,3,0) -> #N/A
H25: =VLOOKUP(A25,'CODE NOTE'!D:F,3,0) -> #N/A
H26: =VLOOKUP(A26,'CODE NOTE'!D:F,3,0) -> #N/A
H27: =VLOOKUP(A27,'CODE NOTE'!D:F,3,0) -> #N/A
H28: =VLOOKUP(A28,'CODE NOTE'!D:F,3,0) -> #N/A | J28: Acerola Cherry | K28: Sori | L28: SORI
H29: =VLOOKUP(A29,'CODE NOTE'!D:F,3,0) -> #N/A | J29: Asparagus | K29: Măng tây | L29: MANGTAY
H30: =VLOOKUP(A30,'CODE NOTE'!D:F,3,0) -> #N/A | J30: Banana | K30: Chuối cau | L30: CHUOICAU
H31: =VLOOKUP(A31,'CODE NOTE'!D:F,3,0) -> #N/A | J31: Basil | K31: Húng quế (Việt) | L31: HUNGQUE
H32: =VLOOKUP(A32,'CODE NOTE'!D:F,3,0) -> #N/A | J32: Beetroot | K32: củ dền | L32: CUDEN
H33: =VLOOKUP(A33,'CODE NOTE'!D:F,3,0) -> #N/A | J33: Birdseye Chili (Green) | K33: Ớt hiểm xanh | L33: OTHIEMXANH
H34: =VLOOKUP(A34,'CODE NOTE'!D:F,3,0) -> #N/A | J34: Birdseye Chilli (RED) | K34: Ớt hiểm đỏ | L34: OTHIEM
H35: =VLOOKUP(A35,'CODE NOTE'!D:F,3,0) -> #N/A | J35: Bok Choy | K35: Cải thìa | L35: CAITHIA
H36: =VLOOKUP(A36,'CODE NOTE'!D:F,3,0) -> #N/A | J36: Broccoli | K36: Bông cải xanh | L36: BONGCAIXANH
H37: =VLOOKUP(A37,'CODE NOTE'!D:F,3,0) -> #N/A | J37: Butter Lettuce | K37: Búp đà lạt | L37: BUPDL
H38: =VLOOKUP(A38,'CODE NOTE'!D:F,3,0) -> #N/A | J38: CACHUALON
H39: =VLOOKUP(A39,'CODE NOTE'!D:F,3,0) -> #N/A | J39: Capsicum Red | K39: Ớt đỏ đà lạt | L39: OTDODL
H40: =VLOOKUP(A40,'CODE NOTE'!D:F,3,0) -> #N/A | J40: Capsicum Yellow | K40: Ớt vàng đà lạt | L40: OTVANGDL
...

Sheet KHÁCH NOTE
A1: NHÀ HÀNG
A2: 5G | B2: Khách tự lên đơn, CHANHKHONGHAT, GIALAT, TOIXAY, CAROT, SONNHO, TOILOT, THOMXANH, TAUHUKYKHO | C2: SONNHO: hầu hết
A3: ACECOOK | B3: CAROT, GUNGVN còn vỏ, NAMDONGCO | C3: MIALAU: hầu hết
A4: PON | B4: CACHUAHUOM, OTHIEMXAY 0.5kg/bịch, MANGTAY, Dưa leo trắng 702, CUHUDUATHAN, OTBATRI hườm, THOMXANH 1.1kg, KHOAITAYDL, CAROT, COCNON = cóc thái, DUDUHUOM, CUCAITRANG, CHANHDL, BAPCHUOI 1.2KG/bắp, SONNHO, MONGTOI, NAMBAONGUXAM, BINU, RAUDENCOM, BIDOHOLO, TỎI XAY 0.5kg/bịch, CANTAU, RAUNHUT, CHUOICHAT, NHOKHONGHAT, NGOSEN, RAURUNG Tây Ninh đủ loại, CAINHUN = cải bẹ dúng, món của nhân viên note NV
A5: AMDANG | B5: DAUQUETRANG, CAPHAOXANH = cà da ếch, KHOAITAYDL, HANHTIMTQ, GIALAT, TRUNGGACP, ROTTO, mì vắt = MIVAT, DUDUXANH, DAUQUETRANG, GUNGTQ, TOIBAC = tỏi tép HN, BANHTRANGPIA 1 gói, LAHUONGNHU, hủ tiếu bản dẹt = HUTIEUXAO, DAUHUCHIEN
A6: AN DUYÊN | B6: CUHUDUATHAN, CAIBE, RAURUNGGL, ROTTO, chuối bào = BAPCHUOIBAO, BUPMY, FRISSE, đậu que xanh = DAUQUEPHAP, cà bi đỏ = CACHUABI, củ cải đường = CUCAIDO, NGOSENCONG, GUNGGOT, NAMROM = nấm rơm nhỏ, DAUBO, KHOAIMONCAO củ to
A7: ANH EM RESTAURANT + NOT ONLY (CÙNG 1 HỆ THỐNG) | B7: Cà rốt ĐL cọng tím= CAROTDL, toàn bộ hàng VN, GUNGVN, HANHTIMVN, THOMHUOM, KHOAIMONCAO, OITRAI, CHANHKHONGHAT, CAINHUN = cải bẹ nhún, SONNHO, TAOXANH, BUPDL = búp mỡ, RAUMUONGLA, BONGBI, HANHTAY nhỏ 7-8 củ/kg, DAUQUEPHAP, THOMGOT, CUDEN quả ko lớn
A8: AU SUNSHINE | B8: NGORI, NAMBAONGUXAM, ROTTO, KHOAITAYDL, nấm lên mã kg
A9: BA GÁC | B9: HANHLOTVN, HANHLOTTQ, BANHDACUA, CUHUDUADOT, MITUOI = mì vàng, TAOXANH, THOMXANH (bếp), THOMHUOM (bar), CAIXANH, DUANAOTRANG
A10: BENJI | B10: LOLOXANH = xà lách xoắn xanh, BIDOTRON = bí rơ, NAMKIMCHAM150 150GR/BỊCH, HANHLOTTQ, DAUQUETRANG, ROTTO, BAPCAITRANG, CAICHUA = dưa cải chua, gừng non = GUNGTQ, BAPMYTRAI = bắp ngọt lột vỏ
A11: BẾP CỦA PẤC | B11: TAOMY, KHOQUATAY
A12: BẾP TRANG | B12: BAPCHUOIBAO, CAIBE = cải lá, OTHIEMXANH/ĐỎ DÀI, LOLOXANH, DUALEO, XOAIXANH = xoài keo, CHANHDL, HANHLOTTQ = hành tím/hành lột, NGHE, TOILOT, THOMGOT, RAUMUONGBAO
A13: BIA TUYẾT (BT) | B13: CUHUDUATHAN, CAIBE, GUNGTQ củ to, HUTIEUXAO, OIKOHAT, CAROT, XOAITHAI, THOMXANH, DAUHUTRUNGCAY, DUATUOI, BANHTRANGPIA, DUATUOI gọt vỏ, NHODENKHONGHAT
A14: BIA TUYẾT (ĐƠN NV) | B14: BIDOTRON gọt, KHOAIGOT = khoai mỡ gọt, HUTIEUXAO, CAROT, OIKOHAT, XOAITHAI, THOMXANH, DUATUOI gọt vỏ, NHODENKHONGHAT
A15: BIA TUYẾT (ĐVB) | B15: KHOAIMONGOT, BAPCHUOI, SONNHO, CUHUDUADOT, HUTIEUXAO, DAUHUTRANGCAY, hành tây củ nhỏ = HANHTAYTRUNG, CAROT, OIKOHAT, XOAITHAI, THOMXANH, DUATUOI gọt vỏ, NHODENKHONGHAT
... A130: CHAY LÀNG TA | B130: BONGCAITRANGDL/BONGCAIXANHDL, NAMBAONGUXAM, HANHLOTVN, DAUQUETRANG, BUNNHO = bún sợi trung ăn lẩu, BUNBO, GUNGTQ, MIQUANG, THOMGOT, CAROT, CAIBE, DAUHUTRANG/DAUHUCHIEN, CHANHDL/CHANHKHONGHAT, LOLOXANH, RAUNUOCMAT, NHADAM, MEVAT, CRISPY, KHOAILANGNHAT = khoai lang vàng, CAPHAOMUOI, TAODO giòn nhỏ 5-6 trái/kg, RAUMUONGCONG

Sheet CODE NOTE
A1: mappingcode | B1: itemcode | C1: ItemName | D1: mappingcode | E1: UOMCode | F1: InvStatus
A2: BACHA | B2: I100001 | C2: Bạc hà | D2: BACHA | E2: Kg | F2: 1 bó = 5kg, (dọc mùng/cây bạc hà)
A3: Bachhoaloreto | B3: I100816 | C3: Bạch hoa Loreto | D3: Bachhoaloreto | E3: Hủ | F3: không xuất được hóa đơn
A4: bachquavo | B4: I100781 | C4: Bạch quả không tách vỏ | D4: bachquavo | E4: kg | F4: không xuất được hóa đơn
A5: BACHQUA | B5: I100291 | C5: Bạch quả tươi | D5: BACHQUA | E5: Gói | F5: không xuất được hóa đơn
A6: BACHTUOC | B6: I100407 | C6: Bạch tuộc 2 Da | D6: BACHTUOC | E6: kg | F6: không xuất được hóa đơn
A7: BANHBAO | B7: I100543 | C7: Bánh bao | D7: BANHBAO | E7: Gói | F7: không xuất được hóa đơn
A8: BANHCANH | B8: I100247 | C8: Bánh canh | D8: BANHCANH | E8: Kg | F8: không xuất được hóa đơn
A9: BANHCANHGAO | B9: I100248 | C9: Bánh Canh Bột Gạo | D9: BANHCANHGAO | E9: Kg | F9: không xuất được hóa đơn
A10: banhcanhbotgaothucong | B10: I100903 | C10: Bánh canh bột gạo (thủ công) | D10: banhcanhbotgaothucong | E10: Kg
A11: BANHCANHBOTLOC | B11: I100258 | C11: Bánh Canh Bột Lọc | D11: BANHCANHBOTLOC | E11: Kg | F11: không xuất được hóa đơn
A12: BANHCANHBOTMI | B12: I100760 | C12: BÁNH CANH BỘT MÌ | D12: BANHCANHBOTMI | E12: Kg | F12: không xuất được hóa đơn
A13: BANHCHUNG | B13: I100456 | C13: Bánh chưng | D13: BANHCHUNG | E13: Cái | F13: không xuất được hóa đơn
A14: banhdacua | B14: I100909 | C14: Bánh đa cua | D14: banhdacua | E14: Kg | F14: không xuất được hóa đơn
A15: BANHDALON | B15: I100458 | C15: Bánh da lợn | D15: BANHDALON | E15: Ổ | F15: không xuất được hóa đơn
A16: BANHDAME | B16: I100726 | C16: Bánh đa mè | D16: BANHDAME | E16: kg | F16: không xuất được hóa đơn
A17: BANHDANEM | B17: I100782 | C17: Bánh đa nem | D17: BANHDANEM | E17: Xấp | F17: không xuất được hóa đơn
A18: banhdanuong | B18: I100858 | C18: Bánh đa nướng | D18: banhdanuong | E18: Cái | F18: không xuất được hóa đơn
A19: banhdanuonglon | B19: I100889 | C19: BÁNH ĐA NƯỚNG LỚN | D19: banhdanuonglon | E19: cái | F19: không xuất được hóa đơn
A20: BANHDAY | B20: I100459 | C20: Bánh dày | D20: BANHDAY | E20: Cái | F20: không xuất được hóa đơn
A21: BANHGAOCAY | B21: I100292 | C21: Bánh gạo cây | D21: BANHGAOCAY | E21: kg | F21: không xuất được hóa đơn
A22: BANHGIO | B22: I100544 | C22: Bánh giò | D22: BANHGIO | E22: Cái | F22: không xuất được hóa đơn
... A49: BANHUOTTRON | B49: I100254 | C49: Bánh ướt tròn | D49: BANHUOTTRON | E49: Kg | F49: không xuất được hóa đơn
A50: Bapcaibaby | B50: I100818 | C50: Bắp cải baby | D50: Bapcaibaby | E50: Kg
A51: Bapcaibrussels | B51: I100774 | C51: Bắp cải Brussels | D51: Bapcaibrussels | E51: Kg | F51: không xuất được hóa đơn
A52: BAPCAITIM | B52: I100002 | C52: Bắp cải tím | D52: BAPCAITIM | E52: Kg | F52: 0.8kg/bắp (0.5-1kg/bắp)
A53: BAPTRAITIM | B53: I100547 | C53: Bắp cải trái tim | D53: BAPTRAITIM | E53: Kg
A54: BAPCAITRANG | B54: I100003 | C54: Bắp cải trắng | D54: BAPCAITRANG | E54: Kg | F54: 0.8kg/bắp (0.5-1.2kg/bắp)
A55: BCTLON | B55: I100585 | C55: Bắp cải trắng lớn | D55: BCTLON | E55: Kg
A56: BAPCHUOIBAO | B56: I100004 | C56: Bắp chuối bào | D56: BAPCHUOIBAO | E56: Kg | F56: xuất hđ đổi thành bắp chuối
A57: BAPCHUOIHOTBAO | B57: I100596 | C57: Bắp chuối hột bào | D57: BAPCHUOIHOTBAO | E57: Kg
A58: BAPCHUOIHOT | B58: I100593 | C58: Bắp chuối hột nguyên trái | D58: BAPCHUOIHOT | E58: Kg | F58: 1kg/bắp, Phố 79 3kg/bắp
A59: BAPCHUOI | B59: I100005 | C59: Bắp chuối nguyên trái | D59: BAPCHUOI | E59: Kg | F59: 1.2KG/BẮP (0.5-0.8kg/bắp)
A60: BAPHATLON | B60: I100299 | C60: Bắp hạt lon | D60: BAPHATLON | E60: Lon | F60: không xuất được hóa đơn
A61: BAPVO | B61: I100586 | C61: Bắp mỹ còn vỏ | D61: BAPVO | E61: Trái
A62: BAPDONGLANH | B62: I100674 | C62: Bắp Mỹ Đông Lạnh | D62: BAPDONGLANH | E62: Kg | F62: Bỏ chữ đông lạnh
A63: BAPMYHAT | B63: I100006 | C63: Bắp mỹ hạt | D63: BAPMYHAT | E63: Kg
A64: BAPMYKG | B64: I100007 | C64: Bắp mỹ kg Lột Vỏ | D64: BAPMYKG | E64: Kg | F64: 3 trái/kg
A65: BAPMYTRAI | B65: I100008 | C65: Bắp mỹ trái (Loại 1) | D65: BAPMYTRAI | E65: Trái | F65: 3 trái/kg
A66: BAPNEP | B66: I100300 | C66: Bắp nếp | D66: BAPNEP | E66: trái
...

Sheet Báo cáo
A1: BÁO CÁO ĐƠN HÀNG
A2: STT | B2: Khách hàng | C2: Khách gửi đơn | D2: Trạng thái
A3: 1 | B3: ANDUYEN | C3: KHÔNG | D3: KHÔNG LÊN | H3: BẾP CỦA PẤC | I3: KHÔNG | J3: KHÔNG LÊN | L3: PÂC | M3: BẾP CỦA PẤC
A4: 2 | B4: AN VŨ | C4: KHÔNG | D4: KHÔNG LÊN | H4: CAFÉ BEANS | I4: KHÔNG | J4: KHÔNG LÊN | L4: Beans | M4: Café Beans
A5: 3 | B5: BÒ BTHANH | C5: KHÔNG | D5: KHÔNG LÊN | H5: CHEER HOUSE | I5: KHÔNG | J5: KHÔNG LÊN | L5: Cheer | M5: Cheer House
A6: 4 | B6: BÒ Q10 | C6: KHÔNG | D6: KHÔNG LÊN | H6: CHICKEN PLUS | I6: KHÔNG | J6: KHÔNG LÊN | L6: Chicken | M6: Nh Chicken Plus Sư Vạn Hạnh
A7: 5 | B7: BÒ Q3 | C7: KHÔNG | D7: KHÔNG LÊN | H7: CUNG ỨNG TÀU BIỂN | I7: KHÔNG | J7: KHÔNG LÊN | L7: Tàu Biển | M7: Poseidon Supply
A8: 6 | B8: BÒ Q7 | C8: KHÔNG | D8: KHÔNG LÊN | H8: KARAOKE 127 | I8: KHÔNG | J8: KHÔNG LÊN | L8: 127 NTB | M8: 127 NTB
A9: 7 | B9: BÒ BTAN | C9: KHÔNG | D9: KHÔNG LÊN | H9: KHÁCH SẠN HUAZHU | I9: KHÔNG | J9: KHÔNG LÊN | L9: Zhu | M9: KS HuaZhu
A10: 8 | B10: LONGWANG 3 | C10: KHÔNG | D10: KHÔNG LÊN | H10: LỤC ĐỈNH KÝ | I10: KHÔNG | J10: KHÔNG LÊN | L10: Lục | M10: BD Lục Đỉnh Ký Bình Dương
A11: 9 | B11: LONGWANG 7 | C11: KHÔNG | D11: KHÔNG LÊN | H11: NGƯU ĐỈNH KÝ | I11: KHÔNG | J11: KHÔNG LÊN | L11: Ngưu | M11: Ngưu Đỉnh Ký - Rau Củ Trần Gia
A12: 10 | B12: LONGWANG 1 | C12: KHÔNG | D12: KHÔNG LÊN | H12: NHOÀN CAFÉ | I12: KHÔNG | J12: KHÔNG LÊN | L12: Nhoàn | M12: Nhoàn Café_Vegan foods
A13: 11 | B13: LONGWANG 8 | C13: KHÔNG | D13: KHÔNG LÊN
A14: 12 | B14: CHAY LÀNG TA | C14: KHÔNG | D14: KHÔNG LÊN | H14: PHƯƠNG ĐÔNG 1 | I14: KHÔNG | J14: KHÔNG LÊN | L14: Đông | M14: Phương Đông 01
A15: 13 | B15: CGT | C15: KHÔNG | D15: KHÔNG LÊN | H15: PHƯƠNG ĐÔNG 2 | I15: KHÔNG | J15: KHÔNG LÊN | L15: Đông | M15: Phương Đông 02
A16: 14 | B16: HÀNG DƯƠNG 4 | C16: KHÔNG | D16: KHÔNG LÊN | H16: WALLACE | I16: KHÔNG | J16: KHÔNG LÊN | M16: WALLACE - Trần Gia
A17: 15 | B17: HÀNG DƯƠNG 7 | C17: KHÔNG | D17: KHÔNG LÊN | H17: ANH KIỆT | I17: KHÔNG | J17: KHÔNG LÊN | L17: Kiệt | M17: ANH KIỆT - TRẦN GIA
A18: 16 | B18: HERE AND NOW (NTT) | C18: KHÔNG | D18: KHÔNG LÊN
A19: 17 | B19: HERE AND NOW ( PVC) | C19: KHÔNG | D19: KHÔNG LÊN
A20: 18 | B20: HOA LỘC VỪNG | C20: KHÔNG | D20: KHÔNG LÊN
A21: 19 | B21: WAIKIKI/STATION | C21: KHÔNG | D21: KHÔNG LÊN
A22: 20 | B22: VINFOOD | C22: KHÔNG | D22: KHÔNG LÊN
A23: 21 | B23: PON | C23: KHÔNG | D23: KHÔNG LÊN
A24: 22 | B24: NHOÀN | C24: KHÔNG | D24: KHÔNG LÊN
C25: CÓ | D25: ĐÃ LÊN

Sheet HAPPY LAMB
A2: KHOAIMONCAO | B2: 香芋 | C2: Khoai môn cao | E2: dualeonhat | F2: =VLOOKUP(E2,A:B,2,0) -> 青瓜
A3: KHOAISO | C3: khoai môn sọ | E3: chanhvang | F3: =VLOOKUP(E3,A:B,2,0) -> 黄柠檬
A4: KHOAILANGNHAT | B4: 地瓜 | C4: khoai lang Nhật | E4: cusen | F4: =VLOOKUP(E4,A:B,2,0) -> 莲藕
A5: KHOAILANGMAT | C5: khoai lang mật | E5: khoaitaytq | F5: =VLOOKUP(E5,A:B,2,0) -> 土豆
A6: GIA | B6: 豆芽 | C6: giá tươi | E6: caithao | F6: =VLOOKUP(E6,A:B,2,0) -> 大白菜
A7: KHOAITAYTQ | B7: 土豆 | C7: Khoai tây TQ | E7: cucaitrang | F7: =VLOOKUP(E7,A:B,2,0) -> 白萝卜
A8: CUCAITRANG | B8: 白萝卜 | C8: củ cải trắng (loại 1) | E8: bapmykg | F8: =VLOOKUP(E8,A:B,2,0) -> 甜玉米
A9: CAIMAM | B9: 豆苗 | C9: cải mầm | E9: namlinhchinau | F9: =VLOOKUP(E9,A:B,2,0) -> 蟹味菇
A10: MUONGMAM | B10: 空心菜苗 | C10: rau muống mầm | E10: namdongcogoi | F10: =VLOOKUP(E10,A:B,2,0) -> 香菇
A11: CUSEN | B11: 莲藕 | C11: củ sen | E11: namkimcham2 | F11: =VLOOKUP(E11,A:B,2,0) -> 金针菇
A12: BIDOTRON | B12: 南瓜 | C12: bí đỏ tròn | E12: namduiga | F12: =VLOOKUP(E12,A:B,2,0) -> 杏鲍菇
A13: BIDAO | B13: 冬瓜 | C13: bí đao | E13: namhaisan | F13: =VLOOKUP(E13,A:B,2,0) -> 海鲜菇
A14: BAPMYKG | B14: 甜玉米 | C14: bắp Mỹ kg lột vỏ | E14: othiem | F14: =VLOOKUP(E14,A:B,2,0) -> 红小米椒
A15: MONGTOI | B15: 木耳菜 | C15: Mồng tơi
A16: CAITHIA | B16: 青江菜 | C16: cải thìa
A17: RAUMUONGHAT | B17: 空心菜 | C17: rau muống hạt
A18: caithao | B18: 大白菜 | C18: cải thảo
A19: FRISSE | B19: 生菜 | C19: salad Big frisse
A20: BUPDL | C20: salad búp đl
A21: BUPMY | C21: salad búp mỹ
A22: CAROL | C22: salad carol
A23: LOLOXANH | C23: salad lolo xanh
A24: RADICHIO | C24: salad radichio
A25: SALADCRISPY | C25: salad crispy
A26: ROMAIN | C26: salad romain
A27: SONNHO | C27: salad son nhỏ
A28: SONDL | C28: Salad son đà lạt
A29: ROCKET | C29: Salad rocket
A30: LOLOTIM | B30: 紫生菜 | C30: salad lolo tím
A31: ROTTO | B31: 胡萝卜 | C31: Cà rốt ĐaLat (củ lớn)
A32: GUNGTQ | B32: 生姜 | C32: củ gừng
A33: GUNGVN | C33: Gừng còn vỏ VN
A34: HANHTAY | B34: 洋葱 | C34: hành tây
A35: HANHTAYTIM | B35: 紫洋葱 | C35: hành tây tím
A36: HANHTIMTQ | C36: hành tím củ
A37: HANHTIMVN | C37: hành tím VN nguyên củ
A38: HANHLA | B38: 小葱 | C38: hành lá
A39: TOICU | B39: 蒜米 | C39: tỏi củ
A40: NGORI | B40: 香菜 | C40: ngò rí
A41: HANHPARO | B41: 大葱-兌锅 | C41: hành paro
...

Sheet TÀU BIỂN
A1: Đóng gói bao bì phải ĐỤC NHIỀU LỖ cho thông thoáng trừ tỏi hút chân không. Có nhãn mác đầy đủ. Toàn bộ rau lá PHẢI KHÔ RÁO, không được xịt nước. Hàng vận chuyển xa nên phải lấy hàng mới nhất.
A3: Cải thìa | B3: Kg | C3: 500gr/túi, Đóng gói bao bì phải đục nhiều lỗ thông thoáng
A4: Củ sen | B4: kg | C4: 500gr/túi, Đóng gói bao bì phải đục nhiều lỗ thông thoáng
A5: Hành lá | B5: Kg | C5: 500gr/túi, khô ráo, cắt gốc, làm sạch. Đóng gói bao bì phải đục nhiều lỗ thông thoáng
A6: Đậu Hà lan trái | B6: kg | C6: 500gr/túi, trái to, ít cành, sắp xếp ngay ngắn. Đóng gói bao bì phải đục nhiều lỗ thông thoáng
A7: Giá tươi | B7: Kg | C7: 500gr/túi, Đóng gói bao bì phải đục nhiều lỗ thông thoáng
A8: Nghệ tươi | B8: Kg | C8: 500gr/túi, Đóng gói bao bì phải đục nhiều lỗ thông thoáng
A9: Ớt hiểm xanh | B9: Kg | C9: 250gr/túi, Đóng gói bao bì phải đục nhiều lỗ thông thoáng
A10: Ớt hiểm đỏ | B10: Kg | C10: 250gr/túi, Đóng gói bao bì phải đục nhiều lỗ thông thoáng
A11: Ngò rí | B11: Kg | C11: 500gr/túi, cắt gốc, làm sạch. Đóng gói bao bì phải đục nhiều lỗ thông thoáng
A12: Thì là | B12: Kg | C12: 500gr/túi, cắt gốc, làm sạch. Đóng gói bao bì phải đục nhiều lỗ thông thoáng
A13: Sả cây | B13: Kg | C13: 500gr/túi, Đóng gói bao bì phải đục nhiều lỗ thông thoáng
A14: Húng quế | B14: Kg | C14: 500gr/túi, tươi, mới, xanh đẹp. Đóng gói bao bì phải đục nhiều lỗ thông thoáng

Sheet CHAY TUỆ
B1: CTY CP ẨM THỰC CHAY TUỆ | D1: CỘNG HÒA XÃ HỘI CHỦ NGHĨA VIỆT NAM
B2: 76 Mai Thị Lưu, P. Đa Kao, Q1 | D2: Độc lập – Tự do – Hạnh phúc
B3: MST: 0317499980 | D3: --------------------------------------------------------
A4: YÊU CẦU ĐẶT HÀNG NGUYÊN VẬT LIỆU
A6: STT | B6: RAU CỦ QUẢ | C6: ĐVT | D6: QUY CHUẨN YÊU CẦU | E6: GIÁ
A7: 1 | B7: Bạc Hà Nấu Canh Chua Nam Bộ | C7: Kg | D7: Tươi non, Không héo úa | E7: 14000
A8: 2 | B8: Bắp Cải Tím | C8: Kg | D8: Bắp Cải Đà Lạt | E8: 18000
A9: 3 | B9: Bắp Cải Trắng | C9: Kg | D9: Bắp Cải Đà Lạt | E9: 15000
A10: 4 | B10: Bắp Mỹ | C10: Trái | D10: Lột Vỏ sẵn, Loại 1 Kg/3 Trái | E10: 8000
A11: 5 | B11: Bắp Non | C11: Kg | D11: Non, ngon | E11: 28000
A12: 6 | B12: Baro (Hành paro) | C12: Kg | D12: Hàng đẹp tươi. Không dập úng | E12: 28000
A13: 7 | B13: Bầu | C13: Kg | D13: hàng tươi,non | E13: 13000
A14: 8 | B14: Đậu đũa | C14: Kg | D14: hàng tươi,non | E14: 20000
A15: 9 | B15: Đậu cove | C15: Kg | D15: hàng tươi,non | E15: 28000
A16: 10 | B16: Bí xanh | C16: Kg | D16: hàng tươi,non | E16: 20000
A17: 11 | B17: Bí Hồ Lô | C17: Kg | D17: Độ dẻo mềm, vị ngọt bùi. Vỏ màu xanh, vàng cam, tươi | E17: 15000
A18: 12 | B18: Bí Ngòi Vàng | C18: Kg | D18: Loại 1 Kg/4 Trái | E18: 45000
... A86: 80 | B86: Rau Muống Tuốt Lá | C86: Kg | D86: Tươi non | E86: 20000
A87: 81 | B87: Hoa ăn được | C87: hộp | D87: hoa tươi đẹp,để trong hộp đậy kín có giấy hút ẩm | E87: 78000 | F87: 1 hộp 12gram
A88: 82 | B88: Mít luộc (nguyên trái) | C88: Kg | D88: mít luộc sẵn,chín mềm | E88: 25000
A89: 83 | B89: Rau má | C89: Kg | D89: Tươi non | E89: 25000
A90: 84 | B90: Rau Nhút | C90: Kg | D90: Loại làm sạch, không dài >40cm | E90: 45000
A91: 85 | B91: Rau Ôm | C91: Kg | D91: Tươi đẹp, không dập úng | E91: 20000
A92: 86 | B92: Rau Răm | C92: Kg | D92: Tươi đẹp, không dập úng | E92: 18000
A93: 87 | B93: Rau rừng gia lai | C93: Kg | D93: Tươi đẹp, không dập úng,độ dài từ 20cm-25cm | E93: 45000
A94: 88 | B94: Rau Tần Ô | C94: Kg | D94: Tươi đẹp, không dập úng | E94: 30000
A95: 89 | B95: Sả Cây | C95: Kg | D95: Tươi, độ dài không quá 30cm | E95: 12000
A96: 90 | B96: Sả Xay | C96: Kg | D96: Xay phần củ non | E96: 12000
A97: 91 | B97: Salad Lôlô Tím | C97: Kg | D97: Tươi, không dập úng, độ dài cỡ 20cm | E97: 65000
A98: 92 | B98: Salad Lôlô Xanh | C98: Kg | D98: tươi,ko dập úng, độ dài cỡ 20cm | E98: 30000
A99: 93 | B99: Salad Frisse | C99: Kg | D99: Tươi, không dập úng, độ dài cỡ 20cm, Màu xanh nhạt | E99: 50000
... A105: 99 | B105: Tỏi Lột (Galic Peeled) | C105: Kg | D105: Tỏi lột sẵn (Made in China) | E105: 44000
A106: STT | B106: NẤM CÁC LOẠI | C106: ĐVT
A107: 1 | B107: Nấm Bào Ngư Xám (Nở vừa) | C107: Kg | D107: Hàng VN, khô ráo, nguyên tai==>Không xài hàng hàng để lạnh | E107: 60000
A108: 2 | B108: Nấm Đùi Gà Lớn | C108: Kg | D108: Hàng to, thẳng đẹp,1kg từ 9-11 cây | E108: 50000
A109: 3 | B109: Nấm Kim Châm 200gr | C109: Gói | D109: hàng tươi đẹp,không mềm,chảy nước | E109: 12000
A110: 4 | B110: Nấm Linh Chi Nâu 125gr | C110: Gói | D110: hàng tươi đẹp,không mềm,chảy nước | E110: 10000
A111: 5 | B111: Nấm Linh Chi Trắng 125gr | C111: Gói | D111: hàng tươi đẹp,không mềm,chảy nước | E111: 10000
A112: 6 | B112: Nấm Rơm | C112: Kg | D112: Hàng đẹp, chưa nở, khô ráo | E112: 110000
A113: STT | B113: BÚN CÁC LOẠI | C113: ĐVT
...
